Return Code: 0
Stdout: Exception in main loop: invalid literal for int() with base 10: b'value1'

Stderr: Exception in thread Thread-1 (worker):
Exception in thread Thread-2 (worker):
Exception in thread Thread-3 (worker):
Exception in thread Thread-4 (worker):
Exception in thread Thread-5 (worker):
Exception in thread Thread-6 (worker):
Exception in thread Thread-7 (worker):
Exception in thread Thread-8 (worker):
Exception in thread Thread-9 (worker):
Exception in thread Thread-10 (worker):
Exception in thread Thread-11 (worker):
Exception in thread Thread-12 (worker):
Exception in thread Thread-13 (worker):
Exception in thread Thread-14 (worker):
Exception in thread Thread-16 (worker):
Exception in thread Thread-18 (worker):
Exception in thread Thread-17 (worker):
Exception in thread Thread-15 (worker):
Exception in thread Thread-19 (worker):
Exception in thread Thread-20 (worker):
Exception in thread Thread-21 (worker):
Exception in thread Thread-22 (worker):
Traceback (most recent call last):
Exception in thread Thread-23 (worker):
Traceback (most recent call last):
  File "/home/mrigankp/fuzz4py/cpython/Lib/dbm/sqlite3.py", line 79, in _execute
    return closing(self._cx.execute(*args, **kwargs))
                   ~~~~~~~~~~~~~~~~^^^^^^^^^^^^^^^^^
Exception in thread Thread-24 (worker):
Traceback (most recent call last):
Traceback (most recent call last):
Exception in thread Thread-26 (worker):
Traceback (most recent call last):
Traceback (most recent call last):
Exception in thread Thread-27 (worker):
Traceback (most recent call last):
Traceback (most recent call last):
Traceback (most recent call last):
  File "/home/mrigankp/fuzz4py/cpython/Lib/dbm/sqlite3.py", line 79, in _execute
    return closing(self._cx.execute(*args, **kwargs))
                   ~~~~~~~~~~~~~~~~^^^^^^^^^^^^^^^^^
Traceback (most recent call last):
  File "/home/mrigankp/fuzz4py/cpython/Lib/dbm/sqlite3.py", line 79, in _execute
    return closing(self._cx.execute(*args, **kwargs))
                   ~~~~~~~~~~~~~~~~^^^^^^^^^^^^^^^^^
Traceback (most recent call last):
Traceback (most recent call last):
Traceback (most recent call last):
Traceback (most recent call last):
Traceback (most recent call last):
Traceback (most recent call last):
  File "/home/mrigankp/fuzz4py/cpython/Lib/dbm/sqlite3.py", line 79, in _execute
    return closing(self._cx.execute(*args, **kwargs))
                   ~~~~~~~~~~~~~~~~^^^^^^^^^^^^^^^^^
  File "/home/mrigankp/fuzz4py/cpython/Lib/dbm/sqlite3.py", line 79, in _execute
    return closing(self._cx.execute(*args, **kwargs))
                   ~~~~~~~~~~~~~~~~^^^^^^^^^^^^^^^^^
Traceback (most recent call last):
Traceback (most recent call last):
Exception in thread Thread-32 (worker):
Exception in thread Thread-28 (worker):
Exception in thread Thread-25 (worker):
Exception in thread Thread-33 (worker):
sqlite3.ProgrammingError: SQLite objects created in a thread can only be used in that same thread. The object was created in thread id 130381227054912 and this is thread id 130381070206528.
  File "/home/mrigankp/fuzz4py/cpython/Lib/dbm/sqlite3.py", line 79, in _execute
    return closing(self._cx.execute(*args, **kwargs))
                   ~~~~~~~~~~~~~~~~^^^^^^^^^^^^^^^^^
Exception in thread Thread-34 (worker):
Traceback (most recent call last):
Traceback (most recent call last):
Exception in thread Thread-35 (worker):
  File "/home/mrigankp/fuzz4py/cpython/Lib/dbm/sqlite3.py", line 79, in _execute
    return closing(self._cx.execute(*args, **kwargs))
                   ~~~~~~~~~~~~~~~~^^^^^^^^^^^^^^^^^
Exception in thread Thread-36 (worker):
Traceback (most recent call last):
Exception in thread Thread-30 (worker):
Exception in thread Thread-37 (worker):
sqlite3.ProgrammingError: SQLite objects created in a thread can only be used in that same thread. The object was created in thread id 130381227054912 and this is thread id 130381091178048.
sqlite3.ProgrammingError: SQLite objects created in a thread can only be used in that same thread. The object was created in thread id 130381227054912 and this is thread id 130380709496384.
  File "/home/mrigankp/fuzz4py/cpython/Lib/dbm/sqlite3.py", line 79, in _execute
    return closing(self._cx.execute(*args, **kwargs))
                   ~~~~~~~~~~~~~~~~^^^^^^^^^^^^^^^^^
Traceback (most recent call last):
  File "/home/mrigankp/fuzz4py/cpython/Lib/dbm/sqlite3.py", line 79, in _execute
    return closing(self._cx.execute(*args, **kwargs))
                   ~~~~~~~~~~~~~~~~^^^^^^^^^^^^^^^^^
Exception in thread Thread-39 (worker):
Traceback (most recent call last):
Traceback (most recent call last):
sqlite3.ProgrammingError: SQLite objects created in a thread can only be used in that same thread. The object was created in thread id 130381227054912 and this is thread id 130380508169792.
Exception in thread Thread-41 (worker):
Exception in thread Thread-29 (worker):
Exception in thread Thread-42 (worker):
sqlite3.ProgrammingError: SQLite objects created in a thread can only be used in that same thread. The object was created in thread id 130381227054912 and this is thread id 130381080692288.
  File "/home/mrigankp/fuzz4py/cpython/Lib/dbm/sqlite3.py", line 79, in _execute
    return closing(self._cx.execute(*args, **kwargs))
                   ~~~~~~~~~~~~~~~~^^^^^^^^^^^^^^^^^
Traceback (most recent call last):
  File "/home/mrigankp/fuzz4py/cpython/Lib/dbm/sqlite3.py", line 79, in _execute
    return closing(self._cx.execute(*args, **kwargs))
                   ~~~~~~~~~~~~~~~~^^^^^^^^^^^^^^^^^
Traceback (most recent call last):
sqlite3.ProgrammingError: SQLite objects created in a thread can only be used in that same thread. The object was created in thread id 130381227054912 and this is thread id 130380910822976.
  File "/home/mrigankp/fuzz4py/cpython/Lib/dbm/sqlite3.py", line 79, in _execute
    return closing(self._cx.execute(*args, **kwargs))
                   ~~~~~~~~~~~~~~~~^^^^^^^^^^^^^^^^^
  File "/home/mrigankp/fuzz4py/cpython/Lib/dbm/sqlite3.py", line 79, in _execute
    return closing(self._cx.execute(*args, **kwargs))
                   ~~~~~~~~~~~~~~~~^^^^^^^^^^^^^^^^^
Exception in thread Thread-46 (worker):
  File "/home/mrigankp/fuzz4py/cpython/Lib/dbm/sqlite3.py", line 79, in _execute
    return closing(self._cx.execute(*args, **kwargs))
                   ~~~~~~~~~~~~~~~~^^^^^^^^^^^^^^^^^
Exception in thread Thread-47 (worker):
Exception in thread Thread-48 (worker):

During handling of the above exception, another exception occurred:


During handling of the above exception, another exception occurred:

Exception in thread Thread-49 (worker):
sqlite3.ProgrammingError: SQLite objects created in a thread can only be used in that same thread. The object was created in thread id 130381227054912 and this is thread id 130380699010624.
  File "/home/mrigankp/fuzz4py/cpython/Lib/dbm/sqlite3.py", line 79, in _execute
    return closing(self._cx.execute(*args, **kwargs))
                   ~~~~~~~~~~~~~~~~^^^^^^^^^^^^^^^^^
  File "/home/mrigankp/fuzz4py/cpython/Lib/dbm/sqlite3.py", line 79, in _execute
    return closing(self._cx.execute(*args, **kwargs))
                   ~~~~~~~~~~~~~~~~^^^^^^^^^^^^^^^^^
sqlite3.ProgrammingError: SQLite objects created in a thread can only be used in that same thread. The object was created in thread id 130381227054912 and this is thread id 130381101663808.
  File "/home/mrigankp/fuzz4py/cpython/Lib/dbm/sqlite3.py", line 79, in _execute
    return closing(self._cx.execute(*args, **kwargs))
                   ~~~~~~~~~~~~~~~~^^^^^^^^^^^^^^^^^
Exception in thread Thread-40 (worker):
  File "/home/mrigankp/fuzz4py/cpython/Lib/dbm/sqlite3.py", line 79, in _execute
    return closing(self._cx.execute(*args, **kwargs))
                   ~~~~~~~~~~~~~~~~^^^^^^^^^^^^^^^^^

During handling of the above exception, another exception occurred:

Exception in thread Thread-52 (worker):
Traceback (most recent call last):
Traceback (most recent call last):

During handling of the above exception, another exception occurred:

Exception in thread Thread-54 (worker):
  File "/home/mrigankp/fuzz4py/cpython/Lib/dbm/sqlite3.py", line 79, in _execute
    return closing(self._cx.execute(*args, **kwargs))
                   ~~~~~~~~~~~~~~~~^^^^^^^^^^^^^^^^^
Exception in thread Thread-44 (worker):
Exception in thread Thread-55 (worker):
sqlite3.ProgrammingError: SQLite objects created in a thread can only be used in that same thread. The object was created in thread id 130381227054912 and this is thread id 130380688524864.
  File "/home/mrigankp/fuzz4py/cpython/Lib/dbm/sqlite3.py", line 79, in _execute
    return closing(self._cx.execute(*args, **kwargs))
                   ~~~~~~~~~~~~~~~~^^^^^^^^^^^^^^^^^

During handling of the above exception, another exception occurred:

Exception in thread Thread-45 (worker):
Traceback (most recent call last):
  File "/home/mrigankp/fuzz4py/cpython/Lib/dbm/sqlite3.py", line 79, in _execute
    return closing(self._cx.execute(*args, **kwargs))
                   ~~~~~~~~~~~~~~~~^^^^^^^^^^^^^^^^^
Exception in thread Thread-57 (worker):
sqlite3.ProgrammingError: SQLite objects created in a thread can only be used in that same thread. The object was created in thread id 130381227054912 and this is thread id 130380879365696.
  File "/home/mrigankp/fuzz4py/cpython/Lib/dbm/sqlite3.py", line 79, in _execute
    return closing(self._cx.execute(*args, **kwargs))
                   ~~~~~~~~~~~~~~~~^^^^^^^^^^^^^^^^^
Exception in thread Thread-31 (worker):
Traceback (most recent call last):
Traceback (most recent call last):
Traceback (most recent call last):
Exception in thread Thread-60 (worker):

During handling of the above exception, another exception occurred:

Exception in thread Thread-50 (worker):
Exception in thread Thread-61 (worker):
sqlite3.ProgrammingError: SQLite objects created in a thread can only be used in that same thread. The object was created in thread id 130381227054912 and this is thread id 130381202327104.

During handling of the above exception, another exception occurred:

Exception in thread Thread-51 (worker):
Traceback (most recent call last):
sqlite3.ProgrammingError: SQLite objects created in a thread can only be used in that same thread. The object was created in thread id 130381227054912 and this is thread id 130381191841344.
Traceback (most recent call last):
Exception in thread Thread-53 (worker):
  File "/home/mrigankp/fuzz4py/cpython/Lib/dbm/sqlite3.py", line 79, in _execute
    return closing(self._cx.execute(*args, **kwargs))
                   ~~~~~~~~~~~~~~~~^^^^^^^^^^^^^^^^^
Exception in thread Thread-43 (worker):
Traceback (most recent call last):
Traceback (most recent call last):
Traceback (most recent call last):
sqlite3.ProgrammingError: SQLite objects created in a thread can only be used in that same thread. The object was created in thread id 130381227054912 and this is thread id 130381112149568.
  File "/home/mrigankp/fuzz4py/cpython/Lib/dbm/sqlite3.py", line 79, in _execute
    return closing(self._cx.execute(*args, **kwargs))
                   ~~~~~~~~~~~~~~~~^^^^^^^^^^^^^^^^^
Exception in thread Thread-66 (worker):
Traceback (most recent call last):
Traceback (most recent call last):

During handling of the above exception, another exception occurred:

sqlite3.ProgrammingError: SQLite objects created in a thread can only be used in that same thread. The object was created in thread id 130381227054912 and this is thread id 130380889851456.
Exception in thread Thread-56 (worker):
sqlite3.ProgrammingError: SQLite objects created in a thread can only be used in that same thread. The object was created in thread id 130381227054912 and this is thread id 130380657067584.
  File "/home/mrigankp/fuzz4py/cpython/Lib/dbm/sqlite3.py", line 79, in _execute
    return closing(self._cx.execute(*args, **kwargs))
                   ~~~~~~~~~~~~~~~~^^^^^^^^^^^^^^^^^
Traceback (most recent call last):
sqlite3.ProgrammingError: SQLite objects created in a thread can only be used in that same thread. The object was created in thread id 130381227054912 and this is thread id 130380868879936.
Exception in thread Thread-70 (worker):

During handling of the above exception, another exception occurred:

sqlite3.ProgrammingError: SQLite objects created in a thread can only be used in that same thread. The object was created in thread id 130381227054912 and this is thread id 130380678039104.
Traceback (most recent call last):
Traceback (most recent call last):
Exception in thread Thread-72 (worker):
  File "/home/mrigankp/fuzz4py/cpython/Lib/threading.py", line 1041, in _bootstrap_inner
    self.run()
    ~~~~~~~~^^
  File "/home/mrigankp/fuzz4py/cpython/Lib/dbm/sqlite3.py", line 79, in _execute
    return closing(self._cx.execute(*args, **kwargs))
                   ~~~~~~~~~~~~~~~~^^^^^^^^^^^^^^^^^
Exception in thread Thread-73 (worker):
Traceback (most recent call last):
Traceback (most recent call last):
Exception in thread Thread-74 (worker):
  File "/home/mrigankp/fuzz4py/cpython/Lib/dbm/sqlite3.py", line 79, in _execute
    return closing(self._cx.execute(*args, **kwargs))
                   ~~~~~~~~~~~~~~~~^^^^^^^^^^^^^^^^^
Traceback (most recent call last):
Exception in thread Thread-62 (worker):
Traceback (most recent call last):
sqlite3.ProgrammingError: SQLite objects created in a thread can only be used in that same thread. The object was created in thread id 130381227054912 and this is thread id 130380296357440.

During handling of the above exception, another exception occurred:

Traceback (most recent call last):
Traceback (most recent call last):

During handling of the above exception, another exception occurred:

  File "/home/mrigankp/fuzz4py/cpython/Lib/dbm/sqlite3.py", line 79, in _execute
    return closing(self._cx.execute(*args, **kwargs))
                   ~~~~~~~~~~~~~~~~^^^^^^^^^^^^^^^^^
Exception in thread Thread-80 (worker):
sqlite3.ProgrammingError: SQLite objects created in a thread can only be used in that same thread. The object was created in thread id 130381227054912 and this is thread id 130380105516608.
Traceback (most recent call last):
Exception in thread Thread-81 (worker):
Exception in thread Thread-64 (worker):
  File "/home/mrigankp/fuzz4py/cpython/Lib/dbm/sqlite3.py", line 79, in _execute
    return closing(self._cx.execute(*args, **kwargs))
                   ~~~~~~~~~~~~~~~~^^^^^^^^^^^^^^^^^
Exception in thread Thread-65 (worker):
sqlite3.ProgrammingError: SQLite objects created in a thread can only be used in that same thread. The object was created in thread id 130381227054912 and this is thread id 130380900337216.
Exception in thread Thread-83 (worker):
sqlite3.ProgrammingError: SQLite objects created in a thread can only be used in that same thread. The object was created in thread id 130381227054912 and this is thread id 130380095030848.
Traceback (most recent call last):
Exception in thread Thread-84 (worker):
Exception in thread Thread-67 (worker):
Exception in thread Thread-85 (worker):
Traceback (most recent call last):
Exception in thread Thread-68 (worker):
Traceback (most recent call last):
sqlite3.ProgrammingError: SQLite objects created in a thread can only be used in that same thread. The object was created in thread id 130381227054912 and this is thread id 130380858394176.
Traceback (most recent call last):
Exception in thread Thread-88 (worker):
Exception in thread Thread-69 (worker):
Traceback (most recent call last):
Exception in thread Thread-89 (worker):
Exception in thread Thread-58 (worker):
Traceback (most recent call last):
Traceback (most recent call last):

During handling of the above exception, another exception occurred:

Exception in thread Thread-71 (worker):
  File "/home/mrigankp/fuzz4py/cpython/Lib/dbm/sqlite3.py", line 79, in _execute
    return closing(self._cx.execute(*args, **kwargs))
                   ~~~~~~~~~~~~~~~~^^^^^^^^^^^^^^^^^
Exception in thread Thread-59 (worker):
Exception in thread Thread-93 (worker):
Traceback (most recent call last):
  File "/home/mrigankp/fuzz4py/cpython/Lib/threading.py", line 1041, in _bootstrap_inner
    self.run()
    ~~~~~~~~^^
sqlite3.ProgrammingError: SQLite objects created in a thread can only be used in that same thread. The object was created in thread id 130381227054912 and this is thread id 130379681891904.
  File "/home/mrigankp/fuzz4py/cpython/Lib/dbm/sqlite3.py", line 79, in _execute
    return closing(self._cx.execute(*args, **kwargs))
                   ~~~~~~~~~~~~~~~~^^^^^^^^^^^^^^^^^
Exception in thread Thread-96 (worker):
Exception in thread Thread-97 (worker):
Traceback (most recent call last):
Traceback (most recent call last):

During handling of the above exception, another exception occurred:

Exception in thread Thread-75 (worker):
Exception in thread Thread-99 (worker):
Exception in thread Thread-76 (worker):
Exception in thread Thread-100 (worker):

During handling of the above exception, another exception occurred:

Traceback (most recent call last):
Exception in thread Thread-78 (worker):
Exception in thread Thread-79 (worker):
Traceback (most recent call last):
sqlite3.ProgrammingError: SQLite objects created in a thread can only be used in that same thread. The object was created in thread id 130381227054912 and this is thread id 130380476712512.
sqlite3.ProgrammingError: SQLite objects created in a thread can only be used in that same thread. The object was created in thread id 130381227054912 and this is thread id 130380466226752.

During handling of the above exception, another exception occurred:

Traceback (most recent call last):
  File "/home/mrigankp/fuzz4py/cpython/Lib/dbm/sqlite3.py", line 79, in _execute
    return closing(self._cx.execute(*args, **kwargs))
                   ~~~~~~~~~~~~~~~~^^^^^^^^^^^^^^^^^
Traceback (most recent call last):
Exception in thread Thread-82 (worker):
Traceback (most recent call last):
Traceback (most recent call last):
  File "/home/mrigankp/fuzz4py/cpython/Lib/dbm/sqlite3.py", line 79, in _execute
    return closing(self._cx.execute(*args, **kwargs))
                   ~~~~~~~~~~~~~~~~^^^^^^^^^^^^^^^^^
Traceback (most recent call last):
Traceback (most recent call last):
  File "/home/mrigankp/fuzz4py/cpython/Lib/dbm/sqlite3.py", line 79, in _execute
    return closing(self._cx.execute(*args, **kwargs))
                   ~~~~~~~~~~~~~~~~^^^^^^^^^^^^^^^^^
sqlite3.ProgrammingError: SQLite objects created in a thread can only be used in that same thread. The object was created in thread id 130381227054912 and this is thread id 130379851761216.
Traceback (most recent call last):
Traceback (most recent call last):
Exception in thread Thread-86 (worker):
Traceback (most recent call last):

During handling of the above exception, another exception occurred:

  File "/home/mrigankp/fuzz4py/cpython/Lib/threading.py", line 1041, in _bootstrap_inner
    self.run()
    ~~~~~~~~^^
sqlite3.ProgrammingError: SQLite objects created in a thread can only be used in that same thread. The object was created in thread id 130381227054912 and this is thread id 130380074059328.

During handling of the above exception, another exception occurred:

Traceback (most recent call last):
  File "/home/mrigankp/fuzz4py/cpython/Lib/dbm/sqlite3.py", line 79, in _execute
    return closing(self._cx.execute(*args, **kwargs))
                   ~~~~~~~~~~~~~~~~^^^^^^^^^^^^^^^^^
Traceback (most recent call last):
Traceback (most recent call last):
Traceback (most recent call last):
  File "/home/mrigankp/fuzz4py/cpython/Lib/dbm/sqlite3.py", line 79, in _execute
    return closing(self._cx.execute(*args, **kwargs))
                   ~~~~~~~~~~~~~~~~^^^^^^^^^^^^^^^^^
Traceback (most recent call last):
Exception in thread Thread-92 (worker):
Exception in thread Thread-38 (worker):
Exception in thread Thread-94 (worker):
Traceback (most recent call last):
  File "/home/mrigankp/fuzz4py/cpython/Lib/threading.py", line 992, in run
    self._target(*self._args, **self._kwargs)
    ~~~~~~~~~~~~^^^^^^^^^^^^^^^^^^^^^^^^^^^^^
Traceback (most recent call last):
Exception in thread Thread-95 (worker):
sqlite3.ProgrammingError: SQLite objects created in a thread can only be used in that same thread. The object was created in thread id 130381227054912 and this is thread id 130380306843200.
Traceback (most recent call last):
Traceback (most recent call last):
  File "/home/mrigankp/fuzz4py/cpython/Lib/dbm/sqlite3.py", line 79, in _execute
    return closing(self._cx.execute(*args, **kwargs))
                   ~~~~~~~~~~~~~~~~^^^^^^^^^^^^^^^^^
Traceback (most recent call last):
  File "/home/mrigankp/fuzz4py/cpython/Lib/dbm/sqlite3.py", line 79, in _execute
    return closing(self._cx.execute(*args, **kwargs))
                   ~~~~~~~~~~~~~~~~^^^^^^^^^^^^^^^^^
Traceback (most recent call last):
Exception in thread Thread-77 (worker):
  File "/home/mrigankp/fuzz4py/cpython/Lib/dbm/sqlite3.py", line 79, in _execute
    return closing(self._cx.execute(*args, **kwargs))
                   ~~~~~~~~~~~~~~~~^^^^^^^^^^^^^^^^^
Traceback (most recent call last):
Traceback (most recent call last):
  File "/home/mrigankp/fuzz4py/cpython/Lib/dbm/sqlite3.py", line 79, in _execute
    return closing(self._cx.execute(*args, **kwargs))
                   ~~~~~~~~~~~~~~~~^^^^^^^^^^^^^^^^^
  File "/home/mrigankp/fuzz4py/cpython/Lib/dbm/sqlite3.py", line 79, in _execute
    return closing(self._cx.execute(*args, **kwargs))
                   ~~~~~~~~~~~~~~~~^^^^^^^^^^^^^^^^^
Traceback (most recent call last):
Traceback (most recent call last):
  File "/home/mrigankp/fuzz4py/cpython/Lib/threading.py", line 1041, in _bootstrap_inner
    self.run()
    ~~~~~~~~^^
  File "/home/mrigankp/fuzz4py/cpython/Lib/dbm/sqlite3.py", line 79, in _execute
    return closing(self._cx.execute(*args, **kwargs))
                   ~~~~~~~~~~~~~~~~^^^^^^^^^^^^^^^^^
Traceback (most recent call last):
  File "/home/mrigankp/fuzz4py/cpython/Lib/dbm/sqlite3.py", line 79, in _execute
    return closing(self._cx.execute(*args, **kwargs))
                   ~~~~~~~~~~~~~~~~^^^^^^^^^^^^^^^^^
sqlite3.ProgrammingError: SQLite objects created in a thread can only be used in that same thread. The object was created in thread id 130381227054912 and this is thread id 130379491051072.
sqlite3.ProgrammingError: SQLite objects created in a thread can only be used in that same thread. The object was created in thread id 130381227054912 and this is thread id 130379872732736.

During handling of the above exception, another exception occurred:


During handling of the above exception, another exception occurred:

Traceback (most recent call last):
Traceback (most recent call last):
  File "/home/mrigankp/fuzz4py/cpython/Lib/dbm/sqlite3.py", line 79, in _execute
    return closing(self._cx.execute(*args, **kwargs))
                   ~~~~~~~~~~~~~~~~^^^^^^^^^^^^^^^^^
  File "/home/mrigankp/fuzz4py/cpython/Lib/dbm/sqlite3.py", line 79, in _execute
    return closing(self._cx.execute(*args, **kwargs))
                   ~~~~~~~~~~~~~~~~^^^^^^^^^^^^^^^^^
Traceback (most recent call last):

During handling of the above exception, another exception occurred:

  File "/home/mrigankp/fuzz4py/cpython/Lib/dbm/sqlite3.py", line 79, in _execute
    return closing(self._cx.execute(*args, **kwargs))
                   ~~~~~~~~~~~~~~~~^^^^^^^^^^^^^^^^^
  File "/home/mrigankp/fuzz4py/cpython/Lib/dbm/sqlite3.py", line 79, in _execute
    return closing(self._cx.execute(*args, **kwargs))
                   ~~~~~~~~~~~~~~~~^^^^^^^^^^^^^^^^^

During handling of the above exception, another exception occurred:

Traceback (most recent call last):
  File "/home/mrigankp/fuzz4py/cpython/Lib/dbm/sqlite3.py", line 79, in _execute
    return closing(self._cx.execute(*args, **kwargs))
                   ~~~~~~~~~~~~~~~~^^^^^^^^^^^^^^^^^
Traceback (most recent call last):

During handling of the above exception, another exception occurred:

Traceback (most recent call last):
  File "/home/mrigankp/fuzz4py/cpython/Lib/dbm/sqlite3.py", line 79, in _execute
    return closing(self._cx.execute(*args, **kwargs))
                   ~~~~~~~~~~~~~~~~^^^^^^^^^^^^^^^^^
sqlite3.ProgrammingError: SQLite objects created in a thread can only be used in that same thread. The object was created in thread id 130381227054912 and this is thread id 130379692377664.
Exception in thread Thread-91 (worker):
  File "/home/mrigankp/fuzz4py/cpython/Lib/threading.py", line 1041, in _bootstrap_inner
    self.run()
    ~~~~~~~~^^
  File "/home/mrigankp/fuzz4py/cpython/Lib/dbm/sqlite3.py", line 79, in _execute
    return closing(self._cx.execute(*args, **kwargs))
                   ~~~~~~~~~~~~~~~~^^^^^^^^^^^^^^^^^
sqlite3.ProgrammingError: SQLite objects created in a thread can only be used in that same thread. The object was created in thread id 130381227054912 and this is thread id 130380063573568.
Traceback (most recent call last):
  File "/home/mrigankp/fuzz4py/cpython/Lib/threading.py", line 992, in run
    self._target(*self._args, **self._kwargs)
    ~~~~~~~~~~~~^^^^^^^^^^^^^^^^^^^^^^^^^^^^^
Traceback (most recent call last):
  File "/home/mrigankp/fuzz4py/cpython/Lib/dbm/sqlite3.py", line 79, in _execute
    return closing(self._cx.execute(*args, **kwargs))
                   ~~~~~~~~~~~~~~~~^^^^^^^^^^^^^^^^^
Traceback (most recent call last):
Traceback (most recent call last):

During handling of the above exception, another exception occurred:

sqlite3.ProgrammingError: SQLite objects created in a thread can only be used in that same thread. The object was created in thread id 130381227054912 and this is thread id 130379660920384.
Traceback (most recent call last):

During handling of the above exception, another exception occurred:

Exception in thread Thread-98 (worker):
sqlite3.ProgrammingError: SQLite objects created in a thread can only be used in that same thread. The object was created in thread id 130381227054912 and this is thread id 130380497684032.

During handling of the above exception, another exception occurred:

sqlite3.ProgrammingError: SQLite objects created in a thread can only be used in that same thread. The object was created in thread id 130381227054912 and this is thread id 130378845128256.
sqlite3.ProgrammingError: SQLite objects created in a thread can only be used in that same thread. The object was created in thread id 130381227054912 and this is thread id 130379650434624.
Traceback (most recent call last):
Traceback (most recent call last):
Traceback (most recent call last):
  File "/home/mrigankp/fuzz4py/cpython/Lib/dbm/sqlite3.py", line 79, in _execute
    return closing(self._cx.execute(*args, **kwargs))
                   ~~~~~~~~~~~~~~~~^^^^^^^^^^^^^^^^^
  File "/home/mrigankp/fuzz4py/cpython/Lib/threading.py", line 1041, in _bootstrap_inner
    self.run()
    ~~~~~~~~^^
Exception in thread Thread-63 (worker):
  File "/home/mrigankp/fuzz4py/cpython/Lib/threading.py", line 1041, in _bootstrap_inner
    self.run()
    ~~~~~~~~^^
  File "/home/mrigankp/fuzz4py/cpython/Lib/threading.py", line 992, in run
    self._target(*self._args, **self._kwargs)
    ~~~~~~~~~~~~^^^^^^^^^^^^^^^^^^^^^^^^^^^^^

During handling of the above exception, another exception occurred:

Traceback (most recent call last):
  File "/home/mrigankp/fuzz4py/cpython/Lib/dbm/sqlite3.py", line 79, in _execute
    return closing(self._cx.execute(*args, **kwargs))
                   ~~~~~~~~~~~~~~~~^^^^^^^^^^^^^^^^^
sqlite3.ProgrammingError: SQLite objects created in a thread can only be used in that same thread. The object was created in thread id 130381227054912 and this is thread id 130379862246976.

During handling of the above exception, another exception occurred:

  File "/home/mrigankp/fuzz4py/cpython/Lib/dbm/sqlite3.py", line 79, in _execute
    return closing(self._cx.execute(*args, **kwargs))
                   ~~~~~~~~~~~~~~~~^^^^^^^^^^^^^^^^^
  File "/home/mrigankp/fuzz4py/cpython/Lib/dbm/sqlite3.py", line 79, in _execute
    return closing(self._cx.execute(*args, **kwargs))
                   ~~~~~~~~~~~~~~~~^^^^^^^^^^^^^^^^^
  File "/home/mrigankp/fuzz4py/cpython/Lib/dbm/sqlite3.py", line 79, in _execute
    return closing(self._cx.execute(*args, **kwargs))
                   ~~~~~~~~~~~~~~~~^^^^^^^^^^^^^^^^^
Traceback (most recent call last):
  File "/home/mrigankp/fuzz4py/cpython/Lib/dbm/sqlite3.py", line 79, in _execute
    return closing(self._cx.execute(*args, **kwargs))
                   ~~~~~~~~~~~~~~~~^^^^^^^^^^^^^^^^^
sqlite3.ProgrammingError: SQLite objects created in a thread can only be used in that same thread. The object was created in thread id 130381227054912 and this is thread id 130379470079552.
sqlite3.ProgrammingError: SQLite objects created in a thread can only be used in that same thread. The object was created in thread id 130381227054912 and this is thread id 130381059720768.
  File "/home/mrigankp/fuzz4py/cpython/Lib/threading.py", line 1041, in _bootstrap_inner
    self.run()
    ~~~~~~~~^^
  File "/home/mrigankp/fuzz4py/cpython/Lib/threading.py", line 992, in run
    self._target(*self._args, **self._kwargs)
    ~~~~~~~~~~~~^^^^^^^^^^^^^^^^^^^^^^^^^^^^^
Traceback (most recent call last):
Exception in thread Thread-87 (worker):
sqlite3.ProgrammingError: SQLite objects created in a thread can only be used in that same thread. The object was created in thread id 130381227054912 and this is thread id 130380084545088.
Traceback (most recent call last):
  File "/home/mrigankp/fuzz4py/cpython/Lib/dbm/sqlite3.py", line 79, in _execute
    return closing(self._cx.execute(*args, **kwargs))
                   ~~~~~~~~~~~~~~~~^^^^^^^^^^^^^^^^^
  File "/home/mrigankp/fuzz4py/cpython/Lib/dbm/sqlite3.py", line 79, in _execute
    return closing(self._cx.execute(*args, **kwargs))
                   ~~~~~~~~~~~~~~~~^^^^^^^^^^^^^^^^^
  File "/home/mrigankp/fuzz4py/cpython/Lib/dbm/sqlite3.py", line 79, in _execute
    return closing(self._cx.execute(*args, **kwargs))
                   ~~~~~~~~~~~~~~~~^^^^^^^^^^^^^^^^^
Exception in thread Thread-90 (worker):
sqlite3.ProgrammingError: SQLite objects created in a thread can only be used in that same thread. The object was created in thread id 130381227054912 and this is thread id 130380667553344.
  File "/home/mrigankp/fuzz4py/cpython/Lib/dbm/sqlite3.py", line 79, in _execute
    return closing(self._cx.execute(*args, **kwargs))
                   ~~~~~~~~~~~~~~~~^^^^^^^^^^^^^^^^^

During handling of the above exception, another exception occurred:

  File "/home/mrigankp/fuzz4py/cpython/Lib/threading.py", line 992, in run
    self._target(*self._args, **self._kwargs)
    ~~~~~~~~~~~~^^^^^^^^^^^^^^^^^^^^^^^^^^^^^
Traceback (most recent call last):
Traceback (most recent call last):
  File "/home/mrigankp/fuzz4py/cpython/Lib/threading.py", line 1041, in _bootstrap_inner
    self.run()
    ~~~~~~~~^^
  File "/home/mrigankp/fuzz4py/fuzz4py/inputs/790.py", line 15, in worker
    db[str(data)] = data * 2
    ~~^^^^^^^^^^^
  File "/home/mrigankp/fuzz4py/cpython/Lib/dbm/sqlite3.py", line 79, in _execute
    return closing(self._cx.execute(*args, **kwargs))
                   ~~~~~~~~~~~~~~~~^^^^^^^^^^^^^^^^^
sqlite3.ProgrammingError: SQLite objects created in a thread can only be used in that same thread. The object was created in thread id 130381227054912 and this is thread id 130378866099776.
  File "/home/mrigankp/fuzz4py/cpython/Lib/dbm/sqlite3.py", line 79, in _execute
    return closing(self._cx.execute(*args, **kwargs))
                   ~~~~~~~~~~~~~~~~^^^^^^^^^^^^^^^^^
Traceback (most recent call last):
Traceback (most recent call last):
  File "/home/mrigankp/fuzz4py/cpython/Lib/dbm/sqlite3.py", line 79, in _execute
    return closing(self._cx.execute(*args, **kwargs))
                   ~~~~~~~~~~~~~~~~^^^^^^^^^^^^^^^^^
  File "/home/mrigankp/fuzz4py/cpython/Lib/dbm/sqlite3.py", line 79, in _execute
    return closing(self._cx.execute(*args, **kwargs))
                   ~~~~~~~~~~~~~~~~^^^^^^^^^^^^^^^^^
Traceback (most recent call last):
  File "/home/mrigankp/fuzz4py/cpython/Lib/dbm/sqlite3.py", line 79, in _execute
    return closing(self._cx.execute(*args, **kwargs))
                   ~~~~~~~~~~~~~~~~^^^^^^^^^^^^^^^^^
Traceback (most recent call last):

During handling of the above exception, another exception occurred:


During handling of the above exception, another exception occurred:

Traceback (most recent call last):
  File "/home/mrigankp/fuzz4py/cpython/Lib/dbm/sqlite3.py", line 79, in _execute
    return closing(self._cx.execute(*args, **kwargs))
                   ~~~~~~~~~~~~~~~~^^^^^^^^^^^^^^^^^
sqlite3.ProgrammingError: SQLite objects created in a thread can only be used in that same thread. The object was created in thread id 130381227054912 and this is thread id 130379904190016.

During handling of the above exception, another exception occurred:

  File "/home/mrigankp/fuzz4py/cpython/Lib/dbm/sqlite3.py", line 79, in _execute
    return closing(self._cx.execute(*args, **kwargs))
                   ~~~~~~~~~~~~~~~~^^^^^^^^^^^^^^^^^
  File "/home/mrigankp/fuzz4py/cpython/Lib/threading.py", line 992, in run
    self._target(*self._args, **self._kwargs)
    ~~~~~~~~~~~~^^^^^^^^^^^^^^^^^^^^^^^^^^^^^

During handling of the above exception, another exception occurred:

  File "/home/mrigankp/fuzz4py/cpython/Lib/dbm/sqlite3.py", line 79, in _execute
    return closing(self._cx.execute(*args, **kwargs))
                   ~~~~~~~~~~~~~~~~^^^^^^^^^^^^^^^^^
sqlite3.ProgrammingError: SQLite objects created in a thread can only be used in that same thread. The object was created in thread id 130381227054912 and this is thread id 130378654287424.
Traceback (most recent call last):
  File "/home/mrigankp/fuzz4py/cpython/Lib/dbm/sqlite3.py", line 79, in _execute
    return closing(self._cx.execute(*args, **kwargs))
                   ~~~~~~~~~~~~~~~~^^^^^^^^^^^^^^^^^
  File "/home/mrigankp/fuzz4py/cpython/Lib/threading.py", line 1041, in _bootstrap_inner
    self.run()
    ~~~~~~~~^^
sqlite3.ProgrammingError: SQLite objects created in a thread can only be used in that same thread. The object was created in thread id 130381227054912 and this is thread id 130379480565312.
  File "/home/mrigankp/fuzz4py/cpython/Lib/dbm/sqlite3.py", line 79, in _execute
    return closing(self._cx.execute(*args, **kwargs))
                   ~~~~~~~~~~~~~~~~^^^^^^^^^^^^^^^^^

During handling of the above exception, another exception occurred:

sqlite3.ProgrammingError: SQLite objects created in a thread can only be used in that same thread. The object was created in thread id 130381227054912 and this is thread id 130380285871680.
Traceback (most recent call last):
sqlite3.ProgrammingError: SQLite objects created in a thread can only be used in that same thread. The object was created in thread id 130381227054912 and this is thread id 130379088397888.
sqlite3.ProgrammingError: SQLite objects created in a thread can only be used in that same thread. The object was created in thread id 130381227054912 and this is thread id 130379077912128.
  File "/home/mrigankp/fuzz4py/cpython/Lib/threading.py", line 1041, in _bootstrap_inner
    self.run()
    ~~~~~~~~^^
sqlite3.ProgrammingError: SQLite objects created in a thread can only be used in that same thread. The object was created in thread id 130381227054912 and this is thread id 130378473932352.

During handling of the above exception, another exception occurred:


During handling of the above exception, another exception occurred:

  File "/home/mrigankp/fuzz4py/cpython/Lib/dbm/sqlite3.py", line 79, in _execute
    return closing(self._cx.execute(*args, **kwargs))
                   ~~~~~~~~~~~~~~~~^^^^^^^^^^^^^^^^^
sqlite3.ProgrammingError: SQLite objects created in a thread can only be used in that same thread. The object was created in thread id 130381227054912 and this is thread id 130378452960832.

During handling of the above exception, another exception occurred:

Traceback (most recent call last):
  File "/home/mrigankp/fuzz4py/cpython/Lib/threading.py", line 992, in run
    self._target(*self._args, **self._kwargs)
    ~~~~~~~~~~~~^^^^^^^^^^^^^^^^^^^^^^^^^^^^^
  File "/home/mrigankp/fuzz4py/cpython/Lib/threading.py", line 1041, in _bootstrap_inner
    self.run()
    ~~~~~~~~^^
sqlite3.ProgrammingError: SQLite objects created in a thread can only be used in that same thread. The object was created in thread id 130381227054912 and this is thread id 130379702863424.
Traceback (most recent call last):
sqlite3.ProgrammingError: SQLite objects created in a thread can only be used in that same thread. The object was created in thread id 130381227054912 and this is thread id 130378442475072.
  File "/home/mrigankp/fuzz4py/cpython/Lib/threading.py", line 1041, in _bootstrap_inner
    self.run()
    ~~~~~~~~^^
  File "/home/mrigankp/fuzz4py/cpython/Lib/dbm/sqlite3.py", line 79, in _execute
    return closing(self._cx.execute(*args, **kwargs))
                   ~~~~~~~~~~~~~~~~^^^^^^^^^^^^^^^^^
  File "/home/mrigankp/fuzz4py/cpython/Lib/dbm/sqlite3.py", line 79, in _execute
    return closing(self._cx.execute(*args, **kwargs))
                   ~~~~~~~~~~~~~~~~^^^^^^^^^^^^^^^^^
sqlite3.ProgrammingError: SQLite objects created in a thread can only be used in that same thread. The object was created in thread id 130381227054912 and this is thread id 130379671406144.
sqlite3.ProgrammingError: SQLite objects created in a thread can only be used in that same thread. The object was created in thread id 130381227054912 and this is thread id 130379300210240.

During handling of the above exception, another exception occurred:

Traceback (most recent call last):
  File "/home/mrigankp/fuzz4py/cpython/Lib/dbm/sqlite3.py", line 79, in _execute
    return closing(self._cx.execute(*args, **kwargs))
                   ~~~~~~~~~~~~~~~~^^^^^^^^^^^^^^^^^
  File "/home/mrigankp/fuzz4py/cpython/Lib/threading.py", line 992, in run
    self._target(*self._args, **self._kwargs)
    ~~~~~~~~~~~~^^^^^^^^^^^^^^^^^^^^^^^^^^^^^
  File "/home/mrigankp/fuzz4py/fuzz4py/inputs/790.py", line 15, in worker
    db[str(data)] = data * 2
    ~~^^^^^^^^^^^
  File "/home/mrigankp/fuzz4py/cpython/Lib/dbm/sqlite3.py", line 96, in __setitem__
    self._execute(STORE_KV, (key, value))
    ~~~~~~~~~~~~~^^^^^^^^^^^^^^^^^^^^^^^^

During handling of the above exception, another exception occurred:

sqlite3.ProgrammingError: SQLite objects created in a thread can only be used in that same thread. The object was created in thread id 130381227054912 and this is thread id 130378081764928.
  File "/home/mrigankp/fuzz4py/cpython/Lib/threading.py", line 1041, in _bootstrap_inner
    self.run()
    ~~~~~~~~^^
  File "/home/mrigankp/fuzz4py/cpython/Lib/dbm/sqlite3.py", line 79, in _execute
    return closing(self._cx.execute(*args, **kwargs))
                   ~~~~~~~~~~~~~~~~^^^^^^^^^^^^^^^^^
sqlite3.ProgrammingError: SQLite objects created in a thread can only be used in that same thread. The object was created in thread id 130381227054912 and this is thread id 130379268752960.
sqlite3.ProgrammingError: SQLite objects created in a thread can only be used in that same thread. The object was created in thread id 130381227054912 and this is thread id 130378071279168.
sqlite3.ProgrammingError: SQLite objects created in a thread can only be used in that same thread. The object was created in thread id 130381227054912 and this is thread id 130378060793408.
  File "/home/mrigankp/fuzz4py/cpython/Lib/threading.py", line 1041, in _bootstrap_inner
    self.run()
    ~~~~~~~~^^
Traceback (most recent call last):
  File "/home/mrigankp/fuzz4py/cpython/Lib/dbm/sqlite3.py", line 79, in _execute
    return closing(self._cx.execute(*args, **kwargs))
                   ~~~~~~~~~~~~~~~~^^^^^^^^^^^^^^^^^
  File "/home/mrigankp/fuzz4py/cpython/Lib/threading.py", line 1041, in _bootstrap_inner
    self.run()
    ~~~~~~~~^^
  File "/home/mrigankp/fuzz4py/cpython/Lib/dbm/sqlite3.py", line 79, in _execute
    return closing(self._cx.execute(*args, **kwargs))
                   ~~~~~~~~~~~~~~~~^^^^^^^^^^^^^^^^^
sqlite3.ProgrammingError: SQLite objects created in a thread can only be used in that same thread. The object was created in thread id 130381227054912 and this is thread id 130378685744704.
Traceback (most recent call last):
sqlite3.ProgrammingError: SQLite objects created in a thread can only be used in that same thread. The object was created in thread id 130381227054912 and this is thread id 130377890924096.
  File "/home/mrigankp/fuzz4py/fuzz4py/inputs/790.py", line 15, in worker
    db[str(data)] = data * 2
    ~~^^^^^^^^^^^
Traceback (most recent call last):
sqlite3.ProgrammingError: SQLite objects created in a thread can only be used in that same thread. The object was created in thread id 130381227054912 and this is thread id 130379883218496.
  File "/home/mrigankp/fuzz4py/cpython/Lib/threading.py", line 992, in run
    self._target(*self._args, **self._kwargs)
    ~~~~~~~~~~~~^^^^^^^^^^^^^^^^^^^^^^^^^^^^^
Traceback (most recent call last):
  File "/home/mrigankp/fuzz4py/cpython/Lib/threading.py", line 992, in run
    self._target(*self._args, **self._kwargs)
    ~~~~~~~~~~~~^^^^^^^^^^^^^^^^^^^^^^^^^^^^^
sqlite3.ProgrammingError: SQLite objects created in a thread can only be used in that same thread. The object was created in thread id 130381227054912 and this is thread id 130378643801664.
Traceback (most recent call last):
Traceback (most recent call last):
sqlite3.ProgrammingError: SQLite objects created in a thread can only be used in that same thread. The object was created in thread id 130381227054912 and this is thread id 130380455740992.

During handling of the above exception, another exception occurred:


During handling of the above exception, another exception occurred:

  File "/home/mrigankp/fuzz4py/cpython/Lib/threading.py", line 992, in run
    self._target(*self._args, **self._kwargs)
    ~~~~~~~~~~~~^^^^^^^^^^^^^^^^^^^^^^^^^^^^^

During handling of the above exception, another exception occurred:

Traceback (most recent call last):
sqlite3.ProgrammingError: SQLite objects created in a thread can only be used in that same thread. The object was created in thread id 130381227054912 and this is thread id 130378463446592.
  File "/home/mrigankp/fuzz4py/cpython/Lib/threading.py", line 1041, in _bootstrap_inner
    self.run()
    ~~~~~~~~^^
Traceback (most recent call last):
  File "/home/mrigankp/fuzz4py/cpython/Lib/dbm/sqlite3.py", line 79, in _execute
    return closing(self._cx.execute(*args, **kwargs))
                   ~~~~~~~~~~~~~~~~^^^^^^^^^^^^^^^^^
sqlite3.ProgrammingError: SQLite objects created in a thread can only be used in that same thread. The object was created in thread id 130381227054912 and this is thread id 130379449108032.
  File "/home/mrigankp/fuzz4py/fuzz4py/inputs/790.py", line 15, in worker
    db[str(data)] = data * 2
    ~~^^^^^^^^^^^
Traceback (most recent call last):
  File "/home/mrigankp/fuzz4py/cpython/Lib/threading.py", line 992, in run
    self._target(*self._args, **self._kwargs)
    ~~~~~~~~~~~~^^^^^^^^^^^^^^^^^^^^^^^^^^^^^
sqlite3.ProgrammingError: SQLite objects created in a thread can only be used in that same thread. The object was created in thread id 130381227054912 and this is thread id 130380275385920.
Traceback (most recent call last):

During handling of the above exception, another exception occurred:

sqlite3.ProgrammingError: SQLite objects created in a thread can only be used in that same thread. The object was created in thread id 130381227054912 and this is thread id 130378887071296.
sqlite3.ProgrammingError: SQLite objects created in a thread can only be used in that same thread. The object was created in thread id 130381227054912 and this is thread id 130378897557056.

During handling of the above exception, another exception occurred:

  File "/home/mrigankp/fuzz4py/cpython/Lib/dbm/sqlite3.py", line 79, in _execute
    return closing(self._cx.execute(*args, **kwargs))
                   ~~~~~~~~~~~~~~~~^^^^^^^^^^^^^^^^^

During handling of the above exception, another exception occurred:

  File "/home/mrigankp/fuzz4py/cpython/Lib/dbm/sqlite3.py", line 96, in __setitem__
    self._execute(STORE_KV, (key, value))
    ~~~~~~~~~~~~~^^^^^^^^^^^^^^^^^^^^^^^^
  File "/home/mrigankp/fuzz4py/cpython/Lib/dbm/sqlite3.py", line 79, in _execute
    return closing(self._cx.execute(*args, **kwargs))
                   ~~~~~~~~~~~~~~~~^^^^^^^^^^^^^^^^^
  File "/home/mrigankp/fuzz4py/cpython/Lib/dbm/sqlite3.py", line 79, in _execute
    return closing(self._cx.execute(*args, **kwargs))
                   ~~~~~~~~~~~~~~~~^^^^^^^^^^^^^^^^^
sqlite3.ProgrammingError: SQLite objects created in a thread can only be used in that same thread. The object was created in thread id 130381227054912 and this is thread id 130380487198272.
  File "/home/mrigankp/fuzz4py/cpython/Lib/dbm/sqlite3.py", line 79, in _execute
    return closing(self._cx.execute(*args, **kwargs))
                   ~~~~~~~~~~~~~~~~^^^^^^^^^^^^^^^^^

During handling of the above exception, another exception occurred:

sqlite3.ProgrammingError: SQLite objects created in a thread can only be used in that same thread. The object was created in thread id 130381227054912 and this is thread id 130378855614016.
  File "/home/mrigankp/fuzz4py/cpython/Lib/dbm/sqlite3.py", line 79, in _execute
    return closing(self._cx.execute(*args, **kwargs))
                   ~~~~~~~~~~~~~~~~^^^^^^^^^^^^^^^^^
sqlite3.ProgrammingError: SQLite objects created in a thread can only be used in that same thread. The object was created in thread id 130381227054912 and this is thread id 130380254414400.
  File "/home/mrigankp/fuzz4py/cpython/Lib/dbm/sqlite3.py", line 79, in _execute
    return closing(self._cx.execute(*args, **kwargs))
                   ~~~~~~~~~~~~~~~~^^^^^^^^^^^^^^^^^
  File "/home/mrigankp/fuzz4py/cpython/Lib/dbm/sqlite3.py", line 79, in _execute
    return closing(self._cx.execute(*args, **kwargs))
                   ~~~~~~~~~~~~~~~~^^^^^^^^^^^^^^^^^
sqlite3.ProgrammingError: SQLite objects created in a thread can only be used in that same thread. The object was created in thread id 130381227054912 and this is thread id 130378039821888.
Traceback (most recent call last):
sqlite3.ProgrammingError: SQLite objects created in a thread can only be used in that same thread. The object was created in thread id 130381227054912 and this is thread id 130378696230464.
sqlite3.ProgrammingError: SQLite objects created in a thread can only be used in that same thread. The object was created in thread id 130381227054912 and this is thread id 130378675258944.
  File "/home/mrigankp/fuzz4py/cpython/Lib/threading.py", line 1041, in _bootstrap_inner
    self.run()
    ~~~~~~~~^^
Traceback (most recent call last):

During handling of the above exception, another exception occurred:

sqlite3.ProgrammingError: SQLite objects created in a thread can only be used in that same thread. The object was created in thread id 130381227054912 and this is thread id 130379501536832.
Traceback (most recent call last):
  File "/home/mrigankp/fuzz4py/fuzz4py/inputs/790.py", line 15, in worker
    db[str(data)] = data * 2
    ~~^^^^^^^^^^^

During handling of the above exception, another exception occurred:

  File "/home/mrigankp/fuzz4py/cpython/Lib/dbm/sqlite3.py", line 79, in _execute
    return closing(self._cx.execute(*args, **kwargs))
                   ~~~~~~~~~~~~~~~~^^^^^^^^^^^^^^^^^
Traceback (most recent call last):

During handling of the above exception, another exception occurred:

  File "/home/mrigankp/fuzz4py/cpython/Lib/threading.py", line 1041, in _bootstrap_inner
    self.run()
    ~~~~~~~~^^
sqlite3.ProgrammingError: SQLite objects created in a thread can only be used in that same thread. The object was created in thread id 130381227054912 and this is thread id 130378494903872.
  File "/home/mrigankp/fuzz4py/cpython/Lib/threading.py", line 1041, in _bootstrap_inner
    self.run()
    ~~~~~~~~^^

During handling of the above exception, another exception occurred:

  File "/home/mrigankp/fuzz4py/cpython/Lib/threading.py", line 1041, in _bootstrap_inner
    self.run()
    ~~~~~~~~^^
  File "/home/mrigankp/fuzz4py/cpython/Lib/dbm/sqlite3.py", line 79, in _execute
    return closing(self._cx.execute(*args, **kwargs))
                   ~~~~~~~~~~~~~~~~^^^^^^^^^^^^^^^^^
Traceback (most recent call last):
Traceback (most recent call last):
Traceback (most recent call last):
  File "/home/mrigankp/fuzz4py/fuzz4py/inputs/790.py", line 15, in worker
    db[str(data)] = data * 2
    ~~^^^^^^^^^^^

During handling of the above exception, another exception occurred:


During handling of the above exception, another exception occurred:

  File "/home/mrigankp/fuzz4py/cpython/Lib/threading.py", line 1041, in _bootstrap_inner
    self.run()
    ~~~~~~~~^^
  File "/home/mrigankp/fuzz4py/cpython/Lib/threading.py", line 992, in run
    self._target(*self._args, **self._kwargs)
    ~~~~~~~~~~~~^^^^^^^^^^^^^^^^^^^^^^^^^^^^^
sqlite3.ProgrammingError: SQLite objects created in a thread can only be used in that same thread. The object was created in thread id 130381227054912 and this is thread id 130379046454848.

During handling of the above exception, another exception occurred:


During handling of the above exception, another exception occurred:

  File "/home/mrigankp/fuzz4py/cpython/Lib/threading.py", line 1041, in _bootstrap_inner
    self.run()
    ~~~~~~~~^^
  File "/home/mrigankp/fuzz4py/cpython/Lib/threading.py", line 992, in run
    self._target(*self._args, **self._kwargs)
    ~~~~~~~~~~~~^^^^^^^^^^^^^^^^^^^^^^^^^^^^^
Traceback (most recent call last):
  File "/home/mrigankp/fuzz4py/fuzz4py/inputs/790.py", line 15, in worker
    db[str(data)] = data * 2
    ~~^^^^^^^^^^^
  File "/home/mrigankp/fuzz4py/cpython/Lib/dbm/sqlite3.py", line 96, in __setitem__
    self._execute(STORE_KV, (key, value))
    ~~~~~~~~~~~~~^^^^^^^^^^^^^^^^^^^^^^^^
sqlite3.ProgrammingError: SQLite objects created in a thread can only be used in that same thread. The object was created in thread id 130381227054912 and this is thread id 130378251634240.
sqlite3.ProgrammingError: SQLite objects created in a thread can only be used in that same thread. The object was created in thread id 130381227054912 and this is thread id 130378272605760.
sqlite3.ProgrammingError: SQLite objects created in a thread can only be used in that same thread. The object was created in thread id 130381227054912 and this is thread id 130378876585536.
  File "/home/mrigankp/fuzz4py/cpython/Lib/dbm/sqlite3.py", line 79, in _execute
    return closing(self._cx.execute(*args, **kwargs))
                   ~~~~~~~~~~~~~~~~^^^^^^^^^^^^^^^^^
sqlite3.ProgrammingError: SQLite objects created in a thread can only be used in that same thread. The object was created in thread id 130381227054912 and this is thread id 130380264900160.

During handling of the above exception, another exception occurred:


During handling of the above exception, another exception occurred:


During handling of the above exception, another exception occurred:

  File "/home/mrigankp/fuzz4py/cpython/Lib/threading.py", line 992, in run
    self._target(*self._args, **self._kwargs)
    ~~~~~~~~~~~~^^^^^^^^^^^^^^^^^^^^^^^^^^^^^
Traceback (most recent call last):

During handling of the above exception, another exception occurred:


During handling of the above exception, another exception occurred:

Traceback (most recent call last):
sqlite3.ProgrammingError: SQLite objects created in a thread can only be used in that same thread. The object was created in thread id 130381227054912 and this is thread id 130379258267200.
  File "/home/mrigankp/fuzz4py/cpython/Lib/threading.py", line 992, in run
    self._target(*self._args, **self._kwargs)
    ~~~~~~~~~~~~^^^^^^^^^^^^^^^^^^^^^^^^^^^^^
  File "/home/mrigankp/fuzz4py/cpython/Lib/threading.py", line 1041, in _bootstrap_inner
    self.run()
    ~~~~~~~~^^
  File "/home/mrigankp/fuzz4py/cpython/Lib/threading.py", line 992, in run
    self._target(*self._args, **self._kwargs)
    ~~~~~~~~~~~~^^^^^^^^^^^^^^^^^^^^^^^^^^^^^
  File "/home/mrigankp/fuzz4py/fuzz4py/inputs/790.py", line 15, in worker
    db[str(data)] = data * 2
    ~~^^^^^^^^^^^

During handling of the above exception, another exception occurred:

Traceback (most recent call last):
  File "/home/mrigankp/fuzz4py/cpython/Lib/threading.py", line 1041, in _bootstrap_inner
    self.run()
    ~~~~~~~~^^
  File "/home/mrigankp/fuzz4py/cpython/Lib/threading.py", line 1041, in _bootstrap_inner
    self.run()
    ~~~~~~~~^^

During handling of the above exception, another exception occurred:

  File "/home/mrigankp/fuzz4py/cpython/Lib/dbm/sqlite3.py", line 96, in __setitem__
    self._execute(STORE_KV, (key, value))
    ~~~~~~~~~~~~~^^^^^^^^^^^^^^^^^^^^^^^^
  File "/home/mrigankp/fuzz4py/cpython/Lib/threading.py", line 1041, in _bootstrap_inner
    self.run()
    ~~~~~~~~^^
  File "/home/mrigankp/fuzz4py/cpython/Lib/dbm/sqlite3.py", line 79, in _execute
    return closing(self._cx.execute(*args, **kwargs))
                   ~~~~~~~~~~~~~~~~^^^^^^^^^^^^^^^^^
sqlite3.ProgrammingError: SQLite objects created in a thread can only be used in that same thread. The object was created in thread id 130381227054912 and this is thread id 130379098883648.

During handling of the above exception, another exception occurred:

  File "/home/mrigankp/fuzz4py/cpython/Lib/threading.py", line 1041, in _bootstrap_inner
    self.run()
    ~~~~~~~~^^

During handling of the above exception, another exception occurred:

  File "/home/mrigankp/fuzz4py/cpython/Lib/threading.py", line 1041, in _bootstrap_inner
    self.run()
    ~~~~~~~~^^

During handling of the above exception, another exception occurred:

  File "/home/mrigankp/fuzz4py/cpython/Lib/dbm/sqlite3.py", line 79, in _execute
    return closing(self._cx.execute(*args, **kwargs))
                   ~~~~~~~~~~~~~~~~^^^^^^^^^^^^^^^^^
Traceback (most recent call last):
  File "/home/mrigankp/fuzz4py/cpython/Lib/dbm/sqlite3.py", line 79, in _execute
    return closing(self._cx.execute(*args, **kwargs))
                   ~~~~~~~~~~~~~~~~^^^^^^^^^^^^^^^^^
  File "/home/mrigankp/fuzz4py/fuzz4py/inputs/790.py", line 15, in worker
    db[str(data)] = data * 2
    ~~^^^^^^^^^^^
  File "/home/mrigankp/fuzz4py/cpython/Lib/threading.py", line 1041, in _bootstrap_inner
    self.run()
    ~~~~~~~~^^
  File "/home/mrigankp/fuzz4py/cpython/Lib/dbm/sqlite3.py", line 79, in _execute
    return closing(self._cx.execute(*args, **kwargs))
                   ~~~~~~~~~~~~~~~~^^^^^^^^^^^^^^^^^
sqlite3.ProgrammingError: SQLite objects created in a thread can only be used in that same thread. The object was created in thread id 130381227054912 and this is thread id 130379056940608.
  File "/home/mrigankp/fuzz4py/cpython/Lib/dbm/sqlite3.py", line 96, in __setitem__
    self._execute(STORE_KV, (key, value))
    ~~~~~~~~~~~~~^^^^^^^^^^^^^^^^^^^^^^^^
Traceback (most recent call last):
Traceback (most recent call last):
  File "/home/mrigankp/fuzz4py/fuzz4py/inputs/790.py", line 15, in worker
    db[str(data)] = data * 2
    ~~^^^^^^^^^^^
  File "/home/mrigankp/fuzz4py/cpython/Lib/dbm/sqlite3.py", line 96, in __setitem__
    self._execute(STORE_KV, (key, value))
    ~~~~~~~~~~~~~^^^^^^^^^^^^^^^^^^^^^^^^
  File "/home/mrigankp/fuzz4py/cpython/Lib/dbm/sqlite3.py", line 81, in _execute
    raise error(str(exc))
Traceback (most recent call last):
Traceback (most recent call last):
Traceback (most recent call last):
  File "/home/mrigankp/fuzz4py/fuzz4py/inputs/790.py", line 15, in worker
    db[str(data)] = data * 2
    ~~^^^^^^^^^^^

During handling of the above exception, another exception occurred:

  File "/home/mrigankp/fuzz4py/cpython/Lib/dbm/sqlite3.py", line 81, in _execute
    raise error(str(exc))
Traceback (most recent call last):
Traceback (most recent call last):
  File "/home/mrigankp/fuzz4py/cpython/Lib/dbm/sqlite3.py", line 81, in _execute
    raise error(str(exc))

During handling of the above exception, another exception occurred:

  File "/home/mrigankp/fuzz4py/cpython/Lib/dbm/sqlite3.py", line 79, in _execute
    return closing(self._cx.execute(*args, **kwargs))
                   ~~~~~~~~~~~~~~~~^^^^^^^^^^^^^^^^^
  File "/home/mrigankp/fuzz4py/cpython/Lib/dbm/sqlite3.py", line 81, in _execute
    raise error(str(exc))
  File "/home/mrigankp/fuzz4py/fuzz4py/inputs/790.py", line 15, in worker
    db[str(data)] = data * 2
    ~~^^^^^^^^^^^
Traceback (most recent call last):
Traceback (most recent call last):
  File "/home/mrigankp/fuzz4py/cpython/Lib/threading.py", line 1041, in _bootstrap_inner
    self.run()
    ~~~~~~~~^^

During handling of the above exception, another exception occurred:

Traceback (most recent call last):
Traceback (most recent call last):
  File "/home/mrigankp/fuzz4py/cpython/Lib/threading.py", line 1041, in _bootstrap_inner
    self.run()
    ~~~~~~~~^^
Traceback (most recent call last):
  File "/home/mrigankp/fuzz4py/cpython/Lib/threading.py", line 1041, in _bootstrap_inner
    self.run()
    ~~~~~~~~^^
  File "/home/mrigankp/fuzz4py/fuzz4py/inputs/790.py", line 15, in worker
    db[str(data)] = data * 2
    ~~^^^^^^^^^^^
  File "/home/mrigankp/fuzz4py/cpython/Lib/threading.py", line 1041, in _bootstrap_inner
    self.run()
    ~~~~~~~~^^
sqlite3.ProgrammingError: SQLite objects created in a thread can only be used in that same thread. The object was created in thread id 130381227054912 and this is thread id 130379893704256.
Traceback (most recent call last):

During handling of the above exception, another exception occurred:

  File "/home/mrigankp/fuzz4py/cpython/Lib/threading.py", line 992, in run
    self._target(*self._args, **self._kwargs)
    ~~~~~~~~~~~~^^^^^^^^^^^^^^^^^^^^^^^^^^^^^
Traceback (most recent call last):
Traceback (most recent call last):
  File "/home/mrigankp/fuzz4py/fuzz4py/inputs/790.py", line 15, in worker
    db[str(data)] = data * 2
    ~~^^^^^^^^^^^

During handling of the above exception, another exception occurred:

Traceback (most recent call last):
Traceback (most recent call last):
  File "/home/mrigankp/fuzz4py/cpython/Lib/threading.py", line 992, in run
    self._target(*self._args, **self._kwargs)
    ~~~~~~~~~~~~^^^^^^^^^^^^^^^^^^^^^^^^^^^^^
Traceback (most recent call last):
  File "/home/mrigankp/fuzz4py/cpython/Lib/threading.py", line 992, in run
    self._target(*self._args, **self._kwargs)
    ~~~~~~~~~~~~^^^^^^^^^^^^^^^^^^^^^^^^^^^^^
Traceback (most recent call last):
sqlite3.ProgrammingError: SQLite objects created in a thread can only be used in that same thread. The object was created in thread id 130381227054912 and this is thread id 130378484418112.
  File "/home/mrigankp/fuzz4py/cpython/Lib/threading.py", line 992, in run
    self._target(*self._args, **self._kwargs)
    ~~~~~~~~~~~~^^^^^^^^^^^^^^^^^^^^^^^^^^^^^
  File "/home/mrigankp/fuzz4py/cpython/Lib/threading.py", line 1041, in _bootstrap_inner
    self.run()
    ~~~~~~~~^^
  File "/home/mrigankp/fuzz4py/cpython/Lib/dbm/sqlite3.py", line 96, in __setitem__
    self._execute(STORE_KV, (key, value))
    ~~~~~~~~~~~~~^^^^^^^^^^^^^^^^^^^^^^^^
  File "/home/mrigankp/fuzz4py/cpython/Lib/threading.py", line 992, in run
    self._target(*self._args, **self._kwargs)
    ~~~~~~~~~~~~^^^^^^^^^^^^^^^^^^^^^^^^^^^^^

During handling of the above exception, another exception occurred:


During handling of the above exception, another exception occurred:

Traceback (most recent call last):
  File "/home/mrigankp/fuzz4py/cpython/Lib/threading.py", line 1041, in _bootstrap_inner
    self.run()
    ~~~~~~~~^^
  File "/home/mrigankp/fuzz4py/cpython/Lib/threading.py", line 1041, in _bootstrap_inner
    self.run()
    ~~~~~~~~^^
  File "/home/mrigankp/fuzz4py/fuzz4py/inputs/790.py", line 15, in worker
    db[str(data)] = data * 2
    ~~^^^^^^^^^^^
  File "/home/mrigankp/fuzz4py/cpython/Lib/dbm/sqlite3.py", line 96, in __setitem__
    self._execute(STORE_KV, (key, value))
    ~~~~~~~~~~~~~^^^^^^^^^^^^^^^^^^^^^^^^
dbm.sqlite3.error: SQLite objects created in a thread can only be used in that same thread. The object was created in thread id 130381227054912 and this is thread id 130380910822976.
Traceback (most recent call last):
  File "/home/mrigankp/fuzz4py/cpython/Lib/threading.py", line 1041, in _bootstrap_inner
    self.run()
    ~~~~~~~~^^
  File "/home/mrigankp/fuzz4py/cpython/Lib/dbm/sqlite3.py", line 96, in __setitem__
    self._execute(STORE_KV, (key, value))
    ~~~~~~~~~~~~~^^^^^^^^^^^^^^^^^^^^^^^^
  File "/home/mrigankp/fuzz4py/cpython/Lib/threading.py", line 1041, in _bootstrap_inner
    self.run()
    ~~~~~~~~^^
  File "/home/mrigankp/fuzz4py/cpython/Lib/threading.py", line 992, in run
    self._target(*self._args, **self._kwargs)
    ~~~~~~~~~~~~^^^^^^^^^^^^^^^^^^^^^^^^^^^^^
  File "/home/mrigankp/fuzz4py/cpython/Lib/threading.py", line 1041, in _bootstrap_inner
    self.run()
    ~~~~~~~~^^
dbm.sqlite3.error: SQLite objects created in a thread can only be used in that same thread. The object was created in thread id 130381227054912 and this is thread id 130380879365696.
dbm.sqlite3.error: SQLite objects created in a thread can only be used in that same thread. The object was created in thread id 130381227054912 and this is thread id 130381091178048.
sqlite3.ProgrammingError: SQLite objects created in a thread can only be used in that same thread. The object was created in thread id 130381227054912 and this is thread id 130378092250688.
sqlite3.ProgrammingError: SQLite objects created in a thread can only be used in that same thread. The object was created in thread id 130381227054912 and this is thread id 130379279238720.

During handling of the above exception, another exception occurred:

sqlite3.ProgrammingError: SQLite objects created in a thread can only be used in that same thread. The object was created in thread id 130381227054912 and this is thread id 130380053087808.
  File "/home/mrigankp/fuzz4py/cpython/Lib/threading.py", line 1041, in _bootstrap_inner
    self.run()
    ~~~~~~~~^^
  File "/home/mrigankp/fuzz4py/cpython/Lib/threading.py", line 992, in run
    self._target(*self._args, **self._kwargs)
    ~~~~~~~~~~~~^^^^^^^^^^^^^^^^^^^^^^^^^^^^^
  File "/home/mrigankp/fuzz4py/cpython/Lib/threading.py", line 1041, in _bootstrap_inner
    self.run()
    ~~~~~~~~^^

During handling of the above exception, another exception occurred:

Traceback (most recent call last):
  File "/home/mrigankp/fuzz4py/cpython/Lib/threading.py", line 992, in run
    self._target(*self._args, **self._kwargs)
    ~~~~~~~~~~~~^^^^^^^^^^^^^^^^^^^^^^^^^^^^^
  File "/home/mrigankp/fuzz4py/cpython/Lib/dbm/sqlite3.py", line 79, in _execute
    return closing(self._cx.execute(*args, **kwargs))
                   ~~~~~~~~~~~~~~~~^^^^^^^^^^^^^^^^^
  File "/home/mrigankp/fuzz4py/cpython/Lib/threading.py", line 1041, in _bootstrap_inner
    self.run()
    ~~~~~~~~^^
  File "/home/mrigankp/fuzz4py/cpython/Lib/threading.py", line 992, in run
    self._target(*self._args, **self._kwargs)
    ~~~~~~~~~~~~^^^^^^^^^^^^^^^^^^^^^^^^^^^^^
  File "/home/mrigankp/fuzz4py/fuzz4py/inputs/790.py", line 15, in worker
    db[str(data)] = data * 2
    ~~^^^^^^^^^^^
  File "/home/mrigankp/fuzz4py/cpython/Lib/threading.py", line 992, in run
    self._target(*self._args, **self._kwargs)
    ~~~~~~~~~~~~^^^^^^^^^^^^^^^^^^^^^^^^^^^^^
  File "/home/mrigankp/fuzz4py/cpython/Lib/threading.py", line 992, in run
    self._target(*self._args, **self._kwargs)
    ~~~~~~~~~~~~^^^^^^^^^^^^^^^^^^^^^^^^^^^^^
  File "/home/mrigankp/fuzz4py/cpython/Lib/threading.py", line 992, in run
    self._target(*self._args, **self._kwargs)
    ~~~~~~~~~~~~^^^^^^^^^^^^^^^^^^^^^^^^^^^^^
  File "/home/mrigankp/fuzz4py/cpython/Lib/dbm/sqlite3.py", line 96, in __setitem__
    self._execute(STORE_KV, (key, value))
    ~~~~~~~~~~~~~^^^^^^^^^^^^^^^^^^^^^^^^
  File "/home/mrigankp/fuzz4py/fuzz4py/inputs/790.py", line 15, in worker
    db[str(data)] = data * 2
    ~~^^^^^^^^^^^
  File "/home/mrigankp/fuzz4py/cpython/Lib/dbm/sqlite3.py", line 81, in _execute
    raise error(str(exc))
  File "/home/mrigankp/fuzz4py/cpython/Lib/threading.py", line 1041, in _bootstrap_inner
    self.run()
    ~~~~~~~~^^
sqlite3.ProgrammingError: SQLite objects created in a thread can only be used in that same thread. The object was created in thread id 130381227054912 and this is thread id 130378664773184.
  File "/home/mrigankp/fuzz4py/fuzz4py/inputs/790.py", line 15, in worker
    db[str(data)] = data * 2
    ~~^^^^^^^^^^^
  File "/home/mrigankp/fuzz4py/cpython/Lib/dbm/sqlite3.py", line 96, in __setitem__
    self._execute(STORE_KV, (key, value))
    ~~~~~~~~~~~~~^^^^^^^^^^^^^^^^^^^^^^^^
  File "/home/mrigankp/fuzz4py/cpython/Lib/threading.py", line 992, in run
    self._target(*self._args, **self._kwargs)
    ~~~~~~~~~~~~^^^^^^^^^^^^^^^^^^^^^^^^^^^^^
  File "/home/mrigankp/fuzz4py/fuzz4py/inputs/790.py", line 15, in worker
    db[str(data)] = data * 2
    ~~^^^^^^^^^^^

During handling of the above exception, another exception occurred:

  File "/home/mrigankp/fuzz4py/fuzz4py/inputs/790.py", line 15, in worker
    db[str(data)] = data * 2
    ~~^^^^^^^^^^^
sqlite3.ProgrammingError: SQLite objects created in a thread can only be used in that same thread. The object was created in thread id 130381227054912 and this is thread id 130379067426368.

During handling of the above exception, another exception occurred:

  File "/home/mrigankp/fuzz4py/fuzz4py/inputs/790.py", line 15, in worker
    db[str(data)] = data * 2
    ~~^^^^^^^^^^^
  File "/home/mrigankp/fuzz4py/cpython/Lib/threading.py", line 992, in run
    self._target(*self._args, **self._kwargs)
    ~~~~~~~~~~~~^^^^^^^^^^^^^^^^^^^^^^^^^^^^^
  File "/home/mrigankp/fuzz4py/cpython/Lib/dbm/sqlite3.py", line 81, in _execute
    raise error(str(exc))
Traceback (most recent call last):
  File "/home/mrigankp/fuzz4py/cpython/Lib/dbm/sqlite3.py", line 81, in _execute
    raise error(str(exc))
Traceback (most recent call last):

During handling of the above exception, another exception occurred:

  File "/home/mrigankp/fuzz4py/cpython/Lib/threading.py", line 992, in run
    self._target(*self._args, **self._kwargs)
    ~~~~~~~~~~~~^^^^^^^^^^^^^^^^^^^^^^^^^^^^^
  File "/home/mrigankp/fuzz4py/cpython/Lib/dbm/sqlite3.py", line 96, in __setitem__
    self._execute(STORE_KV, (key, value))
    ~~~~~~~~~~~~~^^^^^^^^^^^^^^^^^^^^^^^^
  File "/home/mrigankp/fuzz4py/cpython/Lib/dbm/sqlite3.py", line 79, in _execute
    return closing(self._cx.execute(*args, **kwargs))
                   ~~~~~~~~~~~~~~~~^^^^^^^^^^^^^^^^^
  File "/home/mrigankp/fuzz4py/cpython/Lib/threading.py", line 992, in run
    self._target(*self._args, **self._kwargs)
    ~~~~~~~~~~~~^^^^^^^^^^^^^^^^^^^^^^^^^^^^^
  File "/home/mrigankp/fuzz4py/cpython/Lib/dbm/sqlite3.py", line 79, in _execute
    return closing(self._cx.execute(*args, **kwargs))
                   ~~~~~~~~~~~~~~~~^^^^^^^^^^^^^^^^^

During handling of the above exception, another exception occurred:

  File "/home/mrigankp/fuzz4py/cpython/Lib/threading.py", line 1041, in _bootstrap_inner
    self.run()
    ~~~~~~~~^^
Traceback (most recent call last):
  File "/home/mrigankp/fuzz4py/fuzz4py/inputs/790.py", line 15, in worker
    db[str(data)] = data * 2
    ~~^^^^^^^^^^^
  File "/home/mrigankp/fuzz4py/cpython/Lib/dbm/sqlite3.py", line 96, in __setitem__
    self._execute(STORE_KV, (key, value))
    ~~~~~~~~~~~~~^^^^^^^^^^^^^^^^^^^^^^^^

During handling of the above exception, another exception occurred:

Traceback (most recent call last):

During handling of the above exception, another exception occurred:

Traceback (most recent call last):
Traceback (most recent call last):
  File "/home/mrigankp/fuzz4py/cpython/Lib/dbm/sqlite3.py", line 96, in __setitem__
    self._execute(STORE_KV, (key, value))
    ~~~~~~~~~~~~~^^^^^^^^^^^^^^^^^^^^^^^^
  File "/home/mrigankp/fuzz4py/cpython/Lib/threading.py", line 992, in run
    self._target(*self._args, **self._kwargs)
    ~~~~~~~~~~~~^^^^^^^^^^^^^^^^^^^^^^^^^^^^^
  File "/home/mrigankp/fuzz4py/fuzz4py/inputs/790.py", line 15, in worker
    db[str(data)] = data * 2
    ~~^^^^^^^^^^^
Traceback (most recent call last):

During handling of the above exception, another exception occurred:

Traceback (most recent call last):
  File "/home/mrigankp/fuzz4py/fuzz4py/inputs/790.py", line 15, in worker
    db[str(data)] = data * 2
    ~~^^^^^^^^^^^
sqlite3.ProgrammingError: SQLite objects created in a thread can only be used in that same thread. The object was created in thread id 130381227054912 and this is thread id 130377880438336.
  File "/home/mrigankp/fuzz4py/cpython/Lib/dbm/sqlite3.py", line 96, in __setitem__
    self._execute(STORE_KV, (key, value))
    ~~~~~~~~~~~~~^^^^^^^^^^^^^^^^^^^^^^^^
  File "/home/mrigankp/fuzz4py/cpython/Lib/dbm/sqlite3.py", line 81, in _execute
    raise error(str(exc))
  File "/home/mrigankp/fuzz4py/cpython/Lib/dbm/sqlite3.py", line 96, in __setitem__
    self._execute(STORE_KV, (key, value))
    ~~~~~~~~~~~~~^^^^^^^^^^^^^^^^^^^^^^^^
  File "/home/mrigankp/fuzz4py/fuzz4py/inputs/790.py", line 15, in worker
    db[str(data)] = data * 2
    ~~^^^^^^^^^^^
  File "/home/mrigankp/fuzz4py/cpython/Lib/dbm/sqlite3.py", line 96, in __setitem__
    self._execute(STORE_KV, (key, value))
    ~~~~~~~~~~~~~^^^^^^^^^^^^^^^^^^^^^^^^
  File "/home/mrigankp/fuzz4py/cpython/Lib/dbm/sqlite3.py", line 81, in _execute
    raise error(str(exc))
  File "/home/mrigankp/fuzz4py/cpython/Lib/dbm/sqlite3.py", line 81, in _execute
    raise error(str(exc))
  File "/home/mrigankp/fuzz4py/cpython/Lib/threading.py", line 992, in run
    self._target(*self._args, **self._kwargs)
    ~~~~~~~~~~~~^^^^^^^^^^^^^^^^^^^^^^^^^^^^^

During handling of the above exception, another exception occurred:


During handling of the above exception, another exception occurred:

Traceback (most recent call last):

During handling of the above exception, another exception occurred:

  File "/home/mrigankp/fuzz4py/cpython/Lib/dbm/sqlite3.py", line 96, in __setitem__
    self._execute(STORE_KV, (key, value))
    ~~~~~~~~~~~~~^^^^^^^^^^^^^^^^^^^^^^^^
  File "/home/mrigankp/fuzz4py/cpython/Lib/threading.py", line 1041, in _bootstrap_inner
    self.run()
    ~~~~~~~~^^
  File "/home/mrigankp/fuzz4py/cpython/Lib/dbm/sqlite3.py", line 96, in __setitem__
    self._execute(STORE_KV, (key, value))
    ~~~~~~~~~~~~~^^^^^^^^^^^^^^^^^^^^^^^^
sqlite3.ProgrammingError: SQLite objects created in a thread can only be used in that same thread. The object was created in thread id 130381227054912 and this is thread id 130379459593792.

During handling of the above exception, another exception occurred:

Traceback (most recent call last):
  File "/home/mrigankp/fuzz4py/cpython/Lib/dbm/sqlite3.py", line 96, in __setitem__
    self._execute(STORE_KV, (key, value))
    ~~~~~~~~~~~~~^^^^^^^^^^^^^^^^^^^^^^^^
  File "/home/mrigankp/fuzz4py/fuzz4py/inputs/790.py", line 15, in worker
    db[str(data)] = data * 2
    ~~^^^^^^^^^^^
  File "/home/mrigankp/fuzz4py/cpython/Lib/dbm/sqlite3.py", line 96, in __setitem__
    self._execute(STORE_KV, (key, value))
    ~~~~~~~~~~~~~^^^^^^^^^^^^^^^^^^^^^^^^
  File "/home/mrigankp/fuzz4py/cpython/Lib/threading.py", line 1041, in _bootstrap_inner
    self.run()
    ~~~~~~~~^^
  File "/home/mrigankp/fuzz4py/cpython/Lib/dbm/sqlite3.py", line 79, in _execute
    return closing(self._cx.execute(*args, **kwargs))
                   ~~~~~~~~~~~~~~~~^^^^^^^^^^^^^^^^^
Traceback (most recent call last):
  File "/home/mrigankp/fuzz4py/cpython/Lib/threading.py", line 1041, in _bootstrap_inner
    self.run()
    ~~~~~~~~^^
  File "/home/mrigankp/fuzz4py/cpython/Lib/dbm/sqlite3.py", line 81, in _execute
    raise error(str(exc))
sqlite3.ProgrammingError: SQLite objects created in a thread can only be used in that same thread. The object was created in thread id 130381227054912 and this is thread id 130378262120000.
  File "/home/mrigankp/fuzz4py/cpython/Lib/threading.py", line 992, in run
    self._target(*self._args, **self._kwargs)
    ~~~~~~~~~~~~^^^^^^^^^^^^^^^^^^^^^^^^^^^^^
  File "/home/mrigankp/fuzz4py/fuzz4py/inputs/790.py", line 15, in worker
    db[str(data)] = data * 2
    ~~^^^^^^^^^^^
Traceback (most recent call last):

During handling of the above exception, another exception occurred:

  File "/home/mrigankp/fuzz4py/cpython/Lib/dbm/sqlite3.py", line 81, in _execute
    raise error(str(exc))
  File "/home/mrigankp/fuzz4py/cpython/Lib/threading.py", line 1041, in _bootstrap_inner
    self.run()
    ~~~~~~~~^^
  File "/home/mrigankp/fuzz4py/cpython/Lib/dbm/sqlite3.py", line 81, in _execute
    raise error(str(exc))

During handling of the above exception, another exception occurred:

Traceback (most recent call last):
  File "/home/mrigankp/fuzz4py/cpython/Lib/threading.py", line 1041, in _bootstrap_inner
    self.run()
    ~~~~~~~~^^
Traceback (most recent call last):
  File "/home/mrigankp/fuzz4py/cpython/Lib/threading.py", line 1041, in _bootstrap_inner
    self.run()
    ~~~~~~~~^^
  File "/home/mrigankp/fuzz4py/fuzz4py/inputs/790.py", line 15, in worker
    db[str(data)] = data * 2
    ~~^^^^^^^^^^^
  File "/home/mrigankp/fuzz4py/fuzz4py/inputs/790.py", line 15, in worker
    db[str(data)] = data * 2
    ~~^^^^^^^^^^^
  File "/home/mrigankp/fuzz4py/cpython/Lib/dbm/sqlite3.py", line 96, in __setitem__
    self._execute(STORE_KV, (key, value))
    ~~~~~~~~~~~~~^^^^^^^^^^^^^^^^^^^^^^^^
  File "/home/mrigankp/fuzz4py/cpython/Lib/threading.py", line 992, in run
    self._target(*self._args, **self._kwargs)
    ~~~~~~~~~~~~^^^^^^^^^^^^^^^^^^^^^^^^^^^^^
  File "/home/mrigankp/fuzz4py/fuzz4py/inputs/790.py", line 15, in worker
    db[str(data)] = data * 2
    ~~^^^^^^^^^^^
  File "/home/mrigankp/fuzz4py/cpython/Lib/threading.py", line 1041, in _bootstrap_inner
    self.run()
    ~~~~~~~~^^
  File "/home/mrigankp/fuzz4py/cpython/Lib/dbm/sqlite3.py", line 96, in __setitem__
    self._execute(STORE_KV, (key, value))
    ~~~~~~~~~~~~~^^^^^^^^^^^^^^^^^^^^^^^^

During handling of the above exception, another exception occurred:

  File "/home/mrigankp/fuzz4py/cpython/Lib/dbm/sqlite3.py", line 96, in __setitem__
    self._execute(STORE_KV, (key, value))
    ~~~~~~~~~~~~~^^^^^^^^^^^^^^^^^^^^^^^^
  File "/home/mrigankp/fuzz4py/cpython/Lib/dbm/sqlite3.py", line 81, in _execute
    raise error(str(exc))
dbm.sqlite3.error: SQLite objects created in a thread can only be used in that same thread. The object was created in thread id 130381227054912 and this is thread id 130381101663808.
  File "/home/mrigankp/fuzz4py/fuzz4py/inputs/790.py", line 15, in worker
    db[str(data)] = data * 2
    ~~^^^^^^^^^^^
  File "/home/mrigankp/fuzz4py/cpython/Lib/dbm/sqlite3.py", line 96, in __setitem__
    self._execute(STORE_KV, (key, value))
    ~~~~~~~~~~~~~^^^^^^^^^^^^^^^^^^^^^^^^
  File "/home/mrigankp/fuzz4py/cpython/Lib/dbm/sqlite3.py", line 81, in _execute
    raise error(str(exc))
dbm.sqlite3.error: SQLite objects created in a thread can only be used in that same thread. The object was created in thread id 130381227054912 and this is thread id 130380296357440.
dbm.sqlite3.error: SQLite objects created in a thread can only be used in that same thread. The object was created in thread id 130381227054912 and this is thread id 130381191841344.
  File "/home/mrigankp/fuzz4py/cpython/Lib/threading.py", line 1041, in _bootstrap_inner
    self.run()
    ~~~~~~~~^^
  File "/home/mrigankp/fuzz4py/cpython/Lib/threading.py", line 992, in run
    self._target(*self._args, **self._kwargs)
    ~~~~~~~~~~~~^^^^^^^^^^^^^^^^^^^^^^^^^^^^^
Traceback (most recent call last):
Traceback (most recent call last):
  File "/home/mrigankp/fuzz4py/cpython/Lib/threading.py", line 1041, in _bootstrap_inner
    self.run()
    ~~~~~~~~^^
  File "/home/mrigankp/fuzz4py/fuzz4py/inputs/790.py", line 15, in worker
    db[str(data)] = data * 2
    ~~^^^^^^^^^^^
  File "/home/mrigankp/fuzz4py/cpython/Lib/dbm/sqlite3.py", line 96, in __setitem__
    self._execute(STORE_KV, (key, value))
    ~~~~~~~~~~~~~^^^^^^^^^^^^^^^^^^^^^^^^
Traceback (most recent call last):
  File "/home/mrigankp/fuzz4py/cpython/Lib/threading.py", line 992, in run
    self._target(*self._args, **self._kwargs)
    ~~~~~~~~~~~~^^^^^^^^^^^^^^^^^^^^^^^^^^^^^
  File "/home/mrigankp/fuzz4py/cpython/Lib/dbm/sqlite3.py", line 81, in _execute
    raise error(str(exc))
  File "/home/mrigankp/fuzz4py/cpython/Lib/threading.py", line 1041, in _bootstrap_inner
    self.run()
    ~~~~~~~~^^
Traceback (most recent call last):
  File "/home/mrigankp/fuzz4py/fuzz4py/inputs/790.py", line 15, in worker
    db[str(data)] = data * 2
    ~~^^^^^^^^^^^
  File "/home/mrigankp/fuzz4py/cpython/Lib/dbm/sqlite3.py", line 81, in _execute
    raise error(str(exc))
dbm.sqlite3.error: SQLite objects created in a thread can only be used in that same thread. The object was created in thread id 130381227054912 and this is thread id 130379872732736.
dbm.sqlite3.error: SQLite objects created in a thread can only be used in that same thread. The object was created in thread id 130381227054912 and this is thread id 130380900337216.
  File "/home/mrigankp/fuzz4py/cpython/Lib/threading.py", line 992, in run
    self._target(*self._args, **self._kwargs)
    ~~~~~~~~~~~~^^^^^^^^^^^^^^^^^^^^^^^^^^^^^
sqlite3.ProgrammingError: SQLite objects created in a thread can only be used in that same thread. The object was created in thread id 130381227054912 and this is thread id 130378293577280.
  File "/home/mrigankp/fuzz4py/cpython/Lib/threading.py", line 1041, in _bootstrap_inner
    self.run()
    ~~~~~~~~^^
  File "/home/mrigankp/fuzz4py/cpython/Lib/threading.py", line 992, in run
    self._target(*self._args, **self._kwargs)
    ~~~~~~~~~~~~^^^^^^^^^^^^^^^^^^^^^^^^^^^^^
dbm.sqlite3.error: SQLite objects created in a thread can only be used in that same thread. The object was created in thread id 130381227054912 and this is thread id 130380657067584.

During handling of the above exception, another exception occurred:

  File "/home/mrigankp/fuzz4py/cpython/Lib/dbm/sqlite3.py", line 96, in __setitem__
    self._execute(STORE_KV, (key, value))
    ~~~~~~~~~~~~~^^^^^^^^^^^^^^^^^^^^^^^^
  File "/home/mrigankp/fuzz4py/cpython/Lib/threading.py", line 992, in run
    self._target(*self._args, **self._kwargs)
    ~~~~~~~~~~~~^^^^^^^^^^^^^^^^^^^^^^^^^^^^^
dbm.sqlite3.error: SQLite objects created in a thread can only be used in that same thread. The object was created in thread id 130381227054912 and this is thread id 130380868879936.
  File "/home/mrigankp/fuzz4py/cpython/Lib/threading.py", line 992, in run
    self._target(*self._args, **self._kwargs)
    ~~~~~~~~~~~~^^^^^^^^^^^^^^^^^^^^^^^^^^^^^
  File "/home/mrigankp/fuzz4py/cpython/Lib/threading.py", line 1041, in _bootstrap_inner
    self.run()
    ~~~~~~~~^^
Traceback (most recent call last):
  File "/home/mrigankp/fuzz4py/cpython/Lib/threading.py", line 1041, in _bootstrap_inner
    self.run()
    ~~~~~~~~^^
  File "/home/mrigankp/fuzz4py/cpython/Lib/threading.py", line 992, in run
    self._target(*self._args, **self._kwargs)
    ~~~~~~~~~~~~^^^^^^^^^^^^^^^^^^^^^^^^^^^^^
  File "/home/mrigankp/fuzz4py/cpython/Lib/threading.py", line 1041, in _bootstrap_inner
    self.run()
    ~~~~~~~~^^
  File "/home/mrigankp/fuzz4py/cpython/Lib/threading.py", line 992, in run
    self._target(*self._args, **self._kwargs)
    ~~~~~~~~~~~~^^^^^^^^^^^^^^^^^^^^^^^^^^^^^
  File "/home/mrigankp/fuzz4py/cpython/Lib/dbm/sqlite3.py", line 81, in _execute
    raise error(str(exc))
  File "/home/mrigankp/fuzz4py/cpython/Lib/threading.py", line 992, in run
    self._target(*self._args, **self._kwargs)
    ~~~~~~~~~~~~^^^^^^^^^^^^^^^^^^^^^^^^^^^^^
  File "/home/mrigankp/fuzz4py/cpython/Lib/threading.py", line 1041, in _bootstrap_inner
    self.run()
    ~~~~~~~~^^
  File "/home/mrigankp/fuzz4py/cpython/Lib/threading.py", line 1041, in _bootstrap_inner
    self.run()
    ~~~~~~~~^^
  File "/home/mrigankp/fuzz4py/cpython/Lib/threading.py", line 1041, in _bootstrap_inner
    self.run()
    ~~~~~~~~^^

During handling of the above exception, another exception occurred:

  File "/home/mrigankp/fuzz4py/cpython/Lib/threading.py", line 992, in run
    self._target(*self._args, **self._kwargs)
    ~~~~~~~~~~~~^^^^^^^^^^^^^^^^^^^^^^^^^^^^^
  File "/home/mrigankp/fuzz4py/cpython/Lib/dbm/sqlite3.py", line 81, in _execute
    raise error(str(exc))

During handling of the above exception, another exception occurred:

  File "/home/mrigankp/fuzz4py/fuzz4py/inputs/790.py", line 15, in worker
    db[str(data)] = data * 2
    ~~^^^^^^^^^^^

During handling of the above exception, another exception occurred:

Traceback (most recent call last):
dbm.sqlite3.error: SQLite objects created in a thread can only be used in that same thread. The object was created in thread id 130381227054912 and this is thread id 130381070206528.
  File "/home/mrigankp/fuzz4py/fuzz4py/inputs/790.py", line 15, in worker
    db[str(data)] = data * 2
    ~~^^^^^^^^^^^
  File "/home/mrigankp/fuzz4py/fuzz4py/inputs/790.py", line 15, in worker
    db[str(data)] = data * 2
    ~~^^^^^^^^^^^
  File "/home/mrigankp/fuzz4py/cpython/Lib/dbm/sqlite3.py", line 81, in _execute
    raise error(str(exc))
  File "/home/mrigankp/fuzz4py/cpython/Lib/threading.py", line 1041, in _bootstrap_inner
    self.run()
    ~~~~~~~~^^
  File "/home/mrigankp/fuzz4py/cpython/Lib/threading.py", line 992, in run
    self._target(*self._args, **self._kwargs)
    ~~~~~~~~~~~~^^^^^^^^^^^^^^^^^^^^^^^^^^^^^
  File "/home/mrigankp/fuzz4py/fuzz4py/inputs/790.py", line 15, in worker
    db[str(data)] = data * 2
    ~~^^^^^^^^^^^
  File "/home/mrigankp/fuzz4py/cpython/Lib/threading.py", line 992, in run
    self._target(*self._args, **self._kwargs)
    ~~~~~~~~~~~~^^^^^^^^^^^^^^^^^^^^^^^^^^^^^
  File "/home/mrigankp/fuzz4py/cpython/Lib/threading.py", line 1041, in _bootstrap_inner
    self.run()
    ~~~~~~~~^^
Traceback (most recent call last):
dbm.sqlite3.error: SQLite objects created in a thread can only be used in that same thread. The object was created in thread id 130381227054912 and this is thread id 130379491051072.
  File "/home/mrigankp/fuzz4py/cpython/Lib/threading.py", line 992, in run
    self._target(*self._args, **self._kwargs)
    ~~~~~~~~~~~~^^^^^^^^^^^^^^^^^^^^^^^^^^^^^
  File "/home/mrigankp/fuzz4py/cpython/Lib/threading.py", line 1041, in _bootstrap_inner
    self.run()
    ~~~~~~~~^^
  File "/home/mrigankp/fuzz4py/cpython/Lib/threading.py", line 1041, in _bootstrap_inner
    self.run()
    ~~~~~~~~^^
  File "/home/mrigankp/fuzz4py/cpython/Lib/dbm/sqlite3.py", line 81, in _execute
    raise error(str(exc))
  File "/home/mrigankp/fuzz4py/cpython/Lib/threading.py", line 992, in run
    self._target(*self._args, **self._kwargs)
    ~~~~~~~~~~~~^^^^^^^^^^^^^^^^^^^^^^^^^^^^^
  File "/home/mrigankp/fuzz4py/cpython/Lib/threading.py", line 1041, in _bootstrap_inner
    self.run()
    ~~~~~~~~^^
  File "/home/mrigankp/fuzz4py/fuzz4py/inputs/790.py", line 15, in worker
    db[str(data)] = data * 2
    ~~^^^^^^^^^^^

During handling of the above exception, another exception occurred:

  File "/home/mrigankp/fuzz4py/cpython/Lib/threading.py", line 1041, in _bootstrap_inner
    self.run()
    ~~~~~~~~^^
  File "/home/mrigankp/fuzz4py/cpython/Lib/dbm/sqlite3.py", line 81, in _execute
    raise error(str(exc))
  File "/home/mrigankp/fuzz4py/cpython/Lib/threading.py", line 992, in run
    self._target(*self._args, **self._kwargs)
    ~~~~~~~~~~~~^^^^^^^^^^^^^^^^^^^^^^^^^^^^^
Traceback (most recent call last):

During handling of the above exception, another exception occurred:

Traceback (most recent call last):
  File "/home/mrigankp/fuzz4py/cpython/Lib/threading.py", line 1041, in _bootstrap_inner
    self.run()
    ~~~~~~~~^^
  File "/home/mrigankp/fuzz4py/cpython/Lib/threading.py", line 992, in run
    self._target(*self._args, **self._kwargs)
    ~~~~~~~~~~~~^^^^^^^^^^^^^^^^^^^^^^^^^^^^^
  File "/home/mrigankp/fuzz4py/fuzz4py/inputs/790.py", line 15, in worker
    db[str(data)] = data * 2
    ~~^^^^^^^^^^^
dbm.sqlite3.error: SQLite objects created in a thread can only be used in that same thread. The object was created in thread id 130381227054912 and this is thread id 130378442475072.
Traceback (most recent call last):

During handling of the above exception, another exception occurred:

  File "/home/mrigankp/fuzz4py/fuzz4py/inputs/790.py", line 15, in worker
    db[str(data)] = data * 2
    ~~^^^^^^^^^^^
  File "/home/mrigankp/fuzz4py/cpython/Lib/threading.py", line 1041, in _bootstrap_inner
    self.run()
    ~~~~~~~~^^
  File "/home/mrigankp/fuzz4py/fuzz4py/inputs/790.py", line 15, in worker
    db[str(data)] = data * 2
    ~~^^^^^^^^^^^
  File "/home/mrigankp/fuzz4py/cpython/Lib/dbm/sqlite3.py", line 96, in __setitem__
    self._execute(STORE_KV, (key, value))
    ~~~~~~~~~~~~~^^^^^^^^^^^^^^^^^^^^^^^^
dbm.sqlite3.error: SQLite objects created in a thread can only be used in that same thread. The object was created in thread id 130381227054912 and this is thread id 130380678039104.
  File "/home/mrigankp/fuzz4py/cpython/Lib/dbm/sqlite3.py", line 96, in __setitem__
    self._execute(STORE_KV, (key, value))
    ~~~~~~~~~~~~~^^^^^^^^^^^^^^^^^^^^^^^^
  File "/home/mrigankp/fuzz4py/cpython/Lib/dbm/sqlite3.py", line 96, in __setitem__
    self._execute(STORE_KV, (key, value))
    ~~~~~~~~~~~~~^^^^^^^^^^^^^^^^^^^^^^^^
  File "/home/mrigankp/fuzz4py/cpython/Lib/threading.py", line 992, in run
    self._target(*self._args, **self._kwargs)
    ~~~~~~~~~~~~^^^^^^^^^^^^^^^^^^^^^^^^^^^^^
Traceback (most recent call last):
  File "/home/mrigankp/fuzz4py/fuzz4py/inputs/790.py", line 15, in worker
    db[str(data)] = data * 2
    ~~^^^^^^^^^^^
Traceback (most recent call last):
dbm.sqlite3.error: SQLite objects created in a thread can only be used in that same thread. The object was created in thread id 130381227054912 and this is thread id 130379660920384.
  File "/home/mrigankp/fuzz4py/cpython/Lib/dbm/sqlite3.py", line 96, in __setitem__
    self._execute(STORE_KV, (key, value))
    ~~~~~~~~~~~~~^^^^^^^^^^^^^^^^^^^^^^^^
  File "/home/mrigankp/fuzz4py/cpython/Lib/dbm/sqlite3.py", line 96, in __setitem__
    self._execute(STORE_KV, (key, value))
    ~~~~~~~~~~~~~^^^^^^^^^^^^^^^^^^^^^^^^
dbm.sqlite3.error: SQLite objects created in a thread can only be used in that same thread. The object was created in thread id 130381227054912 and this is thread id 130379904190016.
  File "/home/mrigankp/fuzz4py/cpython/Lib/threading.py", line 1041, in _bootstrap_inner
    self.run()
    ~~~~~~~~^^
  File "/home/mrigankp/fuzz4py/cpython/Lib/dbm/sqlite3.py", line 96, in __setitem__
    self._execute(STORE_KV, (key, value))
    ~~~~~~~~~~~~~^^^^^^^^^^^^^^^^^^^^^^^^
  File "/home/mrigankp/fuzz4py/cpython/Lib/dbm/sqlite3.py", line 96, in __setitem__
    self._execute(STORE_KV, (key, value))
    ~~~~~~~~~~~~~^^^^^^^^^^^^^^^^^^^^^^^^
Traceback (most recent call last):
  File "/home/mrigankp/fuzz4py/cpython/Lib/dbm/sqlite3.py", line 81, in _execute
    raise error(str(exc))
  File "/home/mrigankp/fuzz4py/cpython/Lib/threading.py", line 1041, in _bootstrap_inner
    self.run()
    ~~~~~~~~^^
  File "/home/mrigankp/fuzz4py/fuzz4py/inputs/790.py", line 15, in worker
    db[str(data)] = data * 2
    ~~^^^^^^^^^^^
  File "/home/mrigankp/fuzz4py/fuzz4py/inputs/790.py", line 15, in worker
    db[str(data)] = data * 2
    ~~^^^^^^^^^^^

During handling of the above exception, another exception occurred:

Traceback (most recent call last):
  File "/home/mrigankp/fuzz4py/cpython/Lib/threading.py", line 1041, in _bootstrap_inner
    self.run()
    ~~~~~~~~^^
  File "/home/mrigankp/fuzz4py/cpython/Lib/dbm/sqlite3.py", line 96, in __setitem__
    self._execute(STORE_KV, (key, value))
    ~~~~~~~~~~~~~^^^^^^^^^^^^^^^^^^^^^^^^
  File "/home/mrigankp/fuzz4py/cpython/Lib/threading.py", line 992, in run
    self._target(*self._args, **self._kwargs)
    ~~~~~~~~~~~~^^^^^^^^^^^^^^^^^^^^^^^^^^^^^
  File "/home/mrigankp/fuzz4py/fuzz4py/inputs/790.py", line 15, in worker
    db[str(data)] = data * 2
    ~~^^^^^^^^^^^
  File "/home/mrigankp/fuzz4py/cpython/Lib/threading.py", line 992, in run
    self._target(*self._args, **self._kwargs)
    ~~~~~~~~~~~~^^^^^^^^^^^^^^^^^^^^^^^^^^^^^
  File "/home/mrigankp/fuzz4py/fuzz4py/inputs/790.py", line 15, in worker
    db[str(data)] = data * 2
    ~~^^^^^^^^^^^
  File "/home/mrigankp/fuzz4py/cpython/Lib/threading.py", line 992, in run
    self._target(*self._args, **self._kwargs)
    ~~~~~~~~~~~~^^^^^^^^^^^^^^^^^^^^^^^^^^^^^
  File "/home/mrigankp/fuzz4py/cpython/Lib/threading.py", line 992, in run
    self._target(*self._args, **self._kwargs)
    ~~~~~~~~~~~~^^^^^^^^^^^^^^^^^^^^^^^^^^^^^
  File "/home/mrigankp/fuzz4py/fuzz4py/inputs/790.py", line 15, in worker
    db[str(data)] = data * 2
    ~~^^^^^^^^^^^
  File "/home/mrigankp/fuzz4py/cpython/Lib/dbm/sqlite3.py", line 81, in _execute
    raise error(str(exc))
  File "/home/mrigankp/fuzz4py/fuzz4py/inputs/790.py", line 15, in worker
    db[str(data)] = data * 2
    ~~^^^^^^^^^^^
  File "/home/mrigankp/fuzz4py/cpython/Lib/threading.py", line 1041, in _bootstrap_inner
    self.run()
    ~~~~~~~~^^
sqlite3.ProgrammingError: SQLite objects created in a thread can only be used in that same thread. The object was created in thread id 130381227054912 and this is thread id 130378241148480.
  File "/home/mrigankp/fuzz4py/cpython/Lib/threading.py", line 992, in run
    self._target(*self._args, **self._kwargs)
    ~~~~~~~~~~~~^^^^^^^^^^^^^^^^^^^^^^^^^^^^^
  File "/home/mrigankp/fuzz4py/cpython/Lib/threading.py", line 992, in run
    self._target(*self._args, **self._kwargs)
    ~~~~~~~~~~~~^^^^^^^^^^^^^^^^^^^^^^^^^^^^^
  File "/home/mrigankp/fuzz4py/fuzz4py/inputs/790.py", line 15, in worker
    db[str(data)] = data * 2
    ~~^^^^^^^^^^^
  File "/home/mrigankp/fuzz4py/cpython/Lib/threading.py", line 1041, in _bootstrap_inner
    self.run()
    ~~~~~~~~^^
Traceback (most recent call last):
  File "/home/mrigankp/fuzz4py/cpython/Lib/threading.py", line 1041, in _bootstrap_inner
    self.run()
    ~~~~~~~~^^
  File "/home/mrigankp/fuzz4py/cpython/Lib/threading.py", line 1041, in _bootstrap_inner
    self.run()
    ~~~~~~~~^^
  File "/home/mrigankp/fuzz4py/cpython/Lib/threading.py", line 992, in run
    self._target(*self._args, **self._kwargs)
    ~~~~~~~~~~~~^^^^^^^^^^^^^^^^^^^^^^^^^^^^^
  File "/home/mrigankp/fuzz4py/cpython/Lib/threading.py", line 992, in run
    self._target(*self._args, **self._kwargs)
    ~~~~~~~~~~~~^^^^^^^^^^^^^^^^^^^^^^^^^^^^^
  File "/home/mrigankp/fuzz4py/cpython/Lib/dbm/sqlite3.py", line 81, in _execute
    raise error(str(exc))
dbm.sqlite3.error: SQLite objects created in a thread can only be used in that same thread. The object was created in thread id 130381227054912 and this is thread id 130380699010624.
  File "/home/mrigankp/fuzz4py/cpython/Lib/threading.py", line 992, in run
    self._target(*self._args, **self._kwargs)
    ~~~~~~~~~~~~^^^^^^^^^^^^^^^^^^^^^^^^^^^^^
  File "/home/mrigankp/fuzz4py/cpython/Lib/threading.py", line 992, in run
    self._target(*self._args, **self._kwargs)
    ~~~~~~~~~~~~^^^^^^^^^^^^^^^^^^^^^^^^^^^^^
  File "/home/mrigankp/fuzz4py/fuzz4py/inputs/790.py", line 15, in worker
    db[str(data)] = data * 2
    ~~^^^^^^^^^^^
sqlite3.ProgrammingError: SQLite objects created in a thread can only be used in that same thread. The object was created in thread id 130381227054912 and this is thread id 130378050307648.
dbm.sqlite3.error: SQLite objects created in a thread can only be used in that same thread. The object was created in thread id 130381227054912 and this is thread id 130379650434624.
  File "/home/mrigankp/fuzz4py/cpython/Lib/threading.py", line 1041, in _bootstrap_inner
    self.run()
    ~~~~~~~~^^
Traceback (most recent call last):
  File "/home/mrigankp/fuzz4py/cpython/Lib/dbm/sqlite3.py", line 81, in _execute
    raise error(str(exc))
  File "/home/mrigankp/fuzz4py/cpython/Lib/dbm/sqlite3.py", line 79, in _execute
    return closing(self._cx.execute(*args, **kwargs))
                   ~~~~~~~~~~~~~~~~^^^^^^^^^^^^^^^^^
  File "/home/mrigankp/fuzz4py/cpython/Lib/dbm/sqlite3.py", line 96, in __setitem__
    self._execute(STORE_KV, (key, value))
    ~~~~~~~~~~~~~^^^^^^^^^^^^^^^^^^^^^^^^
  File "/home/mrigankp/fuzz4py/cpython/Lib/threading.py", line 1041, in _bootstrap_inner
    self.run()
    ~~~~~~~~^^
  File "/home/mrigankp/fuzz4py/cpython/Lib/dbm/sqlite3.py", line 81, in _execute
    raise error(str(exc))
  File "/home/mrigankp/fuzz4py/cpython/Lib/dbm/sqlite3.py", line 81, in _execute
    raise error(str(exc))
dbm.sqlite3.error: SQLite objects created in a thread can only be used in that same thread. The object was created in thread id 130381227054912 and this is thread id 130381080692288.
  File "/home/mrigankp/fuzz4py/cpython/Lib/threading.py", line 1041, in _bootstrap_inner
    self.run()
    ~~~~~~~~^^
  File "/home/mrigankp/fuzz4py/cpython/Lib/dbm/sqlite3.py", line 81, in _execute
    raise error(str(exc))
  File "/home/mrigankp/fuzz4py/cpython/Lib/threading.py", line 992, in run
    self._target(*self._args, **self._kwargs)
    ~~~~~~~~~~~~^^^^^^^^^^^^^^^^^^^^^^^^^^^^^
  File "/home/mrigankp/fuzz4py/cpython/Lib/dbm/sqlite3.py", line 96, in __setitem__
    self._execute(STORE_KV, (key, value))
    ~~~~~~~~~~~~~^^^^^^^^^^^^^^^^^^^^^^^^
  File "/home/mrigankp/fuzz4py/cpython/Lib/threading.py", line 1041, in _bootstrap_inner
    self.run()
    ~~~~~~~~^^
  File "/home/mrigankp/fuzz4py/cpython/Lib/threading.py", line 1041, in _bootstrap_inner
    self.run()
    ~~~~~~~~^^
  File "/home/mrigankp/fuzz4py/cpython/Lib/threading.py", line 992, in run
    self._target(*self._args, **self._kwargs)
    ~~~~~~~~~~~~^^^^^^^^^^^^^^^^^^^^^^^^^^^^^
dbm.sqlite3.error: SQLite objects created in a thread can only be used in that same thread. The object was created in thread id 130381227054912 and this is thread id 130379077912128.
  File "/home/mrigankp/fuzz4py/fuzz4py/inputs/790.py", line 15, in worker
    db[str(data)] = data * 2
    ~~^^^^^^^^^^^
  File "/home/mrigankp/fuzz4py/cpython/Lib/dbm/sqlite3.py", line 96, in __setitem__
    self._execute(STORE_KV, (key, value))
    ~~~~~~~~~~~~~^^^^^^^^^^^^^^^^^^^^^^^^
  File "/home/mrigankp/fuzz4py/cpython/Lib/dbm/sqlite3.py", line 96, in __setitem__
    self._execute(STORE_KV, (key, value))
    ~~~~~~~~~~~~~^^^^^^^^^^^^^^^^^^^^^^^^
  File "/home/mrigankp/fuzz4py/fuzz4py/inputs/790.py", line 15, in worker
    db[str(data)] = data * 2
    ~~^^^^^^^^^^^
sqlite3.ProgrammingError: SQLite objects created in a thread can only be used in that same thread. The object was created in thread id 130381227054912 and this is thread id 130379289724480.
  File "/home/mrigankp/fuzz4py/fuzz4py/inputs/790.py", line 15, in worker
    db[str(data)] = data * 2
    ~~^^^^^^^^^^^
  File "/home/mrigankp/fuzz4py/fuzz4py/inputs/790.py", line 15, in worker
    db[str(data)] = data * 2
    ~~^^^^^^^^^^^
  File "/home/mrigankp/fuzz4py/cpython/Lib/threading.py", line 992, in run
    self._target(*self._args, **self._kwargs)
    ~~~~~~~~~~~~^^^^^^^^^^^^^^^^^^^^^^^^^^^^^
dbm.sqlite3.error: SQLite objects created in a thread can only be used in that same thread. The object was created in thread id 130381227054912 and this is thread id 130380074059328.
  File "/home/mrigankp/fuzz4py/fuzz4py/inputs/790.py", line 15, in worker
    db[str(data)] = data * 2
    ~~^^^^^^^^^^^
  File "/home/mrigankp/fuzz4py/cpython/Lib/dbm/sqlite3.py", line 96, in __setitem__
    self._execute(STORE_KV, (key, value))
    ~~~~~~~~~~~~~^^^^^^^^^^^^^^^^^^^^^^^^
dbm.sqlite3.error: SQLite objects created in a thread can only be used in that same thread. The object was created in thread id 130381227054912 and this is thread id 130380709496384.
  File "/home/mrigankp/fuzz4py/cpython/Lib/threading.py", line 992, in run
    self._target(*self._args, **self._kwargs)
    ~~~~~~~~~~~~^^^^^^^^^^^^^^^^^^^^^^^^^^^^^
  File "/home/mrigankp/fuzz4py/cpython/Lib/threading.py", line 992, in run
    self._target(*self._args, **self._kwargs)
    ~~~~~~~~~~~~^^^^^^^^^^^^^^^^^^^^^^^^^^^^^
  File "/home/mrigankp/fuzz4py/cpython/Lib/dbm/sqlite3.py", line 96, in __setitem__
    self._execute(STORE_KV, (key, value))
    ~~~~~~~~~~~~~^^^^^^^^^^^^^^^^^^^^^^^^
  File "/home/mrigankp/fuzz4py/cpython/Lib/dbm/sqlite3.py", line 96, in __setitem__
    self._execute(STORE_KV, (key, value))
    ~~~~~~~~~~~~~^^^^^^^^^^^^^^^^^^^^^^^^
  File "/home/mrigankp/fuzz4py/fuzz4py/inputs/790.py", line 15, in worker
    db[str(data)] = data * 2
    ~~^^^^^^^^^^^
  File "/home/mrigankp/fuzz4py/cpython/Lib/threading.py", line 1041, in _bootstrap_inner
    self.run()
    ~~~~~~~~^^
  File "/home/mrigankp/fuzz4py/cpython/Lib/threading.py", line 992, in run
    self._target(*self._args, **self._kwargs)
    ~~~~~~~~~~~~^^^^^^^^^^^^^^^^^^^^^^^^^^^^^
  File "/home/mrigankp/fuzz4py/cpython/Lib/dbm/sqlite3.py", line 81, in _execute
    raise error(str(exc))
  File "/home/mrigankp/fuzz4py/cpython/Lib/threading.py", line 1041, in _bootstrap_inner
    self.run()
    ~~~~~~~~^^

During handling of the above exception, another exception occurred:

  File "/home/mrigankp/fuzz4py/cpython/Lib/dbm/sqlite3.py", line 81, in _execute
    raise error(str(exc))
  File "/home/mrigankp/fuzz4py/cpython/Lib/threading.py", line 1041, in _bootstrap_inner
    self.run()
    ~~~~~~~~^^
  File "/home/mrigankp/fuzz4py/cpython/Lib/threading.py", line 992, in run
    self._target(*self._args, **self._kwargs)
    ~~~~~~~~~~~~^^^^^^^^^^^^^^^^^^^^^^^^^^^^^
  File "/home/mrigankp/fuzz4py/fuzz4py/inputs/790.py", line 15, in worker
    db[str(data)] = data * 2
    ~~^^^^^^^^^^^
  File "/home/mrigankp/fuzz4py/cpython/Lib/threading.py", line 992, in run
    self._target(*self._args, **self._kwargs)
    ~~~~~~~~~~~~^^^^^^^^^^^^^^^^^^^^^^^^^^^^^
sqlite3.ProgrammingError: SQLite objects created in a thread can only be used in that same thread. The object was created in thread id 130381227054912 and this is thread id 130379247781440.
dbm.sqlite3.error: SQLite objects created in a thread can only be used in that same thread. The object was created in thread id 130381227054912 and this is thread id 130380508169792.
dbm.sqlite3.error: SQLite objects created in a thread can only be used in that same thread. The object was created in thread id 130381227054912 and this is thread id 130377890924096.
  File "/home/mrigankp/fuzz4py/cpython/Lib/threading.py", line 992, in run
    self._target(*self._args, **self._kwargs)
    ~~~~~~~~~~~~^^^^^^^^^^^^^^^^^^^^^^^^^^^^^
dbm.sqlite3.error: SQLite objects created in a thread can only be used in that same thread. The object was created in thread id 130381227054912 and this is thread id 130380466226752.
Traceback (most recent call last):
  File "/home/mrigankp/fuzz4py/cpython/Lib/threading.py", line 992, in run
    self._target(*self._args, **self._kwargs)
    ~~~~~~~~~~~~^^^^^^^^^^^^^^^^^^^^^^^^^^^^^
  File "/home/mrigankp/fuzz4py/cpython/Lib/threading.py", line 992, in run
    self._target(*self._args, **self._kwargs)
    ~~~~~~~~~~~~^^^^^^^^^^^^^^^^^^^^^^^^^^^^^
  File "/home/mrigankp/fuzz4py/cpython/Lib/dbm/sqlite3.py", line 81, in _execute
    raise error(str(exc))
  File "/home/mrigankp/fuzz4py/cpython/Lib/dbm/sqlite3.py", line 79, in _execute
    return closing(self._cx.execute(*args, **kwargs))
                   ~~~~~~~~~~~~~~~~^^^^^^^^^^^^^^^^^
  File "/home/mrigankp/fuzz4py/cpython/Lib/dbm/sqlite3.py", line 96, in __setitem__
    self._execute(STORE_KV, (key, value))
    ~~~~~~~~~~~~~^^^^^^^^^^^^^^^^^^^^^^^^
  File "/home/mrigankp/fuzz4py/cpython/Lib/dbm/sqlite3.py", line 81, in _execute
    raise error(str(exc))
  File "/home/mrigankp/fuzz4py/fuzz4py/inputs/790.py", line 15, in worker
    db[str(data)] = data * 2
    ~~^^^^^^^^^^^
dbm.sqlite3.error: SQLite objects created in a thread can only be used in that same thread. The object was created in thread id 130381227054912 and this is thread id 130380858394176.

During handling of the above exception, another exception occurred:

  File "/home/mrigankp/fuzz4py/cpython/Lib/dbm/sqlite3.py", line 96, in __setitem__
    self._execute(STORE_KV, (key, value))
    ~~~~~~~~~~~~~^^^^^^^^^^^^^^^^^^^^^^^^
  File "/home/mrigankp/fuzz4py/cpython/Lib/dbm/sqlite3.py", line 96, in __setitem__
    self._execute(STORE_KV, (key, value))
    ~~~~~~~~~~~~~^^^^^^^^^^^^^^^^^^^^^^^^
  File "/home/mrigankp/fuzz4py/cpython/Lib/dbm/sqlite3.py", line 96, in __setitem__
    self._execute(STORE_KV, (key, value))
    ~~~~~~~~~~~~~^^^^^^^^^^^^^^^^^^^^^^^^
  File "/home/mrigankp/fuzz4py/cpython/Lib/threading.py", line 1041, in _bootstrap_inner
    self.run()
    ~~~~~~~~^^
  File "/home/mrigankp/fuzz4py/cpython/Lib/dbm/sqlite3.py", line 96, in __setitem__
    self._execute(STORE_KV, (key, value))
    ~~~~~~~~~~~~~^^^^^^^^^^^^^^^^^^^^^^^^
  File "/home/mrigankp/fuzz4py/fuzz4py/inputs/790.py", line 15, in worker
    db[str(data)] = data * 2
    ~~^^^^^^^^^^^
  File "/home/mrigankp/fuzz4py/cpython/Lib/dbm/sqlite3.py", line 81, in _execute
    raise error(str(exc))
  File "/home/mrigankp/fuzz4py/fuzz4py/inputs/790.py", line 15, in worker
    db[str(data)] = data * 2
    ~~^^^^^^^^^^^
  File "/home/mrigankp/fuzz4py/fuzz4py/inputs/790.py", line 15, in worker
    db[str(data)] = data * 2
    ~~^^^^^^^^^^^
  File "/home/mrigankp/fuzz4py/cpython/Lib/dbm/sqlite3.py", line 81, in _execute
    raise error(str(exc))
  File "/home/mrigankp/fuzz4py/fuzz4py/inputs/790.py", line 15, in worker
    db[str(data)] = data * 2
    ~~^^^^^^^^^^^
  File "/home/mrigankp/fuzz4py/cpython/Lib/dbm/sqlite3.py", line 81, in _execute
    raise error(str(exc))
  File "/home/mrigankp/fuzz4py/cpython/Lib/dbm/sqlite3.py", line 81, in _execute
    raise error(str(exc))
  File "/home/mrigankp/fuzz4py/fuzz4py/inputs/790.py", line 15, in worker
    db[str(data)] = data * 2
    ~~^^^^^^^^^^^
  File "/home/mrigankp/fuzz4py/cpython/Lib/dbm/sqlite3.py", line 96, in __setitem__
    self._execute(STORE_KV, (key, value))
    ~~~~~~~~~~~~~^^^^^^^^^^^^^^^^^^^^^^^^
  File "/home/mrigankp/fuzz4py/cpython/Lib/threading.py", line 992, in run
    self._target(*self._args, **self._kwargs)
    ~~~~~~~~~~~~^^^^^^^^^^^^^^^^^^^^^^^^^^^^^
Traceback (most recent call last):
Traceback (most recent call last):
dbm.sqlite3.error: SQLite objects created in a thread can only be used in that same thread. The object was created in thread id 130381227054912 and this is thread id 130381202327104.
  File "/home/mrigankp/fuzz4py/cpython/Lib/threading.py", line 992, in run
    self._target(*self._args, **self._kwargs)
    ~~~~~~~~~~~~^^^^^^^^^^^^^^^^^^^^^^^^^^^^^
  File "/home/mrigankp/fuzz4py/fuzz4py/inputs/790.py", line 15, in worker
    db[str(data)] = data * 2
    ~~^^^^^^^^^^^
  File "/home/mrigankp/fuzz4py/cpython/Lib/dbm/sqlite3.py", line 81, in _execute
    raise error(str(exc))
  File "/home/mrigankp/fuzz4py/cpython/Lib/dbm/sqlite3.py", line 96, in __setitem__
    self._execute(STORE_KV, (key, value))
    ~~~~~~~~~~~~~^^^^^^^^^^^^^^^^^^^^^^^^
  File "/home/mrigankp/fuzz4py/cpython/Lib/threading.py", line 992, in run
    self._target(*self._args, **self._kwargs)
    ~~~~~~~~~~~~^^^^^^^^^^^^^^^^^^^^^^^^^^^^^
  File "/home/mrigankp/fuzz4py/fuzz4py/inputs/790.py", line 15, in worker
    db[str(data)] = data * 2
    ~~^^^^^^^^^^^
  File "/home/mrigankp/fuzz4py/cpython/Lib/threading.py", line 1041, in _bootstrap_inner
    self.run()
    ~~~~~~~~^^
  File "/home/mrigankp/fuzz4py/cpython/Lib/dbm/sqlite3.py", line 96, in __setitem__
    self._execute(STORE_KV, (key, value))
    ~~~~~~~~~~~~~^^^^^^^^^^^^^^^^^^^^^^^^
  File "/home/mrigankp/fuzz4py/fuzz4py/inputs/790.py", line 15, in worker
    db[str(data)] = data * 2
    ~~^^^^^^^^^^^
  File "/home/mrigankp/fuzz4py/cpython/Lib/dbm/sqlite3.py", line 81, in _execute
    raise error(str(exc))
  File "/home/mrigankp/fuzz4py/cpython/Lib/threading.py", line 1041, in _bootstrap_inner
    self.run()
    ~~~~~~~~^^
  File "/home/mrigankp/fuzz4py/fuzz4py/inputs/790.py", line 15, in worker
    db[str(data)] = data * 2
    ~~^^^^^^^^^^^
  File "/home/mrigankp/fuzz4py/fuzz4py/inputs/790.py", line 15, in worker
    db[str(data)] = data * 2
    ~~^^^^^^^^^^^
dbm.sqlite3.error: SQLite objects created in a thread can only be used in that same thread. The object was created in thread id 130381227054912 and this is thread id 130380455740992.
Traceback (most recent call last):
  File "/home/mrigankp/fuzz4py/cpython/Lib/dbm/sqlite3.py", line 81, in _execute
    raise error(str(exc))
  File "/home/mrigankp/fuzz4py/cpython/Lib/dbm/sqlite3.py", line 96, in __setitem__
    self._execute(STORE_KV, (key, value))
    ~~~~~~~~~~~~~^^^^^^^^^^^^^^^^^^^^^^^^
  File "/home/mrigankp/fuzz4py/cpython/Lib/dbm/sqlite3.py", line 96, in __setitem__
    self._execute(STORE_KV, (key, value))
    ~~~~~~~~~~~~~^^^^^^^^^^^^^^^^^^^^^^^^
  File "/home/mrigankp/fuzz4py/cpython/Lib/dbm/sqlite3.py", line 81, in _execute
    raise error(str(exc))
  File "/home/mrigankp/fuzz4py/fuzz4py/inputs/790.py", line 15, in worker
    db[str(data)] = data * 2
    ~~^^^^^^^^^^^
  File "/home/mrigankp/fuzz4py/cpython/Lib/dbm/sqlite3.py", line 81, in _execute
    raise error(str(exc))
  File "/home/mrigankp/fuzz4py/cpython/Lib/dbm/sqlite3.py", line 81, in _execute
    raise error(str(exc))
  File "/home/mrigankp/fuzz4py/cpython/Lib/dbm/sqlite3.py", line 96, in __setitem__
    self._execute(STORE_KV, (key, value))
    ~~~~~~~~~~~~~^^^^^^^^^^^^^^^^^^^^^^^^

During handling of the above exception, another exception occurred:


During handling of the above exception, another exception occurred:

  File "/home/mrigankp/fuzz4py/cpython/Lib/dbm/sqlite3.py", line 96, in __setitem__
    self._execute(STORE_KV, (key, value))
    ~~~~~~~~~~~~~^^^^^^^^^^^^^^^^^^^^^^^^
  File "/home/mrigankp/fuzz4py/cpython/Lib/dbm/sqlite3.py", line 96, in __setitem__
    self._execute(STORE_KV, (key, value))
    ~~~~~~~~~~~~~^^^^^^^^^^^^^^^^^^^^^^^^
  File "/home/mrigankp/fuzz4py/cpython/Lib/dbm/sqlite3.py", line 96, in __setitem__
    self._execute(STORE_KV, (key, value))
    ~~~~~~~~~~~~~^^^^^^^^^^^^^^^^^^^^^^^^
  File "/home/mrigankp/fuzz4py/cpython/Lib/threading.py", line 992, in run
    self._target(*self._args, **self._kwargs)
    ~~~~~~~~~~~~^^^^^^^^^^^^^^^^^^^^^^^^^^^^^
dbm.sqlite3.error: SQLite objects created in a thread can only be used in that same thread. The object was created in thread id 130381227054912 and this is thread id 130379681891904.
  File "/home/mrigankp/fuzz4py/fuzz4py/inputs/790.py", line 15, in worker
    db[str(data)] = data * 2
    ~~^^^^^^^^^^^
dbm.sqlite3.error: SQLite objects created in a thread can only be used in that same thread. The object was created in thread id 130381227054912 and this is thread id 130380306843200.
  File "/home/mrigankp/fuzz4py/cpython/Lib/dbm/sqlite3.py", line 81, in _execute
    raise error(str(exc))
  File "/home/mrigankp/fuzz4py/fuzz4py/inputs/790.py", line 15, in worker
    db[str(data)] = data * 2
    ~~^^^^^^^^^^^
  File "/home/mrigankp/fuzz4py/cpython/Lib/dbm/sqlite3.py", line 81, in _execute
    raise error(str(exc))
dbm.sqlite3.error: SQLite objects created in a thread can only be used in that same thread. The object was created in thread id 130381227054912 and this is thread id 130378845128256.
  File "/home/mrigankp/fuzz4py/cpython/Lib/threading.py", line 1041, in _bootstrap_inner
    self.run()
    ~~~~~~~~^^
dbm.sqlite3.error: SQLite objects created in a thread can only be used in that same thread. The object was created in thread id 130381227054912 and this is thread id 130380105516608.
  File "/home/mrigankp/fuzz4py/cpython/Lib/dbm/sqlite3.py", line 81, in _execute
    raise error(str(exc))
  File "/home/mrigankp/fuzz4py/cpython/Lib/dbm/sqlite3.py", line 96, in __setitem__
    self._execute(STORE_KV, (key, value))
    ~~~~~~~~~~~~~^^^^^^^^^^^^^^^^^^^^^^^^
  File "/home/mrigankp/fuzz4py/cpython/Lib/dbm/sqlite3.py", line 96, in __setitem__
    self._execute(STORE_KV, (key, value))
    ~~~~~~~~~~~~~^^^^^^^^^^^^^^^^^^^^^^^^
  File "/home/mrigankp/fuzz4py/cpython/Lib/threading.py", line 992, in run
    self._target(*self._args, **self._kwargs)
    ~~~~~~~~~~~~^^^^^^^^^^^^^^^^^^^^^^^^^^^^^
  File "/home/mrigankp/fuzz4py/cpython/Lib/dbm/sqlite3.py", line 81, in _execute
    raise error(str(exc))
  File "/home/mrigankp/fuzz4py/cpython/Lib/threading.py", line 992, in run
    self._target(*self._args, **self._kwargs)
    ~~~~~~~~~~~~^^^^^^^^^^^^^^^^^^^^^^^^^^^^^
dbm.sqlite3.error: SQLite objects created in a thread can only be used in that same thread. The object was created in thread id 130381227054912 and this is thread id 130381112149568.
  File "/home/mrigankp/fuzz4py/cpython/Lib/dbm/sqlite3.py", line 96, in __setitem__
    self._execute(STORE_KV, (key, value))
    ~~~~~~~~~~~~~^^^^^^^^^^^^^^^^^^^^^^^^
  File "/home/mrigankp/fuzz4py/cpython/Lib/dbm/sqlite3.py", line 96, in __setitem__
    self._execute(STORE_KV, (key, value))
    ~~~~~~~~~~~~~^^^^^^^^^^^^^^^^^^^^^^^^
dbm.sqlite3.error: SQLite objects created in a thread can only be used in that same thread. The object was created in thread id 130381227054912 and this is thread id 130380688524864.
dbm.sqlite3.error: SQLite objects created in a thread can only be used in that same thread. The object was created in thread id 130381227054912 and this is thread id 130378484418112.
  File "/home/mrigankp/fuzz4py/cpython/Lib/dbm/sqlite3.py", line 96, in __setitem__
    self._execute(STORE_KV, (key, value))
    ~~~~~~~~~~~~~^^^^^^^^^^^^^^^^^^^^^^^^
  File "/home/mrigankp/fuzz4py/cpython/Lib/dbm/sqlite3.py", line 81, in _execute
    raise error(str(exc))
  File "/home/mrigankp/fuzz4py/cpython/Lib/dbm/sqlite3.py", line 81, in _execute
    raise error(str(exc))
dbm.sqlite3.error: SQLite objects created in a thread can only be used in that same thread. The object was created in thread id 130381227054912 and this is thread id 130378463446592.
  File "/home/mrigankp/fuzz4py/cpython/Lib/dbm/sqlite3.py", line 96, in __setitem__
    self._execute(STORE_KV, (key, value))
    ~~~~~~~~~~~~~^^^^^^^^^^^^^^^^^^^^^^^^
  File "/home/mrigankp/fuzz4py/cpython/Lib/threading.py", line 992, in run
    self._target(*self._args, **self._kwargs)
    ~~~~~~~~~~~~^^^^^^^^^^^^^^^^^^^^^^^^^^^^^
dbm.sqlite3.error: SQLite objects created in a thread can only be used in that same thread. The object was created in thread id 130381227054912 and this is thread id 130381059720768.
  File "/home/mrigankp/fuzz4py/cpython/Lib/dbm/sqlite3.py", line 81, in _execute
    raise error(str(exc))
Traceback (most recent call last):
  File "/home/mrigankp/fuzz4py/cpython/Lib/threading.py", line 992, in run
    self._target(*self._args, **self._kwargs)
    ~~~~~~~~~~~~^^^^^^^^^^^^^^^^^^^^^^^^^^^^^
  File "/home/mrigankp/fuzz4py/cpython/Lib/dbm/sqlite3.py", line 81, in _execute
    raise error(str(exc))
  File "/home/mrigankp/fuzz4py/cpython/Lib/dbm/sqlite3.py", line 81, in _execute
    raise error(str(exc))
dbm.sqlite3.error: SQLite objects created in a thread can only be used in that same thread. The object was created in thread id 130381227054912 and this is thread id 130379279238720.
  File "/home/mrigankp/fuzz4py/cpython/Lib/dbm/sqlite3.py", line 96, in __setitem__
    self._execute(STORE_KV, (key, value))
    ~~~~~~~~~~~~~^^^^^^^^^^^^^^^^^^^^^^^^
  File "/home/mrigankp/fuzz4py/fuzz4py/inputs/790.py", line 15, in worker
    db[str(data)] = data * 2
    ~~^^^^^^^^^^^
dbm.sqlite3.error: SQLite objects created in a thread can only be used in that same thread. The object was created in thread id 130381227054912 and this is thread id 130380264900160.
  File "/home/mrigankp/fuzz4py/cpython/Lib/dbm/sqlite3.py", line 96, in __setitem__
    self._execute(STORE_KV, (key, value))
    ~~~~~~~~~~~~~^^^^^^^^^^^^^^^^^^^^^^^^
  File "/home/mrigankp/fuzz4py/cpython/Lib/threading.py", line 1041, in _bootstrap_inner
    self.run()
    ~~~~~~~~^^
  File "/home/mrigankp/fuzz4py/cpython/Lib/dbm/sqlite3.py", line 96, in __setitem__
    self._execute(STORE_KV, (key, value))
    ~~~~~~~~~~~~~^^^^^^^^^^^^^^^^^^^^^^^^
  File "/home/mrigankp/fuzz4py/cpython/Lib/dbm/sqlite3.py", line 81, in _execute
    raise error(str(exc))
  File "/home/mrigankp/fuzz4py/cpython/Lib/threading.py", line 1041, in _bootstrap_inner
    self.run()
    ~~~~~~~~^^
  File "/home/mrigankp/fuzz4py/cpython/Lib/dbm/sqlite3.py", line 96, in __setitem__
    self._execute(STORE_KV, (key, value))
    ~~~~~~~~~~~~~^^^^^^^^^^^^^^^^^^^^^^^^
  File "/home/mrigankp/fuzz4py/fuzz4py/inputs/790.py", line 15, in worker
    db[str(data)] = data * 2
    ~~^^^^^^^^^^^
  File "/home/mrigankp/fuzz4py/cpython/Lib/threading.py", line 992, in run
    self._target(*self._args, **self._kwargs)
    ~~~~~~~~~~~~^^^^^^^^^^^^^^^^^^^^^^^^^^^^^
  File "/home/mrigankp/fuzz4py/cpython/Lib/dbm/sqlite3.py", line 81, in _execute
    raise error(str(exc))

During handling of the above exception, another exception occurred:

  File "/home/mrigankp/fuzz4py/fuzz4py/inputs/790.py", line 15, in worker
    db[str(data)] = data * 2
    ~~^^^^^^^^^^^
dbm.sqlite3.error: SQLite objects created in a thread can only be used in that same thread. The object was created in thread id 130381227054912 and this is thread id 130378643801664.
  File "/home/mrigankp/fuzz4py/fuzz4py/inputs/790.py", line 15, in worker
    db[str(data)] = data * 2
    ~~^^^^^^^^^^^
sqlite3.ProgrammingError: SQLite objects created in a thread can only be used in that same thread. The object was created in thread id 130381227054912 and this is thread id 130378283091520.
  File "/home/mrigankp/fuzz4py/cpython/Lib/dbm/sqlite3.py", line 81, in _execute
    raise error(str(exc))
  File "/home/mrigankp/fuzz4py/cpython/Lib/threading.py", line 1041, in _bootstrap_inner
    self.run()
    ~~~~~~~~^^
  File "/home/mrigankp/fuzz4py/fuzz4py/inputs/790.py", line 15, in worker
    db[str(data)] = data * 2
    ~~^^^^^^^^^^^
Traceback (most recent call last):
Traceback (most recent call last):
dbm.sqlite3.error: SQLite objects created in a thread can only be used in that same thread. The object was created in thread id 130381227054912 and this is thread id 130379449108032.
  File "/home/mrigankp/fuzz4py/cpython/Lib/dbm/sqlite3.py", line 81, in _execute
    raise error(str(exc))
  File "/home/mrigankp/fuzz4py/fuzz4py/inputs/790.py", line 15, in worker
    db[str(data)] = data * 2
    ~~^^^^^^^^^^^
dbm.sqlite3.error: SQLite objects created in a thread can only be used in that same thread. The object was created in thread id 130381227054912 and this is thread id 130380667553344.
dbm.sqlite3.error: SQLite objects created in a thread can only be used in that same thread. The object was created in thread id 130381227054912 and this is thread id 130380063573568.
  File "/home/mrigankp/fuzz4py/fuzz4py/inputs/790.py", line 15, in worker
    db[str(data)] = data * 2
    ~~^^^^^^^^^^^
  File "/home/mrigankp/fuzz4py/cpython/Lib/dbm/sqlite3.py", line 96, in __setitem__
    self._execute(STORE_KV, (key, value))
    ~~~~~~~~~~~~~^^^^^^^^^^^^^^^^^^^^^^^^
  File "/home/mrigankp/fuzz4py/fuzz4py/inputs/790.py", line 15, in worker
    db[str(data)] = data * 2
    ~~^^^^^^^^^^^
dbm.sqlite3.error: SQLite objects created in a thread can only be used in that same thread. The object was created in thread id 130381227054912 and this is thread id 130378866099776.
  File "/home/mrigankp/fuzz4py/cpython/Lib/dbm/sqlite3.py", line 81, in _execute
    raise error(str(exc))
  File "/home/mrigankp/fuzz4py/cpython/Lib/dbm/sqlite3.py", line 81, in _execute
    raise error(str(exc))
  File "/home/mrigankp/fuzz4py/cpython/Lib/dbm/sqlite3.py", line 96, in __setitem__
    self._execute(STORE_KV, (key, value))
    ~~~~~~~~~~~~~^^^^^^^^^^^^^^^^^^^^^^^^
  File "/home/mrigankp/fuzz4py/cpython/Lib/dbm/sqlite3.py", line 96, in __setitem__
    self._execute(STORE_KV, (key, value))
    ~~~~~~~~~~~~~^^^^^^^^^^^^^^^^^^^^^^^^
  File "/home/mrigankp/fuzz4py/cpython/Lib/dbm/sqlite3.py", line 81, in _execute
    raise error(str(exc))
  File "/home/mrigankp/fuzz4py/cpython/Lib/threading.py", line 992, in run
    self._target(*self._args, **self._kwargs)
    ~~~~~~~~~~~~^^^^^^^^^^^^^^^^^^^^^^^^^^^^^
  File "/home/mrigankp/fuzz4py/cpython/Lib/threading.py", line 1041, in _bootstrap_inner
    self.run()
    ~~~~~~~~^^
dbm.sqlite3.error: SQLite objects created in a thread can only be used in that same thread. The object was created in thread id 130381227054912 and this is thread id 130380497684032.
  File "/home/mrigankp/fuzz4py/cpython/Lib/threading.py", line 992, in run
    self._target(*self._args, **self._kwargs)
    ~~~~~~~~~~~~^^^^^^^^^^^^^^^^^^^^^^^^^^^^^
dbm.sqlite3.error: SQLite objects created in a thread can only be used in that same thread. The object was created in thread id 130381227054912 and this is thread id 130380476712512.
  File "/home/mrigankp/fuzz4py/cpython/Lib/dbm/sqlite3.py", line 81, in _execute
    raise error(str(exc))
dbm.sqlite3.error: SQLite objects created in a thread can only be used in that same thread. The object was created in thread id 130381227054912 and this is thread id 130378654287424.
  File "/home/mrigankp/fuzz4py/cpython/Lib/dbm/sqlite3.py", line 96, in __setitem__
    self._execute(STORE_KV, (key, value))
    ~~~~~~~~~~~~~^^^^^^^^^^^^^^^^^^^^^^^^
  File "/home/mrigankp/fuzz4py/fuzz4py/inputs/790.py", line 15, in worker
    db[str(data)] = data * 2
    ~~^^^^^^^^^^^
dbm.sqlite3.error: SQLite objects created in a thread can only be used in that same thread. The object was created in thread id 130381227054912 and this is thread id 130378685744704.
Traceback (most recent call last):
  File "/home/mrigankp/fuzz4py/cpython/Lib/dbm/sqlite3.py", line 96, in __setitem__
    self._execute(STORE_KV, (key, value))
    ~~~~~~~~~~~~~^^^^^^^^^^^^^^^^^^^^^^^^
  File "/home/mrigankp/fuzz4py/cpython/Lib/threading.py", line 992, in run
    self._target(*self._args, **self._kwargs)
    ~~~~~~~~~~~~^^^^^^^^^^^^^^^^^^^^^^^^^^^^^
  File "/home/mrigankp/fuzz4py/cpython/Lib/dbm/sqlite3.py", line 96, in __setitem__
    self._execute(STORE_KV, (key, value))
    ~~~~~~~~~~~~~^^^^^^^^^^^^^^^^^^^^^^^^

During handling of the above exception, another exception occurred:

dbm.sqlite3.error: SQLite objects created in a thread can only be used in that same thread. The object was created in thread id 130381227054912 and this is thread id 130379088397888.
  File "/home/mrigankp/fuzz4py/cpython/Lib/dbm/sqlite3.py", line 81, in _execute
    raise error(str(exc))
dbm.sqlite3.error: SQLite objects created in a thread can only be used in that same thread. The object was created in thread id 130381227054912 and this is thread id 130380084545088.
  File "/home/mrigankp/fuzz4py/cpython/Lib/dbm/sqlite3.py", line 81, in _execute
    raise error(str(exc))
  File "/home/mrigankp/fuzz4py/cpython/Lib/threading.py", line 992, in run
    self._target(*self._args, **self._kwargs)
    ~~~~~~~~~~~~^^^^^^^^^^^^^^^^^^^^^^^^^^^^^
  File "/home/mrigankp/fuzz4py/cpython/Lib/threading.py", line 1041, in _bootstrap_inner
    self.run()
    ~~~~~~~~^^
  File "/home/mrigankp/fuzz4py/cpython/Lib/threading.py", line 1041, in _bootstrap_inner
    self.run()
    ~~~~~~~~^^
dbm.sqlite3.error: SQLite objects created in a thread can only be used in that same thread. The object was created in thread id 130381227054912 and this is thread id 130379692377664.
Traceback (most recent call last):
  File "/home/mrigankp/fuzz4py/cpython/Lib/threading.py", line 1041, in _bootstrap_inner
    self.run()
    ~~~~~~~~^^
  File "/home/mrigankp/fuzz4py/cpython/Lib/dbm/sqlite3.py", line 81, in _execute
    raise error(str(exc))
dbm.sqlite3.error: SQLite objects created in a thread can only be used in that same thread. The object was created in thread id 130381227054912 and this is thread id 130378092250688.
dbm.sqlite3.error: SQLite objects created in a thread can only be used in that same thread. The object was created in thread id 130381227054912 and this is thread id 130380487198272.
  File "/home/mrigankp/fuzz4py/cpython/Lib/dbm/sqlite3.py", line 81, in _execute
    raise error(str(exc))
  File "/home/mrigankp/fuzz4py/cpython/Lib/dbm/sqlite3.py", line 81, in _execute
    raise error(str(exc))
dbm.sqlite3.error: SQLite objects created in a thread can only be used in that same thread. The object was created in thread id 130381227054912 and this is thread id 130379268752960.
  File "/home/mrigankp/fuzz4py/fuzz4py/inputs/790.py", line 15, in worker
    db[str(data)] = data * 2
    ~~^^^^^^^^^^^
dbm.sqlite3.error: SQLite objects created in a thread can only be used in that same thread. The object was created in thread id 130381227054912 and this is thread id 130378039821888.
  File "/home/mrigankp/fuzz4py/fuzz4py/inputs/790.py", line 15, in worker
    db[str(data)] = data * 2
    ~~^^^^^^^^^^^
  File "/home/mrigankp/fuzz4py/fuzz4py/inputs/790.py", line 15, in worker
    db[str(data)] = data * 2
    ~~^^^^^^^^^^^
  File "/home/mrigankp/fuzz4py/cpython/Lib/dbm/sqlite3.py", line 96, in __setitem__
    self._execute(STORE_KV, (key, value))
    ~~~~~~~~~~~~~^^^^^^^^^^^^^^^^^^^^^^^^
  File "/home/mrigankp/fuzz4py/fuzz4py/inputs/790.py", line 15, in worker
    db[str(data)] = data * 2
    ~~^^^^^^^^^^^
  File "/home/mrigankp/fuzz4py/cpython/Lib/dbm/sqlite3.py", line 81, in _execute
    raise error(str(exc))
  File "/home/mrigankp/fuzz4py/fuzz4py/inputs/790.py", line 15, in worker
    db[str(data)] = data * 2
    ~~^^^^^^^^^^^
  File "/home/mrigankp/fuzz4py/cpython/Lib/dbm/sqlite3.py", line 96, in __setitem__
    self._execute(STORE_KV, (key, value))
    ~~~~~~~~~~~~~^^^^^^^^^^^^^^^^^^^^^^^^
  File "/home/mrigankp/fuzz4py/cpython/Lib/dbm/sqlite3.py", line 81, in _execute
    raise error(str(exc))
  File "/home/mrigankp/fuzz4py/cpython/Lib/threading.py", line 992, in run
    self._target(*self._args, **self._kwargs)
    ~~~~~~~~~~~~^^^^^^^^^^^^^^^^^^^^^^^^^^^^^
dbm.sqlite3.error: SQLite objects created in a thread can only be used in that same thread. The object was created in thread id 130381227054912 and this is thread id 130379056940608.
dbm.sqlite3.error: SQLite objects created in a thread can only be used in that same thread. The object was created in thread id 130381227054912 and this is thread id 130380275385920.
  File "/home/mrigankp/fuzz4py/cpython/Lib/dbm/sqlite3.py", line 96, in __setitem__
    self._execute(STORE_KV, (key, value))
    ~~~~~~~~~~~~~^^^^^^^^^^^^^^^^^^^^^^^^
  File "/home/mrigankp/fuzz4py/cpython/Lib/threading.py", line 992, in run
    self._target(*self._args, **self._kwargs)
    ~~~~~~~~~~~~^^^^^^^^^^^^^^^^^^^^^^^^^^^^^
  File "/home/mrigankp/fuzz4py/cpython/Lib/dbm/sqlite3.py", line 96, in __setitem__
    self._execute(STORE_KV, (key, value))
    ~~~~~~~~~~~~~^^^^^^^^^^^^^^^^^^^^^^^^
  File "/home/mrigankp/fuzz4py/cpython/Lib/threading.py", line 992, in run
    self._target(*self._args, **self._kwargs)
    ~~~~~~~~~~~~^^^^^^^^^^^^^^^^^^^^^^^^^^^^^
  File "/home/mrigankp/fuzz4py/cpython/Lib/dbm/sqlite3.py", line 96, in __setitem__
    self._execute(STORE_KV, (key, value))
    ~~~~~~~~~~~~~^^^^^^^^^^^^^^^^^^^^^^^^
dbm.sqlite3.error: SQLite objects created in a thread can only be used in that same thread. The object was created in thread id 130381227054912 and this is thread id 130378897557056.
dbm.sqlite3.error: SQLite objects created in a thread can only be used in that same thread. The object was created in thread id 130381227054912 and this is thread id 130378272605760.
dbm.sqlite3.error: SQLite objects created in a thread can only be used in that same thread. The object was created in thread id 130381227054912 and this is thread id 130380254414400.
  File "/home/mrigankp/fuzz4py/cpython/Lib/threading.py", line 992, in run
    self._target(*self._args, **self._kwargs)
    ~~~~~~~~~~~~^^^^^^^^^^^^^^^^^^^^^^^^^^^^^
  File "/home/mrigankp/fuzz4py/cpython/Lib/threading.py", line 992, in run
    self._target(*self._args, **self._kwargs)
    ~~~~~~~~~~~~^^^^^^^^^^^^^^^^^^^^^^^^^^^^^
  File "/home/mrigankp/fuzz4py/cpython/Lib/threading.py", line 992, in run
    self._target(*self._args, **self._kwargs)
    ~~~~~~~~~~~~^^^^^^^^^^^^^^^^^^^^^^^^^^^^^
dbm.sqlite3.error: SQLite objects created in a thread can only be used in that same thread. The object was created in thread id 130381227054912 and this is thread id 130379501536832.
  File "/home/mrigankp/fuzz4py/fuzz4py/inputs/790.py", line 15, in worker
    db[str(data)] = data * 2
    ~~^^^^^^^^^^^
  File "/home/mrigankp/fuzz4py/cpython/Lib/dbm/sqlite3.py", line 96, in __setitem__
    self._execute(STORE_KV, (key, value))
    ~~~~~~~~~~~~~^^^^^^^^^^^^^^^^^^^^^^^^
  File "/home/mrigankp/fuzz4py/cpython/Lib/threading.py", line 1041, in _bootstrap_inner
    self.run()
    ~~~~~~~~^^
dbm.sqlite3.error: SQLite objects created in a thread can only be used in that same thread. The object was created in thread id 130381227054912 and this is thread id 130380095030848.
dbm.sqlite3.error: SQLite objects created in a thread can only be used in that same thread. The object was created in thread id 130381227054912 and this is thread id 130378452960832.
Traceback (most recent call last):
dbm.sqlite3.error: SQLite objects created in a thread can only be used in that same thread. The object was created in thread id 130381227054912 and this is thread id 130378473932352.
  File "/home/mrigankp/fuzz4py/fuzz4py/inputs/790.py", line 15, in worker
    db[str(data)] = data * 2
    ~~^^^^^^^^^^^
dbm.sqlite3.error: SQLite objects created in a thread can only be used in that same thread. The object was created in thread id 130381227054912 and this is thread id 130380889851456.
  File "/home/mrigankp/fuzz4py/fuzz4py/inputs/790.py", line 15, in worker
    db[str(data)] = data * 2
    ~~^^^^^^^^^^^
  File "/home/mrigankp/fuzz4py/cpython/Lib/dbm/sqlite3.py", line 96, in __setitem__
    self._execute(STORE_KV, (key, value))
    ~~~~~~~~~~~~~^^^^^^^^^^^^^^^^^^^^^^^^
  File "/home/mrigankp/fuzz4py/cpython/Lib/threading.py", line 1041, in _bootstrap_inner
    self.run()
    ~~~~~~~~^^
  File "/home/mrigankp/fuzz4py/cpython/Lib/dbm/sqlite3.py", line 81, in _execute
    raise error(str(exc))
  File "/home/mrigankp/fuzz4py/fuzz4py/inputs/790.py", line 15, in worker
    db[str(data)] = data * 2
    ~~^^^^^^^^^^^
  File "/home/mrigankp/fuzz4py/cpython/Lib/dbm/sqlite3.py", line 96, in __setitem__
    self._execute(STORE_KV, (key, value))
    ~~~~~~~~~~~~~^^^^^^^^^^^^^^^^^^^^^^^^
  File "/home/mrigankp/fuzz4py/cpython/Lib/dbm/sqlite3.py", line 81, in _execute
    raise error(str(exc))
dbm.sqlite3.error: SQLite objects created in a thread can only be used in that same thread. The object was created in thread id 130381227054912 and this is thread id 130378071279168.
  File "/home/mrigankp/fuzz4py/fuzz4py/inputs/790.py", line 15, in worker
    db[str(data)] = data * 2
    ~~^^^^^^^^^^^
  File "/home/mrigankp/fuzz4py/fuzz4py/inputs/790.py", line 15, in worker
    db[str(data)] = data * 2
    ~~^^^^^^^^^^^
  File "/home/mrigankp/fuzz4py/cpython/Lib/dbm/sqlite3.py", line 81, in _execute
    raise error(str(exc))
  File "/home/mrigankp/fuzz4py/cpython/Lib/dbm/sqlite3.py", line 81, in _execute
    raise error(str(exc))
  File "/home/mrigankp/fuzz4py/cpython/Lib/dbm/sqlite3.py", line 96, in __setitem__
    self._execute(STORE_KV, (key, value))
    ~~~~~~~~~~~~~^^^^^^^^^^^^^^^^^^^^^^^^
  File "/home/mrigankp/fuzz4py/cpython/Lib/dbm/sqlite3.py", line 81, in _execute
    raise error(str(exc))
  File "/home/mrigankp/fuzz4py/cpython/Lib/dbm/sqlite3.py", line 81, in _execute
    raise error(str(exc))
  File "/home/mrigankp/fuzz4py/cpython/Lib/threading.py", line 992, in run
    self._target(*self._args, **self._kwargs)
    ~~~~~~~~~~~~^^^^^^^^^^^^^^^^^^^^^^^^^^^^^
  File "/home/mrigankp/fuzz4py/cpython/Lib/dbm/sqlite3.py", line 96, in __setitem__
    self._execute(STORE_KV, (key, value))
    ~~~~~~~~~~~~~^^^^^^^^^^^^^^^^^^^^^^^^
  File "/home/mrigankp/fuzz4py/cpython/Lib/dbm/sqlite3.py", line 96, in __setitem__
    self._execute(STORE_KV, (key, value))
    ~~~~~~~~~~~~~^^^^^^^^^^^^^^^^^^^^^^^^
  File "/home/mrigankp/fuzz4py/cpython/Lib/dbm/sqlite3.py", line 81, in _execute
    raise error(str(exc))
  File "/home/mrigankp/fuzz4py/cpython/Lib/dbm/sqlite3.py", line 81, in _execute
    raise error(str(exc))
  File "/home/mrigankp/fuzz4py/cpython/Lib/dbm/sqlite3.py", line 81, in _execute
    raise error(str(exc))
  File "/home/mrigankp/fuzz4py/cpython/Lib/threading.py", line 1041, in _bootstrap_inner
    self.run()
    ~~~~~~~~^^
  File "/home/mrigankp/fuzz4py/fuzz4py/inputs/790.py", line 15, in worker
    db[str(data)] = data * 2
    ~~^^^^^^^^^^^
  File "/home/mrigankp/fuzz4py/cpython/Lib/dbm/sqlite3.py", line 96, in __setitem__
    self._execute(STORE_KV, (key, value))
    ~~~~~~~~~~~~~^^^^^^^^^^^^^^^^^^^^^^^^
  File "/home/mrigankp/fuzz4py/cpython/Lib/dbm/sqlite3.py", line 96, in __setitem__
    self._execute(STORE_KV, (key, value))
    ~~~~~~~~~~~~~^^^^^^^^^^^^^^^^^^^^^^^^
  File "/home/mrigankp/fuzz4py/cpython/Lib/dbm/sqlite3.py", line 96, in __setitem__
    self._execute(STORE_KV, (key, value))
    ~~~~~~~~~~~~~^^^^^^^^^^^^^^^^^^^^^^^^
  File "/home/mrigankp/fuzz4py/cpython/Lib/dbm/sqlite3.py", line 96, in __setitem__
    self._execute(STORE_KV, (key, value))
    ~~~~~~~~~~~~~^^^^^^^^^^^^^^^^^^^^^^^^
dbm.sqlite3.error: SQLite objects created in a thread can only be used in that same thread. The object was created in thread id 130381227054912 and this is thread id 130379480565312.
  File "/home/mrigankp/fuzz4py/cpython/Lib/dbm/sqlite3.py", line 81, in _execute
    raise error(str(exc))
dbm.sqlite3.error: SQLite objects created in a thread can only be used in that same thread. The object was created in thread id 130381227054912 and this is thread id 130379862246976.
dbm.sqlite3.error: SQLite objects created in a thread can only be used in that same thread. The object was created in thread id 130381227054912 and this is thread id 130379067426368.
  File "/home/mrigankp/fuzz4py/fuzz4py/inputs/790.py", line 15, in worker
    db[str(data)] = data * 2
    ~~^^^^^^^^^^^
  File "/home/mrigankp/fuzz4py/cpython/Lib/dbm/sqlite3.py", line 81, in _execute
    raise error(str(exc))
  File "/home/mrigankp/fuzz4py/cpython/Lib/dbm/sqlite3.py", line 81, in _execute
    raise error(str(exc))
  File "/home/mrigankp/fuzz4py/fuzz4py/inputs/790.py", line 15, in worker
    db[str(data)] = data * 2
    ~~^^^^^^^^^^^
dbm.sqlite3.error: SQLite objects created in a thread can only be used in that same thread. The object was created in thread id 130381227054912 and this is thread id 130378876585536.
dbm.sqlite3.error: SQLite objects created in a thread can only be used in that same thread. The object was created in thread id 130381227054912 and this is thread id 130378262120000.
dbm.sqlite3.error: SQLite objects created in a thread can only be used in that same thread. The object was created in thread id 130381227054912 and this is thread id 130378251634240.
  File "/home/mrigankp/fuzz4py/cpython/Lib/dbm/sqlite3.py", line 96, in __setitem__
    self._execute(STORE_KV, (key, value))
    ~~~~~~~~~~~~~^^^^^^^^^^^^^^^^^^^^^^^^
  File "/home/mrigankp/fuzz4py/cpython/Lib/dbm/sqlite3.py", line 81, in _execute
    raise error(str(exc))
  File "/home/mrigankp/fuzz4py/cpython/Lib/dbm/sqlite3.py", line 81, in _execute
    raise error(str(exc))
dbm.sqlite3.error: SQLite objects created in a thread can only be used in that same thread. The object was created in thread id 130381227054912 and this is thread id 130378664773184.
  File "/home/mrigankp/fuzz4py/cpython/Lib/dbm/sqlite3.py", line 81, in _execute
    raise error(str(exc))
  File "/home/mrigankp/fuzz4py/cpython/Lib/dbm/sqlite3.py", line 81, in _execute
    raise error(str(exc))
dbm.sqlite3.error: SQLite objects created in a thread can only be used in that same thread. The object was created in thread id 130381227054912 and this is thread id 130378494903872.
  File "/home/mrigankp/fuzz4py/cpython/Lib/dbm/sqlite3.py", line 81, in _execute
    raise error(str(exc))
  File "/home/mrigankp/fuzz4py/cpython/Lib/threading.py", line 1041, in _bootstrap_inner
    self.run()
    ~~~~~~~~^^
dbm.sqlite3.error: SQLite objects created in a thread can only be used in that same thread. The object was created in thread id 130381227054912 and this is thread id 130379702863424.
dbm.sqlite3.error: SQLite objects created in a thread can only be used in that same thread. The object was created in thread id 130381227054912 and this is thread id 130379671406144.
dbm.sqlite3.error: SQLite objects created in a thread can only be used in that same thread. The object was created in thread id 130381227054912 and this is thread id 130379300210240.
  File "/home/mrigankp/fuzz4py/cpython/Lib/threading.py", line 992, in run
    self._target(*self._args, **self._kwargs)
    ~~~~~~~~~~~~^^^^^^^^^^^^^^^^^^^^^^^^^^^^^
  File "/home/mrigankp/fuzz4py/cpython/Lib/threading.py", line 992, in run
    self._target(*self._args, **self._kwargs)
    ~~~~~~~~~~~~^^^^^^^^^^^^^^^^^^^^^^^^^^^^^
  File "/home/mrigankp/fuzz4py/cpython/Lib/dbm/sqlite3.py", line 81, in _execute
    raise error(str(exc))
dbm.sqlite3.error: SQLite objects created in a thread can only be used in that same thread. The object was created in thread id 130381227054912 and this is thread id 130378241148480.
  File "/home/mrigankp/fuzz4py/fuzz4py/inputs/790.py", line 15, in worker
    db[str(data)] = data * 2
    ~~^^^^^^^^^^^
  File "/home/mrigankp/fuzz4py/cpython/Lib/dbm/sqlite3.py", line 96, in __setitem__
    self._execute(STORE_KV, (key, value))
    ~~~~~~~~~~~~~^^^^^^^^^^^^^^^^^^^^^^^^
dbm.sqlite3.error: SQLite objects created in a thread can only be used in that same thread. The object was created in thread id 130381227054912 and this is thread id 130378696230464.
dbm.sqlite3.error: SQLite objects created in a thread can only be used in that same thread. The object was created in thread id 130381227054912 and this is thread id 130380285871680.
  File "/home/mrigankp/fuzz4py/cpython/Lib/dbm/sqlite3.py", line 81, in _execute
    raise error(str(exc))
dbm.sqlite3.error: SQLite objects created in a thread can only be used in that same thread. The object was created in thread id 130381227054912 and this is thread id 130379851761216.
  File "/home/mrigankp/fuzz4py/cpython/Lib/threading.py", line 992, in run
    self._target(*self._args, **self._kwargs)
    ~~~~~~~~~~~~^^^^^^^^^^^^^^^^^^^^^^^^^^^^^
  File "/home/mrigankp/fuzz4py/cpython/Lib/dbm/sqlite3.py", line 96, in __setitem__
    self._execute(STORE_KV, (key, value))
    ~~~~~~~~~~~~~^^^^^^^^^^^^^^^^^^^^^^^^
  File "/home/mrigankp/fuzz4py/cpython/Lib/dbm/sqlite3.py", line 96, in __setitem__
    self._execute(STORE_KV, (key, value))
    ~~~~~~~~~~~~~^^^^^^^^^^^^^^^^^^^^^^^^
  File "/home/mrigankp/fuzz4py/fuzz4py/inputs/790.py", line 15, in worker
    db[str(data)] = data * 2
    ~~^^^^^^^^^^^
  File "/home/mrigankp/fuzz4py/cpython/Lib/dbm/sqlite3.py", line 81, in _execute
    raise error(str(exc))
  File "/home/mrigankp/fuzz4py/fuzz4py/inputs/790.py", line 15, in worker
    db[str(data)] = data * 2
    ~~^^^^^^^^^^^
  File "/home/mrigankp/fuzz4py/cpython/Lib/dbm/sqlite3.py", line 81, in _execute
    raise error(str(exc))
  File "/home/mrigankp/fuzz4py/cpython/Lib/dbm/sqlite3.py", line 96, in __setitem__
    self._execute(STORE_KV, (key, value))
    ~~~~~~~~~~~~~^^^^^^^^^^^^^^^^^^^^^^^^
  File "/home/mrigankp/fuzz4py/cpython/Lib/dbm/sqlite3.py", line 96, in __setitem__
    self._execute(STORE_KV, (key, value))
    ~~~~~~~~~~~~~^^^^^^^^^^^^^^^^^^^^^^^^
  File "/home/mrigankp/fuzz4py/cpython/Lib/threading.py", line 992, in run
    self._target(*self._args, **self._kwargs)
    ~~~~~~~~~~~~^^^^^^^^^^^^^^^^^^^^^^^^^^^^^
  File "/home/mrigankp/fuzz4py/fuzz4py/inputs/790.py", line 15, in worker
    db[str(data)] = data * 2
    ~~^^^^^^^^^^^
  File "/home/mrigankp/fuzz4py/cpython/Lib/dbm/sqlite3.py", line 81, in _execute
    raise error(str(exc))
  File "/home/mrigankp/fuzz4py/cpython/Lib/threading.py", line 992, in run
    self._target(*self._args, **self._kwargs)
    ~~~~~~~~~~~~^^^^^^^^^^^^^^^^^^^^^^^^^^^^^
  File "/home/mrigankp/fuzz4py/cpython/Lib/dbm/sqlite3.py", line 96, in __setitem__
    self._execute(STORE_KV, (key, value))
    ~~~~~~~~~~~~~^^^^^^^^^^^^^^^^^^^^^^^^
dbm.sqlite3.error: SQLite objects created in a thread can only be used in that same thread. The object was created in thread id 130381227054912 and this is thread id 130379258267200.
  File "/home/mrigankp/fuzz4py/cpython/Lib/dbm/sqlite3.py", line 96, in __setitem__
    self._execute(STORE_KV, (key, value))
    ~~~~~~~~~~~~~^^^^^^^^^^^^^^^^^^^^^^^^
  File "/home/mrigankp/fuzz4py/cpython/Lib/dbm/sqlite3.py", line 81, in _execute
    raise error(str(exc))
  File "/home/mrigankp/fuzz4py/cpython/Lib/dbm/sqlite3.py", line 81, in _execute
    raise error(str(exc))
dbm.sqlite3.error: SQLite objects created in a thread can only be used in that same thread. The object was created in thread id 130381227054912 and this is thread id 130379459593792.
  File "/home/mrigankp/fuzz4py/cpython/Lib/dbm/sqlite3.py", line 96, in __setitem__
    self._execute(STORE_KV, (key, value))
    ~~~~~~~~~~~~~^^^^^^^^^^^^^^^^^^^^^^^^
  File "/home/mrigankp/fuzz4py/cpython/Lib/dbm/sqlite3.py", line 81, in _execute
    raise error(str(exc))
dbm.sqlite3.error: SQLite objects created in a thread can only be used in that same thread. The object was created in thread id 130381227054912 and this is thread id 130378887071296.
  File "/home/mrigankp/fuzz4py/cpython/Lib/dbm/sqlite3.py", line 96, in __setitem__
    self._execute(STORE_KV, (key, value))
    ~~~~~~~~~~~~~^^^^^^^^^^^^^^^^^^^^^^^^
  File "/home/mrigankp/fuzz4py/cpython/Lib/dbm/sqlite3.py", line 81, in _execute
    raise error(str(exc))
dbm.sqlite3.error: SQLite objects created in a thread can only be used in that same thread. The object was created in thread id 130381227054912 and this is thread id 130379893704256.
  File "/home/mrigankp/fuzz4py/cpython/Lib/dbm/sqlite3.py", line 96, in __setitem__
    self._execute(STORE_KV, (key, value))
    ~~~~~~~~~~~~~^^^^^^^^^^^^^^^^^^^^^^^^
dbm.sqlite3.error: SQLite objects created in a thread can only be used in that same thread. The object was created in thread id 130381227054912 and this is thread id 130378293577280.
  File "/home/mrigankp/fuzz4py/cpython/Lib/dbm/sqlite3.py", line 81, in _execute
    raise error(str(exc))
dbm.sqlite3.error: SQLite objects created in a thread can only be used in that same thread. The object was created in thread id 130381227054912 and this is thread id 130378081764928.
dbm.sqlite3.error: SQLite objects created in a thread can only be used in that same thread. The object was created in thread id 130381227054912 and this is thread id 130378855614016.
dbm.sqlite3.error: SQLite objects created in a thread can only be used in that same thread. The object was created in thread id 130381227054912 and this is thread id 130380053087808.
  File "/home/mrigankp/fuzz4py/cpython/Lib/dbm/sqlite3.py", line 81, in _execute
    raise error(str(exc))
dbm.sqlite3.error: SQLite objects created in a thread can only be used in that same thread. The object was created in thread id 130381227054912 and this is thread id 130379883218496.
  File "/home/mrigankp/fuzz4py/cpython/Lib/dbm/sqlite3.py", line 81, in _execute
    raise error(str(exc))
dbm.sqlite3.error: SQLite objects created in a thread can only be used in that same thread. The object was created in thread id 130381227054912 and this is thread id 130379046454848.
  File "/home/mrigankp/fuzz4py/fuzz4py/inputs/790.py", line 15, in worker
    db[str(data)] = data * 2
    ~~^^^^^^^^^^^
  File "/home/mrigankp/fuzz4py/cpython/Lib/dbm/sqlite3.py", line 81, in _execute
    raise error(str(exc))
  File "/home/mrigankp/fuzz4py/cpython/Lib/dbm/sqlite3.py", line 81, in _execute
    raise error(str(exc))
dbm.sqlite3.error: SQLite objects created in a thread can only be used in that same thread. The object was created in thread id 130381227054912 and this is thread id 130378675258944.
dbm.sqlite3.error: SQLite objects created in a thread can only be used in that same thread. The object was created in thread id 130381227054912 and this is thread id 130379247781440.
dbm.sqlite3.error: SQLite objects created in a thread can only be used in that same thread. The object was created in thread id 130381227054912 and this is thread id 130379289724480.
dbm.sqlite3.error: SQLite objects created in a thread can only be used in that same thread. The object was created in thread id 130381227054912 and this is thread id 130377880438336.
dbm.sqlite3.error: SQLite objects created in a thread can only be used in that same thread. The object was created in thread id 130381227054912 and this is thread id 130378050307648.
dbm.sqlite3.error: SQLite objects created in a thread can only be used in that same thread. The object was created in thread id 130381227054912 and this is thread id 130379470079552.
  File "/home/mrigankp/fuzz4py/fuzz4py/inputs/790.py", line 15, in worker
    db[str(data)] = data * 2
    ~~^^^^^^^^^^^
  File "/home/mrigankp/fuzz4py/cpython/Lib/dbm/sqlite3.py", line 96, in __setitem__
    self._execute(STORE_KV, (key, value))
    ~~~~~~~~~~~~~^^^^^^^^^^^^^^^^^^^^^^^^
  File "/home/mrigankp/fuzz4py/cpython/Lib/dbm/sqlite3.py", line 96, in __setitem__
    self._execute(STORE_KV, (key, value))
    ~~~~~~~~~~~~~^^^^^^^^^^^^^^^^^^^^^^^^
dbm.sqlite3.error: SQLite objects created in a thread can only be used in that same thread. The object was created in thread id 130381227054912 and this is thread id 130379098883648.
  File "/home/mrigankp/fuzz4py/cpython/Lib/dbm/sqlite3.py", line 81, in _execute
    raise error(str(exc))
  File "/home/mrigankp/fuzz4py/cpython/Lib/dbm/sqlite3.py", line 81, in _execute
    raise error(str(exc))
dbm.sqlite3.error: SQLite objects created in a thread can only be used in that same thread. The object was created in thread id 130381227054912 and this is thread id 130378283091520.
dbm.sqlite3.error: SQLite objects created in a thread can only be used in that same thread. The object was created in thread id 130381227054912 and this is thread id 130378060793408.

