Return Code: 0
Stdout: Exception in main loop: invalid literal for int() with base 10: b'value1'

Stderr: Exception in thread Thread-1 (worker):
Exception in thread Thread-2 (worker):
Exception in thread Thread-3 (worker):
Exception in thread Thread-4 (worker):
Exception in thread Thread-5 (worker):
Exception in thread Thread-6 (worker):
Exception in thread Thread-7 (worker):
Exception in thread Thread-9 (worker):
Exception in thread Thread-8 (worker):
Exception in thread Thread-10 (worker):
Exception in thread Thread-11 (worker):
Exception in thread Thread-12 (worker):
Exception in thread Thread-13 (worker):
Exception in thread Thread-14 (worker):
Exception in thread Thread-15 (worker):
Exception in thread Thread-16 (worker):
Exception in thread Thread-17 (worker):
Exception in thread Thread-18 (worker):
Exception in thread Thread-19 (worker):
Exception in thread Thread-21 (worker):
Exception in thread Thread-22 (worker):
Exception in thread Thread-20 (worker):
Exception in thread Thread-24 (worker):
Traceback (most recent call last):
Exception in thread Thread-23 (worker):
Traceback (most recent call last):
Traceback (most recent call last):
Traceback (most recent call last):
Traceback (most recent call last):
Exception in thread Thread-25 (worker):
Traceback (most recent call last):
Traceback (most recent call last):
Exception in thread Thread-26 (worker):
Traceback (most recent call last):
Traceback (most recent call last):
Traceback (most recent call last):
  File "/home/mrigankp/fuzz4py/cpython/Lib/dbm/sqlite3.py", line 79, in _execute
    return closing(self._cx.execute(*args, **kwargs))
                   ~~~~~~~~~~~~~~~~^^^^^^^^^^^^^^^^^
Traceback (most recent call last):
Traceback (most recent call last):
  File "/home/mrigankp/fuzz4py/cpython/Lib/dbm/sqlite3.py", line 79, in _execute
    return closing(self._cx.execute(*args, **kwargs))
                   ~~~~~~~~~~~~~~~~^^^^^^^^^^^^^^^^^
Traceback (most recent call last):
  File "/home/mrigankp/fuzz4py/cpython/Lib/dbm/sqlite3.py", line 79, in _execute
    return closing(self._cx.execute(*args, **kwargs))
                   ~~~~~~~~~~~~~~~~^^^^^^^^^^^^^^^^^
  File "/home/mrigankp/fuzz4py/cpython/Lib/dbm/sqlite3.py", line 79, in _execute
    return closing(self._cx.execute(*args, **kwargs))
                   ~~~~~~~~~~~~~~~~^^^^^^^^^^^^^^^^^
  File "/home/mrigankp/fuzz4py/cpython/Lib/dbm/sqlite3.py", line 79, in _execute
    return closing(self._cx.execute(*args, **kwargs))
                   ~~~~~~~~~~~~~~~~^^^^^^^^^^^^^^^^^
Traceback (most recent call last):
Traceback (most recent call last):
Traceback (most recent call last):
Exception in thread Thread-32 (worker):
  File "/home/mrigankp/fuzz4py/cpython/Lib/dbm/sqlite3.py", line 79, in _execute
    return closing(self._cx.execute(*args, **kwargs))
                   ~~~~~~~~~~~~~~~~^^^^^^^^^^^^^^^^^
Traceback (most recent call last):
Traceback (most recent call last):
Exception in thread Thread-34 (worker):
Exception in thread Thread-27 (worker):
Traceback (most recent call last):
Exception in thread Thread-35 (worker):
  File "/home/mrigankp/fuzz4py/cpython/Lib/dbm/sqlite3.py", line 79, in _execute
    return closing(self._cx.execute(*args, **kwargs))
                   ~~~~~~~~~~~~~~~~^^^^^^^^^^^^^^^^^
Traceback (most recent call last):
Exception in thread Thread-36 (worker):
Exception in thread Thread-29 (worker):
Traceback (most recent call last):
Exception in thread Thread-37 (worker):
sqlite3.ProgrammingError: SQLite objects created in a thread can only be used in that same thread. The object was created in thread id 123988330428224 and this is thread id 123988145604160.
sqlite3.ProgrammingError: SQLite objects created in a thread can only be used in that same thread. The object was created in thread id 123988330428224 and this is thread id 123987954763328.
  File "/home/mrigankp/fuzz4py/cpython/Lib/dbm/sqlite3.py", line 79, in _execute
    return closing(self._cx.execute(*args, **kwargs))
                   ~~~~~~~~~~~~~~~~^^^^^^^^^^^^^^^^^
Exception in thread Thread-38 (worker):
Traceback (most recent call last):
  File "/home/mrigankp/fuzz4py/cpython/Lib/dbm/sqlite3.py", line 79, in _execute
    return closing(self._cx.execute(*args, **kwargs))
                   ~~~~~~~~~~~~~~~~^^^^^^^^^^^^^^^^^
Traceback (most recent call last):
Exception in thread Thread-40 (worker):
sqlite3.ProgrammingError: SQLite objects created in a thread can only be used in that same thread. The object was created in thread id 123988330428224 and this is thread id 123987742950976.
  File "/home/mrigankp/fuzz4py/cpython/Lib/dbm/sqlite3.py", line 79, in _execute
    return closing(self._cx.execute(*args, **kwargs))
                   ~~~~~~~~~~~~~~~~^^^^^^^^^^^^^^^^^
  File "/home/mrigankp/fuzz4py/cpython/Lib/dbm/sqlite3.py", line 79, in _execute
    return closing(self._cx.execute(*args, **kwargs))
                   ~~~~~~~~~~~~~~~~^^^^^^^^^^^^^^^^^
  File "/home/mrigankp/fuzz4py/cpython/Lib/dbm/sqlite3.py", line 79, in _execute
    return closing(self._cx.execute(*args, **kwargs))
                   ~~~~~~~~~~~~~~~~^^^^^^^^^^^^^^^^^
Exception in thread Thread-42 (worker):
  File "/home/mrigankp/fuzz4py/cpython/Lib/dbm/sqlite3.py", line 79, in _execute
    return closing(self._cx.execute(*args, **kwargs))
                   ~~~~~~~~~~~~~~~~^^^^^^^^^^^^^^^^^
sqlite3.ProgrammingError: SQLite objects created in a thread can only be used in that same thread. The object was created in thread id 123988330428224 and this is thread id 123987583567424.
Traceback (most recent call last):
Exception in thread Thread-43 (worker):
  File "/home/mrigankp/fuzz4py/cpython/Lib/dbm/sqlite3.py", line 79, in _execute
    return closing(self._cx.execute(*args, **kwargs))
                   ~~~~~~~~~~~~~~~~^^^^^^^^^^^^^^^^^
  File "/home/mrigankp/fuzz4py/cpython/Lib/dbm/sqlite3.py", line 79, in _execute
    return closing(self._cx.execute(*args, **kwargs))
                   ~~~~~~~~~~~~~~~~^^^^^^^^^^^^^^^^^
sqlite3.ProgrammingError: SQLite objects created in a thread can only be used in that same thread. The object was created in thread id 123988330428224 and this is thread id 123987944277568.
Traceback (most recent call last):
Traceback (most recent call last):
Exception in thread Thread-30 (worker):
Traceback (most recent call last):

During handling of the above exception, another exception occurred:

  File "/home/mrigankp/fuzz4py/cpython/Lib/dbm/sqlite3.py", line 79, in _execute
    return closing(self._cx.execute(*args, **kwargs))
                   ~~~~~~~~~~~~~~~~^^^^^^^^^^^^^^^^^
  File "/home/mrigankp/fuzz4py/cpython/Lib/dbm/sqlite3.py", line 79, in _execute
    return closing(self._cx.execute(*args, **kwargs))
                   ~~~~~~~~~~~~~~~~^^^^^^^^^^^^^^^^^
Exception in thread Thread-39 (worker):
Traceback (most recent call last):
Traceback (most recent call last):
Exception in thread Thread-49 (worker):
  File "/home/mrigankp/fuzz4py/cpython/Lib/dbm/sqlite3.py", line 79, in _execute
    return closing(self._cx.execute(*args, **kwargs))
                   ~~~~~~~~~~~~~~~~^^^^^^^^^^^^^^^^^
Traceback (most recent call last):
Exception in thread Thread-41 (worker):
Traceback (most recent call last):
Exception in thread Thread-51 (worker):
sqlite3.ProgrammingError: SQLite objects created in a thread can only be used in that same thread. The object was created in thread id 123988330428224 and this is thread id 123987573081664.
sqlite3.ProgrammingError: SQLite objects created in a thread can only be used in that same thread. The object was created in thread id 123988330428224 and this is thread id 123987784894016.
Exception in thread Thread-28 (worker):
  File "/home/mrigankp/fuzz4py/cpython/Lib/dbm/sqlite3.py", line 79, in _execute
    return closing(self._cx.execute(*args, **kwargs))
                   ~~~~~~~~~~~~~~~~^^^^^^^^^^^^^^^^^
Traceback (most recent call last):
Traceback (most recent call last):
Traceback (most recent call last):
sqlite3.ProgrammingError: SQLite objects created in a thread can only be used in that same thread. The object was created in thread id 123988330428224 and this is thread id 123987975734848.
Exception in thread Thread-54 (worker):
Exception in thread Thread-44 (worker):
  File "/home/mrigankp/fuzz4py/cpython/Lib/dbm/sqlite3.py", line 79, in _execute
    return closing(self._cx.execute(*args, **kwargs))
                   ~~~~~~~~~~~~~~~~^^^^^^^^^^^^^^^^^
Exception in thread Thread-55 (worker):
  File "/home/mrigankp/fuzz4py/cpython/Lib/dbm/sqlite3.py", line 79, in _execute
    return closing(self._cx.execute(*args, **kwargs))
                   ~~~~~~~~~~~~~~~~^^^^^^^^^^^^^^^^^
  File "/home/mrigankp/fuzz4py/cpython/Lib/dbm/sqlite3.py", line 79, in _execute
    return closing(self._cx.execute(*args, **kwargs))
                   ~~~~~~~~~~~~~~~~^^^^^^^^^^^^^^^^^
Traceback (most recent call last):
  File "/home/mrigankp/fuzz4py/cpython/Lib/dbm/sqlite3.py", line 79, in _execute
    return closing(self._cx.execute(*args, **kwargs))
                   ~~~~~~~~~~~~~~~~^^^^^^^^^^^^^^^^^
Exception in thread Thread-46 (worker):
Exception in thread Thread-57 (worker):
sqlite3.ProgrammingError: SQLite objects created in a thread can only be used in that same thread. The object was created in thread id 123988330428224 and this is thread id 123987753436736.
sqlite3.ProgrammingError: SQLite objects created in a thread can only be used in that same thread. The object was created in thread id 123988330428224 and this is thread id 123987763922496.
Exception in thread Thread-58 (worker):
Exception in thread Thread-48 (worker):
Traceback (most recent call last):
sqlite3.ProgrammingError: SQLite objects created in a thread can only be used in that same thread. The object was created in thread id 123988330428224 and this is thread id 123987562595904.
Exception in thread Thread-33 (worker):
  File "/home/mrigankp/fuzz4py/cpython/Lib/dbm/sqlite3.py", line 79, in _execute
    return closing(self._cx.execute(*args, **kwargs))
                   ~~~~~~~~~~~~~~~~^^^^^^^^^^^^^^^^^
Traceback (most recent call last):
Exception in thread Thread-50 (worker):

During handling of the above exception, another exception occurred:

sqlite3.ProgrammingError: SQLite objects created in a thread can only be used in that same thread. The object was created in thread id 123988330428224 and this is thread id 123988166575680.
  File "/home/mrigankp/fuzz4py/cpython/Lib/dbm/sqlite3.py", line 79, in _execute
    return closing(self._cx.execute(*args, **kwargs))
                   ~~~~~~~~~~~~~~~~^^^^^^^^^^^^^^^^^
sqlite3.ProgrammingError: SQLite objects created in a thread can only be used in that same thread. The object was created in thread id 123988330428224 and this is thread id 123988307084864.
Traceback (most recent call last):
Traceback (most recent call last):
sqlite3.ProgrammingError: SQLite objects created in a thread can only be used in that same thread. The object was created in thread id 123988330428224 and this is thread id 123988156089920.
Exception in thread Thread-65 (worker):
sqlite3.ProgrammingError: SQLite objects created in a thread can only be used in that same thread. The object was created in thread id 123988330428224 and this is thread id 123988286113344.
Exception in thread Thread-52 (worker):
  File "/home/mrigankp/fuzz4py/cpython/Lib/dbm/sqlite3.py", line 79, in _execute
    return closing(self._cx.execute(*args, **kwargs))
                   ~~~~~~~~~~~~~~~~^^^^^^^^^^^^^^^^^
Exception in thread Thread-67 (worker):
  File "/home/mrigankp/fuzz4py/cpython/Lib/dbm/sqlite3.py", line 79, in _execute
    return closing(self._cx.execute(*args, **kwargs))
                   ~~~~~~~~~~~~~~~~^^^^^^^^^^^^^^^^^

During handling of the above exception, another exception occurred:

sqlite3.ProgrammingError: SQLite objects created in a thread can only be used in that same thread. The object was created in thread id 123988330428224 and this is thread id 123987774408256.
sqlite3.ProgrammingError: SQLite objects created in a thread can only be used in that same thread. The object was created in thread id 123988330428224 and this is thread id 123987965249088.

During handling of the above exception, another exception occurred:

Traceback (most recent call last):
Exception in thread Thread-45 (worker):
sqlite3.ProgrammingError: SQLite objects created in a thread can only be used in that same thread. The object was created in thread id 123988330428224 and this is thread id 123987170428480.
Exception in thread Thread-31 (worker):
Traceback (most recent call last):
  File "/home/mrigankp/fuzz4py/cpython/Lib/dbm/sqlite3.py", line 79, in _execute
    return closing(self._cx.execute(*args, **kwargs))
                   ~~~~~~~~~~~~~~~~^^^^^^^^^^^^^^^^^
sqlite3.ProgrammingError: SQLite objects created in a thread can only be used in that same thread. The object was created in thread id 123988330428224 and this is thread id 123987382240832.
Traceback (most recent call last):
sqlite3.ProgrammingError: SQLite objects created in a thread can only be used in that same thread. The object was created in thread id 123988330428224 and this is thread id 123987986220608.
Exception in thread Thread-47 (worker):
Exception in thread Thread-74 (worker):
  File "/home/mrigankp/fuzz4py/cpython/Lib/dbm/sqlite3.py", line 79, in _execute
    return closing(self._cx.execute(*args, **kwargs))
                   ~~~~~~~~~~~~~~~~^^^^^^^^^^^^^^^^^
Exception in thread Thread-59 (worker):
  File "/home/mrigankp/fuzz4py/cpython/Lib/dbm/sqlite3.py", line 79, in _execute
    return closing(self._cx.execute(*args, **kwargs))
                   ~~~~~~~~~~~~~~~~^^^^^^^^^^^^^^^^^
Exception in thread Thread-76 (worker):
Exception in thread Thread-60 (worker):
  File "/home/mrigankp/fuzz4py/cpython/Lib/dbm/sqlite3.py", line 79, in _execute
    return closing(self._cx.execute(*args, **kwargs))
                   ~~~~~~~~~~~~~~~~^^^^^^^^^^^^^^^^^
Exception in thread Thread-77 (worker):
Exception in thread Thread-78 (worker):
Traceback (most recent call last):
Exception in thread Thread-62 (worker):
  File "/home/mrigankp/fuzz4py/cpython/Lib/dbm/sqlite3.py", line 79, in _execute
    return closing(self._cx.execute(*args, **kwargs))
                   ~~~~~~~~~~~~~~~~^^^^^^^^^^^^^^^^^
Traceback (most recent call last):
Traceback (most recent call last):

During handling of the above exception, another exception occurred:

sqlite3.ProgrammingError: SQLite objects created in a thread can only be used in that same thread. The object was created in thread id 123988330428224 and this is thread id 123988135118400.

During handling of the above exception, another exception occurred:


During handling of the above exception, another exception occurred:

Exception in thread Thread-64 (worker):
Exception in thread Thread-81 (worker):

During handling of the above exception, another exception occurred:

Exception in thread Thread-66 (worker):
Traceback (most recent call last):
  File "/home/mrigankp/fuzz4py/cpython/Lib/dbm/sqlite3.py", line 79, in _execute
    return closing(self._cx.execute(*args, **kwargs))
                   ~~~~~~~~~~~~~~~~^^^^^^^^^^^^^^^^^
  File "/home/mrigankp/fuzz4py/cpython/Lib/dbm/sqlite3.py", line 79, in _execute
    return closing(self._cx.execute(*args, **kwargs))
                   ~~~~~~~~~~~~~~~~^^^^^^^^^^^^^^^^^
Exception in thread Thread-83 (worker):
Traceback (most recent call last):
Traceback (most recent call last):
Traceback (most recent call last):
Exception in thread Thread-69 (worker):
Traceback (most recent call last):
Exception in thread Thread-85 (worker):
Traceback (most recent call last):
  File "/home/mrigankp/fuzz4py/cpython/Lib/dbm/sqlite3.py", line 79, in _execute
    return closing(self._cx.execute(*args, **kwargs))
                   ~~~~~~~~~~~~~~~~^^^^^^^^^^^^^^^^^
Exception in thread Thread-71 (worker):

During handling of the above exception, another exception occurred:

Traceback (most recent call last):
  File "/home/mrigankp/fuzz4py/cpython/Lib/dbm/sqlite3.py", line 79, in _execute
    return closing(self._cx.execute(*args, **kwargs))
                   ~~~~~~~~~~~~~~~~^^^^^^^^^^^^^^^^^
Traceback (most recent call last):
sqlite3.ProgrammingError: SQLite objects created in a thread can only be used in that same thread. The object was created in thread id 123988330428224 and this is thread id 123987159942720.

During handling of the above exception, another exception occurred:

Exception in thread Thread-73 (worker):
Traceback (most recent call last):
Traceback (most recent call last):
Exception in thread Thread-89 (worker):
sqlite3.ProgrammingError: SQLite objects created in a thread can only be used in that same thread. The object was created in thread id 123988330428224 and this is thread id 123988296599104.
Exception in thread Thread-75 (worker):
Exception in thread Thread-90 (worker):
sqlite3.ProgrammingError: SQLite objects created in a thread can only be used in that same thread. The object was created in thread id 123988330428224 and this is thread id 123987149456960.
Traceback (most recent call last):
Exception in thread Thread-91 (worker):

During handling of the above exception, another exception occurred:

Traceback (most recent call last):
Exception in thread Thread-61 (worker):
sqlite3.ProgrammingError: SQLite objects created in a thread can only be used in that same thread. The object was created in thread id 123988330428224 and this is thread id 123987350783552.
  File "/home/mrigankp/fuzz4py/cpython/Lib/dbm/sqlite3.py", line 79, in _execute
    return closing(self._cx.execute(*args, **kwargs))
                   ~~~~~~~~~~~~~~~~^^^^^^^^^^^^^^^^^
Traceback (most recent call last):
Exception in thread Thread-94 (worker):
sqlite3.ProgrammingError: SQLite objects created in a thread can only be used in that same thread. The object was created in thread id 123988330428224 and this is thread id 123987128485440.
Exception in thread Thread-95 (worker):
Exception in thread Thread-79 (worker):
  File "/home/mrigankp/fuzz4py/cpython/Lib/threading.py", line 1041, in _bootstrap_inner
    self.run()
    ~~~~~~~~^^
Traceback (most recent call last):
Exception in thread Thread-80 (worker):

During handling of the above exception, another exception occurred:

  File "/home/mrigankp/fuzz4py/cpython/Lib/dbm/sqlite3.py", line 79, in _execute
    return closing(self._cx.execute(*args, **kwargs))
                   ~~~~~~~~~~~~~~~~^^^^^^^^^^^^^^^^^
Traceback (most recent call last):

During handling of the above exception, another exception occurred:

Exception in thread Thread-98 (worker):
Traceback (most recent call last):
Traceback (most recent call last):
Traceback (most recent call last):

During handling of the above exception, another exception occurred:

Traceback (most recent call last):
sqlite3.ProgrammingError: SQLite objects created in a thread can only be used in that same thread. The object was created in thread id 123988330428224 and this is thread id 123986969101888.
Exception in thread Thread-53 (worker):
Traceback (most recent call last):
Exception in thread Thread-68 (worker):
Exception in thread Thread-84 (worker):
  File "/home/mrigankp/fuzz4py/cpython/Lib/threading.py", line 1041, in _bootstrap_inner
    self.run()
    ~~~~~~~~^^
Traceback (most recent call last):
Exception in thread Thread-70 (worker):
Traceback (most recent call last):

During handling of the above exception, another exception occurred:

Exception in thread Thread-86 (worker):
Traceback (most recent call last):
  File "/home/mrigankp/fuzz4py/cpython/Lib/dbm/sqlite3.py", line 79, in _execute
    return closing(self._cx.execute(*args, **kwargs))
                   ~~~~~~~~~~~~~~~~^^^^^^^^^^^^^^^^^
Exception in thread Thread-87 (worker):
  File "/home/mrigankp/fuzz4py/cpython/Lib/dbm/sqlite3.py", line 79, in _execute
    return closing(self._cx.execute(*args, **kwargs))
                   ~~~~~~~~~~~~~~~~^^^^^^^^^^^^^^^^^
Exception in thread Thread-72 (worker):
Exception in thread Thread-88 (worker):

During handling of the above exception, another exception occurred:

  File "/home/mrigankp/fuzz4py/cpython/Lib/dbm/sqlite3.py", line 79, in _execute
    return closing(self._cx.execute(*args, **kwargs))
                   ~~~~~~~~~~~~~~~~^^^^^^^^^^^^^^^^^

During handling of the above exception, another exception occurred:


During handling of the above exception, another exception occurred:

Traceback (most recent call last):
Traceback (most recent call last):
Traceback (most recent call last):

During handling of the above exception, another exception occurred:

Traceback (most recent call last):
  File "/home/mrigankp/fuzz4py/cpython/Lib/dbm/sqlite3.py", line 79, in _execute
    return closing(self._cx.execute(*args, **kwargs))
                   ~~~~~~~~~~~~~~~~^^^^^^^^^^^^^^^^^
Exception in thread Thread-92 (worker):
sqlite3.ProgrammingError: SQLite objects created in a thread can only be used in that same thread. The object was created in thread id 123988330428224 and this is thread id 123987933791808.
Exception in thread Thread-93 (worker):

During handling of the above exception, another exception occurred:

Traceback (most recent call last):
sqlite3.ProgrammingError: SQLite objects created in a thread can only be used in that same thread. The object was created in thread id 123988330428224 and this is thread id 123987340297792.
  File "/home/mrigankp/fuzz4py/cpython/Lib/dbm/sqlite3.py", line 79, in _execute
    return closing(self._cx.execute(*args, **kwargs))
                   ~~~~~~~~~~~~~~~~^^^^^^^^^^^^^^^^^

During handling of the above exception, another exception occurred:

Traceback (most recent call last):
  File "/home/mrigankp/fuzz4py/cpython/Lib/dbm/sqlite3.py", line 79, in _execute
    return closing(self._cx.execute(*args, **kwargs))
                   ~~~~~~~~~~~~~~~~^^^^^^^^^^^^^^^^^
Traceback (most recent call last):
  File "/home/mrigankp/fuzz4py/cpython/Lib/threading.py", line 992, in run
    self._target(*self._args, **self._kwargs)
    ~~~~~~~~~~~~^^^^^^^^^^^^^^^^^^^^^^^^^^^^^
Traceback (most recent call last):
  File "/home/mrigankp/fuzz4py/cpython/Lib/threading.py", line 1041, in _bootstrap_inner
    self.run()
    ~~~~~~~~^^
sqlite3.ProgrammingError: SQLite objects created in a thread can only be used in that same thread. The object was created in thread id 123988330428224 and this is thread id 123986736318016.
  File "/home/mrigankp/fuzz4py/cpython/Lib/dbm/sqlite3.py", line 79, in _execute
    return closing(self._cx.execute(*args, **kwargs))
                   ~~~~~~~~~~~~~~~~^^^^^^^^^^^^^^^^^
Traceback (most recent call last):
  File "/home/mrigankp/fuzz4py/cpython/Lib/threading.py", line 1041, in _bootstrap_inner
    self.run()
    ~~~~~~~~^^
Traceback (most recent call last):
  File "/home/mrigankp/fuzz4py/cpython/Lib/dbm/sqlite3.py", line 79, in _execute
    return closing(self._cx.execute(*args, **kwargs))
                   ~~~~~~~~~~~~~~~~^^^^^^^^^^^^^^^^^
  File "/home/mrigankp/fuzz4py/cpython/Lib/dbm/sqlite3.py", line 79, in _execute
    return closing(self._cx.execute(*args, **kwargs))
                   ~~~~~~~~~~~~~~~~^^^^^^^^^^^^^^^^^
  File "/home/mrigankp/fuzz4py/cpython/Lib/dbm/sqlite3.py", line 79, in _execute
    return closing(self._cx.execute(*args, **kwargs))
                   ~~~~~~~~~~~~~~~~^^^^^^^^^^^^^^^^^
Traceback (most recent call last):
sqlite3.ProgrammingError: SQLite objects created in a thread can only be used in that same thread. The object was created in thread id 123988330428224 and this is thread id 123987541624384.

During handling of the above exception, another exception occurred:

  File "/home/mrigankp/fuzz4py/cpython/Lib/dbm/sqlite3.py", line 79, in _execute
    return closing(self._cx.execute(*args, **kwargs))
                   ~~~~~~~~~~~~~~~~^^^^^^^^^^^^^^^^^
  File "/home/mrigankp/fuzz4py/cpython/Lib/dbm/sqlite3.py", line 79, in _execute
    return closing(self._cx.execute(*args, **kwargs))
                   ~~~~~~~~~~~~~~~~^^^^^^^^^^^^^^^^^

During handling of the above exception, another exception occurred:

Traceback (most recent call last):
  File "/home/mrigankp/fuzz4py/cpython/Lib/dbm/sqlite3.py", line 79, in _execute
    return closing(self._cx.execute(*args, **kwargs))
                   ~~~~~~~~~~~~~~~~^^^^^^^^^^^^^^^^^
  File "/home/mrigankp/fuzz4py/cpython/Lib/dbm/sqlite3.py", line 79, in _execute
    return closing(self._cx.execute(*args, **kwargs))
                   ~~~~~~~~~~~~~~~~^^^^^^^^^^^^^^^^^
Traceback (most recent call last):
sqlite3.ProgrammingError: SQLite objects created in a thread can only be used in that same thread. The object was created in thread id 123988330428224 and this is thread id 123986566448704.
sqlite3.ProgrammingError: SQLite objects created in a thread can only be used in that same thread. The object was created in thread id 123988330428224 and this is thread id 123988187547200.
Traceback (most recent call last):
sqlite3.ProgrammingError: SQLite objects created in a thread can only be used in that same thread. The object was created in thread id 123988330428224 and this is thread id 123986555962944.
Exception in thread Thread-56 (worker):
Traceback (most recent call last):
Traceback (most recent call last):
Traceback (most recent call last):
Traceback (most recent call last):
Traceback (most recent call last):
Traceback (most recent call last):
Traceback (most recent call last):
Traceback (most recent call last):
  File "/home/mrigankp/fuzz4py/cpython/Lib/dbm/sqlite3.py", line 79, in _execute
    return closing(self._cx.execute(*args, **kwargs))
                   ~~~~~~~~~~~~~~~~^^^^^^^^^^^^^^^^^
  File "/home/mrigankp/fuzz4py/cpython/Lib/dbm/sqlite3.py", line 79, in _execute
    return closing(self._cx.execute(*args, **kwargs))
                   ~~~~~~~~~~~~~~~~^^^^^^^^^^^^^^^^^
Traceback (most recent call last):
Traceback (most recent call last):
Traceback (most recent call last):
Traceback (most recent call last):
  File "/home/mrigankp/fuzz4py/cpython/Lib/dbm/sqlite3.py", line 79, in _execute
    return closing(self._cx.execute(*args, **kwargs))
                   ~~~~~~~~~~~~~~~~^^^^^^^^^^^^^^^^^

During handling of the above exception, another exception occurred:

sqlite3.ProgrammingError: SQLite objects created in a thread can only be used in that same thread. The object was created in thread id 123988330428224 and this is thread id 123988275627584.
  File "/home/mrigankp/fuzz4py/cpython/Lib/dbm/sqlite3.py", line 79, in _execute
    return closing(self._cx.execute(*args, **kwargs))
                   ~~~~~~~~~~~~~~~~^^^^^^^^^^^^^^^^^
Traceback (most recent call last):

During handling of the above exception, another exception occurred:

sqlite3.ProgrammingError: SQLite objects created in a thread can only be used in that same thread. The object was created in thread id 123988330428224 and this is thread id 123987552110144.
Traceback (most recent call last):
  File "/home/mrigankp/fuzz4py/cpython/Lib/dbm/sqlite3.py", line 79, in _execute
    return closing(self._cx.execute(*args, **kwargs))
                   ~~~~~~~~~~~~~~~~^^^^^^^^^^^^^^^^^
Exception in thread Thread-63 (worker):
  File "/home/mrigankp/fuzz4py/cpython/Lib/dbm/sqlite3.py", line 79, in _execute
    return closing(self._cx.execute(*args, **kwargs))
                   ~~~~~~~~~~~~~~~~^^^^^^^^^^^^^^^^^
  File "/home/mrigankp/fuzz4py/fuzz4py/inputs/790.py", line 15, in worker
    db[str(data)] = data * 2
    ~~^^^^^^^^^^^
Exception in thread Thread-97 (worker):
  File "/home/mrigankp/fuzz4py/cpython/Lib/threading.py", line 1041, in _bootstrap_inner
    self.run()
    ~~~~~~~~^^
Traceback (most recent call last):
Traceback (most recent call last):
Exception in thread Thread-99 (worker):
Exception in thread Thread-82 (worker):
  File "/home/mrigankp/fuzz4py/cpython/Lib/threading.py", line 1041, in _bootstrap_inner
    self.run()
    ~~~~~~~~^^
Exception in thread Thread-100 (worker):
  File "/home/mrigankp/fuzz4py/cpython/Lib/dbm/sqlite3.py", line 79, in _execute
    return closing(self._cx.execute(*args, **kwargs))
                   ~~~~~~~~~~~~~~~~^^^^^^^^^^^^^^^^^
  File "/home/mrigankp/fuzz4py/cpython/Lib/dbm/sqlite3.py", line 79, in _execute
    return closing(self._cx.execute(*args, **kwargs))
                   ~~~~~~~~~~~~~~~~^^^^^^^^^^^^^^^^^

During handling of the above exception, another exception occurred:

sqlite3.ProgrammingError: SQLite objects created in a thread can only be used in that same thread. The object was created in thread id 123988330428224 and this is thread id 123988177061440.
Traceback (most recent call last):
sqlite3.ProgrammingError: SQLite objects created in a thread can only be used in that same thread. The object was created in thread id 123988330428224 and this is thread id 123986958616128.
sqlite3.ProgrammingError: SQLite objects created in a thread can only be used in that same thread. The object was created in thread id 123988330428224 and this is thread id 123985570301504.

During handling of the above exception, another exception occurred:

  File "/home/mrigankp/fuzz4py/cpython/Lib/dbm/sqlite3.py", line 79, in _execute
    return closing(self._cx.execute(*args, **kwargs))
                   ~~~~~~~~~~~~~~~~^^^^^^^^^^^^^^^^^
sqlite3.ProgrammingError: SQLite objects created in a thread can only be used in that same thread. The object was created in thread id 123988330428224 and this is thread id 123987732465216.
sqlite3.ProgrammingError: SQLite objects created in a thread can only be used in that same thread. The object was created in thread id 123988330428224 and this is thread id 123986132338240.
  File "/home/mrigankp/fuzz4py/cpython/Lib/dbm/sqlite3.py", line 79, in _execute
    return closing(self._cx.execute(*args, **kwargs))
                   ~~~~~~~~~~~~~~~~^^^^^^^^^^^^^^^^^
  File "/home/mrigankp/fuzz4py/cpython/Lib/dbm/sqlite3.py", line 79, in _execute
    return closing(self._cx.execute(*args, **kwargs))
                   ~~~~~~~~~~~~~~~~^^^^^^^^^^^^^^^^^

During handling of the above exception, another exception occurred:

  File "/home/mrigankp/fuzz4py/cpython/Lib/dbm/sqlite3.py", line 79, in _execute
    return closing(self._cx.execute(*args, **kwargs))
                   ~~~~~~~~~~~~~~~~^^^^^^^^^^^^^^^^^
sqlite3.ProgrammingError: SQLite objects created in a thread can only be used in that same thread. The object was created in thread id 123988330428224 and this is thread id 123987371755072.
Traceback (most recent call last):

During handling of the above exception, another exception occurred:

  File "/home/mrigankp/fuzz4py/cpython/Lib/dbm/sqlite3.py", line 79, in _execute
    return closing(self._cx.execute(*args, **kwargs))
                   ~~~~~~~~~~~~~~~~^^^^^^^^^^^^^^^^^
Traceback (most recent call last):
  File "/home/mrigankp/fuzz4py/cpython/Lib/threading.py", line 1041, in _bootstrap_inner
    self.run()
    ~~~~~~~~^^
sqlite3.ProgrammingError: SQLite objects created in a thread can only be used in that same thread. The object was created in thread id 123988330428224 and this is thread id 123986927158848.
  File "/home/mrigankp/fuzz4py/cpython/Lib/dbm/sqlite3.py", line 79, in _execute
    return closing(self._cx.execute(*args, **kwargs))
                   ~~~~~~~~~~~~~~~~^^^^^^^^^^^^^^^^^

During handling of the above exception, another exception occurred:

  File "/home/mrigankp/fuzz4py/cpython/Lib/threading.py", line 1041, in _bootstrap_inner
    self.run()
    ~~~~~~~~^^
sqlite3.ProgrammingError: SQLite objects created in a thread can only be used in that same thread. The object was created in thread id 123988330428224 and this is thread id 123985941497408.
  File "/home/mrigankp/fuzz4py/cpython/Lib/dbm/sqlite3.py", line 79, in _execute
    return closing(self._cx.execute(*args, **kwargs))
                   ~~~~~~~~~~~~~~~~^^^^^^^^^^^^^^^^^
Traceback (most recent call last):
  File "/home/mrigankp/fuzz4py/cpython/Lib/dbm/sqlite3.py", line 79, in _execute
    return closing(self._cx.execute(*args, **kwargs))
                   ~~~~~~~~~~~~~~~~^^^^^^^^^^^^^^^^^
Traceback (most recent call last):
  File "/home/mrigankp/fuzz4py/cpython/Lib/dbm/sqlite3.py", line 79, in _execute
    return closing(self._cx.execute(*args, **kwargs))
                   ~~~~~~~~~~~~~~~~^^^^^^^^^^^^^^^^^
sqlite3.ProgrammingError: SQLite objects created in a thread can only be used in that same thread. The object was created in thread id 123988330428224 and this is thread id 123986365122112.
Traceback (most recent call last):
Traceback (most recent call last):
sqlite3.ProgrammingError: SQLite objects created in a thread can only be used in that same thread. The object was created in thread id 123988330428224 and this is thread id 123986757289536.
  File "/home/mrigankp/fuzz4py/cpython/Lib/dbm/sqlite3.py", line 79, in _execute
    return closing(self._cx.execute(*args, **kwargs))
                   ~~~~~~~~~~~~~~~~^^^^^^^^^^^^^^^^^
Traceback (most recent call last):
Traceback (most recent call last):
sqlite3.ProgrammingError: SQLite objects created in a thread can only be used in that same thread. The object was created in thread id 123988330428224 and this is thread id 123986979587648.
sqlite3.ProgrammingError: SQLite objects created in a thread can only be used in that same thread. The object was created in thread id 123988330428224 and this is thread id 123986344150592.
sqlite3.ProgrammingError: SQLite objects created in a thread can only be used in that same thread. The object was created in thread id 123988330428224 and this is thread id 123985167648320.
  File "/home/mrigankp/fuzz4py/cpython/Lib/dbm/sqlite3.py", line 96, in __setitem__
    self._execute(STORE_KV, (key, value))
    ~~~~~~~~~~~~~^^^^^^^^^^^^^^^^^^^^^^^^
  File "/home/mrigankp/fuzz4py/cpython/Lib/threading.py", line 1041, in _bootstrap_inner
    self.run()
    ~~~~~~~~^^
  File "/home/mrigankp/fuzz4py/cpython/Lib/threading.py", line 992, in run
    self._target(*self._args, **self._kwargs)
    ~~~~~~~~~~~~^^^^^^^^^^^^^^^^^^^^^^^^^^^^^
Traceback (most recent call last):
  File "/home/mrigankp/fuzz4py/cpython/Lib/dbm/sqlite3.py", line 79, in _execute
    return closing(self._cx.execute(*args, **kwargs))
                   ~~~~~~~~~~~~~~~~^^^^^^^^^^^^^^^^^
  File "/home/mrigankp/fuzz4py/cpython/Lib/threading.py", line 992, in run
    self._target(*self._args, **self._kwargs)
    ~~~~~~~~~~~~^^^^^^^^^^^^^^^^^^^^^^^^^^^^^
  File "/home/mrigankp/fuzz4py/cpython/Lib/threading.py", line 1041, in _bootstrap_inner
    self.run()
    ~~~~~~~~^^
Traceback (most recent call last):
  File "/home/mrigankp/fuzz4py/cpython/Lib/threading.py", line 992, in run
    self._target(*self._args, **self._kwargs)
    ~~~~~~~~~~~~^^^^^^^^^^^^^^^^^^^^^^^^^^^^^
Traceback (most recent call last):
sqlite3.ProgrammingError: SQLite objects created in a thread can only be used in that same thread. The object was created in thread id 123988330428224 and this is thread id 123986174281280.
sqlite3.ProgrammingError: SQLite objects created in a thread can only be used in that same thread. The object was created in thread id 123988330428224 and this is thread id 123986725832256.
Traceback (most recent call last):
Traceback (most recent call last):
  File "/home/mrigankp/fuzz4py/cpython/Lib/threading.py", line 1041, in _bootstrap_inner
    self.run()
    ~~~~~~~~^^
Traceback (most recent call last):

During handling of the above exception, another exception occurred:

sqlite3.ProgrammingError: SQLite objects created in a thread can only be used in that same thread. The object was created in thread id 123988330428224 and this is thread id 123986948130368.
sqlite3.ProgrammingError: SQLite objects created in a thread can only be used in that same thread. The object was created in thread id 123988330428224 and this is thread id 123986142824000.

During handling of the above exception, another exception occurred:


During handling of the above exception, another exception occurred:

sqlite3.ProgrammingError: SQLite objects created in a thread can only be used in that same thread. The object was created in thread id 123988330428224 and this is thread id 123985549329984.
sqlite3.ProgrammingError: SQLite objects created in a thread can only be used in that same thread. The object was created in thread id 123988330428224 and this is thread id 123987361269312.
Traceback (most recent call last):
sqlite3.ProgrammingError: SQLite objects created in a thread can only be used in that same thread. The object was created in thread id 123988330428224 and this is thread id 123986937644608.
  File "/home/mrigankp/fuzz4py/cpython/Lib/dbm/sqlite3.py", line 79, in _execute
    return closing(self._cx.execute(*args, **kwargs))
                   ~~~~~~~~~~~~~~~~^^^^^^^^^^^^^^^^^
Traceback (most recent call last):
Traceback (most recent call last):
sqlite3.ProgrammingError: SQLite objects created in a thread can only be used in that same thread. The object was created in thread id 123988330428224 and this is thread id 123985528358464.
  File "/home/mrigankp/fuzz4py/cpython/Lib/dbm/sqlite3.py", line 79, in _execute
    return closing(self._cx.execute(*args, **kwargs))
                   ~~~~~~~~~~~~~~~~^^^^^^^^^^^^^^^^^
  File "/home/mrigankp/fuzz4py/cpython/Lib/dbm/sqlite3.py", line 79, in _execute
    return closing(self._cx.execute(*args, **kwargs))
                   ~~~~~~~~~~~~~~~~^^^^^^^^^^^^^^^^^

During handling of the above exception, another exception occurred:

sqlite3.ProgrammingError: SQLite objects created in a thread can only be used in that same thread. The object was created in thread id 123988330428224 and this is thread id 123986534991424.
  File "/home/mrigankp/fuzz4py/cpython/Lib/threading.py", line 1041, in _bootstrap_inner
    self.run()
    ~~~~~~~~^^
  File "/home/mrigankp/fuzz4py/cpython/Lib/threading.py", line 992, in run
    self._target(*self._args, **self._kwargs)
    ~~~~~~~~~~~~^^^^^^^^^^^^^^^^^^^^^^^^^^^^^

During handling of the above exception, another exception occurred:

  File "/home/mrigankp/fuzz4py/cpython/Lib/dbm/sqlite3.py", line 79, in _execute
    return closing(self._cx.execute(*args, **kwargs))
                   ~~~~~~~~~~~~~~~~^^^^^^^^^^^^^^^^^
  File "/home/mrigankp/fuzz4py/cpython/Lib/dbm/sqlite3.py", line 79, in _execute
    return closing(self._cx.execute(*args, **kwargs))
                   ~~~~~~~~~~~~~~~~^^^^^^^^^^^^^^^^^
sqlite3.ProgrammingError: SQLite objects created in a thread can only be used in that same thread. The object was created in thread id 123988330428224 and this is thread id 123985920525888.
  File "/home/mrigankp/fuzz4py/cpython/Lib/threading.py", line 1041, in _bootstrap_inner
    self.run()
    ~~~~~~~~^^
sqlite3.ProgrammingError: SQLite objects created in a thread can only be used in that same thread. The object was created in thread id 123988330428224 and this is thread id 123985348003392.

During handling of the above exception, another exception occurred:

  File "/home/mrigankp/fuzz4py/cpython/Lib/threading.py", line 1041, in _bootstrap_inner
    self.run()
    ~~~~~~~~^^
  File "/home/mrigankp/fuzz4py/cpython/Lib/threading.py", line 1041, in _bootstrap_inner
    self.run()
    ~~~~~~~~^^

During handling of the above exception, another exception occurred:

sqlite3.ProgrammingError: SQLite objects created in a thread can only be used in that same thread. The object was created in thread id 123988330428224 and this is thread id 123985327031872.
  File "/home/mrigankp/fuzz4py/cpython/Lib/dbm/sqlite3.py", line 79, in _execute
    return closing(self._cx.execute(*args, **kwargs))
                   ~~~~~~~~~~~~~~~~^^^^^^^^^^^^^^^^^
  File "/home/mrigankp/fuzz4py/cpython/Lib/threading.py", line 1041, in _bootstrap_inner
    self.run()
    ~~~~~~~~^^

During handling of the above exception, another exception occurred:

Traceback (most recent call last):

During handling of the above exception, another exception occurred:

  File "/home/mrigankp/fuzz4py/cpython/Lib/threading.py", line 992, in run
    self._target(*self._args, **self._kwargs)
    ~~~~~~~~~~~~^^^^^^^^^^^^^^^^^^^^^^^^^^^^^
  File "/home/mrigankp/fuzz4py/cpython/Lib/threading.py", line 992, in run
    self._target(*self._args, **self._kwargs)
    ~~~~~~~~~~~~^^^^^^^^^^^^^^^^^^^^^^^^^^^^^
sqlite3.ProgrammingError: SQLite objects created in a thread can only be used in that same thread. The object was created in thread id 123988330428224 and this is thread id 123987329812032.
  File "/home/mrigankp/fuzz4py/cpython/Lib/dbm/sqlite3.py", line 79, in _execute
    return closing(self._cx.execute(*args, **kwargs))
                   ~~~~~~~~~~~~~~~~^^^^^^^^^^^^^^^^^
Traceback (most recent call last):
sqlite3.ProgrammingError: SQLite objects created in a thread can only be used in that same thread. The object was created in thread id 123988330428224 and this is thread id 123985729685056.
sqlite3.ProgrammingError: SQLite objects created in a thread can only be used in that same thread. The object was created in thread id 123988330428224 and this is thread id 123986323179072.
sqlite3.ProgrammingError: SQLite objects created in a thread can only be used in that same thread. The object was created in thread id 123988330428224 and this is thread id 123986163795520.
  File "/home/mrigankp/fuzz4py/fuzz4py/inputs/790.py", line 15, in worker
    db[str(data)] = data * 2
    ~~^^^^^^^^^^^
sqlite3.ProgrammingError: SQLite objects created in a thread can only be used in that same thread. The object was created in thread id 123988330428224 and this is thread id 123987180914240.
  File "/home/mrigankp/fuzz4py/cpython/Lib/threading.py", line 1041, in _bootstrap_inner
    self.run()
    ~~~~~~~~^^
  File "/home/mrigankp/fuzz4py/cpython/Lib/dbm/sqlite3.py", line 79, in _execute
    return closing(self._cx.execute(*args, **kwargs))
                   ~~~~~~~~~~~~~~~~^^^^^^^^^^^^^^^^^
  File "/home/mrigankp/fuzz4py/cpython/Lib/threading.py", line 1041, in _bootstrap_inner
    self.run()
    ~~~~~~~~^^

During handling of the above exception, another exception occurred:

Traceback (most recent call last):
Traceback (most recent call last):

During handling of the above exception, another exception occurred:


During handling of the above exception, another exception occurred:

Traceback (most recent call last):
sqlite3.ProgrammingError: SQLite objects created in a thread can only be used in that same thread. The object was created in thread id 123988330428224 and this is thread id 123985559815744.

During handling of the above exception, another exception occurred:


During handling of the above exception, another exception occurred:


During handling of the above exception, another exception occurred:


During handling of the above exception, another exception occurred:

sqlite3.ProgrammingError: SQLite objects created in a thread can only be used in that same thread. The object was created in thread id 123988330428224 and this is thread id 123985972954688.
  File "/home/mrigankp/fuzz4py/cpython/Lib/dbm/sqlite3.py", line 79, in _execute
    return closing(self._cx.execute(*args, **kwargs))
                   ~~~~~~~~~~~~~~~~^^^^^^^^^^^^^^^^^
  File "/home/mrigankp/fuzz4py/cpython/Lib/dbm/sqlite3.py", line 79, in _execute
    return closing(self._cx.execute(*args, **kwargs))
                   ~~~~~~~~~~~~~~~~^^^^^^^^^^^^^^^^^

During handling of the above exception, another exception occurred:

  File "/home/mrigankp/fuzz4py/cpython/Lib/threading.py", line 992, in run
    self._target(*self._args, **self._kwargs)
    ~~~~~~~~~~~~^^^^^^^^^^^^^^^^^^^^^^^^^^^^^
sqlite3.ProgrammingError: SQLite objects created in a thread can only be used in that same thread. The object was created in thread id 123988330428224 and this is thread id 123985962468928.
Traceback (most recent call last):
Traceback (most recent call last):
  File "/home/mrigankp/fuzz4py/cpython/Lib/threading.py", line 992, in run
    self._target(*self._args, **self._kwargs)
    ~~~~~~~~~~~~^^^^^^^^^^^^^^^^^^^^^^^^^^^^^
  File "/home/mrigankp/fuzz4py/fuzz4py/inputs/790.py", line 15, in worker
    db[str(data)] = data * 2
    ~~^^^^^^^^^^^
sqlite3.ProgrammingError: SQLite objects created in a thread can only be used in that same thread. The object was created in thread id 123988330428224 and this is thread id 123985358489152.
sqlite3.ProgrammingError: SQLite objects created in a thread can only be used in that same thread. The object was created in thread id 123988330428224 and this is thread id 123987138971200.
sqlite3.ProgrammingError: SQLite objects created in a thread can only be used in that same thread. The object was created in thread id 123988330428224 and this is thread id 123985931011648.

During handling of the above exception, another exception occurred:

Traceback (most recent call last):

During handling of the above exception, another exception occurred:

Traceback (most recent call last):
  File "/home/mrigankp/fuzz4py/cpython/Lib/threading.py", line 992, in run
    self._target(*self._args, **self._kwargs)
    ~~~~~~~~~~~~^^^^^^^^^^^^^^^^^^^^^^^^^^^^^
Traceback (most recent call last):
Traceback (most recent call last):
Traceback (most recent call last):
sqlite3.ProgrammingError: SQLite objects created in a thread can only be used in that same thread. The object was created in thread id 123988330428224 and this is thread id 123985316546112.

During handling of the above exception, another exception occurred:

Traceback (most recent call last):
  File "/home/mrigankp/fuzz4py/cpython/Lib/dbm/sqlite3.py", line 79, in _execute
    return closing(self._cx.execute(*args, **kwargs))
                   ~~~~~~~~~~~~~~~~^^^^^^^^^^^^^^^^^
Traceback (most recent call last):
  File "/home/mrigankp/fuzz4py/fuzz4py/inputs/790.py", line 15, in worker
    db[str(data)] = data * 2
    ~~^^^^^^^^^^^
  File "/home/mrigankp/fuzz4py/cpython/Lib/dbm/sqlite3.py", line 96, in __setitem__
    self._execute(STORE_KV, (key, value))
    ~~~~~~~~~~~~~^^^^^^^^^^^^^^^^^^^^^^^^
  File "/home/mrigankp/fuzz4py/cpython/Lib/dbm/sqlite3.py", line 79, in _execute
    return closing(self._cx.execute(*args, **kwargs))
                   ~~~~~~~~~~~~~~~~^^^^^^^^^^^^^^^^^
sqlite3.ProgrammingError: SQLite objects created in a thread can only be used in that same thread. The object was created in thread id 123988330428224 and this is thread id 123985740170816.
  File "/home/mrigankp/fuzz4py/cpython/Lib/dbm/sqlite3.py", line 79, in _execute
    return closing(self._cx.execute(*args, **kwargs))
                   ~~~~~~~~~~~~~~~~^^^^^^^^^^^^^^^^^

During handling of the above exception, another exception occurred:


During handling of the above exception, another exception occurred:


During handling of the above exception, another exception occurred:

  File "/home/mrigankp/fuzz4py/cpython/Lib/dbm/sqlite3.py", line 79, in _execute
    return closing(self._cx.execute(*args, **kwargs))
                   ~~~~~~~~~~~~~~~~^^^^^^^^^^^^^^^^^

During handling of the above exception, another exception occurred:

  File "/home/mrigankp/fuzz4py/cpython/Lib/threading.py", line 992, in run
    self._target(*self._args, **self._kwargs)
    ~~~~~~~~~~~~^^^^^^^^^^^^^^^^^^^^^^^^^^^^^

During handling of the above exception, another exception occurred:

  File "/home/mrigankp/fuzz4py/cpython/Lib/threading.py", line 992, in run
    self._target(*self._args, **self._kwargs)
    ~~~~~~~~~~~~^^^^^^^^^^^^^^^^^^^^^^^^^^^^^
  File "/home/mrigankp/fuzz4py/cpython/Lib/threading.py", line 992, in run
    self._target(*self._args, **self._kwargs)
    ~~~~~~~~~~~~^^^^^^^^^^^^^^^^^^^^^^^^^^^^^
Traceback (most recent call last):
  File "/home/mrigankp/fuzz4py/cpython/Lib/threading.py", line 1041, in _bootstrap_inner
    self.run()
    ~~~~~~~~^^
Traceback (most recent call last):
Traceback (most recent call last):
Traceback (most recent call last):
  File "/home/mrigankp/fuzz4py/cpython/Lib/threading.py", line 1041, in _bootstrap_inner
    self.run()
    ~~~~~~~~^^
Traceback (most recent call last):
Traceback (most recent call last):
Traceback (most recent call last):
  File "/home/mrigankp/fuzz4py/cpython/Lib/dbm/sqlite3.py", line 79, in _execute
    return closing(self._cx.execute(*args, **kwargs))
                   ~~~~~~~~~~~~~~~~^^^^^^^^^^^^^^^^^
  File "/home/mrigankp/fuzz4py/cpython/Lib/threading.py", line 1041, in _bootstrap_inner
    self.run()
    ~~~~~~~~^^

During handling of the above exception, another exception occurred:

sqlite3.ProgrammingError: SQLite objects created in a thread can only be used in that same thread. The object was created in thread id 123988330428224 and this is thread id 123986545477184.
sqlite3.ProgrammingError: SQLite objects created in a thread can only be used in that same thread. The object was created in thread id 123988330428224 and this is thread id 123985517872704.

During handling of the above exception, another exception occurred:

Traceback (most recent call last):

During handling of the above exception, another exception occurred:

sqlite3.ProgrammingError: SQLite objects created in a thread can only be used in that same thread. The object was created in thread id 123988330428224 and this is thread id 123986375607872.
  File "/home/mrigankp/fuzz4py/cpython/Lib/threading.py", line 1041, in _bootstrap_inner
    self.run()
    ~~~~~~~~^^
Traceback (most recent call last):
sqlite3.ProgrammingError: SQLite objects created in a thread can only be used in that same thread. The object was created in thread id 123988330428224 and this is thread id 123986524505664.
  File "/home/mrigankp/fuzz4py/cpython/Lib/threading.py", line 1041, in _bootstrap_inner
    self.run()
    ~~~~~~~~^^

During handling of the above exception, another exception occurred:


During handling of the above exception, another exception occurred:


During handling of the above exception, another exception occurred:

  File "/home/mrigankp/fuzz4py/cpython/Lib/dbm/sqlite3.py", line 79, in _execute
    return closing(self._cx.execute(*args, **kwargs))
                   ~~~~~~~~~~~~~~~~^^^^^^^^^^^^^^^^^
Traceback (most recent call last):
  File "/home/mrigankp/fuzz4py/fuzz4py/inputs/790.py", line 15, in worker
    db[str(data)] = data * 2
    ~~^^^^^^^^^^^

During handling of the above exception, another exception occurred:


During handling of the above exception, another exception occurred:

  File "/home/mrigankp/fuzz4py/cpython/Lib/threading.py", line 1041, in _bootstrap_inner
    self.run()
    ~~~~~~~~^^
  File "/home/mrigankp/fuzz4py/cpython/Lib/threading.py", line 992, in run
    self._target(*self._args, **self._kwargs)
    ~~~~~~~~~~~~^^^^^^^^^^^^^^^^^^^^^^^^^^^^^

During handling of the above exception, another exception occurred:

Traceback (most recent call last):
  File "/home/mrigankp/fuzz4py/cpython/Lib/dbm/sqlite3.py", line 81, in _execute
    raise error(str(exc))
  File "/home/mrigankp/fuzz4py/cpython/Lib/threading.py", line 1041, in _bootstrap_inner
    self.run()
    ~~~~~~~~^^
  File "/home/mrigankp/fuzz4py/cpython/Lib/threading.py", line 1041, in _bootstrap_inner
    self.run()
    ~~~~~~~~^^

During handling of the above exception, another exception occurred:

sqlite3.ProgrammingError: SQLite objects created in a thread can only be used in that same thread. The object was created in thread id 123988330428224 and this is thread id 123985146676800.
  File "/home/mrigankp/fuzz4py/fuzz4py/inputs/790.py", line 15, in worker
    db[str(data)] = data * 2
    ~~^^^^^^^^^^^

During handling of the above exception, another exception occurred:

sqlite3.ProgrammingError: SQLite objects created in a thread can only be used in that same thread. The object was created in thread id 123988330428224 and this is thread id 123985136191040.
Traceback (most recent call last):
  File "/home/mrigankp/fuzz4py/cpython/Lib/dbm/sqlite3.py", line 96, in __setitem__
    self._execute(STORE_KV, (key, value))
    ~~~~~~~~~~~~~^^^^^^^^^^^^^^^^^^^^^^^^
Traceback (most recent call last):
Traceback (most recent call last):
  File "/home/mrigankp/fuzz4py/cpython/Lib/dbm/sqlite3.py", line 79, in _execute
    return closing(self._cx.execute(*args, **kwargs))
                   ~~~~~~~~~~~~~~~~^^^^^^^^^^^^^^^^^
sqlite3.ProgrammingError: SQLite objects created in a thread can only be used in that same thread. The object was created in thread id 123988330428224 and this is thread id 123986153309760.
  File "/home/mrigankp/fuzz4py/cpython/Lib/threading.py", line 992, in run
    self._target(*self._args, **self._kwargs)
    ~~~~~~~~~~~~^^^^^^^^^^^^^^^^^^^^^^^^^^^^^
Traceback (most recent call last):
  File "/home/mrigankp/fuzz4py/fuzz4py/inputs/790.py", line 15, in worker
    db[str(data)] = data * 2
    ~~^^^^^^^^^^^
  File "/home/mrigankp/fuzz4py/cpython/Lib/threading.py", line 1041, in _bootstrap_inner
    self.run()
    ~~~~~~~~^^

During handling of the above exception, another exception occurred:

Traceback (most recent call last):
  File "/home/mrigankp/fuzz4py/cpython/Lib/threading.py", line 1041, in _bootstrap_inner
    self.run()
    ~~~~~~~~^^
  File "/home/mrigankp/fuzz4py/cpython/Lib/threading.py", line 1041, in _bootstrap_inner
    self.run()
    ~~~~~~~~^^
  File "/home/mrigankp/fuzz4py/cpython/Lib/threading.py", line 992, in run
    self._target(*self._args, **self._kwargs)
    ~~~~~~~~~~~~^^^^^^^^^^^^^^^^^^^^^^^^^^^^^
  File "/home/mrigankp/fuzz4py/cpython/Lib/threading.py", line 1041, in _bootstrap_inner
    self.run()
    ~~~~~~~~^^
  File "/home/mrigankp/fuzz4py/cpython/Lib/dbm/sqlite3.py", line 79, in _execute
    return closing(self._cx.execute(*args, **kwargs))
                   ~~~~~~~~~~~~~~~~^^^^^^^^^^^^^^^^^
  File "/home/mrigankp/fuzz4py/cpython/Lib/threading.py", line 1041, in _bootstrap_inner
    self.run()
    ~~~~~~~~^^
Traceback (most recent call last):
  File "/home/mrigankp/fuzz4py/cpython/Lib/threading.py", line 992, in run
    self._target(*self._args, **self._kwargs)
    ~~~~~~~~~~~~^^^^^^^^^^^^^^^^^^^^^^^^^^^^^
  File "/home/mrigankp/fuzz4py/cpython/Lib/threading.py", line 1041, in _bootstrap_inner
    self.run()
    ~~~~~~~~^^
Traceback (most recent call last):
Traceback (most recent call last):
Traceback (most recent call last):

During handling of the above exception, another exception occurred:

  File "/home/mrigankp/fuzz4py/cpython/Lib/dbm/sqlite3.py", line 79, in _execute
    return closing(self._cx.execute(*args, **kwargs))
                   ~~~~~~~~~~~~~~~~^^^^^^^^^^^^^^^^^
  File "/home/mrigankp/fuzz4py/cpython/Lib/dbm/sqlite3.py", line 79, in _execute
    return closing(self._cx.execute(*args, **kwargs))
                   ~~~~~~~~~~~~~~~~^^^^^^^^^^^^^^^^^
  File "/home/mrigankp/fuzz4py/fuzz4py/inputs/790.py", line 15, in worker
    db[str(data)] = data * 2
    ~~^^^^^^^^^^^
  File "/home/mrigankp/fuzz4py/cpython/Lib/dbm/sqlite3.py", line 96, in __setitem__
    self._execute(STORE_KV, (key, value))
    ~~~~~~~~~~~~~^^^^^^^^^^^^^^^^^^^^^^^^

During handling of the above exception, another exception occurred:

  File "/home/mrigankp/fuzz4py/cpython/Lib/dbm/sqlite3.py", line 79, in _execute
    return closing(self._cx.execute(*args, **kwargs))
                   ~~~~~~~~~~~~~~~~^^^^^^^^^^^^^^^^^
  File "/home/mrigankp/fuzz4py/cpython/Lib/threading.py", line 992, in run
    self._target(*self._args, **self._kwargs)
    ~~~~~~~~~~~~^^^^^^^^^^^^^^^^^^^^^^^^^^^^^
  File "/home/mrigankp/fuzz4py/cpython/Lib/threading.py", line 1041, in _bootstrap_inner
    self.run()
    ~~~~~~~~^^
Traceback (most recent call last):
  File "/home/mrigankp/fuzz4py/cpython/Lib/dbm/sqlite3.py", line 79, in _execute
    return closing(self._cx.execute(*args, **kwargs))
                   ~~~~~~~~~~~~~~~~^^^^^^^^^^^^^^^^^
  File "/home/mrigankp/fuzz4py/cpython/Lib/threading.py", line 992, in run
    self._target(*self._args, **self._kwargs)
    ~~~~~~~~~~~~^^^^^^^^^^^^^^^^^^^^^^^^^^^^^
  File "/home/mrigankp/fuzz4py/cpython/Lib/dbm/sqlite3.py", line 79, in _execute
    return closing(self._cx.execute(*args, **kwargs))
                   ~~~~~~~~~~~~~~~~^^^^^^^^^^^^^^^^^
  File "/home/mrigankp/fuzz4py/cpython/Lib/threading.py", line 1041, in _bootstrap_inner
    self.run()
    ~~~~~~~~^^
Traceback (most recent call last):
Traceback (most recent call last):

During handling of the above exception, another exception occurred:

Traceback (most recent call last):
sqlite3.ProgrammingError: SQLite objects created in a thread can only be used in that same thread. The object was created in thread id 123988330428224 and this is thread id 123986333664832.
dbm.sqlite3.error: SQLite objects created in a thread can only be used in that same thread. The object was created in thread id 123988330428224 and this is thread id 123987742950976.
  File "/home/mrigankp/fuzz4py/cpython/Lib/threading.py", line 992, in run
    self._target(*self._args, **self._kwargs)
    ~~~~~~~~~~~~^^^^^^^^^^^^^^^^^^^^^^^^^^^^^
  File "/home/mrigankp/fuzz4py/fuzz4py/inputs/790.py", line 15, in worker
    db[str(data)] = data * 2
    ~~^^^^^^^^^^^
Traceback (most recent call last):
  File "/home/mrigankp/fuzz4py/cpython/Lib/dbm/sqlite3.py", line 81, in _execute
    raise error(str(exc))
  File "/home/mrigankp/fuzz4py/cpython/Lib/dbm/sqlite3.py", line 96, in __setitem__
    self._execute(STORE_KV, (key, value))
    ~~~~~~~~~~~~~^^^^^^^^^^^^^^^^^^^^^^^^
  File "/home/mrigankp/fuzz4py/cpython/Lib/dbm/sqlite3.py", line 81, in _execute
    raise error(str(exc))
Traceback (most recent call last):
  File "/home/mrigankp/fuzz4py/cpython/Lib/dbm/sqlite3.py", line 79, in _execute
    return closing(self._cx.execute(*args, **kwargs))
                   ~~~~~~~~~~~~~~~~^^^^^^^^^^^^^^^^^
Traceback (most recent call last):
sqlite3.ProgrammingError: SQLite objects created in a thread can only be used in that same thread. The object was created in thread id 123988330428224 and this is thread id 123985719199296.
  File "/home/mrigankp/fuzz4py/cpython/Lib/threading.py", line 1041, in _bootstrap_inner
    self.run()
    ~~~~~~~~^^
  File "/home/mrigankp/fuzz4py/fuzz4py/inputs/790.py", line 15, in worker
    db[str(data)] = data * 2
    ~~^^^^^^^^^^^
sqlite3.ProgrammingError: SQLite objects created in a thread can only be used in that same thread. The object was created in thread id 123988330428224 and this is thread id 123986576934464.
  File "/home/mrigankp/fuzz4py/cpython/Lib/threading.py", line 1041, in _bootstrap_inner
    self.run()
    ~~~~~~~~^^
  File "/home/mrigankp/fuzz4py/cpython/Lib/dbm/sqlite3.py", line 96, in __setitem__
    self._execute(STORE_KV, (key, value))
    ~~~~~~~~~~~~~^^^^^^^^^^^^^^^^^^^^^^^^
  File "/home/mrigankp/fuzz4py/cpython/Lib/threading.py", line 992, in run
    self._target(*self._args, **self._kwargs)
    ~~~~~~~~~~~~^^^^^^^^^^^^^^^^^^^^^^^^^^^^^
  File "/home/mrigankp/fuzz4py/cpython/Lib/threading.py", line 992, in run
    self._target(*self._args, **self._kwargs)
    ~~~~~~~~~~~~^^^^^^^^^^^^^^^^^^^^^^^^^^^^^
  File "/home/mrigankp/fuzz4py/cpython/Lib/threading.py", line 992, in run
    self._target(*self._args, **self._kwargs)
    ~~~~~~~~~~~~^^^^^^^^^^^^^^^^^^^^^^^^^^^^^
  File "/home/mrigankp/fuzz4py/cpython/Lib/threading.py", line 1041, in _bootstrap_inner
    self.run()
    ~~~~~~~~^^

During handling of the above exception, another exception occurred:

  File "/home/mrigankp/fuzz4py/fuzz4py/inputs/790.py", line 15, in worker
    db[str(data)] = data * 2
    ~~^^^^^^^^^^^
  File "/home/mrigankp/fuzz4py/cpython/Lib/threading.py", line 992, in run
    self._target(*self._args, **self._kwargs)
    ~~~~~~~~~~~~^^^^^^^^^^^^^^^^^^^^^^^^^^^^^
sqlite3.ProgrammingError: SQLite objects created in a thread can only be used in that same thread. The object was created in thread id 123988330428224 and this is thread id 123986121852480.
  File "/home/mrigankp/fuzz4py/cpython/Lib/threading.py", line 992, in run
    self._target(*self._args, **self._kwargs)
    ~~~~~~~~~~~~^^^^^^^^^^^^^^^^^^^^^^^^^^^^^
sqlite3.ProgrammingError: SQLite objects created in a thread can only be used in that same thread. The object was created in thread id 123988330428224 and this is thread id 123985538844224.
  File "/home/mrigankp/fuzz4py/fuzz4py/inputs/790.py", line 15, in worker
    db[str(data)] = data * 2
    ~~^^^^^^^^^^^
sqlite3.ProgrammingError: SQLite objects created in a thread can only be used in that same thread. The object was created in thread id 123988330428224 and this is thread id 123985951983168.

During handling of the above exception, another exception occurred:

Traceback (most recent call last):
  File "/home/mrigankp/fuzz4py/cpython/Lib/dbm/sqlite3.py", line 79, in _execute
    return closing(self._cx.execute(*args, **kwargs))
                   ~~~~~~~~~~~~~~~~^^^^^^^^^^^^^^^^^
  File "/home/mrigankp/fuzz4py/cpython/Lib/threading.py", line 1041, in _bootstrap_inner
    self.run()
    ~~~~~~~~^^
  File "/home/mrigankp/fuzz4py/cpython/Lib/threading.py", line 992, in run
    self._target(*self._args, **self._kwargs)
    ~~~~~~~~~~~~^^^^^^^^^^^^^^^^^^^^^^^^^^^^^
sqlite3.ProgrammingError: SQLite objects created in a thread can only be used in that same thread. The object was created in thread id 123988330428224 and this is thread id 123986778261056.
  File "/home/mrigankp/fuzz4py/cpython/Lib/threading.py", line 992, in run
    self._target(*self._args, **self._kwargs)
    ~~~~~~~~~~~~^^^^^^^^^^^^^^^^^^^^^^^^^^^^^
  File "/home/mrigankp/fuzz4py/cpython/Lib/dbm/sqlite3.py", line 81, in _execute
    raise error(str(exc))
Traceback (most recent call last):
Traceback (most recent call last):
  File "/home/mrigankp/fuzz4py/fuzz4py/inputs/790.py", line 15, in worker
    db[str(data)] = data * 2
    ~~^^^^^^^^^^^
  File "/home/mrigankp/fuzz4py/cpython/Lib/threading.py", line 992, in run
    self._target(*self._args, **self._kwargs)
    ~~~~~~~~~~~~^^^^^^^^^^^^^^^^^^^^^^^^^^^^^
sqlite3.ProgrammingError: SQLite objects created in a thread can only be used in that same thread. The object was created in thread id 123988330428224 and this is thread id 123986354636352.
sqlite3.ProgrammingError: SQLite objects created in a thread can only be used in that same thread. The object was created in thread id 123988330428224 and this is thread id 123985761142336.
  File "/home/mrigankp/fuzz4py/fuzz4py/inputs/790.py", line 15, in worker
    db[str(data)] = data * 2
    ~~^^^^^^^^^^^
sqlite3.ProgrammingError: SQLite objects created in a thread can only be used in that same thread. The object was created in thread id 123988330428224 and this is thread id 123986746803776.
  File "/home/mrigankp/fuzz4py/cpython/Lib/threading.py", line 992, in run
    self._target(*self._args, **self._kwargs)
    ~~~~~~~~~~~~^^^^^^^^^^^^^^^^^^^^^^^^^^^^^
  File "/home/mrigankp/fuzz4py/cpython/Lib/dbm/sqlite3.py", line 79, in _execute
    return closing(self._cx.execute(*args, **kwargs))
                   ~~~~~~~~~~~~~~~~^^^^^^^^^^^^^^^^^
  File "/home/mrigankp/fuzz4py/cpython/Lib/threading.py", line 1041, in _bootstrap_inner
    self.run()
    ~~~~~~~~^^
Traceback (most recent call last):
Traceback (most recent call last):
  File "/home/mrigankp/fuzz4py/cpython/Lib/threading.py", line 1041, in _bootstrap_inner
    self.run()
    ~~~~~~~~^^
  File "/home/mrigankp/fuzz4py/fuzz4py/inputs/790.py", line 15, in worker
    db[str(data)] = data * 2
    ~~^^^^^^^^^^^
  File "/home/mrigankp/fuzz4py/fuzz4py/inputs/790.py", line 15, in worker
    db[str(data)] = data * 2
    ~~^^^^^^^^^^^

During handling of the above exception, another exception occurred:

  File "/home/mrigankp/fuzz4py/cpython/Lib/threading.py", line 992, in run
    self._target(*self._args, **self._kwargs)
    ~~~~~~~~~~~~^^^^^^^^^^^^^^^^^^^^^^^^^^^^^
Traceback (most recent call last):

During handling of the above exception, another exception occurred:


During handling of the above exception, another exception occurred:


During handling of the above exception, another exception occurred:

Traceback (most recent call last):
  File "/home/mrigankp/fuzz4py/cpython/Lib/threading.py", line 992, in run
    self._target(*self._args, **self._kwargs)
    ~~~~~~~~~~~~^^^^^^^^^^^^^^^^^^^^^^^^^^^^^
  File "/home/mrigankp/fuzz4py/cpython/Lib/dbm/sqlite3.py", line 96, in __setitem__
    self._execute(STORE_KV, (key, value))
    ~~~~~~~~~~~~~^^^^^^^^^^^^^^^^^^^^^^^^

During handling of the above exception, another exception occurred:

  File "/home/mrigankp/fuzz4py/fuzz4py/inputs/790.py", line 15, in worker
    db[str(data)] = data * 2
    ~~^^^^^^^^^^^
  File "/home/mrigankp/fuzz4py/cpython/Lib/threading.py", line 992, in run
    self._target(*self._args, **self._kwargs)
    ~~~~~~~~~~~~^^^^^^^^^^^^^^^^^^^^^^^^^^^^^
  File "/home/mrigankp/fuzz4py/cpython/Lib/dbm/sqlite3.py", line 81, in _execute
    raise error(str(exc))
Traceback (most recent call last):
  File "/home/mrigankp/fuzz4py/fuzz4py/inputs/790.py", line 15, in worker
    db[str(data)] = data * 2
    ~~^^^^^^^^^^^
  File "/home/mrigankp/fuzz4py/fuzz4py/inputs/790.py", line 15, in worker
    db[str(data)] = data * 2
    ~~^^^^^^^^^^^
  File "/home/mrigankp/fuzz4py/cpython/Lib/threading.py", line 1041, in _bootstrap_inner
    self.run()
    ~~~~~~~~^^
Traceback (most recent call last):
  File "/home/mrigankp/fuzz4py/cpython/Lib/threading.py", line 992, in run
    self._target(*self._args, **self._kwargs)
    ~~~~~~~~~~~~^^^^^^^^^^^^^^^^^^^^^^^^^^^^^

During handling of the above exception, another exception occurred:


During handling of the above exception, another exception occurred:

  File "/home/mrigankp/fuzz4py/cpython/Lib/threading.py", line 1041, in _bootstrap_inner
    self.run()
    ~~~~~~~~^^

During handling of the above exception, another exception occurred:

  File "/home/mrigankp/fuzz4py/cpython/Lib/dbm/sqlite3.py", line 96, in __setitem__
    self._execute(STORE_KV, (key, value))
    ~~~~~~~~~~~~~^^^^^^^^^^^^^^^^^^^^^^^^
  File "/home/mrigankp/fuzz4py/fuzz4py/inputs/790.py", line 15, in worker
    db[str(data)] = data * 2
    ~~^^^^^^^^^^^
Traceback (most recent call last):
sqlite3.ProgrammingError: SQLite objects created in a thread can only be used in that same thread. The object was created in thread id 123988330428224 and this is thread id 123985368974912.
Traceback (most recent call last):

During handling of the above exception, another exception occurred:

  File "/home/mrigankp/fuzz4py/fuzz4py/inputs/790.py", line 15, in worker
    db[str(data)] = data * 2
    ~~^^^^^^^^^^^

During handling of the above exception, another exception occurred:

  File "/home/mrigankp/fuzz4py/fuzz4py/inputs/790.py", line 15, in worker
    db[str(data)] = data * 2
    ~~^^^^^^^^^^^

During handling of the above exception, another exception occurred:

Traceback (most recent call last):
  File "/home/mrigankp/fuzz4py/cpython/Lib/dbm/sqlite3.py", line 79, in _execute
    return closing(self._cx.execute(*args, **kwargs))
                   ~~~~~~~~~~~~~~~~^^^^^^^^^^^^^^^^^
  File "/home/mrigankp/fuzz4py/cpython/Lib/threading.py", line 1041, in _bootstrap_inner
    self.run()
    ~~~~~~~~^^
Traceback (most recent call last):
  File "/home/mrigankp/fuzz4py/cpython/Lib/threading.py", line 1041, in _bootstrap_inner
    self.run()
    ~~~~~~~~^^

During handling of the above exception, another exception occurred:

  File "/home/mrigankp/fuzz4py/cpython/Lib/dbm/sqlite3.py", line 96, in __setitem__
    self._execute(STORE_KV, (key, value))
    ~~~~~~~~~~~~~^^^^^^^^^^^^^^^^^^^^^^^^
Exception in thread Thread-96 (worker):
  File "/home/mrigankp/fuzz4py/cpython/Lib/threading.py", line 992, in run
    self._target(*self._args, **self._kwargs)
    ~~~~~~~~~~~~^^^^^^^^^^^^^^^^^^^^^^^^^^^^^
sqlite3.ProgrammingError: SQLite objects created in a thread can only be used in that same thread. The object was created in thread id 123988330428224 and this is thread id 123985750656576.
  File "/home/mrigankp/fuzz4py/cpython/Lib/threading.py", line 992, in run
    self._target(*self._args, **self._kwargs)
    ~~~~~~~~~~~~^^^^^^^^^^^^^^^^^^^^^^^^^^^^^

During handling of the above exception, another exception occurred:

  File "/home/mrigankp/fuzz4py/cpython/Lib/threading.py", line 1041, in _bootstrap_inner
    self.run()
    ~~~~~~~~^^
  File "/home/mrigankp/fuzz4py/cpython/Lib/threading.py", line 992, in run
    self._target(*self._args, **self._kwargs)
    ~~~~~~~~~~~~^^^^^^^^^^^^^^^^^^^^^^^^^^^^^
  File "/home/mrigankp/fuzz4py/cpython/Lib/threading.py", line 992, in run
    self._target(*self._args, **self._kwargs)
    ~~~~~~~~~~~~^^^^^^^^^^^^^^^^^^^^^^^^^^^^^
  File "/home/mrigankp/fuzz4py/cpython/Lib/dbm/sqlite3.py", line 96, in __setitem__
    self._execute(STORE_KV, (key, value))
    ~~~~~~~~~~~~~^^^^^^^^^^^^^^^^^^^^^^^^
  File "/home/mrigankp/fuzz4py/cpython/Lib/threading.py", line 1041, in _bootstrap_inner
    self.run()
    ~~~~~~~~^^
  File "/home/mrigankp/fuzz4py/fuzz4py/inputs/790.py", line 15, in worker
    db[str(data)] = data * 2
    ~~^^^^^^^^^^^
  File "/home/mrigankp/fuzz4py/cpython/Lib/dbm/sqlite3.py", line 96, in __setitem__
    self._execute(STORE_KV, (key, value))
    ~~~~~~~~~~~~~^^^^^^^^^^^^^^^^^^^^^^^^
Traceback (most recent call last):
Traceback (most recent call last):
sqlite3.ProgrammingError: SQLite objects created in a thread can only be used in that same thread. The object was created in thread id 123988330428224 and this is thread id 123985125705280.
  File "/home/mrigankp/fuzz4py/cpython/Lib/threading.py", line 1041, in _bootstrap_inner
    self.run()
    ~~~~~~~~^^
  File "/home/mrigankp/fuzz4py/cpython/Lib/threading.py", line 1041, in _bootstrap_inner
    self.run()
    ~~~~~~~~^^

During handling of the above exception, another exception occurred:

  File "/home/mrigankp/fuzz4py/fuzz4py/inputs/790.py", line 15, in worker
    db[str(data)] = data * 2
    ~~^^^^^^^^^^^
  File "/home/mrigankp/fuzz4py/cpython/Lib/dbm/sqlite3.py", line 96, in __setitem__
    self._execute(STORE_KV, (key, value))
    ~~~~~~~~~~~~~^^^^^^^^^^^^^^^^^^^^^^^^
  File "/home/mrigankp/fuzz4py/fuzz4py/inputs/790.py", line 15, in worker
    db[str(data)] = data * 2
    ~~^^^^^^^^^^^
  File "/home/mrigankp/fuzz4py/fuzz4py/inputs/790.py", line 15, in worker
    db[str(data)] = data * 2
    ~~^^^^^^^^^^^
  File "/home/mrigankp/fuzz4py/cpython/Lib/threading.py", line 1041, in _bootstrap_inner
    self.run()
    ~~~~~~~~^^
  File "/home/mrigankp/fuzz4py/cpython/Lib/threading.py", line 1041, in _bootstrap_inner
    self.run()
    ~~~~~~~~^^
  File "/home/mrigankp/fuzz4py/cpython/Lib/threading.py", line 992, in run
    self._target(*self._args, **self._kwargs)
    ~~~~~~~~~~~~^^^^^^^^^^^^^^^^^^^^^^^^^^^^^
  File "/home/mrigankp/fuzz4py/cpython/Lib/dbm/sqlite3.py", line 96, in __setitem__
    self._execute(STORE_KV, (key, value))
    ~~~~~~~~~~~~~^^^^^^^^^^^^^^^^^^^^^^^^
  File "/home/mrigankp/fuzz4py/cpython/Lib/dbm/sqlite3.py", line 96, in __setitem__
    self._execute(STORE_KV, (key, value))
    ~~~~~~~~~~~~~^^^^^^^^^^^^^^^^^^^^^^^^
  File "/home/mrigankp/fuzz4py/cpython/Lib/dbm/sqlite3.py", line 81, in _execute
    raise error(str(exc))
  File "/home/mrigankp/fuzz4py/cpython/Lib/threading.py", line 1041, in _bootstrap_inner
    self.run()
    ~~~~~~~~^^
Traceback (most recent call last):
Traceback (most recent call last):
  File "/home/mrigankp/fuzz4py/cpython/Lib/threading.py", line 992, in run
    self._target(*self._args, **self._kwargs)
    ~~~~~~~~~~~~^^^^^^^^^^^^^^^^^^^^^^^^^^^^^
Traceback (most recent call last):
  File "/home/mrigankp/fuzz4py/cpython/Lib/threading.py", line 1041, in _bootstrap_inner
    self.run()
    ~~~~~~~~^^
  File "/home/mrigankp/fuzz4py/cpython/Lib/dbm/sqlite3.py", line 96, in __setitem__
    self._execute(STORE_KV, (key, value))
    ~~~~~~~~~~~~~^^^^^^^^^^^^^^^^^^^^^^^^

During handling of the above exception, another exception occurred:

Traceback (most recent call last):
Traceback (most recent call last):
  File "/home/mrigankp/fuzz4py/cpython/Lib/dbm/sqlite3.py", line 96, in __setitem__
    self._execute(STORE_KV, (key, value))
    ~~~~~~~~~~~~~^^^^^^^^^^^^^^^^^^^^^^^^
  File "/home/mrigankp/fuzz4py/cpython/Lib/threading.py", line 992, in run
    self._target(*self._args, **self._kwargs)
    ~~~~~~~~~~~~^^^^^^^^^^^^^^^^^^^^^^^^^^^^^
dbm.sqlite3.error: SQLite objects created in a thread can only be used in that same thread. The object was created in thread id 123988330428224 and this is thread id 123987753436736.
  File "/home/mrigankp/fuzz4py/cpython/Lib/dbm/sqlite3.py", line 96, in __setitem__
    self._execute(STORE_KV, (key, value))
    ~~~~~~~~~~~~~^^^^^^^^^^^^^^^^^^^^^^^^
  File "/home/mrigankp/fuzz4py/cpython/Lib/threading.py", line 1041, in _bootstrap_inner
    self.run()
    ~~~~~~~~^^
  File "/home/mrigankp/fuzz4py/cpython/Lib/dbm/sqlite3.py", line 96, in __setitem__
    self._execute(STORE_KV, (key, value))
    ~~~~~~~~~~~~~^^^^^^^^^^^^^^^^^^^^^^^^
  File "/home/mrigankp/fuzz4py/fuzz4py/inputs/790.py", line 15, in worker
    db[str(data)] = data * 2
    ~~^^^^^^^^^^^

During handling of the above exception, another exception occurred:

  File "/home/mrigankp/fuzz4py/cpython/Lib/threading.py", line 992, in run
    self._target(*self._args, **self._kwargs)
    ~~~~~~~~~~~~^^^^^^^^^^^^^^^^^^^^^^^^^^^^^
  File "/home/mrigankp/fuzz4py/cpython/Lib/threading.py", line 1041, in _bootstrap_inner
    self.run()
    ~~~~~~~~^^
  File "/home/mrigankp/fuzz4py/cpython/Lib/dbm/sqlite3.py", line 81, in _execute
    raise error(str(exc))

During handling of the above exception, another exception occurred:

  File "/home/mrigankp/fuzz4py/fuzz4py/inputs/790.py", line 15, in worker
    db[str(data)] = data * 2
    ~~^^^^^^^^^^^
  File "/home/mrigankp/fuzz4py/cpython/Lib/threading.py", line 1041, in _bootstrap_inner
    self.run()
    ~~~~~~~~^^

During handling of the above exception, another exception occurred:

  File "/home/mrigankp/fuzz4py/fuzz4py/inputs/790.py", line 15, in worker
    db[str(data)] = data * 2
    ~~^^^^^^^^^^^
Traceback (most recent call last):
  File "/home/mrigankp/fuzz4py/cpython/Lib/dbm/sqlite3.py", line 96, in __setitem__
    self._execute(STORE_KV, (key, value))
    ~~~~~~~~~~~~~^^^^^^^^^^^^^^^^^^^^^^^^
  File "/home/mrigankp/fuzz4py/fuzz4py/inputs/790.py", line 15, in worker
    db[str(data)] = data * 2
    ~~^^^^^^^^^^^
  File "/home/mrigankp/fuzz4py/cpython/Lib/dbm/sqlite3.py", line 96, in __setitem__
    self._execute(STORE_KV, (key, value))
    ~~~~~~~~~~~~~^^^^^^^^^^^^^^^^^^^^^^^^
Traceback (most recent call last):
dbm.sqlite3.error: SQLite objects created in a thread can only be used in that same thread. The object was created in thread id 123988330428224 and this is thread id 123987784894016.
  File "/home/mrigankp/fuzz4py/cpython/Lib/dbm/sqlite3.py", line 81, in _execute
    raise error(str(exc))
  File "/home/mrigankp/fuzz4py/cpython/Lib/dbm/sqlite3.py", line 79, in _execute
    return closing(self._cx.execute(*args, **kwargs))
                   ~~~~~~~~~~~~~~~~^^^^^^^^^^^^^^^^^
  File "/home/mrigankp/fuzz4py/cpython/Lib/dbm/sqlite3.py", line 81, in _execute
    raise error(str(exc))

During handling of the above exception, another exception occurred:

  File "/home/mrigankp/fuzz4py/cpython/Lib/threading.py", line 1041, in _bootstrap_inner
    self.run()
    ~~~~~~~~^^
  File "/home/mrigankp/fuzz4py/cpython/Lib/threading.py", line 992, in run
    self._target(*self._args, **self._kwargs)
    ~~~~~~~~~~~~^^^^^^^^^^^^^^^^^^^^^^^^^^^^^
  File "/home/mrigankp/fuzz4py/fuzz4py/inputs/790.py", line 15, in worker
    db[str(data)] = data * 2
    ~~^^^^^^^^^^^
Traceback (most recent call last):
Traceback (most recent call last):
  File "/home/mrigankp/fuzz4py/cpython/Lib/threading.py", line 1041, in _bootstrap_inner
    self.run()
    ~~~~~~~~^^
  File "/home/mrigankp/fuzz4py/cpython/Lib/dbm/sqlite3.py", line 96, in __setitem__
    self._execute(STORE_KV, (key, value))
    ~~~~~~~~~~~~~^^^^^^^^^^^^^^^^^^^^^^^^
  File "/home/mrigankp/fuzz4py/cpython/Lib/dbm/sqlite3.py", line 96, in __setitem__
    self._execute(STORE_KV, (key, value))
    ~~~~~~~~~~~~~^^^^^^^^^^^^^^^^^^^^^^^^
  File "/home/mrigankp/fuzz4py/cpython/Lib/dbm/sqlite3.py", line 96, in __setitem__
    self._execute(STORE_KV, (key, value))
    ~~~~~~~~~~~~~^^^^^^^^^^^^^^^^^^^^^^^^
  File "/home/mrigankp/fuzz4py/cpython/Lib/threading.py", line 992, in run
    self._target(*self._args, **self._kwargs)
    ~~~~~~~~~~~~^^^^^^^^^^^^^^^^^^^^^^^^^^^^^
Traceback (most recent call last):
  File "/home/mrigankp/fuzz4py/cpython/Lib/threading.py", line 992, in run
    self._target(*self._args, **self._kwargs)
    ~~~~~~~~~~~~^^^^^^^^^^^^^^^^^^^^^^^^^^^^^
  File "/home/mrigankp/fuzz4py/cpython/Lib/threading.py", line 1041, in _bootstrap_inner
    self.run()
    ~~~~~~~~^^
dbm.sqlite3.error: SQLite objects created in a thread can only be used in that same thread. The object was created in thread id 123988330428224 and this is thread id 123987732465216.
  File "/home/mrigankp/fuzz4py/cpython/Lib/threading.py", line 992, in run
    self._target(*self._args, **self._kwargs)
    ~~~~~~~~~~~~^^^^^^^^^^^^^^^^^^^^^^^^^^^^^
  File "/home/mrigankp/fuzz4py/cpython/Lib/threading.py", line 992, in run
    self._target(*self._args, **self._kwargs)
    ~~~~~~~~~~~~^^^^^^^^^^^^^^^^^^^^^^^^^^^^^
  File "/home/mrigankp/fuzz4py/cpython/Lib/dbm/sqlite3.py", line 81, in _execute
    raise error(str(exc))
  File "/home/mrigankp/fuzz4py/cpython/Lib/threading.py", line 1041, in _bootstrap_inner
    self.run()
    ~~~~~~~~^^
  File "/home/mrigankp/fuzz4py/cpython/Lib/threading.py", line 1041, in _bootstrap_inner
    self.run()
    ~~~~~~~~^^
  File "/home/mrigankp/fuzz4py/cpython/Lib/threading.py", line 1041, in _bootstrap_inner
    self.run()
    ~~~~~~~~^^
  File "/home/mrigankp/fuzz4py/cpython/Lib/dbm/sqlite3.py", line 81, in _execute
    raise error(str(exc))
Traceback (most recent call last):
  File "/home/mrigankp/fuzz4py/cpython/Lib/dbm/sqlite3.py", line 96, in __setitem__
    self._execute(STORE_KV, (key, value))
    ~~~~~~~~~~~~~^^^^^^^^^^^^^^^^^^^^^^^^
  File "/home/mrigankp/fuzz4py/cpython/Lib/threading.py", line 1041, in _bootstrap_inner
    self.run()
    ~~~~~~~~^^
  File "/home/mrigankp/fuzz4py/cpython/Lib/dbm/sqlite3.py", line 81, in _execute
    raise error(str(exc))
  File "/home/mrigankp/fuzz4py/fuzz4py/inputs/790.py", line 15, in worker
    db[str(data)] = data * 2
    ~~^^^^^^^^^^^
sqlite3.ProgrammingError: SQLite objects created in a thread can only be used in that same thread. The object was created in thread id 123988330428224 and this is thread id 123985337517632.
Traceback (most recent call last):
sqlite3.ProgrammingError: SQLite objects created in a thread can only be used in that same thread. The object was created in thread id 123988330428224 and this is thread id 123985771628096.
  File "/home/mrigankp/fuzz4py/cpython/Lib/dbm/sqlite3.py", line 81, in _execute
    raise error(str(exc))
  File "/home/mrigankp/fuzz4py/cpython/Lib/dbm/sqlite3.py", line 96, in __setitem__
    self._execute(STORE_KV, (key, value))
    ~~~~~~~~~~~~~^^^^^^^^^^^^^^^^^^^^^^^^
Traceback (most recent call last):
  File "/home/mrigankp/fuzz4py/fuzz4py/inputs/790.py", line 15, in worker
    db[str(data)] = data * 2
    ~~^^^^^^^^^^^
  File "/home/mrigankp/fuzz4py/cpython/Lib/threading.py", line 992, in run
    self._target(*self._args, **self._kwargs)
    ~~~~~~~~~~~~^^^^^^^^^^^^^^^^^^^^^^^^^^^^^
dbm.sqlite3.error: SQLite objects created in a thread can only be used in that same thread. The object was created in thread id 123988330428224 and this is thread id 123987350783552.
  File "/home/mrigankp/fuzz4py/fuzz4py/inputs/790.py", line 15, in worker
    db[str(data)] = data * 2
    ~~^^^^^^^^^^^
  File "/home/mrigankp/fuzz4py/cpython/Lib/dbm/sqlite3.py", line 96, in __setitem__
    self._execute(STORE_KV, (key, value))
    ~~~~~~~~~~~~~^^^^^^^^^^^^^^^^^^^^^^^^
  File "/home/mrigankp/fuzz4py/cpython/Lib/threading.py", line 992, in run
    self._target(*self._args, **self._kwargs)
    ~~~~~~~~~~~~^^^^^^^^^^^^^^^^^^^^^^^^^^^^^

During handling of the above exception, another exception occurred:

  File "/home/mrigankp/fuzz4py/cpython/Lib/threading.py", line 1041, in _bootstrap_inner
    self.run()
    ~~~~~~~~^^
sqlite3.ProgrammingError: SQLite objects created in a thread can only be used in that same thread. The object was created in thread id 123988330428224 and this is thread id 123987531138624.
  File "/home/mrigankp/fuzz4py/fuzz4py/inputs/790.py", line 15, in worker
    db[str(data)] = data * 2
    ~~^^^^^^^^^^^
  File "/home/mrigankp/fuzz4py/cpython/Lib/dbm/sqlite3.py", line 96, in __setitem__
    self._execute(STORE_KV, (key, value))
    ~~~~~~~~~~~~~^^^^^^^^^^^^^^^^^^^^^^^^
  File "/home/mrigankp/fuzz4py/cpython/Lib/dbm/sqlite3.py", line 81, in _execute
    raise error(str(exc))
  File "/home/mrigankp/fuzz4py/cpython/Lib/threading.py", line 1041, in _bootstrap_inner
    self.run()
    ~~~~~~~~^^
dbm.sqlite3.error: SQLite objects created in a thread can only be used in that same thread. The object was created in thread id 123988330428224 and this is thread id 123987583567424.
  File "/home/mrigankp/fuzz4py/cpython/Lib/threading.py", line 1041, in _bootstrap_inner
    self.run()
    ~~~~~~~~^^
sqlite3.ProgrammingError: SQLite objects created in a thread can only be used in that same thread. The object was created in thread id 123988330428224 and this is thread id 123985115219520.
dbm.sqlite3.error: SQLite objects created in a thread can only be used in that same thread. The object was created in thread id 123988330428224 and this is thread id 123988166575680.
  File "/home/mrigankp/fuzz4py/cpython/Lib/threading.py", line 1041, in _bootstrap_inner
    self.run()
    ~~~~~~~~^^
Traceback (most recent call last):
  File "/home/mrigankp/fuzz4py/cpython/Lib/threading.py", line 992, in run
    self._target(*self._args, **self._kwargs)
    ~~~~~~~~~~~~^^^^^^^^^^^^^^^^^^^^^^^^^^^^^
  File "/home/mrigankp/fuzz4py/fuzz4py/inputs/790.py", line 15, in worker
    db[str(data)] = data * 2
    ~~^^^^^^^^^^^
  File "/home/mrigankp/fuzz4py/cpython/Lib/dbm/sqlite3.py", line 81, in _execute
    raise error(str(exc))
  File "/home/mrigankp/fuzz4py/cpython/Lib/dbm/sqlite3.py", line 96, in __setitem__
    self._execute(STORE_KV, (key, value))
    ~~~~~~~~~~~~~^^^^^^^^^^^^^^^^^^^^^^^^
  File "/home/mrigankp/fuzz4py/cpython/Lib/threading.py", line 1041, in _bootstrap_inner
    self.run()
    ~~~~~~~~^^
  File "/home/mrigankp/fuzz4py/cpython/Lib/threading.py", line 992, in run
    self._target(*self._args, **self._kwargs)
    ~~~~~~~~~~~~^^^^^^^^^^^^^^^^^^^^^^^^^^^^^
  File "/home/mrigankp/fuzz4py/fuzz4py/inputs/790.py", line 15, in worker
    db[str(data)] = data * 2
    ~~^^^^^^^^^^^
  File "/home/mrigankp/fuzz4py/cpython/Lib/threading.py", line 1041, in _bootstrap_inner
    self.run()
    ~~~~~~~~^^
  File "/home/mrigankp/fuzz4py/cpython/Lib/threading.py", line 1041, in _bootstrap_inner
    self.run()
    ~~~~~~~~^^
  File "/home/mrigankp/fuzz4py/cpython/Lib/dbm/sqlite3.py", line 81, in _execute
    raise error(str(exc))
  File "/home/mrigankp/fuzz4py/cpython/Lib/dbm/sqlite3.py", line 81, in _execute
    raise error(str(exc))
  File "/home/mrigankp/fuzz4py/cpython/Lib/threading.py", line 1041, in _bootstrap_inner
    self.run()
    ~~~~~~~~^^
  File "/home/mrigankp/fuzz4py/fuzz4py/inputs/790.py", line 15, in worker
    db[str(data)] = data * 2
    ~~^^^^^^^^^^^
  File "/home/mrigankp/fuzz4py/fuzz4py/inputs/790.py", line 15, in worker
    db[str(data)] = data * 2
    ~~^^^^^^^^^^^
  File "/home/mrigankp/fuzz4py/fuzz4py/inputs/790.py", line 15, in worker
    db[str(data)] = data * 2
    ~~^^^^^^^^^^^
  File "/home/mrigankp/fuzz4py/fuzz4py/inputs/790.py", line 15, in worker
    db[str(data)] = data * 2
    ~~^^^^^^^^^^^
dbm.sqlite3.error: SQLite objects created in a thread can only be used in that same thread. The object was created in thread id 123988330428224 and this is thread id 123987954763328.
  File "/home/mrigankp/fuzz4py/cpython/Lib/threading.py", line 992, in run
    self._target(*self._args, **self._kwargs)
    ~~~~~~~~~~~~^^^^^^^^^^^^^^^^^^^^^^^^^^^^^
  File "/home/mrigankp/fuzz4py/cpython/Lib/threading.py", line 1041, in _bootstrap_inner
    self.run()
    ~~~~~~~~^^
  File "/home/mrigankp/fuzz4py/cpython/Lib/threading.py", line 992, in run
    self._target(*self._args, **self._kwargs)
    ~~~~~~~~~~~~^^^^^^^^^^^^^^^^^^^^^^^^^^^^^
sqlite3.ProgrammingError: SQLite objects created in a thread can only be used in that same thread. The object was created in thread id 123988330428224 and this is thread id 123986767775296.
  File "/home/mrigankp/fuzz4py/cpython/Lib/threading.py", line 1041, in _bootstrap_inner
    self.run()
    ~~~~~~~~^^
  File "/home/mrigankp/fuzz4py/cpython/Lib/threading.py", line 1041, in _bootstrap_inner
    self.run()
    ~~~~~~~~^^
  File "/home/mrigankp/fuzz4py/cpython/Lib/dbm/sqlite3.py", line 81, in _execute
    raise error(str(exc))
  File "/home/mrigankp/fuzz4py/cpython/Lib/dbm/sqlite3.py", line 96, in __setitem__
    self._execute(STORE_KV, (key, value))
    ~~~~~~~~~~~~~^^^^^^^^^^^^^^^^^^^^^^^^

During handling of the above exception, another exception occurred:


During handling of the above exception, another exception occurred:

  File "/home/mrigankp/fuzz4py/cpython/Lib/threading.py", line 992, in run
    self._target(*self._args, **self._kwargs)
    ~~~~~~~~~~~~^^^^^^^^^^^^^^^^^^^^^^^^^^^^^
dbm.sqlite3.error: SQLite objects created in a thread can only be used in that same thread. The object was created in thread id 123988330428224 and this is thread id 123987149456960.
  File "/home/mrigankp/fuzz4py/cpython/Lib/threading.py", line 1041, in _bootstrap_inner
    self.run()
    ~~~~~~~~^^
Traceback (most recent call last):
  File "/home/mrigankp/fuzz4py/cpython/Lib/dbm/sqlite3.py", line 96, in __setitem__
    self._execute(STORE_KV, (key, value))
    ~~~~~~~~~~~~~^^^^^^^^^^^^^^^^^^^^^^^^
Traceback (most recent call last):
Traceback (most recent call last):
  File "/home/mrigankp/fuzz4py/cpython/Lib/dbm/sqlite3.py", line 96, in __setitem__
    self._execute(STORE_KV, (key, value))
    ~~~~~~~~~~~~~^^^^^^^^^^^^^^^^^^^^^^^^
Traceback (most recent call last):
  File "/home/mrigankp/fuzz4py/cpython/Lib/dbm/sqlite3.py", line 96, in __setitem__
    self._execute(STORE_KV, (key, value))
    ~~~~~~~~~~~~~^^^^^^^^^^^^^^^^^^^^^^^^
  File "/home/mrigankp/fuzz4py/cpython/Lib/threading.py", line 992, in run
    self._target(*self._args, **self._kwargs)
    ~~~~~~~~~~~~^^^^^^^^^^^^^^^^^^^^^^^^^^^^^
  File "/home/mrigankp/fuzz4py/cpython/Lib/dbm/sqlite3.py", line 81, in _execute
    raise error(str(exc))

During handling of the above exception, another exception occurred:

  File "/home/mrigankp/fuzz4py/cpython/Lib/dbm/sqlite3.py", line 96, in __setitem__
    self._execute(STORE_KV, (key, value))
    ~~~~~~~~~~~~~^^^^^^^^^^^^^^^^^^^^^^^^
  File "/home/mrigankp/fuzz4py/cpython/Lib/dbm/sqlite3.py", line 81, in _execute
    raise error(str(exc))
  File "/home/mrigankp/fuzz4py/cpython/Lib/threading.py", line 992, in run
    self._target(*self._args, **self._kwargs)
    ~~~~~~~~~~~~^^^^^^^^^^^^^^^^^^^^^^^^^^^^^
  File "/home/mrigankp/fuzz4py/cpython/Lib/threading.py", line 992, in run
    self._target(*self._args, **self._kwargs)
    ~~~~~~~~~~~~^^^^^^^^^^^^^^^^^^^^^^^^^^^^^
dbm.sqlite3.error: SQLite objects created in a thread can only be used in that same thread. The object was created in thread id 123988330428224 and this is thread id 123988156089920.
  File "/home/mrigankp/fuzz4py/cpython/Lib/threading.py", line 992, in run
    self._target(*self._args, **self._kwargs)
    ~~~~~~~~~~~~^^^^^^^^^^^^^^^^^^^^^^^^^^^^^
  File "/home/mrigankp/fuzz4py/cpython/Lib/threading.py", line 1041, in _bootstrap_inner
    self.run()
    ~~~~~~~~^^
  File "/home/mrigankp/fuzz4py/cpython/Lib/threading.py", line 1041, in _bootstrap_inner
    self.run()
    ~~~~~~~~^^
  File "/home/mrigankp/fuzz4py/cpython/Lib/dbm/sqlite3.py", line 96, in __setitem__
    self._execute(STORE_KV, (key, value))
    ~~~~~~~~~~~~~^^^^^^^^^^^^^^^^^^^^^^^^
  File "/home/mrigankp/fuzz4py/cpython/Lib/dbm/sqlite3.py", line 81, in _execute
    raise error(str(exc))
  File "/home/mrigankp/fuzz4py/cpython/Lib/dbm/sqlite3.py", line 81, in _execute
    raise error(str(exc))
  File "/home/mrigankp/fuzz4py/cpython/Lib/dbm/sqlite3.py", line 81, in _execute
    raise error(str(exc))
  File "/home/mrigankp/fuzz4py/cpython/Lib/threading.py", line 992, in run
    self._target(*self._args, **self._kwargs)
    ~~~~~~~~~~~~^^^^^^^^^^^^^^^^^^^^^^^^^^^^^
  File "/home/mrigankp/fuzz4py/cpython/Lib/dbm/sqlite3.py", line 81, in _execute
    raise error(str(exc))
  File "/home/mrigankp/fuzz4py/fuzz4py/inputs/790.py", line 15, in worker
    db[str(data)] = data * 2
    ~~^^^^^^^^^^^
  File "/home/mrigankp/fuzz4py/cpython/Lib/threading.py", line 1041, in _bootstrap_inner
    self.run()
    ~~~~~~~~^^
  File "/home/mrigankp/fuzz4py/cpython/Lib/threading.py", line 992, in run
    self._target(*self._args, **self._kwargs)
    ~~~~~~~~~~~~^^^^^^^^^^^^^^^^^^^^^^^^^^^^^
dbm.sqlite3.error: SQLite objects created in a thread can only be used in that same thread. The object was created in thread id 123988330428224 and this is thread id 123987965249088.
dbm.sqlite3.error: SQLite objects created in a thread can only be used in that same thread. The object was created in thread id 123988330428224 and this is thread id 123985570301504.
  File "/home/mrigankp/fuzz4py/cpython/Lib/threading.py", line 992, in run
    self._target(*self._args, **self._kwargs)
    ~~~~~~~~~~~~^^^^^^^^^^^^^^^^^^^^^^^^^^^^^
  File "/home/mrigankp/fuzz4py/cpython/Lib/dbm/sqlite3.py", line 96, in __setitem__
    self._execute(STORE_KV, (key, value))
    ~~~~~~~~~~~~~^^^^^^^^^^^^^^^^^^^^^^^^
  File "/home/mrigankp/fuzz4py/cpython/Lib/threading.py", line 1041, in _bootstrap_inner
    self.run()
    ~~~~~~~~^^
  File "/home/mrigankp/fuzz4py/cpython/Lib/dbm/sqlite3.py", line 96, in __setitem__
    self._execute(STORE_KV, (key, value))
    ~~~~~~~~~~~~~^^^^^^^^^^^^^^^^^^^^^^^^

During handling of the above exception, another exception occurred:

  File "/home/mrigankp/fuzz4py/cpython/Lib/threading.py", line 992, in run
    self._target(*self._args, **self._kwargs)
    ~~~~~~~~~~~~^^^^^^^^^^^^^^^^^^^^^^^^^^^^^
  File "/home/mrigankp/fuzz4py/cpython/Lib/threading.py", line 992, in run
    self._target(*self._args, **self._kwargs)
    ~~~~~~~~~~~~^^^^^^^^^^^^^^^^^^^^^^^^^^^^^
  File "/home/mrigankp/fuzz4py/fuzz4py/inputs/790.py", line 15, in worker
    db[str(data)] = data * 2
    ~~^^^^^^^^^^^
  File "/home/mrigankp/fuzz4py/cpython/Lib/threading.py", line 1041, in _bootstrap_inner
    self.run()
    ~~~~~~~~^^
  File "/home/mrigankp/fuzz4py/cpython/Lib/threading.py", line 992, in run
    self._target(*self._args, **self._kwargs)
    ~~~~~~~~~~~~^^^^^^^^^^^^^^^^^^^^^^^^^^^^^
  File "/home/mrigankp/fuzz4py/cpython/Lib/threading.py", line 992, in run
    self._target(*self._args, **self._kwargs)
    ~~~~~~~~~~~~^^^^^^^^^^^^^^^^^^^^^^^^^^^^^
dbm.sqlite3.error: SQLite objects created in a thread can only be used in that same thread. The object was created in thread id 123988330428224 and this is thread id 123986927158848.
  File "/home/mrigankp/fuzz4py/cpython/Lib/threading.py", line 992, in run
    self._target(*self._args, **self._kwargs)
    ~~~~~~~~~~~~^^^^^^^^^^^^^^^^^^^^^^^^^^^^^
  File "/home/mrigankp/fuzz4py/cpython/Lib/dbm/sqlite3.py", line 81, in _execute
    raise error(str(exc))
Traceback (most recent call last):
  File "/home/mrigankp/fuzz4py/cpython/Lib/dbm/sqlite3.py", line 96, in __setitem__
    self._execute(STORE_KV, (key, value))
    ~~~~~~~~~~~~~^^^^^^^^^^^^^^^^^^^^^^^^
  File "/home/mrigankp/fuzz4py/cpython/Lib/dbm/sqlite3.py", line 81, in _execute
    raise error(str(exc))
  File "/home/mrigankp/fuzz4py/cpython/Lib/threading.py", line 1041, in _bootstrap_inner
    self.run()
    ~~~~~~~~^^
  File "/home/mrigankp/fuzz4py/cpython/Lib/threading.py", line 992, in run
    self._target(*self._args, **self._kwargs)
    ~~~~~~~~~~~~^^^^^^^^^^^^^^^^^^^^^^^^^^^^^
  File "/home/mrigankp/fuzz4py/fuzz4py/inputs/790.py", line 15, in worker
    db[str(data)] = data * 2
    ~~^^^^^^^^^^^
  File "/home/mrigankp/fuzz4py/cpython/Lib/dbm/sqlite3.py", line 81, in _execute
    raise error(str(exc))
  File "/home/mrigankp/fuzz4py/cpython/Lib/threading.py", line 1041, in _bootstrap_inner
    self.run()
    ~~~~~~~~^^
  File "/home/mrigankp/fuzz4py/cpython/Lib/dbm/sqlite3.py", line 81, in _execute
    raise error(str(exc))
  File "/home/mrigankp/fuzz4py/cpython/Lib/threading.py", line 1041, in _bootstrap_inner
    self.run()
    ~~~~~~~~^^
Traceback (most recent call last):
  File "/home/mrigankp/fuzz4py/cpython/Lib/dbm/sqlite3.py", line 81, in _execute
    raise error(str(exc))
  File "/home/mrigankp/fuzz4py/fuzz4py/inputs/790.py", line 15, in worker
    db[str(data)] = data * 2
    ~~^^^^^^^^^^^
dbm.sqlite3.error: SQLite objects created in a thread can only be used in that same thread. The object was created in thread id 123988330428224 and this is thread id 123987573081664.
  File "/home/mrigankp/fuzz4py/cpython/Lib/dbm/sqlite3.py", line 81, in _execute
    raise error(str(exc))
  File "/home/mrigankp/fuzz4py/cpython/Lib/dbm/sqlite3.py", line 81, in _execute
    raise error(str(exc))
dbm.sqlite3.error: SQLite objects created in a thread can only be used in that same thread. The object was created in thread id 123988330428224 and this is thread id 123987128485440.

During handling of the above exception, another exception occurred:

  File "/home/mrigankp/fuzz4py/fuzz4py/inputs/790.py", line 15, in worker
    db[str(data)] = data * 2
    ~~^^^^^^^^^^^

During handling of the above exception, another exception occurred:

  File "/home/mrigankp/fuzz4py/cpython/Lib/threading.py", line 1041, in _bootstrap_inner
    self.run()
    ~~~~~~~~^^
  File "/home/mrigankp/fuzz4py/cpython/Lib/threading.py", line 992, in run
    self._target(*self._args, **self._kwargs)
    ~~~~~~~~~~~~^^^^^^^^^^^^^^^^^^^^^^^^^^^^^
  File "/home/mrigankp/fuzz4py/fuzz4py/inputs/790.py", line 15, in worker
    db[str(data)] = data * 2
    ~~^^^^^^^^^^^
  File "/home/mrigankp/fuzz4py/cpython/Lib/dbm/sqlite3.py", line 96, in __setitem__
    self._execute(STORE_KV, (key, value))
    ~~~~~~~~~~~~~^^^^^^^^^^^^^^^^^^^^^^^^
  File "/home/mrigankp/fuzz4py/cpython/Lib/dbm/sqlite3.py", line 81, in _execute
    raise error(str(exc))
dbm.sqlite3.error: SQLite objects created in a thread can only be used in that same thread. The object was created in thread id 123988330428224 and this is thread id 123986969101888.
dbm.sqlite3.error: SQLite objects created in a thread can only be used in that same thread. The object was created in thread id 123988330428224 and this is thread id 123987975734848.
dbm.sqlite3.error: SQLite objects created in a thread can only be used in that same thread. The object was created in thread id 123988330428224 and this is thread id 123987774408256.
  File "/home/mrigankp/fuzz4py/fuzz4py/inputs/790.py", line 15, in worker
    db[str(data)] = data * 2
    ~~^^^^^^^^^^^
dbm.sqlite3.error: SQLite objects created in a thread can only be used in that same thread. The object was created in thread id 123988330428224 and this is thread id 123987944277568.
  File "/home/mrigankp/fuzz4py/fuzz4py/inputs/790.py", line 15, in worker
    db[str(data)] = data * 2
    ~~^^^^^^^^^^^
  File "/home/mrigankp/fuzz4py/fuzz4py/inputs/790.py", line 15, in worker
    db[str(data)] = data * 2
    ~~^^^^^^^^^^^
  File "/home/mrigankp/fuzz4py/fuzz4py/inputs/790.py", line 15, in worker
    db[str(data)] = data * 2
    ~~^^^^^^^^^^^
  File "/home/mrigankp/fuzz4py/cpython/Lib/dbm/sqlite3.py", line 81, in _execute
    raise error(str(exc))
  File "/home/mrigankp/fuzz4py/cpython/Lib/dbm/sqlite3.py", line 96, in __setitem__
    self._execute(STORE_KV, (key, value))
    ~~~~~~~~~~~~~^^^^^^^^^^^^^^^^^^^^^^^^
  File "/home/mrigankp/fuzz4py/cpython/Lib/dbm/sqlite3.py", line 81, in _execute
    raise error(str(exc))
Traceback (most recent call last):
  File "/home/mrigankp/fuzz4py/cpython/Lib/threading.py", line 1041, in _bootstrap_inner
    self.run()
    ~~~~~~~~^^
  File "/home/mrigankp/fuzz4py/fuzz4py/inputs/790.py", line 15, in worker
    db[str(data)] = data * 2
    ~~^^^^^^^^^^^
  File "/home/mrigankp/fuzz4py/cpython/Lib/dbm/sqlite3.py", line 96, in __setitem__
    self._execute(STORE_KV, (key, value))
    ~~~~~~~~~~~~~^^^^^^^^^^^^^^^^^^^^^^^^
  File "/home/mrigankp/fuzz4py/cpython/Lib/threading.py", line 992, in run
    self._target(*self._args, **self._kwargs)
    ~~~~~~~~~~~~^^^^^^^^^^^^^^^^^^^^^^^^^^^^^
  File "/home/mrigankp/fuzz4py/fuzz4py/inputs/790.py", line 15, in worker
    db[str(data)] = data * 2
    ~~^^^^^^^^^^^
  File "/home/mrigankp/fuzz4py/cpython/Lib/dbm/sqlite3.py", line 81, in _execute
    raise error(str(exc))
  File "/home/mrigankp/fuzz4py/cpython/Lib/threading.py", line 1041, in _bootstrap_inner
    self.run()
    ~~~~~~~~^^
  File "/home/mrigankp/fuzz4py/cpython/Lib/threading.py", line 1041, in _bootstrap_inner
    self.run()
    ~~~~~~~~^^
  File "/home/mrigankp/fuzz4py/fuzz4py/inputs/790.py", line 15, in worker
    db[str(data)] = data * 2
    ~~^^^^^^^^^^^
  File "/home/mrigankp/fuzz4py/cpython/Lib/dbm/sqlite3.py", line 81, in _execute
    raise error(str(exc))
dbm.sqlite3.error: SQLite objects created in a thread can only be used in that same thread. The object was created in thread id 123988330428224 and this is thread id 123985941497408.
  File "/home/mrigankp/fuzz4py/cpython/Lib/threading.py", line 992, in run
    self._target(*self._args, **self._kwargs)
    ~~~~~~~~~~~~^^^^^^^^^^^^^^^^^^^^^^^^^^^^^
  File "/home/mrigankp/fuzz4py/fuzz4py/inputs/790.py", line 15, in worker
    db[str(data)] = data * 2
    ~~^^^^^^^^^^^
  File "/home/mrigankp/fuzz4py/cpython/Lib/dbm/sqlite3.py", line 79, in _execute
    return closing(self._cx.execute(*args, **kwargs))
                   ~~~~~~~~~~~~~~~~^^^^^^^^^^^^^^^^^
  File "/home/mrigankp/fuzz4py/cpython/Lib/threading.py", line 992, in run
    self._target(*self._args, **self._kwargs)
    ~~~~~~~~~~~~^^^^^^^^^^^^^^^^^^^^^^^^^^^^^
dbm.sqlite3.error: SQLite objects created in a thread can only be used in that same thread. The object was created in thread id 123988330428224 and this is thread id 123986757289536.
  File "/home/mrigankp/fuzz4py/cpython/Lib/threading.py", line 1041, in _bootstrap_inner
    self.run()
    ~~~~~~~~^^
  File "/home/mrigankp/fuzz4py/cpython/Lib/threading.py", line 1041, in _bootstrap_inner
    self.run()
    ~~~~~~~~^^
dbm.sqlite3.error: SQLite objects created in a thread can only be used in that same thread. The object was created in thread id 123988330428224 and this is thread id 123987552110144.
Traceback (most recent call last):
  File "/home/mrigankp/fuzz4py/cpython/Lib/threading.py", line 992, in run
    self._target(*self._args, **self._kwargs)
    ~~~~~~~~~~~~^^^^^^^^^^^^^^^^^^^^^^^^^^^^^
dbm.sqlite3.error: SQLite objects created in a thread can only be used in that same thread. The object was created in thread id 123988330428224 and this is thread id 123986979587648.
  File "/home/mrigankp/fuzz4py/fuzz4py/inputs/790.py", line 15, in worker
    db[str(data)] = data * 2
    ~~^^^^^^^^^^^
  File "/home/mrigankp/fuzz4py/cpython/Lib/dbm/sqlite3.py", line 96, in __setitem__
    self._execute(STORE_KV, (key, value))
    ~~~~~~~~~~~~~^^^^^^^^^^^^^^^^^^^^^^^^
  File "/home/mrigankp/fuzz4py/cpython/Lib/threading.py", line 992, in run
    self._target(*self._args, **self._kwargs)
    ~~~~~~~~~~~~^^^^^^^^^^^^^^^^^^^^^^^^^^^^^
  File "/home/mrigankp/fuzz4py/cpython/Lib/threading.py", line 992, in run
    self._target(*self._args, **self._kwargs)
    ~~~~~~~~~~~~^^^^^^^^^^^^^^^^^^^^^^^^^^^^^
  File "/home/mrigankp/fuzz4py/cpython/Lib/threading.py", line 992, in run
    self._target(*self._args, **self._kwargs)
    ~~~~~~~~~~~~^^^^^^^^^^^^^^^^^^^^^^^^^^^^^
  File "/home/mrigankp/fuzz4py/cpython/Lib/dbm/sqlite3.py", line 81, in _execute
    raise error(str(exc))
dbm.sqlite3.error: SQLite objects created in a thread can only be used in that same thread. The object was created in thread id 123988330428224 and this is thread id 123986323179072.
  File "/home/mrigankp/fuzz4py/cpython/Lib/threading.py", line 992, in run
    self._target(*self._args, **self._kwargs)
    ~~~~~~~~~~~~^^^^^^^^^^^^^^^^^^^^^^^^^^^^^
  File "/home/mrigankp/fuzz4py/cpython/Lib/dbm/sqlite3.py", line 96, in __setitem__
    self._execute(STORE_KV, (key, value))
    ~~~~~~~~~~~~~^^^^^^^^^^^^^^^^^^^^^^^^
  File "/home/mrigankp/fuzz4py/cpython/Lib/threading.py", line 992, in run
    self._target(*self._args, **self._kwargs)
    ~~~~~~~~~~~~^^^^^^^^^^^^^^^^^^^^^^^^^^^^^
  File "/home/mrigankp/fuzz4py/cpython/Lib/dbm/sqlite3.py", line 96, in __setitem__
    self._execute(STORE_KV, (key, value))
    ~~~~~~~~~~~~~^^^^^^^^^^^^^^^^^^^^^^^^
  File "/home/mrigankp/fuzz4py/fuzz4py/inputs/790.py", line 15, in worker
    db[str(data)] = data * 2
    ~~^^^^^^^^^^^
  File "/home/mrigankp/fuzz4py/cpython/Lib/dbm/sqlite3.py", line 96, in __setitem__
    self._execute(STORE_KV, (key, value))
    ~~~~~~~~~~~~~^^^^^^^^^^^^^^^^^^^^^^^^
  File "/home/mrigankp/fuzz4py/cpython/Lib/dbm/sqlite3.py", line 81, in _execute
    raise error(str(exc))
dbm.sqlite3.error: SQLite objects created in a thread can only be used in that same thread. The object was created in thread id 123988330428224 and this is thread id 123985549329984.
  File "/home/mrigankp/fuzz4py/fuzz4py/inputs/790.py", line 15, in worker
    db[str(data)] = data * 2
    ~~^^^^^^^^^^^
  File "/home/mrigankp/fuzz4py/fuzz4py/inputs/790.py", line 15, in worker
    db[str(data)] = data * 2
    ~~^^^^^^^^^^^
dbm.sqlite3.error: SQLite objects created in a thread can only be used in that same thread. The object was created in thread id 123988330428224 and this is thread id 123987382240832.

During handling of the above exception, another exception occurred:

  File "/home/mrigankp/fuzz4py/cpython/Lib/dbm/sqlite3.py", line 96, in __setitem__
    self._execute(STORE_KV, (key, value))
    ~~~~~~~~~~~~~^^^^^^^^^^^^^^^^^^^^^^^^
  File "/home/mrigankp/fuzz4py/cpython/Lib/threading.py", line 992, in run
    self._target(*self._args, **self._kwargs)
    ~~~~~~~~~~~~^^^^^^^^^^^^^^^^^^^^^^^^^^^^^
  File "/home/mrigankp/fuzz4py/fuzz4py/inputs/790.py", line 15, in worker
    db[str(data)] = data * 2
    ~~^^^^^^^^^^^
dbm.sqlite3.error: SQLite objects created in a thread can only be used in that same thread. The object was created in thread id 123988330428224 and this is thread id 123987763922496.
dbm.sqlite3.error: SQLite objects created in a thread can only be used in that same thread. The object was created in thread id 123988330428224 and this is thread id 123988296599104.
  File "/home/mrigankp/fuzz4py/cpython/Lib/threading.py", line 992, in run
    self._target(*self._args, **self._kwargs)
    ~~~~~~~~~~~~^^^^^^^^^^^^^^^^^^^^^^^^^^^^^
Traceback (most recent call last):
dbm.sqlite3.error: SQLite objects created in a thread can only be used in that same thread. The object was created in thread id 123988330428224 and this is thread id 123987933791808.
  File "/home/mrigankp/fuzz4py/cpython/Lib/threading.py", line 1041, in _bootstrap_inner
    self.run()
    ~~~~~~~~^^
  File "/home/mrigankp/fuzz4py/cpython/Lib/dbm/sqlite3.py", line 96, in __setitem__
    self._execute(STORE_KV, (key, value))
    ~~~~~~~~~~~~~^^^^^^^^^^^^^^^^^^^^^^^^
dbm.sqlite3.error: SQLite objects created in a thread can only be used in that same thread. The object was created in thread id 123988330428224 and this is thread id 123985931011648.
  File "/home/mrigankp/fuzz4py/fuzz4py/inputs/790.py", line 15, in worker
    db[str(data)] = data * 2
    ~~^^^^^^^^^^^
  File "/home/mrigankp/fuzz4py/fuzz4py/inputs/790.py", line 15, in worker
    db[str(data)] = data * 2
    ~~^^^^^^^^^^^
  File "/home/mrigankp/fuzz4py/cpython/Lib/threading.py", line 992, in run
    self._target(*self._args, **self._kwargs)
    ~~~~~~~~~~~~^^^^^^^^^^^^^^^^^^^^^^^^^^^^^
  File "/home/mrigankp/fuzz4py/cpython/Lib/dbm/sqlite3.py", line 96, in __setitem__
    self._execute(STORE_KV, (key, value))
    ~~~~~~~~~~~~~^^^^^^^^^^^^^^^^^^^^^^^^
dbm.sqlite3.error: SQLite objects created in a thread can only be used in that same thread. The object was created in thread id 123988330428224 and this is thread id 123988135118400.
dbm.sqlite3.error: SQLite objects created in a thread can only be used in that same thread. The object was created in thread id 123988330428224 and this is thread id 123985167648320.
Traceback (most recent call last):
Traceback (most recent call last):
  File "/home/mrigankp/fuzz4py/fuzz4py/inputs/790.py", line 15, in worker
    db[str(data)] = data * 2
    ~~^^^^^^^^^^^
  File "/home/mrigankp/fuzz4py/fuzz4py/inputs/790.py", line 15, in worker
    db[str(data)] = data * 2
    ~~^^^^^^^^^^^
  File "/home/mrigankp/fuzz4py/cpython/Lib/dbm/sqlite3.py", line 96, in __setitem__
    self._execute(STORE_KV, (key, value))
    ~~~~~~~~~~~~~^^^^^^^^^^^^^^^^^^^^^^^^
  File "/home/mrigankp/fuzz4py/fuzz4py/inputs/790.py", line 15, in worker
    db[str(data)] = data * 2
    ~~^^^^^^^^^^^
dbm.sqlite3.error: SQLite objects created in a thread can only be used in that same thread. The object was created in thread id 123988330428224 and this is thread id 123987541624384.
  File "/home/mrigankp/fuzz4py/cpython/Lib/dbm/sqlite3.py", line 96, in __setitem__
    self._execute(STORE_KV, (key, value))
    ~~~~~~~~~~~~~^^^^^^^^^^^^^^^^^^^^^^^^
  File "/home/mrigankp/fuzz4py/cpython/Lib/dbm/sqlite3.py", line 81, in _execute
    raise error(str(exc))
  File "/home/mrigankp/fuzz4py/cpython/Lib/dbm/sqlite3.py", line 96, in __setitem__
    self._execute(STORE_KV, (key, value))
    ~~~~~~~~~~~~~^^^^^^^^^^^^^^^^^^^^^^^^
  File "/home/mrigankp/fuzz4py/cpython/Lib/threading.py", line 1041, in _bootstrap_inner
    self.run()
    ~~~~~~~~^^
  File "/home/mrigankp/fuzz4py/cpython/Lib/dbm/sqlite3.py", line 81, in _execute
    raise error(str(exc))
  File "/home/mrigankp/fuzz4py/cpython/Lib/threading.py", line 992, in run
    self._target(*self._args, **self._kwargs)
    ~~~~~~~~~~~~^^^^^^^^^^^^^^^^^^^^^^^^^^^^^
  File "/home/mrigankp/fuzz4py/cpython/Lib/dbm/sqlite3.py", line 81, in _execute
    raise error(str(exc))
  File "/home/mrigankp/fuzz4py/cpython/Lib/dbm/sqlite3.py", line 96, in __setitem__
    self._execute(STORE_KV, (key, value))
    ~~~~~~~~~~~~~^^^^^^^^^^^^^^^^^^^^^^^^
  File "/home/mrigankp/fuzz4py/cpython/Lib/threading.py", line 1041, in _bootstrap_inner
    self.run()
    ~~~~~~~~^^
  File "/home/mrigankp/fuzz4py/cpython/Lib/dbm/sqlite3.py", line 81, in _execute
    raise error(str(exc))
Traceback (most recent call last):
  File "/home/mrigankp/fuzz4py/cpython/Lib/dbm/sqlite3.py", line 81, in _execute
    raise error(str(exc))
  File "/home/mrigankp/fuzz4py/cpython/Lib/dbm/sqlite3.py", line 96, in __setitem__
    self._execute(STORE_KV, (key, value))
    ~~~~~~~~~~~~~^^^^^^^^^^^^^^^^^^^^^^^^
  File "/home/mrigankp/fuzz4py/fuzz4py/inputs/790.py", line 15, in worker
    db[str(data)] = data * 2
    ~~^^^^^^^^^^^
dbm.sqlite3.error: SQLite objects created in a thread can only be used in that same thread. The object was created in thread id 123988330428224 and this is thread id 123987562595904.
  File "/home/mrigankp/fuzz4py/fuzz4py/inputs/790.py", line 15, in worker
    db[str(data)] = data * 2
    ~~^^^^^^^^^^^
  File "/home/mrigankp/fuzz4py/cpython/Lib/threading.py", line 1041, in _bootstrap_inner
    self.run()
    ~~~~~~~~^^
  File "/home/mrigankp/fuzz4py/fuzz4py/inputs/790.py", line 15, in worker
    db[str(data)] = data * 2
    ~~^^^^^^^^^^^
  File "/home/mrigankp/fuzz4py/cpython/Lib/dbm/sqlite3.py", line 96, in __setitem__
    self._execute(STORE_KV, (key, value))
    ~~~~~~~~~~~~~^^^^^^^^^^^^^^^^^^^^^^^^
  File "/home/mrigankp/fuzz4py/cpython/Lib/dbm/sqlite3.py", line 81, in _execute
    raise error(str(exc))
  File "/home/mrigankp/fuzz4py/cpython/Lib/dbm/sqlite3.py", line 96, in __setitem__
    self._execute(STORE_KV, (key, value))
    ~~~~~~~~~~~~~^^^^^^^^^^^^^^^^^^^^^^^^
  File "/home/mrigankp/fuzz4py/cpython/Lib/threading.py", line 992, in run
    self._target(*self._args, **self._kwargs)
    ~~~~~~~~~~~~^^^^^^^^^^^^^^^^^^^^^^^^^^^^^
  File "/home/mrigankp/fuzz4py/cpython/Lib/threading.py", line 1041, in _bootstrap_inner
    self.run()
    ~~~~~~~~^^
  File "/home/mrigankp/fuzz4py/fuzz4py/inputs/790.py", line 15, in worker
    db[str(data)] = data * 2
    ~~^^^^^^^^^^^
  File "/home/mrigankp/fuzz4py/fuzz4py/inputs/790.py", line 15, in worker
    db[str(data)] = data * 2
    ~~^^^^^^^^^^^
  File "/home/mrigankp/fuzz4py/cpython/Lib/dbm/sqlite3.py", line 81, in _execute
    raise error(str(exc))
  File "/home/mrigankp/fuzz4py/fuzz4py/inputs/790.py", line 15, in worker
    db[str(data)] = data * 2
    ~~^^^^^^^^^^^
  File "/home/mrigankp/fuzz4py/cpython/Lib/dbm/sqlite3.py", line 96, in __setitem__
    self._execute(STORE_KV, (key, value))
    ~~~~~~~~~~~~~^^^^^^^^^^^^^^^^^^^^^^^^
  File "/home/mrigankp/fuzz4py/fuzz4py/inputs/790.py", line 15, in worker
    db[str(data)] = data * 2
    ~~^^^^^^^^^^^
  File "/home/mrigankp/fuzz4py/cpython/Lib/dbm/sqlite3.py", line 81, in _execute
    raise error(str(exc))
dbm.sqlite3.error: SQLite objects created in a thread can only be used in that same thread. The object was created in thread id 123988330428224 and this is thread id 123985729685056.
  File "/home/mrigankp/fuzz4py/cpython/Lib/dbm/sqlite3.py", line 96, in __setitem__
    self._execute(STORE_KV, (key, value))
    ~~~~~~~~~~~~~^^^^^^^^^^^^^^^^^^^^^^^^
  File "/home/mrigankp/fuzz4py/fuzz4py/inputs/790.py", line 15, in worker
    db[str(data)] = data * 2
    ~~^^^^^^^^^^^
  File "/home/mrigankp/fuzz4py/cpython/Lib/dbm/sqlite3.py", line 81, in _execute
    raise error(str(exc))
  File "/home/mrigankp/fuzz4py/fuzz4py/inputs/790.py", line 15, in worker
    db[str(data)] = data * 2
    ~~^^^^^^^^^^^
  File "/home/mrigankp/fuzz4py/cpython/Lib/dbm/sqlite3.py", line 81, in _execute
    raise error(str(exc))
  File "/home/mrigankp/fuzz4py/fuzz4py/inputs/790.py", line 15, in worker
    db[str(data)] = data * 2
    ~~^^^^^^^^^^^
  File "/home/mrigankp/fuzz4py/cpython/Lib/threading.py", line 992, in run
    self._target(*self._args, **self._kwargs)
    ~~~~~~~~~~~~^^^^^^^^^^^^^^^^^^^^^^^^^^^^^
dbm.sqlite3.error: SQLite objects created in a thread can only be used in that same thread. The object was created in thread id 123988330428224 and this is thread id 123985559815744.
dbm.sqlite3.error: SQLite objects created in a thread can only be used in that same thread. The object was created in thread id 123988330428224 and this is thread id 123987361269312.
  File "/home/mrigankp/fuzz4py/cpython/Lib/threading.py", line 992, in run
    self._target(*self._args, **self._kwargs)
    ~~~~~~~~~~~~^^^^^^^^^^^^^^^^^^^^^^^^^^^^^
Traceback (most recent call last):
  File "/home/mrigankp/fuzz4py/fuzz4py/inputs/790.py", line 15, in worker
    db[str(data)] = data * 2
    ~~^^^^^^^^^^^
  File "/home/mrigankp/fuzz4py/fuzz4py/inputs/790.py", line 15, in worker
    db[str(data)] = data * 2
    ~~^^^^^^^^^^^
  File "/home/mrigankp/fuzz4py/cpython/Lib/dbm/sqlite3.py", line 96, in __setitem__
    self._execute(STORE_KV, (key, value))
    ~~~~~~~~~~~~~^^^^^^^^^^^^^^^^^^^^^^^^
  File "/home/mrigankp/fuzz4py/cpython/Lib/dbm/sqlite3.py", line 96, in __setitem__
    self._execute(STORE_KV, (key, value))
    ~~~~~~~~~~~~~^^^^^^^^^^^^^^^^^^^^^^^^
  File "/home/mrigankp/fuzz4py/cpython/Lib/dbm/sqlite3.py", line 96, in __setitem__
    self._execute(STORE_KV, (key, value))
    ~~~~~~~~~~~~~^^^^^^^^^^^^^^^^^^^^^^^^
  File "/home/mrigankp/fuzz4py/fuzz4py/inputs/790.py", line 15, in worker
    db[str(data)] = data * 2
    ~~^^^^^^^^^^^
  File "/home/mrigankp/fuzz4py/cpython/Lib/threading.py", line 992, in run
    self._target(*self._args, **self._kwargs)
    ~~~~~~~~~~~~^^^^^^^^^^^^^^^^^^^^^^^^^^^^^
  File "/home/mrigankp/fuzz4py/cpython/Lib/dbm/sqlite3.py", line 81, in _execute
    raise error(str(exc))
sqlite3.ProgrammingError: SQLite objects created in a thread can only be used in that same thread. The object was created in thread id 123988330428224 and this is thread id 123985157162560.
dbm.sqlite3.error: SQLite objects created in a thread can only be used in that same thread. The object was created in thread id 123988330428224 and this is thread id 123986365122112.
  File "/home/mrigankp/fuzz4py/cpython/Lib/dbm/sqlite3.py", line 81, in _execute
    raise error(str(exc))
  File "/home/mrigankp/fuzz4py/cpython/Lib/threading.py", line 992, in run
    self._target(*self._args, **self._kwargs)
    ~~~~~~~~~~~~^^^^^^^^^^^^^^^^^^^^^^^^^^^^^
  File "/home/mrigankp/fuzz4py/cpython/Lib/dbm/sqlite3.py", line 96, in __setitem__
    self._execute(STORE_KV, (key, value))
    ~~~~~~~~~~~~~^^^^^^^^^^^^^^^^^^^^^^^^
  File "/home/mrigankp/fuzz4py/cpython/Lib/dbm/sqlite3.py", line 96, in __setitem__
    self._execute(STORE_KV, (key, value))
    ~~~~~~~~~~~~~^^^^^^^^^^^^^^^^^^^^^^^^
  File "/home/mrigankp/fuzz4py/cpython/Lib/threading.py", line 1041, in _bootstrap_inner
    self.run()
    ~~~~~~~~^^
dbm.sqlite3.error: SQLite objects created in a thread can only be used in that same thread. The object was created in thread id 123988330428224 and this is thread id 123985740170816.
  File "/home/mrigankp/fuzz4py/cpython/Lib/dbm/sqlite3.py", line 96, in __setitem__
    self._execute(STORE_KV, (key, value))
    ~~~~~~~~~~~~~^^^^^^^^^^^^^^^^^^^^^^^^
dbm.sqlite3.error: SQLite objects created in a thread can only be used in that same thread. The object was created in thread id 123988330428224 and this is thread id 123988286113344.
  File "/home/mrigankp/fuzz4py/cpython/Lib/dbm/sqlite3.py", line 96, in __setitem__
    self._execute(STORE_KV, (key, value))
    ~~~~~~~~~~~~~^^^^^^^^^^^^^^^^^^^^^^^^
  File "/home/mrigankp/fuzz4py/cpython/Lib/threading.py", line 992, in run
    self._target(*self._args, **self._kwargs)
    ~~~~~~~~~~~~^^^^^^^^^^^^^^^^^^^^^^^^^^^^^
  File "/home/mrigankp/fuzz4py/cpython/Lib/threading.py", line 992, in run
    self._target(*self._args, **self._kwargs)
    ~~~~~~~~~~~~^^^^^^^^^^^^^^^^^^^^^^^^^^^^^
  File "/home/mrigankp/fuzz4py/cpython/Lib/dbm/sqlite3.py", line 96, in __setitem__
    self._execute(STORE_KV, (key, value))
    ~~~~~~~~~~~~~^^^^^^^^^^^^^^^^^^^^^^^^
  File "/home/mrigankp/fuzz4py/cpython/Lib/dbm/sqlite3.py", line 81, in _execute
    raise error(str(exc))
dbm.sqlite3.error: SQLite objects created in a thread can only be used in that same thread. The object was created in thread id 123988330428224 and this is thread id 123986132338240.
  File "/home/mrigankp/fuzz4py/cpython/Lib/dbm/sqlite3.py", line 96, in __setitem__
    self._execute(STORE_KV, (key, value))
    ~~~~~~~~~~~~~^^^^^^^^^^^^^^^^^^^^^^^^
  File "/home/mrigankp/fuzz4py/cpython/Lib/dbm/sqlite3.py", line 81, in _execute
    raise error(str(exc))
  File "/home/mrigankp/fuzz4py/cpython/Lib/dbm/sqlite3.py", line 96, in __setitem__
    self._execute(STORE_KV, (key, value))
    ~~~~~~~~~~~~~^^^^^^^^^^^^^^^^^^^^^^^^
dbm.sqlite3.error: SQLite objects created in a thread can only be used in that same thread. The object was created in thread id 123988330428224 and this is thread id 123987159942720.
  File "/home/mrigankp/fuzz4py/cpython/Lib/dbm/sqlite3.py", line 96, in __setitem__
    self._execute(STORE_KV, (key, value))
    ~~~~~~~~~~~~~^^^^^^^^^^^^^^^^^^^^^^^^
  File "/home/mrigankp/fuzz4py/cpython/Lib/dbm/sqlite3.py", line 81, in _execute
    raise error(str(exc))
  File "/home/mrigankp/fuzz4py/cpython/Lib/threading.py", line 992, in run
    self._target(*self._args, **self._kwargs)
    ~~~~~~~~~~~~^^^^^^^^^^^^^^^^^^^^^^^^^^^^^
  File "/home/mrigankp/fuzz4py/cpython/Lib/threading.py", line 1041, in _bootstrap_inner
    self.run()
    ~~~~~~~~^^
dbm.sqlite3.error: SQLite objects created in a thread can only be used in that same thread. The object was created in thread id 123988330428224 and this is thread id 123985538844224.
  File "/home/mrigankp/fuzz4py/cpython/Lib/threading.py", line 1041, in _bootstrap_inner
    self.run()
    ~~~~~~~~^^
  File "/home/mrigankp/fuzz4py/cpython/Lib/dbm/sqlite3.py", line 81, in _execute
    raise error(str(exc))
  File "/home/mrigankp/fuzz4py/cpython/Lib/dbm/sqlite3.py", line 81, in _execute
    raise error(str(exc))
  File "/home/mrigankp/fuzz4py/cpython/Lib/dbm/sqlite3.py", line 81, in _execute
    raise error(str(exc))
  File "/home/mrigankp/fuzz4py/cpython/Lib/dbm/sqlite3.py", line 96, in __setitem__
    self._execute(STORE_KV, (key, value))
    ~~~~~~~~~~~~~^^^^^^^^^^^^^^^^^^^^^^^^
  File "/home/mrigankp/fuzz4py/cpython/Lib/dbm/sqlite3.py", line 81, in _execute
    raise error(str(exc))
  File "/home/mrigankp/fuzz4py/cpython/Lib/dbm/sqlite3.py", line 81, in _execute
    raise error(str(exc))
  File "/home/mrigankp/fuzz4py/cpython/Lib/threading.py", line 992, in run
    self._target(*self._args, **self._kwargs)
    ~~~~~~~~~~~~^^^^^^^^^^^^^^^^^^^^^^^^^^^^^
  File "/home/mrigankp/fuzz4py/cpython/Lib/dbm/sqlite3.py", line 96, in __setitem__
    self._execute(STORE_KV, (key, value))
    ~~~~~~~~~~~~~^^^^^^^^^^^^^^^^^^^^^^^^
dbm.sqlite3.error: SQLite objects created in a thread can only be used in that same thread. The object was created in thread id 123988330428224 and this is thread id 123985327031872.
  File "/home/mrigankp/fuzz4py/cpython/Lib/dbm/sqlite3.py", line 81, in _execute
    raise error(str(exc))
  File "/home/mrigankp/fuzz4py/cpython/Lib/dbm/sqlite3.py", line 81, in _execute
    raise error(str(exc))
  File "/home/mrigankp/fuzz4py/cpython/Lib/dbm/sqlite3.py", line 81, in _execute
    raise error(str(exc))
  File "/home/mrigankp/fuzz4py/cpython/Lib/dbm/sqlite3.py", line 96, in __setitem__
    self._execute(STORE_KV, (key, value))
    ~~~~~~~~~~~~~^^^^^^^^^^^^^^^^^^^^^^^^
  File "/home/mrigankp/fuzz4py/cpython/Lib/dbm/sqlite3.py", line 81, in _execute
    raise error(str(exc))
  File "/home/mrigankp/fuzz4py/cpython/Lib/dbm/sqlite3.py", line 81, in _execute
    raise error(str(exc))
dbm.sqlite3.error: SQLite objects created in a thread can only be used in that same thread. The object was created in thread id 123988330428224 and this is thread id 123985136191040.
  File "/home/mrigankp/fuzz4py/fuzz4py/inputs/790.py", line 15, in worker
    db[str(data)] = data * 2
    ~~^^^^^^^^^^^
  File "/home/mrigankp/fuzz4py/cpython/Lib/dbm/sqlite3.py", line 96, in __setitem__
    self._execute(STORE_KV, (key, value))
    ~~~~~~~~~~~~~^^^^^^^^^^^^^^^^^^^^^^^^
  File "/home/mrigankp/fuzz4py/fuzz4py/inputs/790.py", line 15, in worker
    db[str(data)] = data * 2
    ~~^^^^^^^^^^^
  File "/home/mrigankp/fuzz4py/cpython/Lib/threading.py", line 992, in run
    self._target(*self._args, **self._kwargs)
    ~~~~~~~~~~~~^^^^^^^^^^^^^^^^^^^^^^^^^^^^^
  File "/home/mrigankp/fuzz4py/fuzz4py/inputs/790.py", line 15, in worker
    db[str(data)] = data * 2
    ~~^^^^^^^^^^^
dbm.sqlite3.error: SQLite objects created in a thread can only be used in that same thread. The object was created in thread id 123988330428224 and this is thread id 123988187547200.
  File "/home/mrigankp/fuzz4py/fuzz4py/inputs/790.py", line 15, in worker
    db[str(data)] = data * 2
    ~~^^^^^^^^^^^
dbm.sqlite3.error: SQLite objects created in a thread can only be used in that same thread. The object was created in thread id 123988330428224 and this is thread id 123986121852480.
dbm.sqlite3.error: SQLite objects created in a thread can only be used in that same thread. The object was created in thread id 123988330428224 and this is thread id 123985517872704.
  File "/home/mrigankp/fuzz4py/cpython/Lib/threading.py", line 992, in run
    self._target(*self._args, **self._kwargs)
    ~~~~~~~~~~~~^^^^^^^^^^^^^^^^^^^^^^^^^^^^^
  File "/home/mrigankp/fuzz4py/cpython/Lib/dbm/sqlite3.py", line 96, in __setitem__
    self._execute(STORE_KV, (key, value))
    ~~~~~~~~~~~~~^^^^^^^^^^^^^^^^^^^^^^^^
  File "/home/mrigankp/fuzz4py/cpython/Lib/threading.py", line 992, in run
    self._target(*self._args, **self._kwargs)
    ~~~~~~~~~~~~^^^^^^^^^^^^^^^^^^^^^^^^^^^^^
  File "/home/mrigankp/fuzz4py/cpython/Lib/threading.py", line 992, in run
    self._target(*self._args, **self._kwargs)
    ~~~~~~~~~~~~^^^^^^^^^^^^^^^^^^^^^^^^^^^^^
  File "/home/mrigankp/fuzz4py/cpython/Lib/threading.py", line 1041, in _bootstrap_inner
    self.run()
    ~~~~~~~~^^
  File "/home/mrigankp/fuzz4py/cpython/Lib/dbm/sqlite3.py", line 96, in __setitem__
    self._execute(STORE_KV, (key, value))
    ~~~~~~~~~~~~~^^^^^^^^^^^^^^^^^^^^^^^^
  File "/home/mrigankp/fuzz4py/fuzz4py/inputs/790.py", line 15, in worker
    db[str(data)] = data * 2
    ~~^^^^^^^^^^^
dbm.sqlite3.error: SQLite objects created in a thread can only be used in that same thread. The object was created in thread id 123988330428224 and this is thread id 123987340297792.

During handling of the above exception, another exception occurred:

dbm.sqlite3.error: SQLite objects created in a thread can only be used in that same thread. The object was created in thread id 123988330428224 and this is thread id 123988275627584.
  File "/home/mrigankp/fuzz4py/cpython/Lib/dbm/sqlite3.py", line 81, in _execute
    raise error(str(exc))
  File "/home/mrigankp/fuzz4py/fuzz4py/inputs/790.py", line 15, in worker
    db[str(data)] = data * 2
    ~~^^^^^^^^^^^
  File "/home/mrigankp/fuzz4py/cpython/Lib/threading.py", line 1041, in _bootstrap_inner
    self.run()
    ~~~~~~~~^^
  File "/home/mrigankp/fuzz4py/cpython/Lib/dbm/sqlite3.py", line 96, in __setitem__
    self._execute(STORE_KV, (key, value))
    ~~~~~~~~~~~~~^^^^^^^^^^^^^^^^^^^^^^^^
dbm.sqlite3.error: SQLite objects created in a thread can only be used in that same thread. The object was created in thread id 123988330428224 and this is thread id 123985750656576.
dbm.sqlite3.error: SQLite objects created in a thread can only be used in that same thread. The object was created in thread id 123988330428224 and this is thread id 123987329812032.
  File "/home/mrigankp/fuzz4py/cpython/Lib/dbm/sqlite3.py", line 81, in _execute
    raise error(str(exc))
dbm.sqlite3.error: SQLite objects created in a thread can only be used in that same thread. The object was created in thread id 123988330428224 and this is thread id 123985146676800.
  File "/home/mrigankp/fuzz4py/fuzz4py/inputs/790.py", line 15, in worker
    db[str(data)] = data * 2
    ~~^^^^^^^^^^^
  File "/home/mrigankp/fuzz4py/cpython/Lib/dbm/sqlite3.py", line 96, in __setitem__
    self._execute(STORE_KV, (key, value))
    ~~~~~~~~~~~~~^^^^^^^^^^^^^^^^^^^^^^^^
  File "/home/mrigankp/fuzz4py/cpython/Lib/dbm/sqlite3.py", line 96, in __setitem__
    self._execute(STORE_KV, (key, value))
    ~~~~~~~~~~~~~^^^^^^^^^^^^^^^^^^^^^^^^
  File "/home/mrigankp/fuzz4py/fuzz4py/inputs/790.py", line 15, in worker
    db[str(data)] = data * 2
    ~~^^^^^^^^^^^
  File "/home/mrigankp/fuzz4py/cpython/Lib/dbm/sqlite3.py", line 81, in _execute
    raise error(str(exc))
  File "/home/mrigankp/fuzz4py/cpython/Lib/dbm/sqlite3.py", line 96, in __setitem__
    self._execute(STORE_KV, (key, value))
    ~~~~~~~~~~~~~^^^^^^^^^^^^^^^^^^^^^^^^
  File "/home/mrigankp/fuzz4py/fuzz4py/inputs/790.py", line 15, in worker
    db[str(data)] = data * 2
    ~~^^^^^^^^^^^
  File "/home/mrigankp/fuzz4py/fuzz4py/inputs/790.py", line 15, in worker
    db[str(data)] = data * 2
    ~~^^^^^^^^^^^
  File "/home/mrigankp/fuzz4py/cpython/Lib/dbm/sqlite3.py", line 81, in _execute
    raise error(str(exc))
  File "/home/mrigankp/fuzz4py/cpython/Lib/dbm/sqlite3.py", line 96, in __setitem__
    self._execute(STORE_KV, (key, value))
    ~~~~~~~~~~~~~^^^^^^^^^^^^^^^^^^^^^^^^
  File "/home/mrigankp/fuzz4py/fuzz4py/inputs/790.py", line 15, in worker
    db[str(data)] = data * 2
    ~~^^^^^^^^^^^
dbm.sqlite3.error: SQLite objects created in a thread can only be used in that same thread. The object was created in thread id 123988330428224 and this is thread id 123987138971200.
dbm.sqlite3.error: SQLite objects created in a thread can only be used in that same thread. The object was created in thread id 123988330428224 and this is thread id 123986354636352.
  File "/home/mrigankp/fuzz4py/cpython/Lib/dbm/sqlite3.py", line 96, in __setitem__
    self._execute(STORE_KV, (key, value))
    ~~~~~~~~~~~~~^^^^^^^^^^^^^^^^^^^^^^^^
  File "/home/mrigankp/fuzz4py/cpython/Lib/threading.py", line 992, in run
    self._target(*self._args, **self._kwargs)
    ~~~~~~~~~~~~^^^^^^^^^^^^^^^^^^^^^^^^^^^^^
dbm.sqlite3.error: SQLite objects created in a thread can only be used in that same thread. The object was created in thread id 123988330428224 and this is thread id 123988307084864.
  File "/home/mrigankp/fuzz4py/cpython/Lib/dbm/sqlite3.py", line 96, in __setitem__
    self._execute(STORE_KV, (key, value))
    ~~~~~~~~~~~~~^^^^^^^^^^^^^^^^^^^^^^^^
  File "/home/mrigankp/fuzz4py/cpython/Lib/threading.py", line 1041, in _bootstrap_inner
    self.run()
    ~~~~~~~~^^
  File "/home/mrigankp/fuzz4py/cpython/Lib/threading.py", line 992, in run
    self._target(*self._args, **self._kwargs)
    ~~~~~~~~~~~~^^^^^^^^^^^^^^^^^^^^^^^^^^^^^
  File "/home/mrigankp/fuzz4py/cpython/Lib/dbm/sqlite3.py", line 96, in __setitem__
    self._execute(STORE_KV, (key, value))
    ~~~~~~~~~~~~~^^^^^^^^^^^^^^^^^^^^^^^^
  File "/home/mrigankp/fuzz4py/cpython/Lib/dbm/sqlite3.py", line 81, in _execute
    raise error(str(exc))
  File "/home/mrigankp/fuzz4py/cpython/Lib/dbm/sqlite3.py", line 81, in _execute
    raise error(str(exc))
  File "/home/mrigankp/fuzz4py/cpython/Lib/dbm/sqlite3.py", line 81, in _execute
    raise error(str(exc))
  File "/home/mrigankp/fuzz4py/cpython/Lib/dbm/sqlite3.py", line 81, in _execute
    raise error(str(exc))
dbm.sqlite3.error: SQLite objects created in a thread can only be used in that same thread. The object was created in thread id 123988330428224 and this is thread id 123988145604160.
dbm.sqlite3.error: SQLite objects created in a thread can only be used in that same thread. The object was created in thread id 123988330428224 and this is thread id 123986566448704.
  File "/home/mrigankp/fuzz4py/cpython/Lib/dbm/sqlite3.py", line 81, in _execute
    raise error(str(exc))
  File "/home/mrigankp/fuzz4py/cpython/Lib/dbm/sqlite3.py", line 81, in _execute
    raise error(str(exc))
  File "/home/mrigankp/fuzz4py/cpython/Lib/dbm/sqlite3.py", line 96, in __setitem__
    self._execute(STORE_KV, (key, value))
    ~~~~~~~~~~~~~^^^^^^^^^^^^^^^^^^^^^^^^
dbm.sqlite3.error: SQLite objects created in a thread can only be used in that same thread. The object was created in thread id 123988330428224 and this is thread id 123985368974912.
dbm.sqlite3.error: SQLite objects created in a thread can only be used in that same thread. The object was created in thread id 123988330428224 and this is thread id 123986534991424.
  File "/home/mrigankp/fuzz4py/cpython/Lib/dbm/sqlite3.py", line 81, in _execute
    raise error(str(exc))
  File "/home/mrigankp/fuzz4py/cpython/Lib/threading.py", line 992, in run
    self._target(*self._args, **self._kwargs)
    ~~~~~~~~~~~~^^^^^^^^^^^^^^^^^^^^^^^^^^^^^
Traceback (most recent call last):
  File "/home/mrigankp/fuzz4py/fuzz4py/inputs/790.py", line 15, in worker
    db[str(data)] = data * 2
    ~~^^^^^^^^^^^
  File "/home/mrigankp/fuzz4py/cpython/Lib/dbm/sqlite3.py", line 81, in _execute
    raise error(str(exc))
  File "/home/mrigankp/fuzz4py/fuzz4py/inputs/790.py", line 15, in worker
    db[str(data)] = data * 2
    ~~^^^^^^^^^^^
dbm.sqlite3.error: SQLite objects created in a thread can only be used in that same thread. The object was created in thread id 123988330428224 and this is thread id 123985719199296.
  File "/home/mrigankp/fuzz4py/cpython/Lib/dbm/sqlite3.py", line 96, in __setitem__
    self._execute(STORE_KV, (key, value))
    ~~~~~~~~~~~~~^^^^^^^^^^^^^^^^^^^^^^^^
dbm.sqlite3.error: SQLite objects created in a thread can only be used in that same thread. The object was created in thread id 123988330428224 and this is thread id 123986174281280.
dbm.sqlite3.error: SQLite objects created in a thread can only be used in that same thread. The object was created in thread id 123988330428224 and this is thread id 123987170428480.
dbm.sqlite3.error: SQLite objects created in a thread can only be used in that same thread. The object was created in thread id 123988330428224 and this is thread id 123986576934464.
dbm.sqlite3.error: SQLite objects created in a thread can only be used in that same thread. The object was created in thread id 123988330428224 and this is thread id 123986958616128.
dbm.sqlite3.error: SQLite objects created in a thread can only be used in that same thread. The object was created in thread id 123988330428224 and this is thread id 123987986220608.
dbm.sqlite3.error: SQLite objects created in a thread can only be used in that same thread. The object was created in thread id 123988330428224 and this is thread id 123985528358464.
dbm.sqlite3.error: SQLite objects created in a thread can only be used in that same thread. The object was created in thread id 123988330428224 and this is thread id 123985972954688.
  File "/home/mrigankp/fuzz4py/cpython/Lib/dbm/sqlite3.py", line 81, in _execute
    raise error(str(exc))
  File "/home/mrigankp/fuzz4py/fuzz4py/inputs/790.py", line 15, in worker
    db[str(data)] = data * 2
    ~~^^^^^^^^^^^
dbm.sqlite3.error: SQLite objects created in a thread can only be used in that same thread. The object was created in thread id 123988330428224 and this is thread id 123985920525888.
  File "/home/mrigankp/fuzz4py/fuzz4py/inputs/790.py", line 15, in worker
    db[str(data)] = data * 2
    ~~^^^^^^^^^^^
  File "/home/mrigankp/fuzz4py/fuzz4py/inputs/790.py", line 15, in worker
    db[str(data)] = data * 2
    ~~^^^^^^^^^^^
  File "/home/mrigankp/fuzz4py/cpython/Lib/threading.py", line 1041, in _bootstrap_inner
    self.run()
    ~~~~~~~~^^
dbm.sqlite3.error: SQLite objects created in a thread can only be used in that same thread. The object was created in thread id 123988330428224 and this is thread id 123986344150592.
  File "/home/mrigankp/fuzz4py/cpython/Lib/dbm/sqlite3.py", line 81, in _execute
    raise error(str(exc))
dbm.sqlite3.error: SQLite objects created in a thread can only be used in that same thread. The object was created in thread id 123988330428224 and this is thread id 123986163795520.
  File "/home/mrigankp/fuzz4py/cpython/Lib/dbm/sqlite3.py", line 81, in _execute
    raise error(str(exc))
  File "/home/mrigankp/fuzz4py/cpython/Lib/dbm/sqlite3.py", line 81, in _execute
    raise error(str(exc))
  File "/home/mrigankp/fuzz4py/cpython/Lib/dbm/sqlite3.py", line 81, in _execute
    raise error(str(exc))
  File "/home/mrigankp/fuzz4py/cpython/Lib/dbm/sqlite3.py", line 96, in __setitem__
    self._execute(STORE_KV, (key, value))
    ~~~~~~~~~~~~~^^^^^^^^^^^^^^^^^^^^^^^^
  File "/home/mrigankp/fuzz4py/cpython/Lib/dbm/sqlite3.py", line 96, in __setitem__
    self._execute(STORE_KV, (key, value))
    ~~~~~~~~~~~~~^^^^^^^^^^^^^^^^^^^^^^^^
  File "/home/mrigankp/fuzz4py/fuzz4py/inputs/790.py", line 15, in worker
    db[str(data)] = data * 2
    ~~^^^^^^^^^^^
  File "/home/mrigankp/fuzz4py/cpython/Lib/dbm/sqlite3.py", line 81, in _execute
    raise error(str(exc))
dbm.sqlite3.error: SQLite objects created in a thread can only be used in that same thread. The object was created in thread id 123988330428224 and this is thread id 123985951983168.
  File "/home/mrigankp/fuzz4py/cpython/Lib/dbm/sqlite3.py", line 96, in __setitem__
    self._execute(STORE_KV, (key, value))
    ~~~~~~~~~~~~~^^^^^^^^^^^^^^^^^^^^^^^^
  File "/home/mrigankp/fuzz4py/cpython/Lib/dbm/sqlite3.py", line 96, in __setitem__
    self._execute(STORE_KV, (key, value))
    ~~~~~~~~~~~~~^^^^^^^^^^^^^^^^^^^^^^^^
  File "/home/mrigankp/fuzz4py/cpython/Lib/dbm/sqlite3.py", line 81, in _execute
    raise error(str(exc))
  File "/home/mrigankp/fuzz4py/cpython/Lib/dbm/sqlite3.py", line 96, in __setitem__
    self._execute(STORE_KV, (key, value))
    ~~~~~~~~~~~~~^^^^^^^^^^^^^^^^^^^^^^^^
  File "/home/mrigankp/fuzz4py/cpython/Lib/threading.py", line 992, in run
    self._target(*self._args, **self._kwargs)
    ~~~~~~~~~~~~^^^^^^^^^^^^^^^^^^^^^^^^^^^^^
  File "/home/mrigankp/fuzz4py/cpython/Lib/threading.py", line 992, in run
    self._target(*self._args, **self._kwargs)
    ~~~~~~~~~~~~^^^^^^^^^^^^^^^^^^^^^^^^^^^^^
dbm.sqlite3.error: SQLite objects created in a thread can only be used in that same thread. The object was created in thread id 123988330428224 and this is thread id 123985316546112.
  File "/home/mrigankp/fuzz4py/cpython/Lib/dbm/sqlite3.py", line 96, in __setitem__
    self._execute(STORE_KV, (key, value))
    ~~~~~~~~~~~~~^^^^^^^^^^^^^^^^^^^^^^^^
  File "/home/mrigankp/fuzz4py/cpython/Lib/dbm/sqlite3.py", line 81, in _execute
    raise error(str(exc))
dbm.sqlite3.error: SQLite objects created in a thread can only be used in that same thread. The object was created in thread id 123988330428224 and this is thread id 123985125705280.
dbm.sqlite3.error: SQLite objects created in a thread can only be used in that same thread. The object was created in thread id 123988330428224 and this is thread id 123986142824000.
  File "/home/mrigankp/fuzz4py/cpython/Lib/dbm/sqlite3.py", line 81, in _execute
    raise error(str(exc))
  File "/home/mrigankp/fuzz4py/cpython/Lib/dbm/sqlite3.py", line 81, in _execute
    raise error(str(exc))
  File "/home/mrigankp/fuzz4py/cpython/Lib/dbm/sqlite3.py", line 96, in __setitem__
    self._execute(STORE_KV, (key, value))
    ~~~~~~~~~~~~~^^^^^^^^^^^^^^^^^^^^^^^^
dbm.sqlite3.error: SQLite objects created in a thread can only be used in that same thread. The object was created in thread id 123988330428224 and this is thread id 123985962468928.
  File "/home/mrigankp/fuzz4py/cpython/Lib/dbm/sqlite3.py", line 81, in _execute
    raise error(str(exc))
  File "/home/mrigankp/fuzz4py/cpython/Lib/threading.py", line 992, in run
    self._target(*self._args, **self._kwargs)
    ~~~~~~~~~~~~^^^^^^^^^^^^^^^^^^^^^^^^^^^^^
  File "/home/mrigankp/fuzz4py/cpython/Lib/dbm/sqlite3.py", line 96, in __setitem__
    self._execute(STORE_KV, (key, value))
    ~~~~~~~~~~~~~^^^^^^^^^^^^^^^^^^^^^^^^
  File "/home/mrigankp/fuzz4py/cpython/Lib/dbm/sqlite3.py", line 96, in __setitem__
    self._execute(STORE_KV, (key, value))
    ~~~~~~~~~~~~~^^^^^^^^^^^^^^^^^^^^^^^^
  File "/home/mrigankp/fuzz4py/cpython/Lib/dbm/sqlite3.py", line 81, in _execute
    raise error(str(exc))
  File "/home/mrigankp/fuzz4py/fuzz4py/inputs/790.py", line 15, in worker
    db[str(data)] = data * 2
    ~~^^^^^^^^^^^
dbm.sqlite3.error: SQLite objects created in a thread can only be used in that same thread. The object was created in thread id 123988330428224 and this is thread id 123986948130368.
dbm.sqlite3.error: SQLite objects created in a thread can only be used in that same thread. The object was created in thread id 123988330428224 and this is thread id 123986153309760.
dbm.sqlite3.error: SQLite objects created in a thread can only be used in that same thread. The object was created in thread id 123988330428224 and this is thread id 123986555962944.
  File "/home/mrigankp/fuzz4py/cpython/Lib/dbm/sqlite3.py", line 96, in __setitem__
    self._execute(STORE_KV, (key, value))
    ~~~~~~~~~~~~~^^^^^^^^^^^^^^^^^^^^^^^^
  File "/home/mrigankp/fuzz4py/cpython/Lib/dbm/sqlite3.py", line 81, in _execute
    raise error(str(exc))
  File "/home/mrigankp/fuzz4py/fuzz4py/inputs/790.py", line 15, in worker
    db[str(data)] = data * 2
    ~~^^^^^^^^^^^
  File "/home/mrigankp/fuzz4py/fuzz4py/inputs/790.py", line 15, in worker
    db[str(data)] = data * 2
    ~~^^^^^^^^^^^
  File "/home/mrigankp/fuzz4py/cpython/Lib/dbm/sqlite3.py", line 81, in _execute
    raise error(str(exc))
  File "/home/mrigankp/fuzz4py/cpython/Lib/threading.py", line 992, in run
    self._target(*self._args, **self._kwargs)
    ~~~~~~~~~~~~^^^^^^^^^^^^^^^^^^^^^^^^^^^^^
dbm.sqlite3.error: SQLite objects created in a thread can only be used in that same thread. The object was created in thread id 123988330428224 and this is thread id 123986725832256.
dbm.sqlite3.error: SQLite objects created in a thread can only be used in that same thread. The object was created in thread id 123988330428224 and this is thread id 123987180914240.
dbm.sqlite3.error: SQLite objects created in a thread can only be used in that same thread. The object was created in thread id 123988330428224 and this is thread id 123987371755072.
  File "/home/mrigankp/fuzz4py/cpython/Lib/dbm/sqlite3.py", line 81, in _execute
    raise error(str(exc))
  File "/home/mrigankp/fuzz4py/cpython/Lib/dbm/sqlite3.py", line 81, in _execute
    raise error(str(exc))
dbm.sqlite3.error: SQLite objects created in a thread can only be used in that same thread. The object was created in thread id 123988330428224 and this is thread id 123986767775296.
  File "/home/mrigankp/fuzz4py/cpython/Lib/dbm/sqlite3.py", line 96, in __setitem__
    self._execute(STORE_KV, (key, value))
    ~~~~~~~~~~~~~^^^^^^^^^^^^^^^^^^^^^^^^
  File "/home/mrigankp/fuzz4py/cpython/Lib/dbm/sqlite3.py", line 96, in __setitem__
    self._execute(STORE_KV, (key, value))
    ~~~~~~~~~~~~~^^^^^^^^^^^^^^^^^^^^^^^^
  File "/home/mrigankp/fuzz4py/fuzz4py/inputs/790.py", line 15, in worker
    db[str(data)] = data * 2
    ~~^^^^^^^^^^^
dbm.sqlite3.error: SQLite objects created in a thread can only be used in that same thread. The object was created in thread id 123988330428224 and this is thread id 123986333664832.
  File "/home/mrigankp/fuzz4py/cpython/Lib/dbm/sqlite3.py", line 96, in __setitem__
    self._execute(STORE_KV, (key, value))
    ~~~~~~~~~~~~~^^^^^^^^^^^^^^^^^^^^^^^^
dbm.sqlite3.error: SQLite objects created in a thread can only be used in that same thread. The object was created in thread id 123988330428224 and this is thread id 123986545477184.
dbm.sqlite3.error: SQLite objects created in a thread can only be used in that same thread. The object was created in thread id 123988330428224 and this is thread id 123985761142336.
  File "/home/mrigankp/fuzz4py/cpython/Lib/dbm/sqlite3.py", line 81, in _execute
    raise error(str(exc))
  File "/home/mrigankp/fuzz4py/cpython/Lib/dbm/sqlite3.py", line 81, in _execute
    raise error(str(exc))
  File "/home/mrigankp/fuzz4py/cpython/Lib/dbm/sqlite3.py", line 96, in __setitem__
    self._execute(STORE_KV, (key, value))
    ~~~~~~~~~~~~~^^^^^^^^^^^^^^^^^^^^^^^^
  File "/home/mrigankp/fuzz4py/fuzz4py/inputs/790.py", line 15, in worker
    db[str(data)] = data * 2
    ~~^^^^^^^^^^^
dbm.sqlite3.error: SQLite objects created in a thread can only be used in that same thread. The object was created in thread id 123988330428224 and this is thread id 123986524505664.
  File "/home/mrigankp/fuzz4py/cpython/Lib/dbm/sqlite3.py", line 81, in _execute
    raise error(str(exc))
dbm.sqlite3.error: SQLite objects created in a thread can only be used in that same thread. The object was created in thread id 123988330428224 and this is thread id 123985358489152.
dbm.sqlite3.error: SQLite objects created in a thread can only be used in that same thread. The object was created in thread id 123988330428224 and this is thread id 123986736318016.
  File "/home/mrigankp/fuzz4py/cpython/Lib/dbm/sqlite3.py", line 81, in _execute
    raise error(str(exc))
  File "/home/mrigankp/fuzz4py/cpython/Lib/dbm/sqlite3.py", line 81, in _execute
    raise error(str(exc))
  File "/home/mrigankp/fuzz4py/cpython/Lib/dbm/sqlite3.py", line 96, in __setitem__
    self._execute(STORE_KV, (key, value))
    ~~~~~~~~~~~~~^^^^^^^^^^^^^^^^^^^^^^^^
  File "/home/mrigankp/fuzz4py/cpython/Lib/dbm/sqlite3.py", line 81, in _execute
    raise error(str(exc))
dbm.sqlite3.error: SQLite objects created in a thread can only be used in that same thread. The object was created in thread id 123988330428224 and this is thread id 123986778261056.
dbm.sqlite3.error: SQLite objects created in a thread can only be used in that same thread. The object was created in thread id 123988330428224 and this is thread id 123985337517632.
dbm.sqlite3.error: SQLite objects created in a thread can only be used in that same thread. The object was created in thread id 123988330428224 and this is thread id 123986746803776.
dbm.sqlite3.error: SQLite objects created in a thread can only be used in that same thread. The object was created in thread id 123988330428224 and this is thread id 123987531138624.
dbm.sqlite3.error: SQLite objects created in a thread can only be used in that same thread. The object was created in thread id 123988330428224 and this is thread id 123985348003392.
dbm.sqlite3.error: SQLite objects created in a thread can only be used in that same thread. The object was created in thread id 123988330428224 and this is thread id 123986937644608.
dbm.sqlite3.error: SQLite objects created in a thread can only be used in that same thread. The object was created in thread id 123988330428224 and this is thread id 123985771628096.
dbm.sqlite3.error: SQLite objects created in a thread can only be used in that same thread. The object was created in thread id 123988330428224 and this is thread id 123988177061440.
  File "/home/mrigankp/fuzz4py/cpython/Lib/dbm/sqlite3.py", line 81, in _execute
    raise error(str(exc))
  File "/home/mrigankp/fuzz4py/cpython/Lib/dbm/sqlite3.py", line 96, in __setitem__
    self._execute(STORE_KV, (key, value))
    ~~~~~~~~~~~~~^^^^^^^^^^^^^^^^^^^^^^^^
  File "/home/mrigankp/fuzz4py/cpython/Lib/dbm/sqlite3.py", line 96, in __setitem__
    self._execute(STORE_KV, (key, value))
    ~~~~~~~~~~~~~^^^^^^^^^^^^^^^^^^^^^^^^
  File "/home/mrigankp/fuzz4py/cpython/Lib/dbm/sqlite3.py", line 81, in _execute
    raise error(str(exc))
  File "/home/mrigankp/fuzz4py/cpython/Lib/dbm/sqlite3.py", line 81, in _execute
    raise error(str(exc))
dbm.sqlite3.error: SQLite objects created in a thread can only be used in that same thread. The object was created in thread id 123988330428224 and this is thread id 123985115219520.
dbm.sqlite3.error: SQLite objects created in a thread can only be used in that same thread. The object was created in thread id 123988330428224 and this is thread id 123986375607872.
dbm.sqlite3.error: SQLite objects created in a thread can only be used in that same thread. The object was created in thread id 123988330428224 and this is thread id 123985157162560.

