Return Code: 0
Stdout: b"Exception in main loop: invalid literal for int() with base 10: b'value1'\n"
Stderr: b'Exception in thread Thread-1 (worker):\nException in thread Thread-2 (worker):\nException in thread Thread-3 (worker):\nException in thread Thread-4 (worker):\nException in thread Thread-5 (worker):\nException in thread Thread-6 (worker):\nException in thread Thread-7 (worker):\nException in thread Thread-8 (worker):\nException in thread Thread-9 (worker):\nException in thread Thread-10 (worker):\nException in thread Thread-11 (worker):\nException in thread Thread-12 (worker):\nException in thread Thread-13 (worker):\nException in thread Thread-14 (worker):\nException in thread Thread-15 (worker):\nException in thread Thread-16 (worker):\nException in thread Thread-17 (worker):\nException in thread Thread-18 (worker):\nException in thread Thread-19 (worker):\nException in thread Thread-20 (worker):\nException in thread Thread-21 (worker):\nException in thread Thread-22 (worker):\nException in thread Thread-23 (worker):\nException in thread Thread-24 (worker):\nException in thread Thread-25 (worker):\nException in thread Thread-26 (worker):\nException in thread Thread-27 (worker):\nException in thread Thread-28 (worker):\nException in thread Thread-29 (worker):\nException in thread Thread-30 (worker):\nTraceback (most recent call last):\nTraceback (most recent call last):\nTraceback (most recent call last):\nTraceback (most recent call last):\nTraceback (most recent call last):\n  File "/home/mrigankp/fuzz4py/cpython/Lib/dbm/sqlite3.py", line 79, in _execute\n    return closing(self._cx.execute(*args, **kwargs))\n                   ~~~~~~~~~~~~~~~~^^^^^^^^^^^^^^^^^\nTraceback (most recent call last):\nTraceback (most recent call last):\n  File "/home/mrigankp/fuzz4py/cpython/Lib/dbm/sqlite3.py", line 79, in _execute\n    return closing(self._cx.execute(*args, **kwargs))\n                   ~~~~~~~~~~~~~~~~^^^^^^^^^^^^^^^^^\nTraceback (most recent call last):\nTraceback (most recent call last):\nTraceback (most recent call last):\nTraceback (most recent call last):\nTraceback (most recent call last):\nTraceback (most recent call last):\nTraceback (most recent call last):\nTraceback (most recent call last):\nTraceback (most recent call last):\nTraceback (most recent call last):\nException in thread Thread-33 (worker):\nTraceback (most recent call last):\n  File "/home/mrigankp/fuzz4py/cpython/Lib/dbm/sqlite3.py", line 79, in _execute\n    return closing(self._cx.execute(*args, **kwargs))\n                   ~~~~~~~~~~~~~~~~^^^^^^^^^^^^^^^^^\nTraceback (most recent call last):\nTraceback (most recent call last):\nTraceback (most recent call last):\nTraceback (most recent call last):\n  File "/home/mrigankp/fuzz4py/cpython/Lib/dbm/sqlite3.py", line 79, in _execute\n    return closing(self._cx.execute(*args, **kwargs))\n                   ~~~~~~~~~~~~~~~~^^^^^^^^^^^^^^^^^\nTraceback (most recent call last):\nTraceback (most recent call last):\n  File "/home/mrigankp/fuzz4py/cpython/Lib/dbm/sqlite3.py", line 79, in _execute\n    return closing(self._cx.execute(*args, **kwargs))\n                   ~~~~~~~~~~~~~~~~^^^^^^^^^^^^^^^^^\nTraceback (most recent call last):\n  File "/home/mrigankp/fuzz4py/cpython/Lib/dbm/sqlite3.py", line 79, in _execute\n    return closing(self._cx.execute(*args, **kwargs))\n                   ~~~~~~~~~~~~~~~~^^^^^^^^^^^^^^^^^\nException in thread Thread-32 (worker):\nException in thread Thread-37 (worker):\n  File "/home/mrigankp/fuzz4py/cpython/Lib/dbm/sqlite3.py", line 79, in _execute\n    return closing(self._cx.execute(*args, **kwargs))\n                   ~~~~~~~~~~~~~~~~^^^^^^^^^^^^^^^^^\n  File "/home/mrigankp/fuzz4py/cpython/Lib/dbm/sqlite3.py", line 79, in _execute\n    return closing(self._cx.execute(*args, **kwargs))\n                   ~~~~~~~~~~~~~~~~^^^^^^^^^^^^^^^^^\nException in thread Thread-38 (worker):\nException in thread Thread-31 (worker):\nException in thread Thread-39 (worker):\nTraceback (most recent call last):\nTraceback (most recent call last):\nTraceback (most recent call last):\nException in thread Thread-40 (worker):\n  File "/home/mrigankp/fuzz4py/cpython/Lib/dbm/sqlite3.py", line 79, in _execute\n    return closing(self._cx.execute(*args, **kwargs))\n                   ~~~~~~~~~~~~~~~~^^^^^^^^^^^^^^^^^\nException in thread Thread-35 (worker):\nException in thread Thread-41 (worker):\n  File "/home/mrigankp/fuzz4py/cpython/Lib/dbm/sqlite3.py", line 79, in _execute\n    return closing(self._cx.execute(*args, **kwargs))\n                   ~~~~~~~~~~~~~~~~^^^^^^^^^^^^^^^^^\nsqlite3.ProgrammingError: SQLite objects created in a thread can only be used in that same thread. The object was created in thread id 124364096350016 and this is thread id 124364072683072.\n  File "/home/mrigankp/fuzz4py/cpython/Lib/dbm/sqlite3.py", line 79, in _execute\n    return closing(self._cx.execute(*args, **kwargs))\n                   ~~~~~~~~~~~~~~~~^^^^^^^^^^^^^^^^^\nTraceback (most recent call last):\nException in thread Thread-36 (worker):\nException in thread Thread-43 (worker):\n  File "/home/mrigankp/fuzz4py/cpython/Lib/dbm/sqlite3.py", line 79, in _execute\n    return closing(self._cx.execute(*args, **kwargs))\n                   ~~~~~~~~~~~~~~~~^^^^^^^^^^^^^^^^^\nException in thread Thread-44 (worker):\n  File "/home/mrigankp/fuzz4py/cpython/Lib/dbm/sqlite3.py", line 79, in _execute\n    return closing(self._cx.execute(*args, **kwargs))\n                   ~~~~~~~~~~~~~~~~^^^^^^^^^^^^^^^^^\nException in thread Thread-45 (worker):\nsqlite3.ProgrammingError: SQLite objects created in a thread can only be used in that same thread. The object was created in thread id 124364096350016 and this is thread id 124363919590976.\nException in thread Thread-46 (worker):\nTraceback (most recent call last):\n  File "/home/mrigankp/fuzz4py/cpython/Lib/dbm/sqlite3.py", line 79, in _execute\n    return closing(self._cx.execute(*args, **kwargs))\n                   ~~~~~~~~~~~~~~~~^^^^^^^^^^^^^^^^^\nException in thread Thread-47 (worker):\nException in thread Thread-48 (worker):\nTraceback (most recent call last):\n  File "/home/mrigankp/fuzz4py/cpython/Lib/dbm/sqlite3.py", line 79, in _execute\n    return closing(self._cx.execute(*args, **kwargs))\n                   ~~~~~~~~~~~~~~~~^^^^^^^^^^^^^^^^^\nsqlite3.ProgrammingError: SQLite objects created in a thread can only be used in that same thread. The object was created in thread id 124364096350016 and this is thread id 124364030740032.\nException in thread Thread-49 (worker):\n  File "/home/mrigankp/fuzz4py/cpython/Lib/dbm/sqlite3.py", line 79, in _execute\n    return closing(self._cx.execute(*args, **kwargs))\n                   ~~~~~~~~~~~~~~~~^^^^^^^^^^^^^^^^^\n  File "/home/mrigankp/fuzz4py/cpython/Lib/dbm/sqlite3.py", line 79, in _execute\n    return closing(self._cx.execute(*args, **kwargs))\n                   ~~~~~~~~~~~~~~~~^^^^^^^^^^^^^^^^^\nTraceback (most recent call last):\n  File "/home/mrigankp/fuzz4py/cpython/Lib/dbm/sqlite3.py", line 79, in _execute\n    return closing(self._cx.execute(*args, **kwargs))\n                   ~~~~~~~~~~~~~~~~^^^^^^^^^^^^^^^^^\nTraceback (most recent call last):\n  File "/home/mrigankp/fuzz4py/cpython/Lib/dbm/sqlite3.py", line 79, in _execute\n    return closing(self._cx.execute(*args, **kwargs))\n                   ~~~~~~~~~~~~~~~~^^^^^^^^^^^^^^^^^\nTraceback (most recent call last):\n\nDuring handling of the above exception, another exception occurred:\n\nException in thread Thread-42 (worker):\n  File "/home/mrigankp/fuzz4py/cpython/Lib/dbm/sqlite3.py", line 79, in _execute\n    return closing(self._cx.execute(*args, **kwargs))\n                   ~~~~~~~~~~~~~~~~^^^^^^^^^^^^^^^^^\nException in thread Thread-53 (worker):\n  File "/home/mrigankp/fuzz4py/cpython/Lib/dbm/sqlite3.py", line 79, in _execute\n    return closing(self._cx.execute(*args, **kwargs))\n                   ~~~~~~~~~~~~~~~~^^^^^^^^^^^^^^^^^\n  File "/home/mrigankp/fuzz4py/cpython/Lib/dbm/sqlite3.py", line 79, in _execute\n    return closing(self._cx.execute(*args, **kwargs))\n                   ~~~~~~~~~~~~~~~~^^^^^^^^^^^^^^^^^\nTraceback (most recent call last):\nsqlite3.ProgrammingError: SQLite objects created in a thread can only be used in that same thread. The object was created in thread id 124364096350016 and this is thread id 124363474994752.\nTraceback (most recent call last):\nTraceback (most recent call last):\n\nDuring handling of the above exception, another exception occurred:\n\nTraceback (most recent call last):\nException in thread Thread-56 (worker):\n  File "/home/mrigankp/fuzz4py/cpython/Lib/dbm/sqlite3.py", line 79, in _execute\n    return closing(self._cx.execute(*args, **kwargs))\n                   ~~~~~~~~~~~~~~~~^^^^^^^^^^^^^^^^^\n  File "/home/mrigankp/fuzz4py/cpython/Lib/dbm/sqlite3.py", line 79, in _execute\n    return closing(self._cx.execute(*args, **kwargs))\n                   ~~~~~~~~~~~~~~~~^^^^^^^^^^^^^^^^^\nTraceback (most recent call last):\nException in thread Thread-57 (worker):\nException in thread Thread-58 (worker):\nTraceback (most recent call last):\n  File "/home/mrigankp/fuzz4py/cpython/Lib/dbm/sqlite3.py", line 79, in _execute\n    return closing(self._cx.execute(*args, **kwargs))\n                   ~~~~~~~~~~~~~~~~^^^^^^^^^^^^^^^^^\n  File "/home/mrigankp/fuzz4py/cpython/Lib/dbm/sqlite3.py", line 79, in _execute\n    return closing(self._cx.execute(*args, **kwargs))\n                   ~~~~~~~~~~~~~~~~^^^^^^^^^^^^^^^^^\n\nDuring handling of the above exception, another exception occurred:\n\n  File "/home/mrigankp/fuzz4py/cpython/Lib/dbm/sqlite3.py", line 79, in _execute\n    return closing(self._cx.execute(*args, **kwargs))\n                   ~~~~~~~~~~~~~~~~^^^^^^^^^^^^^^^^^\nTraceback (most recent call last):\nException in thread Thread-61 (worker):\nsqlite3.ProgrammingError: SQLite objects created in a thread can only be used in that same thread. The object was created in thread id 124364096350016 and this is thread id 124363485480512.\n  File "/home/mrigankp/fuzz4py/cpython/Lib/dbm/sqlite3.py", line 79, in _execute\n    return closing(self._cx.execute(*args, **kwargs))\n                   ~~~~~~~~~~~~~~~~^^^^^^^^^^^^^^^^^\nsqlite3.ProgrammingError: SQLite objects created in a thread can only be used in that same thread. The object was created in thread id 124364096350016 and this is thread id 124363676321344.\nException in thread Thread-51 (worker):\n  File "/home/mrigankp/fuzz4py/cpython/Lib/dbm/sqlite3.py", line 79, in _execute\n    return closing(self._cx.execute(*args, **kwargs))\n                   ~~~~~~~~~~~~~~~~^^^^^^^^^^^^^^^^^\nException in thread Thread-63 (worker):\n  File "/home/mrigankp/fuzz4py/cpython/Lib/dbm/sqlite3.py", line 79, in _execute\n    return closing(self._cx.execute(*args, **kwargs))\n                   ~~~~~~~~~~~~~~~~^^^^^^^^^^^^^^^^^\nTraceback (most recent call last):\nException in thread Thread-64 (worker):\n  File "/home/mrigankp/fuzz4py/cpython/Lib/dbm/sqlite3.py", line 79, in _execute\n    return closing(self._cx.execute(*args, **kwargs))\n                   ~~~~~~~~~~~~~~~~^^^^^^^^^^^^^^^^^\nTraceback (most recent call last):\nsqlite3.ProgrammingError: SQLite objects created in a thread can only be used in that same thread. The object was created in thread id 124364096350016 and this is thread id 124364041225792.\nsqlite3.ProgrammingError: SQLite objects created in a thread can only be used in that same thread. The object was created in thread id 124364096350016 and this is thread id 124363305125440.\nTraceback (most recent call last):\nsqlite3.ProgrammingError: SQLite objects created in a thread can only be used in that same thread. The object was created in thread id 124364096350016 and this is thread id 124364009768512.\n  File "/home/mrigankp/fuzz4py/cpython/Lib/dbm/sqlite3.py", line 79, in _execute\n    return closing(self._cx.execute(*args, **kwargs))\n                   ~~~~~~~~~~~~~~~~^^^^^^^^^^^^^^^^^\nException in thread Thread-68 (worker):\n\nDuring handling of the above exception, another exception occurred:\n\nTraceback (most recent call last):\nException in thread Thread-69 (worker):\nTraceback (most recent call last):\nsqlite3.ProgrammingError: SQLite objects created in a thread can only be used in that same thread. The object was created in thread id 124364096350016 and this is thread id 124363888133696.\nTraceback (most recent call last):\nsqlite3.ProgrammingError: SQLite objects created in a thread can only be used in that same thread. The object was created in thread id 124364096350016 and this is thread id 124364020254272.\nException in thread Thread-70 (worker):\n  File "/home/mrigankp/fuzz4py/cpython/Lib/dbm/sqlite3.py", line 79, in _execute\n    return closing(self._cx.execute(*args, **kwargs))\n                   ~~~~~~~~~~~~~~~~^^^^^^^^^^^^^^^^^\nException in thread Thread-71 (worker):\nException in thread Thread-72 (worker):\nTraceback (most recent call last):\n  File "/home/mrigankp/fuzz4py/cpython/Lib/dbm/sqlite3.py", line 79, in _execute\n    return closing(self._cx.execute(*args, **kwargs))\n                   ~~~~~~~~~~~~~~~~^^^^^^^^^^^^^^^^^\nTraceback (most recent call last):\nsqlite3.ProgrammingError: SQLite objects created in a thread can only be used in that same thread. The object was created in thread id 124364096350016 and this is thread id 124363273668160.\nsqlite3.ProgrammingError: SQLite objects created in a thread can only be used in that same thread. The object was created in thread id 124364096350016 and this is thread id 124363114284608.\nException in thread Thread-34 (worker):\nException in thread Thread-60 (worker):\nException in thread Thread-75 (worker):\n  File "/home/mrigankp/fuzz4py/cpython/Lib/dbm/sqlite3.py", line 79, in _execute\n    return closing(self._cx.execute(*args, **kwargs))\n                   ~~~~~~~~~~~~~~~~^^^^^^^^^^^^^^^^^\nException in thread Thread-50 (worker):\nException in thread Thread-76 (worker):\nsqlite3.ProgrammingError: SQLite objects created in a thread can only be used in that same thread. The object was created in thread id 124364096350016 and this is thread id 124362902472256.\nTraceback (most recent call last):\n\nDuring handling of the above exception, another exception occurred:\n\nTraceback (most recent call last):\nException in thread Thread-78 (worker):\nException in thread Thread-79 (worker):\nException in thread Thread-52 (worker):\nsqlite3.ProgrammingError: SQLite objects created in a thread can only be used in that same thread. The object was created in thread id 124364096350016 and this is thread id 124362891986496.\nsqlite3.ProgrammingError: SQLite objects created in a thread can only be used in that same thread. The object was created in thread id 124364096350016 and this is thread id 124364051711552.\nsqlite3.ProgrammingError: SQLite objects created in a thread can only be used in that same thread. The object was created in thread id 124364096350016 and this is thread id 124363506452032.\n  File "/home/mrigankp/fuzz4py/cpython/Lib/threading.py", line 1041, in _bootstrap_inner\n    self.run()\n    ~~~~~~~~^^\nTraceback (most recent call last):\nException in thread Thread-66 (worker):\nException in thread Thread-54 (worker):\n\nDuring handling of the above exception, another exception occurred:\n\n\nDuring handling of the above exception, another exception occurred:\n\nException in thread Thread-67 (worker):\nsqlite3.ProgrammingError: SQLite objects created in a thread can only be used in that same thread. The object was created in thread id 124364096350016 and this is thread id 124363718264384.\nException in thread Thread-55 (worker):\nsqlite3.ProgrammingError: SQLite objects created in a thread can only be used in that same thread. The object was created in thread id 124364096350016 and this is thread id 124362871014976.\n  File "/home/mrigankp/fuzz4py/cpython/Lib/dbm/sqlite3.py", line 79, in _execute\n    return closing(self._cx.execute(*args, **kwargs))\n                   ~~~~~~~~~~~~~~~~^^^^^^^^^^^^^^^^^\nException in thread Thread-86 (worker):\nTraceback (most recent call last):\n  File "/home/mrigankp/fuzz4py/cpython/Lib/dbm/sqlite3.py", line 79, in _execute\n    return closing(self._cx.execute(*args, **kwargs))\n                   ~~~~~~~~~~~~~~~~^^^^^^^^^^^^^^^^^\nException in thread Thread-88 (worker):\nsqlite3.ProgrammingError: SQLite objects created in a thread can only be used in that same thread. The object was created in thread id 124364096350016 and this is thread id 124363284153920.\n  File "/home/mrigankp/fuzz4py/cpython/Lib/threading.py", line 1041, in _bootstrap_inner\n    self.run()\n    ~~~~~~~~^^\nException in thread Thread-89 (worker):\nTraceback (most recent call last):\n\nDuring handling of the above exception, another exception occurred:\n\n  File "/home/mrigankp/fuzz4py/cpython/Lib/dbm/sqlite3.py", line 79, in _execute\n    return closing(self._cx.execute(*args, **kwargs))\n                   ~~~~~~~~~~~~~~~~^^^^^^^^^^^^^^^^^\nTraceback (most recent call last):\nTraceback (most recent call last):\nTraceback (most recent call last):\nTraceback (most recent call last):\n  File "/home/mrigankp/fuzz4py/cpython/Lib/dbm/sqlite3.py", line 79, in _execute\n    return closing(self._cx.execute(*args, **kwargs))\n                   ~~~~~~~~~~~~~~~~^^^^^^^^^^^^^^^^^\nsqlite3.ProgrammingError: SQLite objects created in a thread can only be used in that same thread. The object was created in thread id 124364096350016 and this is thread id 124362680174144.\nException in thread Thread-73 (worker):\n  File "/home/mrigankp/fuzz4py/cpython/Lib/dbm/sqlite3.py", line 79, in _execute\n    return closing(self._cx.execute(*args, **kwargs))\n                   ~~~~~~~~~~~~~~~~^^^^^^^^^^^^^^^^^\nException in thread Thread-93 (worker):\n\nDuring handling of the above exception, another exception occurred:\n\nException in thread Thread-94 (worker):\nTraceback (most recent call last):\nTraceback (most recent call last):\nsqlite3.ProgrammingError: SQLite objects created in a thread can only be used in that same thread. The object was created in thread id 124364096350016 and this is thread id 124362669688384.\nTraceback (most recent call last):\nException in thread Thread-95 (worker):\n\nDuring handling of the above exception, another exception occurred:\n\n  File "/home/mrigankp/fuzz4py/cpython/Lib/dbm/sqlite3.py", line 79, in _execute\n    return closing(self._cx.execute(*args, **kwargs))\n                   ~~~~~~~~~~~~~~~~^^^^^^^^^^^^^^^^^\nsqlite3.ProgrammingError: SQLite objects created in a thread can only be used in that same thread. The object was created in thread id 124364096350016 and this is thread id 124363707778624.\nTraceback (most recent call last):\n  File "/home/mrigankp/fuzz4py/cpython/Lib/dbm/sqlite3.py", line 79, in _execute\n    return closing(self._cx.execute(*args, **kwargs))\n                   ~~~~~~~~~~~~~~~~^^^^^^^^^^^^^^^^^\nsqlite3.ProgrammingError: SQLite objects created in a thread can only be used in that same thread. The object was created in thread id 124364096350016 and this is thread id 124363093313088.\nTraceback (most recent call last):\nException in thread Thread-80 (worker):\nException in thread Thread-98 (worker):\nTraceback (most recent call last):\nException in thread Thread-65 (worker):\nException in thread Thread-99 (worker):\n\nDuring handling of the above exception, another exception occurred:\n\nTraceback (most recent call last):\n  File "/home/mrigankp/fuzz4py/cpython/Lib/dbm/sqlite3.py", line 79, in _execute\n    return closing(self._cx.execute(*args, **kwargs))\n                   ~~~~~~~~~~~~~~~~^^^^^^^^^^^^^^^^^\n  File "/home/mrigankp/fuzz4py/cpython/Lib/dbm/sqlite3.py", line 79, in _execute\n    return closing(self._cx.execute(*args, **kwargs))\n                   ~~~~~~~~~~~~~~~~^^^^^^^^^^^^^^^^^\nException in thread Thread-83 (worker):\nTraceback (most recent call last):\n  File "/home/mrigankp/fuzz4py/cpython/Lib/dbm/sqlite3.py", line 79, in _execute\n    return closing(self._cx.execute(*args, **kwargs))\n                   ~~~~~~~~~~~~~~~~^^^^^^^^^^^^^^^^^\nException in thread Thread-84 (worker):\nTraceback (most recent call last):\nException in thread Thread-85 (worker):\n\nDuring handling of the above exception, another exception occurred:\n\nTraceback (most recent call last):\n  File "/home/mrigankp/fuzz4py/cpython/Lib/dbm/sqlite3.py", line 79, in _execute\n    return closing(self._cx.execute(*args, **kwargs))\n                   ~~~~~~~~~~~~~~~~^^^^^^^^^^^^^^^^^\nTraceback (most recent call last):\nTraceback (most recent call last):\n  File "/home/mrigankp/fuzz4py/cpython/Lib/dbm/sqlite3.py", line 79, in _execute\n    return closing(self._cx.execute(*args, **kwargs))\n                   ~~~~~~~~~~~~~~~~^^^^^^^^^^^^^^^^^\n\nDuring handling of the above exception, another exception occurred:\n\n  File "/home/mrigankp/fuzz4py/cpython/Lib/threading.py", line 992, in run\n    self._target(*self._args, **self._kwargs)\n    ~~~~~~~~~~~~^^^^^^^^^^^^^^^^^^^^^^^^^^^^^\nTraceback (most recent call last):\n  File "/home/mrigankp/fuzz4py/cpython/Lib/dbm/sqlite3.py", line 79, in _execute\n    return closing(self._cx.execute(*args, **kwargs))\n                   ~~~~~~~~~~~~~~~~^^^^^^^^^^^^^^^^^\nsqlite3.ProgrammingError: SQLite objects created in a thread can only be used in that same thread. The object was created in thread id 124364096350016 and this is thread id 124363315611200.\nsqlite3.ProgrammingError: SQLite objects created in a thread can only be used in that same thread. The object was created in thread id 124364096350016 and this is thread id 124363909105216.\nsqlite3.ProgrammingError: SQLite objects created in a thread can only be used in that same thread. The object was created in thread id 124364096350016 and this is thread id 124362923443776.\n  File "/home/mrigankp/fuzz4py/cpython/Lib/dbm/sqlite3.py", line 79, in _execute\n    return closing(self._cx.execute(*args, **kwargs))\n                   ~~~~~~~~~~~~~~~~^^^^^^^^^^^^^^^^^\nException in thread Thread-91 (worker):\n  File "/home/mrigankp/fuzz4py/cpython/Lib/dbm/sqlite3.py", line 79, in _execute\n    return closing(self._cx.execute(*args, **kwargs))\n                   ~~~~~~~~~~~~~~~~^^^^^^^^^^^^^^^^^\nsqlite3.ProgrammingError: SQLite objects created in a thread can only be used in that same thread. The object was created in thread id 124364096350016 and this is thread id 124363495966272.\nException in thread Thread-92 (worker):\nException in thread Thread-59 (worker):\nTraceback (most recent call last):\nTraceback (most recent call last):\nTraceback (most recent call last):\nTraceback (most recent call last):\n  File "/home/mrigankp/fuzz4py/cpython/Lib/dbm/sqlite3.py", line 79, in _execute\n    return closing(self._cx.execute(*args, **kwargs))\n                   ~~~~~~~~~~~~~~~~^^^^^^^^^^^^^^^^^\nsqlite3.ProgrammingError: SQLite objects created in a thread can only be used in that same thread. The object was created in thread id 124364096350016 and this is thread id 124364062197312.\n  File "/home/mrigankp/fuzz4py/cpython/Lib/dbm/sqlite3.py", line 79, in _execute\n    return closing(self._cx.execute(*args, **kwargs))\n                   ~~~~~~~~~~~~~~~~^^^^^^^^^^^^^^^^^\nsqlite3.ProgrammingError: SQLite objects created in a thread can only be used in that same thread. The object was created in thread id 124364096350016 and this is thread id 124363898619456.\n  File "/home/mrigankp/fuzz4py/cpython/Lib/dbm/sqlite3.py", line 79, in _execute\n    return closing(self._cx.execute(*args, **kwargs))\n                   ~~~~~~~~~~~~~~~~^^^^^^^^^^^^^^^^^\nTraceback (most recent call last):\nTraceback (most recent call last):\n\nDuring handling of the above exception, another exception occurred:\n\nsqlite3.ProgrammingError: SQLite objects created in a thread can only be used in that same thread. The object was created in thread id 124364096350016 and this is thread id 124363326096960.\nException in thread Thread-96 (worker):\n  File "/home/mrigankp/fuzz4py/cpython/Lib/dbm/sqlite3.py", line 79, in _execute\n    return closing(self._cx.execute(*args, **kwargs))\n                   ~~~~~~~~~~~~~~~~^^^^^^^^^^^^^^^^^\nException in thread Thread-97 (worker):\nTraceback (most recent call last):\n\nDuring handling of the above exception, another exception occurred:\n\n  File "/home/mrigankp/fuzz4py/cpython/Lib/dbm/sqlite3.py", line 79, in _execute\n    return closing(self._cx.execute(*args, **kwargs))\n                   ~~~~~~~~~~~~~~~~^^^^^^^^^^^^^^^^^\nsqlite3.ProgrammingError: SQLite objects created in a thread can only be used in that same thread. The object was created in thread id 124364096350016 and this is thread id 124363294639680.\nTraceback (most recent call last):\nException in thread Thread-82 (worker):\nTraceback (most recent call last):\nException in thread Thread-100 (worker):\nTraceback (most recent call last):\nsqlite3.ProgrammingError: SQLite objects created in a thread can only be used in that same thread. The object was created in thread id 124364096350016 and this is thread id 124362881500736.\nTraceback (most recent call last):\nTraceback (most recent call last):\nsqlite3.ProgrammingError: SQLite objects created in a thread can only be used in that same thread. The object was created in thread id 124364096350016 and this is thread id 124362489333312.\n  File "/home/mrigankp/fuzz4py/cpython/Lib/dbm/sqlite3.py", line 79, in _execute\n    return closing(self._cx.execute(*args, **kwargs))\n                   ~~~~~~~~~~~~~~~~^^^^^^^^^^^^^^^^^\nsqlite3.ProgrammingError: SQLite objects created in a thread can only be used in that same thread. The object was created in thread id 124364096350016 and this is thread id 124363697292864.\nTraceback (most recent call last):\n  File "/home/mrigankp/fuzz4py/cpython/Lib/dbm/sqlite3.py", line 79, in _execute\n    return closing(self._cx.execute(*args, **kwargs))\n                   ~~~~~~~~~~~~~~~~^^^^^^^^^^^^^^^^^\nException in thread Thread-87 (worker):\n  File "/home/mrigankp/fuzz4py/cpython/Lib/threading.py", line 1041, in _bootstrap_inner\n    self.run()\n    ~~~~~~~~^^\n  File "/home/mrigankp/fuzz4py/cpython/Lib/threading.py", line 992, in run\n    self._target(*self._args, **self._kwargs)\n    ~~~~~~~~~~~~^^^^^^^^^^^^^^^^^^^^^^^^^^^^^\n  File "/home/mrigankp/fuzz4py/cpython/Lib/dbm/sqlite3.py", line 79, in _execute\n    return closing(self._cx.execute(*args, **kwargs))\n                   ~~~~~~~~~~~~~~~~^^^^^^^^^^^^^^^^^\nTraceback (most recent call last):\n  File "/home/mrigankp/fuzz4py/cpython/Lib/dbm/sqlite3.py", line 79, in _execute\n    return closing(self._cx.execute(*args, **kwargs))\n                   ~~~~~~~~~~~~~~~~^^^^^^^^^^^^^^^^^\nsqlite3.ProgrammingError: SQLite objects created in a thread can only be used in that same thread. The object was created in thread id 124364096350016 and this is thread id 124363728750144.\nTraceback (most recent call last):\nTraceback (most recent call last):\nException in thread Thread-90 (worker):\n  File "/home/mrigankp/fuzz4py/cpython/Lib/dbm/sqlite3.py", line 79, in _execute\n    return closing(self._cx.execute(*args, **kwargs))\n                   ~~~~~~~~~~~~~~~~^^^^^^^^^^^^^^^^^\n  File "/home/mrigankp/fuzz4py/cpython/Lib/dbm/sqlite3.py", line 79, in _execute\n    return closing(self._cx.execute(*args, **kwargs))\n                   ~~~~~~~~~~~~~~~~^^^^^^^^^^^^^^^^^\nTraceback (most recent call last):\nsqlite3.ProgrammingError: SQLite objects created in a thread can only be used in that same thread. The object was created in thread id 124364096350016 and this is thread id 124361885353536.\nTraceback (most recent call last):\n\nDuring handling of the above exception, another exception occurred:\n\nsqlite3.ProgrammingError: SQLite objects created in a thread can only be used in that same thread. The object was created in thread id 124364096350016 and this is thread id 124362298492480.\nTraceback (most recent call last):\nsqlite3.ProgrammingError: SQLite objects created in a thread can only be used in that same thread. The object was created in thread id 124364096350016 and this is thread id 124363527423552.\n  File "/home/mrigankp/fuzz4py/cpython/Lib/dbm/sqlite3.py", line 79, in _execute\n    return closing(self._cx.execute(*args, **kwargs))\n                   ~~~~~~~~~~~~~~~~^^^^^^^^^^^^^^^^^\nsqlite3.ProgrammingError: SQLite objects created in a thread can only be used in that same thread. The object was created in thread id 124364096350016 and this is thread id 124363516937792.\n  File "/home/mrigankp/fuzz4py/cpython/Lib/threading.py", line 1041, in _bootstrap_inner\n    self.run()\n    ~~~~~~~~^^\nsqlite3.ProgrammingError: SQLite objects created in a thread can only be used in that same thread. The object was created in thread id 124364096350016 and this is thread id 124362277520960.\n\nDuring handling of the above exception, another exception occurred:\n\n\nDuring handling of the above exception, another exception occurred:\n\nException in thread Thread-62 (worker):\nsqlite3.ProgrammingError: SQLite objects created in a thread can only be used in that same thread. The object was created in thread id 124364096350016 and this is thread id 124361704998464.\nTraceback (most recent call last):\n  File "/home/mrigankp/fuzz4py/cpython/Lib/dbm/sqlite3.py", line 79, in _execute\n    return closing(self._cx.execute(*args, **kwargs))\n                   ~~~~~~~~~~~~~~~~^^^^^^^^^^^^^^^^^\nTraceback (most recent call last):\n  File "/home/mrigankp/fuzz4py/cpython/Lib/dbm/sqlite3.py", line 79, in _execute\n    return closing(self._cx.execute(*args, **kwargs))\n                   ~~~~~~~~~~~~~~~~^^^^^^^^^^^^^^^^^\n\nDuring handling of the above exception, another exception occurred:\n\nTraceback (most recent call last):\nException in thread Thread-81 (worker):\nTraceback (most recent call last):\nTraceback (most recent call last):\nsqlite3.ProgrammingError: SQLite objects created in a thread can only be used in that same thread. The object was created in thread id 124364096350016 and this is thread id 124362499819072.\n\nDuring handling of the above exception, another exception occurred:\n\n  File "/home/mrigankp/fuzz4py/cpython/Lib/dbm/sqlite3.py", line 79, in _execute\n    return closing(self._cx.execute(*args, **kwargs))\n                   ~~~~~~~~~~~~~~~~^^^^^^^^^^^^^^^^^\n  File "/home/mrigankp/fuzz4py/cpython/Lib/dbm/sqlite3.py", line 79, in _execute\n    return closing(self._cx.execute(*args, **kwargs))\n                   ~~~~~~~~~~~~~~~~^^^^^^^^^^^^^^^^^\nTraceback (most recent call last):\nTraceback (most recent call last):\n  File "/home/mrigankp/fuzz4py/cpython/Lib/dbm/sqlite3.py", line 79, in _execute\n    return closing(self._cx.execute(*args, **kwargs))\n                   ~~~~~~~~~~~~~~~~^^^^^^^^^^^^^^^^^\nTraceback (most recent call last):\n  File "/home/mrigankp/fuzz4py/cpython/Lib/dbm/sqlite3.py", line 79, in _execute\n    return closing(self._cx.execute(*args, **kwargs))\n                   ~~~~~~~~~~~~~~~~^^^^^^^^^^^^^^^^^\n\nDuring handling of the above exception, another exception occurred:\n\n  File "/home/mrigankp/fuzz4py/cpython/Lib/threading.py", line 1041, in _bootstrap_inner\n    self.run()\n    ~~~~~~~~^^\nTraceback (most recent call last):\n\nDuring handling of the above exception, another exception occurred:\n\nsqlite3.ProgrammingError: SQLite objects created in a thread can only be used in that same thread. The object was created in thread id 124364096350016 and this is thread id 124363877647936.\nsqlite3.ProgrammingError: SQLite objects created in a thread can only be used in that same thread. The object was created in thread id 124364096350016 and this is thread id 124361916810816.\n\nDuring handling of the above exception, another exception occurred:\n\n\nDuring handling of the above exception, another exception occurred:\n\n  File "/home/mrigankp/fuzz4py/cpython/Lib/dbm/sqlite3.py", line 79, in _execute\n    return closing(self._cx.execute(*args, **kwargs))\n                   ~~~~~~~~~~~~~~~~^^^^^^^^^^^^^^^^^\nsqlite3.ProgrammingError: SQLite objects created in a thread can only be used in that same thread. The object was created in thread id 124364096350016 and this is thread id 124363072341568.\nTraceback (most recent call last):\n  File "/home/mrigankp/fuzz4py/fuzz4py/inputs/790.py", line 15, in worker\n    db[str(data)] = data * 2\n    ~~^^^^^^^^^^^\nsqlite3.ProgrammingError: SQLite objects created in a thread can only be used in that same thread. The object was created in thread id 124364096350016 and this is thread id 124362701145664.\nsqlite3.ProgrammingError: SQLite objects created in a thread can only be used in that same thread. The object was created in thread id 124364096350016 and this is thread id 124361906325056.\n  File "/home/mrigankp/fuzz4py/cpython/Lib/threading.py", line 1041, in _bootstrap_inner\n    self.run()\n    ~~~~~~~~^^\n\nDuring handling of the above exception, another exception occurred:\n\n\nDuring handling of the above exception, another exception occurred:\n\nTraceback (most recent call last):\n  File "/home/mrigankp/fuzz4py/cpython/Lib/dbm/sqlite3.py", line 79, in _execute\n    return closing(self._cx.execute(*args, **kwargs))\n                   ~~~~~~~~~~~~~~~~^^^^^^^^^^^^^^^^^\n  File "/home/mrigankp/fuzz4py/cpython/Lib/dbm/sqlite3.py", line 79, in _execute\n    return closing(self._cx.execute(*args, **kwargs))\n                   ~~~~~~~~~~~~~~~~^^^^^^^^^^^^^^^^^\n\nDuring handling of the above exception, another exception occurred:\n\n  File "/home/mrigankp/fuzz4py/cpython/Lib/dbm/sqlite3.py", line 79, in _execute\n    return closing(self._cx.execute(*args, **kwargs))\n                   ~~~~~~~~~~~~~~~~^^^^^^^^^^^^^^^^^\n  File "/home/mrigankp/fuzz4py/cpython/Lib/dbm/sqlite3.py", line 79, in _execute\n    return closing(self._cx.execute(*args, **kwargs))\n                   ~~~~~~~~~~~~~~~~^^^^^^^^^^^^^^^^^\nException in thread Thread-74 (worker):\n\nDuring handling of the above exception, another exception occurred:\n\nTraceback (most recent call last):\nTraceback (most recent call last):\n\nDuring handling of the above exception, another exception occurred:\n\nsqlite3.ProgrammingError: SQLite objects created in a thread can only be used in that same thread. The object was created in thread id 124364096350016 and this is thread id 124363103798848.\n\nDuring handling of the above exception, another exception occurred:\n\nTraceback (most recent call last):\n\nDuring handling of the above exception, another exception occurred:\n\n  File "/home/mrigankp/fuzz4py/cpython/Lib/threading.py", line 1041, in _bootstrap_inner\n    self.run()\n    ~~~~~~~~^^\nTraceback (most recent call last):\n  File "/home/mrigankp/fuzz4py/cpython/Lib/threading.py", line 1041, in _bootstrap_inner\n    self.run()\n    ~~~~~~~~^^\n  File "/home/mrigankp/fuzz4py/cpython/Lib/threading.py", line 1041, in _bootstrap_inner\n    self.run()\n    ~~~~~~~~^^\nsqlite3.ProgrammingError: SQLite objects created in a thread can only be used in that same thread. The object was created in thread id 124364096350016 and this is thread id 124362520790592.\nTraceback (most recent call last):\n  File "/home/mrigankp/fuzz4py/cpython/Lib/dbm/sqlite3.py", line 79, in _execute\n    return closing(self._cx.execute(*args, **kwargs))\n                   ~~~~~~~~~~~~~~~~^^^^^^^^^^^^^^^^^\n  File "/home/mrigankp/fuzz4py/cpython/Lib/dbm/sqlite3.py", line 79, in _execute\n    return closing(self._cx.execute(*args, **kwargs))\n                   ~~~~~~~~~~~~~~~~^^^^^^^^^^^^^^^^^\n\nDuring handling of the above exception, another exception occurred:\n\n  File "/home/mrigankp/fuzz4py/cpython/Lib/threading.py", line 992, in run\n    self._target(*self._args, **self._kwargs)\n    ~~~~~~~~~~~~^^^^^^^^^^^^^^^^^^^^^^^^^^^^^\n\nDuring handling of the above exception, another exception occurred:\n\nTraceback (most recent call last):\n  File "/home/mrigankp/fuzz4py/cpython/Lib/dbm/sqlite3.py", line 79, in _execute\n    return closing(self._cx.execute(*args, **kwargs))\n                   ~~~~~~~~~~~~~~~~^^^^^^^^^^^^^^^^^\nsqlite3.ProgrammingError: SQLite objects created in a thread can only be used in that same thread. The object was created in thread id 124364096350016 and this is thread id 124362107651648.\n  File "/home/mrigankp/fuzz4py/cpython/Lib/dbm/sqlite3.py", line 79, in _execute\n    return closing(self._cx.execute(*args, **kwargs))\n                   ~~~~~~~~~~~~~~~~^^^^^^^^^^^^^^^^^\n\nDuring handling of the above exception, another exception occurred:\n\nsqlite3.ProgrammingError: SQLite objects created in a thread can only be used in that same thread. The object was created in thread id 124364096350016 and this is thread id 124362076194368.\nsqlite3.ProgrammingError: SQLite objects created in a thread can only be used in that same thread. The object was created in thread id 124364096350016 and this is thread id 124362478847552.\n\nDuring handling of the above exception, another exception occurred:\n\nTraceback (most recent call last):\nTraceback (most recent call last):\n  File "/home/mrigankp/fuzz4py/cpython/Lib/dbm/sqlite3.py", line 79, in _execute\n    return closing(self._cx.execute(*args, **kwargs))\n                   ~~~~~~~~~~~~~~~~^^^^^^^^^^^^^^^^^\nTraceback (most recent call last):\n\nDuring handling of the above exception, another exception occurred:\n\nTraceback (most recent call last):\nsqlite3.ProgrammingError: SQLite objects created in a thread can only be used in that same thread. The object was created in thread id 124364096350016 and this is thread id 124362722117184.\nTraceback (most recent call last):\n  File "/home/mrigankp/fuzz4py/cpython/Lib/dbm/sqlite3.py", line 79, in _execute\n    return closing(self._cx.execute(*args, **kwargs))\n                   ~~~~~~~~~~~~~~~~^^^^^^^^^^^^^^^^^\n  File "/home/mrigankp/fuzz4py/cpython/Lib/dbm/sqlite3.py", line 79, in _execute\n    return closing(self._cx.execute(*args, **kwargs))\n                   ~~~~~~~~~~~~~~~~^^^^^^^^^^^^^^^^^\n\nDuring handling of the above exception, another exception occurred:\n\n\nDuring handling of the above exception, another exception occurred:\n\n  File "/home/mrigankp/fuzz4py/cpython/Lib/dbm/sqlite3.py", line 79, in _execute\n    return closing(self._cx.execute(*args, **kwargs))\n                   ~~~~~~~~~~~~~~~~^^^^^^^^^^^^^^^^^\nsqlite3.ProgrammingError: SQLite objects created in a thread can only be used in that same thread. The object was created in thread id 124364096350016 and this is thread id 124363686807104.\nTraceback (most recent call last):\nsqlite3.ProgrammingError: SQLite objects created in a thread can only be used in that same thread. The object was created in thread id 124364096350016 and this is thread id 124361895839296.\nsqlite3.ProgrammingError: SQLite objects created in a thread can only be used in that same thread. The object was created in thread id 124364096350016 and this is thread id 124362308978240.\n\nDuring handling of the above exception, another exception occurred:\n\nsqlite3.ProgrammingError: SQLite objects created in a thread can only be used in that same thread. The object was created in thread id 124364096350016 and this is thread id 124361874867776.\nsqlite3.ProgrammingError: SQLite objects created in a thread can only be used in that same thread. The object was created in thread id 124364096350016 and this is thread id 124361260402240.\nTraceback (most recent call last):\n\nDuring handling of the above exception, another exception occurred:\n\n  File "/home/mrigankp/fuzz4py/cpython/Lib/threading.py", line 1041, in _bootstrap_inner\n    self.run()\n    ~~~~~~~~^^\nsqlite3.ProgrammingError: SQLite objects created in a thread can only be used in that same thread. The object was created in thread id 124364096350016 and this is thread id 124361101018688.\n  File "/home/mrigankp/fuzz4py/cpython/Lib/dbm/sqlite3.py", line 79, in _execute\n    return closing(self._cx.execute(*args, **kwargs))\n                   ~~~~~~~~~~~~~~~~^^^^^^^^^^^^^^^^^\n  File "/home/mrigankp/fuzz4py/cpython/Lib/dbm/sqlite3.py", line 79, in _execute\n    return closing(self._cx.execute(*args, **kwargs))\n                   ~~~~~~~~~~~~~~~~^^^^^^^^^^^^^^^^^\n\nDuring handling of the above exception, another exception occurred:\n\n\nDuring handling of the above exception, another exception occurred:\n\nsqlite3.ProgrammingError: SQLite objects created in a thread can only be used in that same thread. The object was created in thread id 124364096350016 and this is thread id 124362267035200.\nException in thread Thread-77 (worker):\n  File "/home/mrigankp/fuzz4py/cpython/Lib/threading.py", line 1041, in _bootstrap_inner\n    self.run()\n    ~~~~~~~~^^\n  File "/home/mrigankp/fuzz4py/cpython/Lib/threading.py", line 992, in run\n    self._target(*self._args, **self._kwargs)\n    ~~~~~~~~~~~~^^^^^^^^^^^^^^^^^^^^^^^^^^^^^\n\nDuring handling of the above exception, another exception occurred:\n\n  File "/home/mrigankp/fuzz4py/cpython/Lib/threading.py", line 992, in run\n    self._target(*self._args, **self._kwargs)\n    ~~~~~~~~~~~~^^^^^^^^^^^^^^^^^^^^^^^^^^^^^\nsqlite3.ProgrammingError: SQLite objects created in a thread can only be used in that same thread. The object was created in thread id 124364096350016 and this is thread id 124363930076736.\n  File "/home/mrigankp/fuzz4py/cpython/Lib/dbm/sqlite3.py", line 79, in _execute\n    return closing(self._cx.execute(*args, **kwargs))\n                   ~~~~~~~~~~~~~~~~^^^^^^^^^^^^^^^^^\n  File "/home/mrigankp/fuzz4py/cpython/Lib/threading.py", line 1041, in _bootstrap_inner\n    self.run()\n    ~~~~~~~~^^\nsqlite3.ProgrammingError: SQLite objects created in a thread can only be used in that same thread. The object was created in thread id 124364096350016 and this is thread id 124361663055424.\nsqlite3.ProgrammingError: SQLite objects created in a thread can only be used in that same thread. The object was created in thread id 124364096350016 and this is thread id 124360910177856.\nTraceback (most recent call last):\n  File "/home/mrigankp/fuzz4py/fuzz4py/inputs/790.py", line 15, in worker\n    db[str(data)] = data * 2\n    ~~^^^^^^^^^^^\nTraceback (most recent call last):\nsqlite3.ProgrammingError: SQLite objects created in a thread can only be used in that same thread. The object was created in thread id 124364096350016 and this is thread id 124362097165888.\nTraceback (most recent call last):\n\nDuring handling of the above exception, another exception occurred:\n\nsqlite3.ProgrammingError: SQLite objects created in a thread can only be used in that same thread. The object was created in thread id 124364096350016 and this is thread id 124361493186112.\nTraceback (most recent call last):\n\nDuring handling of the above exception, another exception occurred:\n\n\nDuring handling of the above exception, another exception occurred:\n\nTraceback (most recent call last):\n  File "/home/mrigankp/fuzz4py/cpython/Lib/threading.py", line 992, in run\n    self._target(*self._args, **self._kwargs)\n    ~~~~~~~~~~~~^^^^^^^^^^^^^^^^^^^^^^^^^^^^^\n  File "/home/mrigankp/fuzz4py/cpython/Lib/threading.py", line 1041, in _bootstrap_inner\n    self.run()\n    ~~~~~~~~^^\nsqlite3.ProgrammingError: SQLite objects created in a thread can only be used in that same thread. The object was created in thread id 124364096350016 and this is thread id 124362468361792.\n  File "/home/mrigankp/fuzz4py/cpython/Lib/dbm/sqlite3.py", line 79, in _execute\n    return closing(self._cx.execute(*args, **kwargs))\n                   ~~~~~~~~~~~~~~~~^^^^^^^^^^^^^^^^^\nTraceback (most recent call last):\nsqlite3.ProgrammingError: SQLite objects created in a thread can only be used in that same thread. The object was created in thread id 124364096350016 and this is thread id 124362711631424.\n\nDuring handling of the above exception, another exception occurred:\n\nTraceback (most recent call last):\n  File "/home/mrigankp/fuzz4py/cpython/Lib/dbm/sqlite3.py", line 79, in _execute\n    return closing(self._cx.execute(*args, **kwargs))\n                   ~~~~~~~~~~~~~~~~^^^^^^^^^^^^^^^^^\n  File "/home/mrigankp/fuzz4py/cpython/Lib/threading.py", line 1041, in _bootstrap_inner\n    self.run()\n    ~~~~~~~~^^\n\nDuring handling of the above exception, another exception occurred:\n\n\nDuring handling of the above exception, another exception occurred:\n\n  File "/home/mrigankp/fuzz4py/cpython/Lib/threading.py", line 992, in run\n    self._target(*self._args, **self._kwargs)\n    ~~~~~~~~~~~~^^^^^^^^^^^^^^^^^^^^^^^^^^^^^\nTraceback (most recent call last):\n\nDuring handling of the above exception, another exception occurred:\n\n  File "/home/mrigankp/fuzz4py/cpython/Lib/dbm/sqlite3.py", line 79, in _execute\n    return closing(self._cx.execute(*args, **kwargs))\n                   ~~~~~~~~~~~~~~~~^^^^^^^^^^^^^^^^^\n\nDuring handling of the above exception, another exception occurred:\n\n\nDuring handling of the above exception, another exception occurred:\n\nTraceback (most recent call last):\n\nDuring handling of the above exception, another exception occurred:\n\n  File "/home/mrigankp/fuzz4py/cpython/Lib/dbm/sqlite3.py", line 79, in _execute\n    return closing(self._cx.execute(*args, **kwargs))\n                   ~~~~~~~~~~~~~~~~^^^^^^^^^^^^^^^^^\nTraceback (most recent call last):\nTraceback (most recent call last):\n\nDuring handling of the above exception, another exception occurred:\n\n  File "/home/mrigankp/fuzz4py/cpython/Lib/threading.py", line 1041, in _bootstrap_inner\n    self.run()\n    ~~~~~~~~^^\nsqlite3.ProgrammingError: SQLite objects created in a thread can only be used in that same thread. The object was created in thread id 124364096350016 and this is thread id 124361111504448.\nTraceback (most recent call last):\nTraceback (most recent call last):\nTraceback (most recent call last):\nTraceback (most recent call last):\n  File "/home/mrigankp/fuzz4py/cpython/Lib/threading.py", line 992, in run\n    self._target(*self._args, **self._kwargs)\n    ~~~~~~~~~~~~^^^^^^^^^^^^^^^^^^^^^^^^^^^^^\n  File "/home/mrigankp/fuzz4py/cpython/Lib/dbm/sqlite3.py", line 79, in _execute\n    return closing(self._cx.execute(*args, **kwargs))\n                   ~~~~~~~~~~~~~~~~^^^^^^^^^^^^^^^^^\nsqlite3.ProgrammingError: SQLite objects created in a thread can only be used in that same thread. The object was created in thread id 124364096350016 and this is thread id 124362510304832.\nTraceback (most recent call last):\n\nDuring handling of the above exception, another exception occurred:\n\n  File "/home/mrigankp/fuzz4py/cpython/Lib/dbm/sqlite3.py", line 79, in _execute\n    return closing(self._cx.execute(*args, **kwargs))\n                   ~~~~~~~~~~~~~~~~^^^^^^^^^^^^^^^^^\nTraceback (most recent call last):\n  File "/home/mrigankp/fuzz4py/cpython/Lib/threading.py", line 992, in run\n    self._target(*self._args, **self._kwargs)\n    ~~~~~~~~~~~~^^^^^^^^^^^^^^^^^^^^^^^^^^^^^\n  File "/home/mrigankp/fuzz4py/cpython/Lib/dbm/sqlite3.py", line 79, in _execute\n    return closing(self._cx.execute(*args, **kwargs))\n                   ~~~~~~~~~~~~~~~~^^^^^^^^^^^^^^^^^\nTraceback (most recent call last):\nTraceback (most recent call last):\nsqlite3.ProgrammingError: SQLite objects created in a thread can only be used in that same thread. The object was created in thread id 124364096350016 and this is thread id 124361514157632.\nsqlite3.ProgrammingError: SQLite objects created in a thread can only be used in that same thread. The object was created in thread id 124364096350016 and this is thread id 124360899692096.\n\nDuring handling of the above exception, another exception occurred:\n\n  File "/home/mrigankp/fuzz4py/cpython/Lib/threading.py", line 1041, in _bootstrap_inner\n    self.run()\n    ~~~~~~~~^^\n  File "/home/mrigankp/fuzz4py/cpython/Lib/dbm/sqlite3.py", line 79, in _execute\n    return closing(self._cx.execute(*args, **kwargs))\n                   ~~~~~~~~~~~~~~~~^^^^^^^^^^^^^^^^^\n\nDuring handling of the above exception, another exception occurred:\n\n  File "/home/mrigankp/fuzz4py/cpython/Lib/threading.py", line 1041, in _bootstrap_inner\n    self.run()\n    ~~~~~~~~^^\n  File "/home/mrigankp/fuzz4py/cpython/Lib/threading.py", line 1041, in _bootstrap_inner\n    self.run()\n    ~~~~~~~~^^\nTraceback (most recent call last):\n  File "/home/mrigankp/fuzz4py/fuzz4py/inputs/790.py", line 15, in worker\n    db[str(data)] = data * 2\n    ~~^^^^^^^^^^^\n  File "/home/mrigankp/fuzz4py/cpython/Lib/threading.py", line 1041, in _bootstrap_inner\n    self.run()\n    ~~~~~~~~^^\n  File "/home/mrigankp/fuzz4py/cpython/Lib/threading.py", line 992, in run\n    self._target(*self._args, **self._kwargs)\n    ~~~~~~~~~~~~^^^^^^^^^^^^^^^^^^^^^^^^^^^^^\n  File "/home/mrigankp/fuzz4py/fuzz4py/inputs/790.py", line 15, in worker\n    db[str(data)] = data * 2\n    ~~^^^^^^^^^^^\nsqlite3.ProgrammingError: SQLite objects created in a thread can only be used in that same thread. The object was created in thread id 124364096350016 and this is thread id 124361461728832.\nsqlite3.ProgrammingError: SQLite objects created in a thread can only be used in that same thread. The object was created in thread id 124364096350016 and this is thread id 124361312831040.\n\nDuring handling of the above exception, another exception occurred:\n\nTraceback (most recent call last):\nsqlite3.ProgrammingError: SQLite objects created in a thread can only be used in that same thread. The object was created in thread id 124364096350016 and this is thread id 124362319464000.\nsqlite3.ProgrammingError: SQLite objects created in a thread can only be used in that same thread. The object was created in thread id 124364096350016 and this is thread id 124361291859520.\n  File "/home/mrigankp/fuzz4py/cpython/Lib/threading.py", line 992, in run\n    self._target(*self._args, **self._kwargs)\n    ~~~~~~~~~~~~^^^^^^^^^^^^^^^^^^^^^^^^^^^^^\nTraceback (most recent call last):\nTraceback (most recent call last):\nsqlite3.ProgrammingError: SQLite objects created in a thread can only be used in that same thread. The object was created in thread id 124364096350016 and this is thread id 124362690659904.\n  File "/home/mrigankp/fuzz4py/cpython/Lib/threading.py", line 1041, in _bootstrap_inner\n    self.run()\n    ~~~~~~~~^^\nsqlite3.ProgrammingError: SQLite objects created in a thread can only be used in that same thread. The object was created in thread id 124364096350016 and this is thread id 124362912958016.\nTraceback (most recent call last):\nTraceback (most recent call last):\nsqlite3.ProgrammingError: SQLite objects created in a thread can only be used in that same thread. The object was created in thread id 124364096350016 and this is thread id 124361864382016.\nTraceback (most recent call last):\nTraceback (most recent call last):\n  File "/home/mrigankp/fuzz4py/cpython/Lib/threading.py", line 992, in run\n    self._target(*self._args, **self._kwargs)\n    ~~~~~~~~~~~~^^^^^^^^^^^^^^^^^^^^^^^^^^^^^\n\nDuring handling of the above exception, another exception occurred:\n\n  File "/home/mrigankp/fuzz4py/cpython/Lib/threading.py", line 992, in run\n    self._target(*self._args, **self._kwargs)\n    ~~~~~~~~~~~~^^^^^^^^^^^^^^^^^^^^^^^^^^^^^\nTraceback (most recent call last):\n  File "/home/mrigankp/fuzz4py/cpython/Lib/threading.py", line 1041, in _bootstrap_inner\n    self.run()\n    ~~~~~~~~^^\n\nDuring handling of the above exception, another exception occurred:\n\nTraceback (most recent call last):\n  File "/home/mrigankp/fuzz4py/cpython/Lib/threading.py", line 1041, in _bootstrap_inner\n    self.run()\n    ~~~~~~~~^^\n  File "/home/mrigankp/fuzz4py/cpython/Lib/threading.py", line 992, in run\n    self._target(*self._args, **self._kwargs)\n    ~~~~~~~~~~~~^^^^^^^^^^^^^^^^^^^^^^^^^^^^^\n  File "/home/mrigankp/fuzz4py/fuzz4py/inputs/790.py", line 15, in worker\n    db[str(data)] = data * 2\n    ~~^^^^^^^^^^^\n  File "/home/mrigankp/fuzz4py/cpython/Lib/threading.py", line 1041, in _bootstrap_inner\n    self.run()\n    ~~~~~~~~^^\n  File "/home/mrigankp/fuzz4py/fuzz4py/inputs/790.py", line 15, in worker\n    db[str(data)] = data * 2\n    ~~^^^^^^^^^^^\n  File "/home/mrigankp/fuzz4py/cpython/Lib/threading.py", line 1041, in _bootstrap_inner\n    self.run()\n    ~~~~~~~~^^\nsqlite3.ProgrammingError: SQLite objects created in a thread can only be used in that same thread. The object was created in thread id 124364096350016 and this is thread id 124361080047168.\n  File "/home/mrigankp/fuzz4py/fuzz4py/inputs/790.py", line 15, in worker\n    db[str(data)] = data * 2\n    ~~^^^^^^^^^^^\nTraceback (most recent call last):\nsqlite3.ProgrammingError: SQLite objects created in a thread can only be used in that same thread. The object was created in thread id 124364096350016 and this is thread id 124361673541184.\nTraceback (most recent call last):\n\nDuring handling of the above exception, another exception occurred:\n\nTraceback (most recent call last):\nsqlite3.ProgrammingError: SQLite objects created in a thread can only be used in that same thread. The object was created in thread id 124364096350016 and this is thread id 124361059075648.\n  File "/home/mrigankp/fuzz4py/cpython/Lib/dbm/sqlite3.py", line 96, in __setitem__\n    self._execute(STORE_KV, (key, value))\n    ~~~~~~~~~~~~~^^^^^^^^^^^^^^^^^^^^^^^^\n\nDuring handling of the above exception, another exception occurred:\n\n  File "/home/mrigankp/fuzz4py/cpython/Lib/dbm/sqlite3.py", line 79, in _execute\n    return closing(self._cx.execute(*args, **kwargs))\n                   ~~~~~~~~~~~~~~~~^^^^^^^^^^^^^^^^^\n  File "/home/mrigankp/fuzz4py/cpython/Lib/dbm/sqlite3.py", line 79, in _execute\n    return closing(self._cx.execute(*args, **kwargs))\n                   ~~~~~~~~~~~~~~~~^^^^^^^^^^^^^^^^^\n  File "/home/mrigankp/fuzz4py/cpython/Lib/threading.py", line 992, in run\n    self._target(*self._args, **self._kwargs)\n    ~~~~~~~~~~~~^^^^^^^^^^^^^^^^^^^^^^^^^^^^^\n\nDuring handling of the above exception, another exception occurred:\n\nTraceback (most recent call last):\nsqlite3.ProgrammingError: SQLite objects created in a thread can only be used in that same thread. The object was created in thread id 124364096350016 and this is thread id 124362065708608.\n  File "/home/mrigankp/fuzz4py/cpython/Lib/dbm/sqlite3.py", line 79, in _execute\n    return closing(self._cx.execute(*args, **kwargs))\n                   ~~~~~~~~~~~~~~~~^^^^^^^^^^^^^^^^^\nTraceback (most recent call last):\n  File "/home/mrigankp/fuzz4py/cpython/Lib/threading.py", line 1041, in _bootstrap_inner\n    self.run()\n    ~~~~~~~~^^\n  File "/home/mrigankp/fuzz4py/cpython/Lib/threading.py", line 1041, in _bootstrap_inner\n    self.run()\n    ~~~~~~~~^^\n  File "/home/mrigankp/fuzz4py/cpython/Lib/threading.py", line 992, in run\n    self._target(*self._args, **self._kwargs)\n    ~~~~~~~~~~~~^^^^^^^^^^^^^^^^^^^^^^^^^^^^^\n\nDuring handling of the above exception, another exception occurred:\n\n  File "/home/mrigankp/fuzz4py/cpython/Lib/dbm/sqlite3.py", line 96, in __setitem__\n    self._execute(STORE_KV, (key, value))\n    ~~~~~~~~~~~~~^^^^^^^^^^^^^^^^^^^^^^^^\n  File "/home/mrigankp/fuzz4py/cpython/Lib/threading.py", line 1041, in _bootstrap_inner\n    self.run()\n    ~~~~~~~~^^\n\nDuring handling of the above exception, another exception occurred:\n\n  File "/home/mrigankp/fuzz4py/cpython/Lib/threading.py", line 1041, in _bootstrap_inner\n    self.run()\n    ~~~~~~~~^^\nsqlite3.ProgrammingError: SQLite objects created in a thread can only be used in that same thread. The object was created in thread id 124364096350016 and this is thread id 124361302345280.\n\nDuring handling of the above exception, another exception occurred:\n\nTraceback (most recent call last):\nTraceback (most recent call last):\n  File "/home/mrigankp/fuzz4py/fuzz4py/inputs/790.py", line 15, in worker\n    db[str(data)] = data * 2\n    ~~^^^^^^^^^^^\n  File "/home/mrigankp/fuzz4py/cpython/Lib/threading.py", line 1041, in _bootstrap_inner\n    self.run()\n    ~~~~~~~~^^\n\nDuring handling of the above exception, another exception occurred:\n\n  File "/home/mrigankp/fuzz4py/cpython/Lib/threading.py", line 992, in run\n    self._target(*self._args, **self._kwargs)\n    ~~~~~~~~~~~~^^^^^^^^^^^^^^^^^^^^^^^^^^^^^\n  File "/home/mrigankp/fuzz4py/fuzz4py/inputs/790.py", line 15, in worker\n    db[str(data)] = data * 2\n    ~~^^^^^^^^^^^\nTraceback (most recent call last):\n\nDuring handling of the above exception, another exception occurred:\n\nTraceback (most recent call last):\n  File "/home/mrigankp/fuzz4py/cpython/Lib/threading.py", line 1041, in _bootstrap_inner\n    self.run()\n    ~~~~~~~~^^\n  File "/home/mrigankp/fuzz4py/cpython/Lib/threading.py", line 1041, in _bootstrap_inner\n    self.run()\n    ~~~~~~~~^^\n  File "/home/mrigankp/fuzz4py/cpython/Lib/threading.py", line 1041, in _bootstrap_inner\n    self.run()\n    ~~~~~~~~^^\n  File "/home/mrigankp/fuzz4py/fuzz4py/inputs/790.py", line 15, in worker\n    db[str(data)] = data * 2\n    ~~^^^^^^^^^^^\n  File "/home/mrigankp/fuzz4py/cpython/Lib/threading.py", line 1041, in _bootstrap_inner\n    self.run()\n    ~~~~~~~~^^\nTraceback (most recent call last):\nsqlite3.ProgrammingError: SQLite objects created in a thread can only be used in that same thread. The object was created in thread id 124364096350016 and this is thread id 124361090532928.\n\nDuring handling of the above exception, another exception occurred:\n\nTraceback (most recent call last):\n\nDuring handling of the above exception, another exception occurred:\n\n  File "/home/mrigankp/fuzz4py/fuzz4py/inputs/790.py", line 15, in worker\n    db[str(data)] = data * 2\n    ~~^^^^^^^^^^^\n  File "/home/mrigankp/fuzz4py/cpython/Lib/dbm/sqlite3.py", line 96, in __setitem__\n    self._execute(STORE_KV, (key, value))\n    ~~~~~~~~~~~~~^^^^^^^^^^^^^^^^^^^^^^^^\n  File "/home/mrigankp/fuzz4py/cpython/Lib/threading.py", line 992, in run\n    self._target(*self._args, **self._kwargs)\n    ~~~~~~~~~~~~^^^^^^^^^^^^^^^^^^^^^^^^^^^^^\n\nDuring handling of the above exception, another exception occurred:\n\n  File "/home/mrigankp/fuzz4py/cpython/Lib/dbm/sqlite3.py", line 96, in __setitem__\n    self._execute(STORE_KV, (key, value))\n    ~~~~~~~~~~~~~^^^^^^^^^^^^^^^^^^^^^^^^\nsqlite3.ProgrammingError: SQLite objects created in a thread can only be used in that same thread. The object was created in thread id 124364096350016 and this is thread id 124361069561408.\n\nDuring handling of the above exception, another exception occurred:\n\n  File "/home/mrigankp/fuzz4py/cpython/Lib/threading.py", line 1041, in _bootstrap_inner\n    self.run()\n    ~~~~~~~~^^\n\nDuring handling of the above exception, another exception occurred:\n\n  File "/home/mrigankp/fuzz4py/cpython/Lib/threading.py", line 1041, in _bootstrap_inner\n    self.run()\n    ~~~~~~~~^^\n  File "/home/mrigankp/fuzz4py/cpython/Lib/threading.py", line 992, in run\n    self._target(*self._args, **self._kwargs)\n    ~~~~~~~~~~~~^^^^^^^^^^^^^^^^^^^^^^^^^^^^^\n\nDuring handling of the above exception, another exception occurred:\n\n  File "/home/mrigankp/fuzz4py/cpython/Lib/threading.py", line 1041, in _bootstrap_inner\n    self.run()\n    ~~~~~~~~^^\n  File "/home/mrigankp/fuzz4py/cpython/Lib/dbm/sqlite3.py", line 79, in _execute\n    return closing(self._cx.execute(*args, **kwargs))\n                   ~~~~~~~~~~~~~~~~^^^^^^^^^^^^^^^^^\nTraceback (most recent call last):\nTraceback (most recent call last):\n  File "/home/mrigankp/fuzz4py/fuzz4py/inputs/790.py", line 15, in worker\n    db[str(data)] = data * 2\n    ~~^^^^^^^^^^^\nTraceback (most recent call last):\nTraceback (most recent call last):\n\nDuring handling of the above exception, another exception occurred:\n\n  File "/home/mrigankp/fuzz4py/cpython/Lib/threading.py", line 992, in run\n    self._target(*self._args, **self._kwargs)\n    ~~~~~~~~~~~~^^^^^^^^^^^^^^^^^^^^^^^^^^^^^\n  File "/home/mrigankp/fuzz4py/fuzz4py/inputs/790.py", line 15, in worker\n    db[str(data)] = data * 2\n    ~~^^^^^^^^^^^\n  File "/home/mrigankp/fuzz4py/cpython/Lib/dbm/sqlite3.py", line 96, in __setitem__\n    self._execute(STORE_KV, (key, value))\n    ~~~~~~~~~~~~~^^^^^^^^^^^^^^^^^^^^^^^^\n  File "/home/mrigankp/fuzz4py/fuzz4py/inputs/790.py", line 15, in worker\n    db[str(data)] = data * 2\n    ~~^^^^^^^^^^^\n  File "/home/mrigankp/fuzz4py/fuzz4py/inputs/790.py", line 15, in worker\n    db[str(data)] = data * 2\n    ~~^^^^^^^^^^^\nTraceback (most recent call last):\n  File "/home/mrigankp/fuzz4py/cpython/Lib/threading.py", line 992, in run\n    self._target(*self._args, **self._kwargs)\n    ~~~~~~~~~~~~^^^^^^^^^^^^^^^^^^^^^^^^^^^^^\nTraceback (most recent call last):\n\nDuring handling of the above exception, another exception occurred:\n\n  File "/home/mrigankp/fuzz4py/cpython/Lib/threading.py", line 992, in run\n    self._target(*self._args, **self._kwargs)\n    ~~~~~~~~~~~~^^^^^^^^^^^^^^^^^^^^^^^^^^^^^\n\nDuring handling of the above exception, another exception occurred:\n\nTraceback (most recent call last):\n  File "/home/mrigankp/fuzz4py/fuzz4py/inputs/790.py", line 15, in worker\n    db[str(data)] = data * 2\n    ~~^^^^^^^^^^^\n  File "/home/mrigankp/fuzz4py/cpython/Lib/threading.py", line 1041, in _bootstrap_inner\n    self.run()\n    ~~~~~~~~^^\n  File "/home/mrigankp/fuzz4py/cpython/Lib/threading.py", line 1041, in _bootstrap_inner\n    self.run()\n    ~~~~~~~~^^\nTraceback (most recent call last):\n  File "/home/mrigankp/fuzz4py/cpython/Lib/dbm/sqlite3.py", line 96, in __setitem__\n    self._execute(STORE_KV, (key, value))\n    ~~~~~~~~~~~~~^^^^^^^^^^^^^^^^^^^^^^^^\n\nDuring handling of the above exception, another exception occurred:\n\n\nDuring handling of the above exception, another exception occurred:\n\nTraceback (most recent call last):\n  File "/home/mrigankp/fuzz4py/cpython/Lib/threading.py", line 1041, in _bootstrap_inner\n    self.run()\n    ~~~~~~~~^^\n  File "/home/mrigankp/fuzz4py/cpython/Lib/threading.py", line 1041, in _bootstrap_inner\n    self.run()\n    ~~~~~~~~^^\n  File "/home/mrigankp/fuzz4py/cpython/Lib/threading.py", line 992, in run\n    self._target(*self._args, **self._kwargs)\n    ~~~~~~~~~~~~^^^^^^^^^^^^^^^^^^^^^^^^^^^^^\n  File "/home/mrigankp/fuzz4py/cpython/Lib/dbm/sqlite3.py", line 96, in __setitem__\n    self._execute(STORE_KV, (key, value))\n    ~~~~~~~~~~~~~^^^^^^^^^^^^^^^^^^^^^^^^\n  File "/home/mrigankp/fuzz4py/cpython/Lib/threading.py", line 992, in run\n    self._target(*self._args, **self._kwargs)\n    ~~~~~~~~~~~~^^^^^^^^^^^^^^^^^^^^^^^^^^^^^\n  File "/home/mrigankp/fuzz4py/fuzz4py/inputs/790.py", line 15, in worker\n    db[str(data)] = data * 2\n    ~~^^^^^^^^^^^\n  File "/home/mrigankp/fuzz4py/cpython/Lib/threading.py", line 992, in run\n    self._target(*self._args, **self._kwargs)\n    ~~~~~~~~~~~~^^^^^^^^^^^^^^^^^^^^^^^^^^^^^\n  File "/home/mrigankp/fuzz4py/cpython/Lib/threading.py", line 992, in run\n    self._target(*self._args, **self._kwargs)\n    ~~~~~~~~~~~~^^^^^^^^^^^^^^^^^^^^^^^^^^^^^\n  File "/home/mrigankp/fuzz4py/cpython/Lib/dbm/sqlite3.py", line 79, in _execute\n    return closing(self._cx.execute(*args, **kwargs))\n                   ~~~~~~~~~~~~~~~~^^^^^^^^^^^^^^^^^\nTraceback (most recent call last):\n  File "/home/mrigankp/fuzz4py/cpython/Lib/threading.py", line 992, in run\n    self._target(*self._args, **self._kwargs)\n    ~~~~~~~~~~~~^^^^^^^^^^^^^^^^^^^^^^^^^^^^^\n  File "/home/mrigankp/fuzz4py/cpython/Lib/dbm/sqlite3.py", line 81, in _execute\n    raise error(str(exc))\n  File "/home/mrigankp/fuzz4py/cpython/Lib/threading.py", line 992, in run\n    self._target(*self._args, **self._kwargs)\n    ~~~~~~~~~~~~^^^^^^^^^^^^^^^^^^^^^^^^^^^^^\n\nDuring handling of the above exception, another exception occurred:\n\n\nDuring handling of the above exception, another exception occurred:\n\nTraceback (most recent call last):\n  File "/home/mrigankp/fuzz4py/cpython/Lib/dbm/sqlite3.py", line 81, in _execute\n    raise error(str(exc))\n  File "/home/mrigankp/fuzz4py/cpython/Lib/dbm/sqlite3.py", line 79, in _execute\n    return closing(self._cx.execute(*args, **kwargs))\n                   ~~~~~~~~~~~~~~~~^^^^^^^^^^^^^^^^^\n  File "/home/mrigankp/fuzz4py/fuzz4py/inputs/790.py", line 15, in worker\n    db[str(data)] = data * 2\n    ~~^^^^^^^^^^^\n  File "/home/mrigankp/fuzz4py/cpython/Lib/threading.py", line 1041, in _bootstrap_inner\n    self.run()\n    ~~~~~~~~^^\n  File "/home/mrigankp/fuzz4py/cpython/Lib/threading.py", line 992, in run\n    self._target(*self._args, **self._kwargs)\n    ~~~~~~~~~~~~^^^^^^^^^^^^^^^^^^^^^^^^^^^^^\n  File "/home/mrigankp/fuzz4py/fuzz4py/inputs/790.py", line 15, in worker\n    db[str(data)] = data * 2\n    ~~^^^^^^^^^^^\nTraceback (most recent call last):\nsqlite3.ProgrammingError: SQLite objects created in a thread can only be used in that same thread. The object was created in thread id 124364096350016 and this is thread id 124363082827328.\nsqlite3.ProgrammingError: SQLite objects created in a thread can only be used in that same thread. The object was created in thread id 124364096350016 and this is thread id 124360889206336.\n  File "/home/mrigankp/fuzz4py/cpython/Lib/dbm/sqlite3.py", line 96, in __setitem__\n    self._execute(STORE_KV, (key, value))\n    ~~~~~~~~~~~~~^^^^^^^^^^^^^^^^^^^^^^^^\nTraceback (most recent call last):\n  File "/home/mrigankp/fuzz4py/cpython/Lib/threading.py", line 1041, in _bootstrap_inner\n    self.run()\n    ~~~~~~~~^^\n  File "/home/mrigankp/fuzz4py/cpython/Lib/threading.py", line 1041, in _bootstrap_inner\n    self.run()\n    ~~~~~~~~^^\nTraceback (most recent call last):\n  File "/home/mrigankp/fuzz4py/cpython/Lib/dbm/sqlite3.py", line 96, in __setitem__\n    self._execute(STORE_KV, (key, value))\n    ~~~~~~~~~~~~~^^^^^^^^^^^^^^^^^^^^^^^^\n  File "/home/mrigankp/fuzz4py/cpython/Lib/dbm/sqlite3.py", line 81, in _execute\n    raise error(str(exc))\nTraceback (most recent call last):\n  File "/home/mrigankp/fuzz4py/cpython/Lib/dbm/sqlite3.py", line 96, in __setitem__\n    self._execute(STORE_KV, (key, value))\n    ~~~~~~~~~~~~~^^^^^^^^^^^^^^^^^^^^^^^^\n  File "/home/mrigankp/fuzz4py/cpython/Lib/dbm/sqlite3.py", line 81, in _execute\n    raise error(str(exc))\n  File "/home/mrigankp/fuzz4py/cpython/Lib/dbm/sqlite3.py", line 81, in _execute\n    raise error(str(exc))\n  File "/home/mrigankp/fuzz4py/fuzz4py/inputs/790.py", line 15, in worker\n    db[str(data)] = data * 2\n    ~~^^^^^^^^^^^\nTraceback (most recent call last):\n  File "/home/mrigankp/fuzz4py/cpython/Lib/threading.py", line 1041, in _bootstrap_inner\n    self.run()\n    ~~~~~~~~^^\n  File "/home/mrigankp/fuzz4py/cpython/Lib/threading.py", line 992, in run\n    self._target(*self._args, **self._kwargs)\n    ~~~~~~~~~~~~^^^^^^^^^^^^^^^^^^^^^^^^^^^^^\nTraceback (most recent call last):\n  File "/home/mrigankp/fuzz4py/cpython/Lib/threading.py", line 1041, in _bootstrap_inner\n    self.run()\n    ~~~~~~~~^^\n  File "/home/mrigankp/fuzz4py/cpython/Lib/threading.py", line 1041, in _bootstrap_inner\n    self.run()\n    ~~~~~~~~^^\n  File "/home/mrigankp/fuzz4py/cpython/Lib/dbm/sqlite3.py", line 96, in __setitem__\n    self._execute(STORE_KV, (key, value))\n    ~~~~~~~~~~~~~^^^^^^^^^^^^^^^^^^^^^^^^\nsqlite3.ProgrammingError: SQLite objects created in a thread can only be used in that same thread. The object was created in thread id 124364096350016 and this is thread id 124361270888000.\n  File "/home/mrigankp/fuzz4py/cpython/Lib/threading.py", line 992, in run\n    self._target(*self._args, **self._kwargs)\n    ~~~~~~~~~~~~^^^^^^^^^^^^^^^^^^^^^^^^^^^^^\n  File "/home/mrigankp/fuzz4py/cpython/Lib/dbm/sqlite3.py", line 81, in _execute\n    raise error(str(exc))\nTraceback (most recent call last):\n  File "/home/mrigankp/fuzz4py/cpython/Lib/threading.py", line 992, in run\n    self._target(*self._args, **self._kwargs)\n    ~~~~~~~~~~~~^^^^^^^^^^^^^^^^^^^^^^^^^^^^^\n  File "/home/mrigankp/fuzz4py/cpython/Lib/dbm/sqlite3.py", line 79, in _execute\n    return closing(self._cx.execute(*args, **kwargs))\n                   ~~~~~~~~~~~~~~~~^^^^^^^^^^^^^^^^^\n  File "/home/mrigankp/fuzz4py/cpython/Lib/threading.py", line 992, in run\n    self._target(*self._args, **self._kwargs)\n    ~~~~~~~~~~~~^^^^^^^^^^^^^^^^^^^^^^^^^^^^^\nsqlite3.ProgrammingError: SQLite objects created in a thread can only be used in that same thread. The object was created in thread id 124364096350016 and this is thread id 124362288006720.\n  File "/home/mrigankp/fuzz4py/cpython/Lib/dbm/sqlite3.py", line 81, in _execute\n    raise error(str(exc))\n  File "/home/mrigankp/fuzz4py/cpython/Lib/threading.py", line 1041, in _bootstrap_inner\n    self.run()\n    ~~~~~~~~^^\n  File "/home/mrigankp/fuzz4py/cpython/Lib/dbm/sqlite3.py", line 96, in __setitem__\n    self._execute(STORE_KV, (key, value))\n    ~~~~~~~~~~~~~^^^^^^^^^^^^^^^^^^^^^^^^\n  File "/home/mrigankp/fuzz4py/cpython/Lib/dbm/sqlite3.py", line 81, in _execute\n    raise error(str(exc))\n  File "/home/mrigankp/fuzz4py/cpython/Lib/threading.py", line 1041, in _bootstrap_inner\n    self.run()\n    ~~~~~~~~^^\n  File "/home/mrigankp/fuzz4py/cpython/Lib/threading.py", line 1041, in _bootstrap_inner\n    self.run()\n    ~~~~~~~~^^\n  File "/home/mrigankp/fuzz4py/cpython/Lib/dbm/sqlite3.py", line 96, in __setitem__\n    self._execute(STORE_KV, (key, value))\n    ~~~~~~~~~~~~~^^^^^^^^^^^^^^^^^^^^^^^^\n  File "/home/mrigankp/fuzz4py/fuzz4py/inputs/790.py", line 15, in worker\n    db[str(data)] = data * 2\n    ~~^^^^^^^^^^^\nsqlite3.ProgrammingError: SQLite objects created in a thread can only be used in that same thread. The object was created in thread id 124364096350016 and this is thread id 124361694512704.\n  File "/home/mrigankp/fuzz4py/fuzz4py/inputs/790.py", line 15, in worker\n    db[str(data)] = data * 2\n    ~~^^^^^^^^^^^\nTraceback (most recent call last):\nTraceback (most recent call last):\n  File "/home/mrigankp/fuzz4py/cpython/Lib/threading.py", line 1041, in _bootstrap_inner\n    self.run()\n    ~~~~~~~~^^\ndbm.sqlite3.error: SQLite objects created in a thread can only be used in that same thread. The object was created in thread id 124364096350016 and this is thread id 124363676321344.\nTraceback (most recent call last):\n  File "/home/mrigankp/fuzz4py/cpython/Lib/dbm/sqlite3.py", line 96, in __setitem__\n    self._execute(STORE_KV, (key, value))\n    ~~~~~~~~~~~~~^^^^^^^^^^^^^^^^^^^^^^^^\n  File "/home/mrigankp/fuzz4py/cpython/Lib/threading.py", line 992, in run\n    self._target(*self._args, **self._kwargs)\n    ~~~~~~~~~~~~^^^^^^^^^^^^^^^^^^^^^^^^^^^^^\n  File "/home/mrigankp/fuzz4py/cpython/Lib/dbm/sqlite3.py", line 81, in _execute\n    raise error(str(exc))\n  File "/home/mrigankp/fuzz4py/cpython/Lib/dbm/sqlite3.py", line 96, in __setitem__\n    self._execute(STORE_KV, (key, value))\n    ~~~~~~~~~~~~~^^^^^^^^^^^^^^^^^^^^^^^^\n  File "/home/mrigankp/fuzz4py/cpython/Lib/dbm/sqlite3.py", line 81, in _execute\n    raise error(str(exc))\n  File "/home/mrigankp/fuzz4py/cpython/Lib/threading.py", line 1041, in _bootstrap_inner\n    self.run()\n    ~~~~~~~~^^\n  File "/home/mrigankp/fuzz4py/cpython/Lib/threading.py", line 1041, in _bootstrap_inner\n    self.run()\n    ~~~~~~~~^^\n\nDuring handling of the above exception, another exception occurred:\n\n  File "/home/mrigankp/fuzz4py/cpython/Lib/dbm/sqlite3.py", line 81, in _execute\n    raise error(str(exc))\n  File "/home/mrigankp/fuzz4py/cpython/Lib/threading.py", line 992, in run\n    self._target(*self._args, **self._kwargs)\n    ~~~~~~~~~~~~^^^^^^^^^^^^^^^^^^^^^^^^^^^^^\n  File "/home/mrigankp/fuzz4py/cpython/Lib/threading.py", line 1041, in _bootstrap_inner\n    self.run()\n    ~~~~~~~~^^\n  File "/home/mrigankp/fuzz4py/cpython/Lib/threading.py", line 992, in run\n    self._target(*self._args, **self._kwargs)\n    ~~~~~~~~~~~~^^^^^^^^^^^^^^^^^^^^^^^^^^^^^\n  File "/home/mrigankp/fuzz4py/cpython/Lib/threading.py", line 992, in run\n    self._target(*self._args, **self._kwargs)\n    ~~~~~~~~~~~~^^^^^^^^^^^^^^^^^^^^^^^^^^^^^\nsqlite3.ProgrammingError: SQLite objects created in a thread can only be used in that same thread. The object was created in thread id 124364096350016 and this is thread id 124363124770368.\n  File "/home/mrigankp/fuzz4py/cpython/Lib/threading.py", line 992, in run\n    self._target(*self._args, **self._kwargs)\n    ~~~~~~~~~~~~^^^^^^^^^^^^^^^^^^^^^^^^^^^^^\n  File "/home/mrigankp/fuzz4py/fuzz4py/inputs/790.py", line 15, in worker\n    db[str(data)] = data * 2\n    ~~^^^^^^^^^^^\n\nDuring handling of the above exception, another exception occurred:\n\n  File "/home/mrigankp/fuzz4py/cpython/Lib/threading.py", line 1041, in _bootstrap_inner\n    self.run()\n    ~~~~~~~~^^\ndbm.sqlite3.error: SQLite objects created in a thread can only be used in that same thread. The object was created in thread id 124364096350016 and this is thread id 124362489333312.\ndbm.sqlite3.error: SQLite objects created in a thread can only be used in that same thread. The object was created in thread id 124364096350016 and this is thread id 124363474994752.\n  File "/home/mrigankp/fuzz4py/cpython/Lib/dbm/sqlite3.py", line 96, in __setitem__\n    self._execute(STORE_KV, (key, value))\n    ~~~~~~~~~~~~~^^^^^^^^^^^^^^^^^^^^^^^^\n  File "/home/mrigankp/fuzz4py/cpython/Lib/threading.py", line 1041, in _bootstrap_inner\n    self.run()\n    ~~~~~~~~^^\n\nDuring handling of the above exception, another exception occurred:\n\nTraceback (most recent call last):\n  File "/home/mrigankp/fuzz4py/cpython/Lib/threading.py", line 1041, in _bootstrap_inner\n    self.run()\n    ~~~~~~~~^^\n  File "/home/mrigankp/fuzz4py/cpython/Lib/threading.py", line 992, in run\n    self._target(*self._args, **self._kwargs)\n    ~~~~~~~~~~~~^^^^^^^^^^^^^^^^^^^^^^^^^^^^^\n  File "/home/mrigankp/fuzz4py/cpython/Lib/dbm/sqlite3.py", line 96, in __setitem__\n    self._execute(STORE_KV, (key, value))\n    ~~~~~~~~~~~~~^^^^^^^^^^^^^^^^^^^^^^^^\n  File "/home/mrigankp/fuzz4py/cpython/Lib/dbm/sqlite3.py", line 81, in _execute\n    raise error(str(exc))\n\nDuring handling of the above exception, another exception occurred:\n\n  File "/home/mrigankp/fuzz4py/fuzz4py/inputs/790.py", line 15, in worker\n    db[str(data)] = data * 2\n    ~~^^^^^^^^^^^\n  File "/home/mrigankp/fuzz4py/cpython/Lib/dbm/sqlite3.py", line 96, in __setitem__\n    self._execute(STORE_KV, (key, value))\n    ~~~~~~~~~~~~~^^^^^^^^^^^^^^^^^^^^^^^^\ndbm.sqlite3.error: SQLite objects created in a thread can only be used in that same thread. The object was created in thread id 124364096350016 and this is thread id 124362923443776.\nTraceback (most recent call last):\n  File "/home/mrigankp/fuzz4py/cpython/Lib/threading.py", line 992, in run\n    self._target(*self._args, **self._kwargs)\n    ~~~~~~~~~~~~^^^^^^^^^^^^^^^^^^^^^^^^^^^^^\n  File "/home/mrigankp/fuzz4py/cpython/Lib/threading.py", line 1041, in _bootstrap_inner\n    self.run()\n    ~~~~~~~~^^\nTraceback (most recent call last):\n  File "/home/mrigankp/fuzz4py/fuzz4py/inputs/790.py", line 15, in worker\n    db[str(data)] = data * 2\n    ~~^^^^^^^^^^^\n  File "/home/mrigankp/fuzz4py/cpython/Lib/dbm/sqlite3.py", line 96, in __setitem__\n    self._execute(STORE_KV, (key, value))\n    ~~~~~~~~~~~~~^^^^^^^^^^^^^^^^^^^^^^^^\nTraceback (most recent call last):\nTraceback (most recent call last):\n  File "/home/mrigankp/fuzz4py/fuzz4py/inputs/790.py", line 15, in worker\n    db[str(data)] = data * 2\n    ~~^^^^^^^^^^^\ndbm.sqlite3.error: SQLite objects created in a thread can only be used in that same thread. The object was created in thread id 124364096350016 and this is thread id 124363527423552.\n  File "/home/mrigankp/fuzz4py/cpython/Lib/threading.py", line 992, in run\n    self._target(*self._args, **self._kwargs)\n    ~~~~~~~~~~~~^^^^^^^^^^^^^^^^^^^^^^^^^^^^^\n  File "/home/mrigankp/fuzz4py/cpython/Lib/dbm/sqlite3.py", line 81, in _execute\n    raise error(str(exc))\ndbm.sqlite3.error: SQLite objects created in a thread can only be used in that same thread. The object was created in thread id 124364096350016 and this is thread id 124362902472256.\n  File "/home/mrigankp/fuzz4py/fuzz4py/inputs/790.py", line 15, in worker\n    db[str(data)] = data * 2\n    ~~^^^^^^^^^^^\n  File "/home/mrigankp/fuzz4py/cpython/Lib/dbm/sqlite3.py", line 96, in __setitem__\n    self._execute(STORE_KV, (key, value))\n    ~~~~~~~~~~~~~^^^^^^^^^^^^^^^^^^^^^^^^\n\nDuring handling of the above exception, another exception occurred:\n\nTraceback (most recent call last):\n  File "/home/mrigankp/fuzz4py/cpython/Lib/threading.py", line 992, in run\n    self._target(*self._args, **self._kwargs)\n    ~~~~~~~~~~~~^^^^^^^^^^^^^^^^^^^^^^^^^^^^^\nsqlite3.ProgrammingError: SQLite objects created in a thread can only be used in that same thread. The object was created in thread id 124364096350016 and this is thread id 124361503671872.\n\nDuring handling of the above exception, another exception occurred:\n\n  File "/home/mrigankp/fuzz4py/cpython/Lib/threading.py", line 1041, in _bootstrap_inner\n    self.run()\n    ~~~~~~~~^^\nTraceback (most recent call last):\n  File "/home/mrigankp/fuzz4py/fuzz4py/inputs/790.py", line 15, in worker\n    db[str(data)] = data * 2\n    ~~^^^^^^^^^^^\n  File "/home/mrigankp/fuzz4py/cpython/Lib/threading.py", line 992, in run\n    self._target(*self._args, **self._kwargs)\n    ~~~~~~~~~~~~^^^^^^^^^^^^^^^^^^^^^^^^^^^^^\n  File "/home/mrigankp/fuzz4py/fuzz4py/inputs/790.py", line 15, in worker\n    db[str(data)] = data * 2\n    ~~^^^^^^^^^^^\nsqlite3.ProgrammingError: SQLite objects created in a thread can only be used in that same thread. The object was created in thread id 124364096350016 and this is thread id 124361482700352.\n\nDuring handling of the above exception, another exception occurred:\n\nTraceback (most recent call last):\n  File "/home/mrigankp/fuzz4py/fuzz4py/inputs/790.py", line 15, in worker\n    db[str(data)] = data * 2\n    ~~^^^^^^^^^^^\n  File "/home/mrigankp/fuzz4py/cpython/Lib/dbm/sqlite3.py", line 96, in __setitem__\n    self._execute(STORE_KV, (key, value))\n    ~~~~~~~~~~~~~^^^^^^^^^^^^^^^^^^^^^^^^\n  File "/home/mrigankp/fuzz4py/cpython/Lib/threading.py", line 992, in run\n    self._target(*self._args, **self._kwargs)\n    ~~~~~~~~~~~~^^^^^^^^^^^^^^^^^^^^^^^^^^^^^\n  File "/home/mrigankp/fuzz4py/cpython/Lib/threading.py", line 1041, in _bootstrap_inner\n    self.run()\n    ~~~~~~~~^^\n\nDuring handling of the above exception, another exception occurred:\n\n  File "/home/mrigankp/fuzz4py/cpython/Lib/dbm/sqlite3.py", line 96, in __setitem__\n    self._execute(STORE_KV, (key, value))\n    ~~~~~~~~~~~~~^^^^^^^^^^^^^^^^^^^^^^^^\n  File "/home/mrigankp/fuzz4py/cpython/Lib/dbm/sqlite3.py", line 96, in __setitem__\n    self._execute(STORE_KV, (key, value))\n    ~~~~~~~~~~~~~^^^^^^^^^^^^^^^^^^^^^^^^\n  File "/home/mrigankp/fuzz4py/cpython/Lib/dbm/sqlite3.py", line 81, in _execute\n    raise error(str(exc))\n  File "/home/mrigankp/fuzz4py/cpython/Lib/threading.py", line 1041, in _bootstrap_inner\n    self.run()\n    ~~~~~~~~^^\n  File "/home/mrigankp/fuzz4py/cpython/Lib/threading.py", line 1041, in _bootstrap_inner\n    self.run()\n    ~~~~~~~~^^\n  File "/home/mrigankp/fuzz4py/cpython/Lib/dbm/sqlite3.py", line 81, in _execute\n    raise error(str(exc))\n  File "/home/mrigankp/fuzz4py/cpython/Lib/threading.py", line 992, in run\n    self._target(*self._args, **self._kwargs)\n    ~~~~~~~~~~~~^^^^^^^^^^^^^^^^^^^^^^^^^^^^^\n  File "/home/mrigankp/fuzz4py/fuzz4py/inputs/790.py", line 15, in worker\n    db[str(data)] = data * 2\n    ~~^^^^^^^^^^^\n  File "/home/mrigankp/fuzz4py/cpython/Lib/threading.py", line 992, in run\n    self._target(*self._args, **self._kwargs)\n    ~~~~~~~~~~~~^^^^^^^^^^^^^^^^^^^^^^^^^^^^^\n  File "/home/mrigankp/fuzz4py/cpython/Lib/threading.py", line 1041, in _bootstrap_inner\n    self.run()\n    ~~~~~~~~^^\n  File "/home/mrigankp/fuzz4py/cpython/Lib/threading.py", line 992, in run\n    self._target(*self._args, **self._kwargs)\n    ~~~~~~~~~~~~^^^^^^^^^^^^^^^^^^^^^^^^^^^^^\n\nDuring handling of the above exception, another exception occurred:\n\ndbm.sqlite3.error: SQLite objects created in a thread can only be used in that same thread. The object was created in thread id 124364096350016 and this is thread id 124364020254272.\n  File "/home/mrigankp/fuzz4py/cpython/Lib/threading.py", line 1041, in _bootstrap_inner\n    self.run()\n    ~~~~~~~~^^\n  File "/home/mrigankp/fuzz4py/cpython/Lib/threading.py", line 992, in run\n    self._target(*self._args, **self._kwargs)\n    ~~~~~~~~~~~~^^^^^^^^^^^^^^^^^^^^^^^^^^^^^\n  File "/home/mrigankp/fuzz4py/fuzz4py/inputs/790.py", line 15, in worker\n    db[str(data)] = data * 2\n    ~~^^^^^^^^^^^\n  File "/home/mrigankp/fuzz4py/cpython/Lib/threading.py", line 1041, in _bootstrap_inner\n    self.run()\n    ~~~~~~~~^^\n  File "/home/mrigankp/fuzz4py/cpython/Lib/threading.py", line 1041, in _bootstrap_inner\n    self.run()\n    ~~~~~~~~^^\n  File "/home/mrigankp/fuzz4py/cpython/Lib/threading.py", line 992, in run\n    self._target(*self._args, **self._kwargs)\n    ~~~~~~~~~~~~^^^^^^^^^^^^^^^^^^^^^^^^^^^^^\n  File "/home/mrigankp/fuzz4py/cpython/Lib/threading.py", line 1041, in _bootstrap_inner\n    self.run()\n    ~~~~~~~~^^\n  File "/home/mrigankp/fuzz4py/cpython/Lib/threading.py", line 992, in run\n    self._target(*self._args, **self._kwargs)\n    ~~~~~~~~~~~~^^^^^^^^^^^^^^^^^^^^^^^^^^^^^\ndbm.sqlite3.error: SQLite objects created in a thread can only be used in that same thread. The object was created in thread id 124364096350016 and this is thread id 124364030740032.\n  File "/home/mrigankp/fuzz4py/cpython/Lib/threading.py", line 1041, in _bootstrap_inner\n    self.run()\n    ~~~~~~~~^^\n  File "/home/mrigankp/fuzz4py/cpython/Lib/threading.py", line 1041, in _bootstrap_inner\n    self.run()\n    ~~~~~~~~^^\n  File "/home/mrigankp/fuzz4py/cpython/Lib/threading.py", line 1041, in _bootstrap_inner\n    self.run()\n    ~~~~~~~~^^\n  File "/home/mrigankp/fuzz4py/cpython/Lib/threading.py", line 992, in run\n    self._target(*self._args, **self._kwargs)\n    ~~~~~~~~~~~~^^^^^^^^^^^^^^^^^^^^^^^^^^^^^\n  File "/home/mrigankp/fuzz4py/fuzz4py/inputs/790.py", line 15, in worker\n    db[str(data)] = data * 2\n    ~~^^^^^^^^^^^\n  File "/home/mrigankp/fuzz4py/cpython/Lib/dbm/sqlite3.py", line 96, in __setitem__\n    self._execute(STORE_KV, (key, value))\n    ~~~~~~~~~~~~~^^^^^^^^^^^^^^^^^^^^^^^^\n  File "/home/mrigankp/fuzz4py/cpython/Lib/dbm/sqlite3.py", line 96, in __setitem__\n    self._execute(STORE_KV, (key, value))\n    ~~~~~~~~~~~~~^^^^^^^^^^^^^^^^^^^^^^^^\nTraceback (most recent call last):\n  File "/home/mrigankp/fuzz4py/cpython/Lib/threading.py", line 1041, in _bootstrap_inner\n    self.run()\n    ~~~~~~~~^^\n  File "/home/mrigankp/fuzz4py/cpython/Lib/dbm/sqlite3.py", line 79, in _execute\n    return closing(self._cx.execute(*args, **kwargs))\n                   ~~~~~~~~~~~~~~~~^^^^^^^^^^^^^^^^^\n  File "/home/mrigankp/fuzz4py/fuzz4py/inputs/790.py", line 15, in worker\n    db[str(data)] = data * 2\n    ~~^^^^^^^^^^^\n  File "/home/mrigankp/fuzz4py/cpython/Lib/dbm/sqlite3.py", line 96, in __setitem__\n    self._execute(STORE_KV, (key, value))\n    ~~~~~~~~~~~~~^^^^^^^^^^^^^^^^^^^^^^^^\n  File "/home/mrigankp/fuzz4py/cpython/Lib/threading.py", line 1041, in _bootstrap_inner\n    self.run()\n    ~~~~~~~~^^\n  File "/home/mrigankp/fuzz4py/cpython/Lib/threading.py", line 992, in run\n    self._target(*self._args, **self._kwargs)\n    ~~~~~~~~~~~~^^^^^^^^^^^^^^^^^^^^^^^^^^^^^\ndbm.sqlite3.error: SQLite objects created in a thread can only be used in that same thread. The object was created in thread id 124364096350016 and this is thread id 124364072683072.\n  File "/home/mrigankp/fuzz4py/cpython/Lib/dbm/sqlite3.py", line 81, in _execute\n    raise error(str(exc))\n  File "/home/mrigankp/fuzz4py/cpython/Lib/threading.py", line 1041, in _bootstrap_inner\n    self.run()\n    ~~~~~~~~^^\n\nDuring handling of the above exception, another exception occurred:\n\nsqlite3.ProgrammingError: SQLite objects created in a thread can only be used in that same thread. The object was created in thread id 124364096350016 and this is thread id 124362086680128.\n  File "/home/mrigankp/fuzz4py/cpython/Lib/threading.py", line 992, in run\n    self._target(*self._args, **self._kwargs)\n    ~~~~~~~~~~~~^^^^^^^^^^^^^^^^^^^^^^^^^^^^^\ndbm.sqlite3.error: SQLite objects created in a thread can only be used in that same thread. The object was created in thread id 124364096350016 and this is thread id 124363294639680.\n  File "/home/mrigankp/fuzz4py/cpython/Lib/threading.py", line 1041, in _bootstrap_inner\n    self.run()\n    ~~~~~~~~^^\nsqlite3.ProgrammingError: SQLite objects created in a thread can only be used in that same thread. The object was created in thread id 124364096350016 and this is thread id 124361472214592.\n  File "/home/mrigankp/fuzz4py/cpython/Lib/dbm/sqlite3.py", line 81, in _execute\n    raise error(str(exc))\n  File "/home/mrigankp/fuzz4py/fuzz4py/inputs/790.py", line 15, in worker\n    db[str(data)] = data * 2\n    ~~^^^^^^^^^^^\n  File "/home/mrigankp/fuzz4py/cpython/Lib/threading.py", line 992, in run\n    self._target(*self._args, **self._kwargs)\n    ~~~~~~~~~~~~^^^^^^^^^^^^^^^^^^^^^^^^^^^^^\ndbm.sqlite3.error: SQLite objects created in a thread can only be used in that same thread. The object was created in thread id 124364096350016 and this is thread id 124363305125440.\n  File "/home/mrigankp/fuzz4py/cpython/Lib/threading.py", line 1041, in _bootstrap_inner\n    self.run()\n    ~~~~~~~~^^\nTraceback (most recent call last):\n  File "/home/mrigankp/fuzz4py/cpython/Lib/dbm/sqlite3.py", line 81, in _execute\n    raise error(str(exc))\n  File "/home/mrigankp/fuzz4py/cpython/Lib/threading.py", line 992, in run\n    self._target(*self._args, **self._kwargs)\n    ~~~~~~~~~~~~^^^^^^^^^^^^^^^^^^^^^^^^^^^^^\n  File "/home/mrigankp/fuzz4py/cpython/Lib/threading.py", line 992, in run\n    self._target(*self._args, **self._kwargs)\n    ~~~~~~~~~~~~^^^^^^^^^^^^^^^^^^^^^^^^^^^^^\nsqlite3.ProgrammingError: SQLite objects created in a thread can only be used in that same thread. The object was created in thread id 124364096350016 and this is thread id 124361281373760.\ndbm.sqlite3.error: SQLite objects created in a thread can only be used in that same thread. The object was created in thread id 124364096350016 and this is thread id 124363877647936.\n  File "/home/mrigankp/fuzz4py/fuzz4py/inputs/790.py", line 15, in worker\n    db[str(data)] = data * 2\n    ~~^^^^^^^^^^^\n  File "/home/mrigankp/fuzz4py/cpython/Lib/dbm/sqlite3.py", line 96, in __setitem__\n    self._execute(STORE_KV, (key, value))\n    ~~~~~~~~~~~~~^^^^^^^^^^^^^^^^^^^^^^^^\n  File "/home/mrigankp/fuzz4py/fuzz4py/inputs/790.py", line 15, in worker\n    db[str(data)] = data * 2\n    ~~^^^^^^^^^^^\n  File "/home/mrigankp/fuzz4py/cpython/Lib/threading.py", line 992, in run\n    self._target(*self._args, **self._kwargs)\n    ~~~~~~~~~~~~^^^^^^^^^^^^^^^^^^^^^^^^^^^^^\n  File "/home/mrigankp/fuzz4py/fuzz4py/inputs/790.py", line 15, in worker\n    db[str(data)] = data * 2\n    ~~^^^^^^^^^^^\n  File "/home/mrigankp/fuzz4py/cpython/Lib/dbm/sqlite3.py", line 81, in _execute\n    raise error(str(exc))\n  File "/home/mrigankp/fuzz4py/cpython/Lib/dbm/sqlite3.py", line 81, in _execute\n    raise error(str(exc))\n  File "/home/mrigankp/fuzz4py/cpython/Lib/threading.py", line 992, in run\n    self._target(*self._args, **self._kwargs)\n    ~~~~~~~~~~~~^^^^^^^^^^^^^^^^^^^^^^^^^^^^^\n  File "/home/mrigankp/fuzz4py/cpython/Lib/dbm/sqlite3.py", line 96, in __setitem__\n    self._execute(STORE_KV, (key, value))\n    ~~~~~~~~~~~~~^^^^^^^^^^^^^^^^^^^^^^^^\n  File "/home/mrigankp/fuzz4py/cpython/Lib/threading.py", line 992, in run\n    self._target(*self._args, **self._kwargs)\n    ~~~~~~~~~~~~^^^^^^^^^^^^^^^^^^^^^^^^^^^^^\n  File "/home/mrigankp/fuzz4py/fuzz4py/inputs/790.py", line 15, in worker\n    db[str(data)] = data * 2\n    ~~^^^^^^^^^^^\n  File "/home/mrigankp/fuzz4py/cpython/Lib/threading.py", line 992, in run\n    self._target(*self._args, **self._kwargs)\n    ~~~~~~~~~~~~^^^^^^^^^^^^^^^^^^^^^^^^^^^^^\n  File "/home/mrigankp/fuzz4py/cpython/Lib/dbm/sqlite3.py", line 81, in _execute\n    raise error(str(exc))\n  File "/home/mrigankp/fuzz4py/fuzz4py/inputs/790.py", line 15, in worker\n    db[str(data)] = data * 2\n    ~~^^^^^^^^^^^\n  File "/home/mrigankp/fuzz4py/cpython/Lib/threading.py", line 992, in run\n    self._target(*self._args, **self._kwargs)\n    ~~~~~~~~~~~~^^^^^^^^^^^^^^^^^^^^^^^^^^^^^\n  File "/home/mrigankp/fuzz4py/cpython/Lib/threading.py", line 992, in run\n    self._target(*self._args, **self._kwargs)\n    ~~~~~~~~~~~~^^^^^^^^^^^^^^^^^^^^^^^^^^^^^\n  File "/home/mrigankp/fuzz4py/fuzz4py/inputs/790.py", line 15, in worker\n    db[str(data)] = data * 2\n    ~~^^^^^^^^^^^\n  File "/home/mrigankp/fuzz4py/cpython/Lib/threading.py", line 1041, in _bootstrap_inner\n    self.run()\n    ~~~~~~~~^^\n  File "/home/mrigankp/fuzz4py/cpython/Lib/dbm/sqlite3.py", line 96, in __setitem__\n    self._execute(STORE_KV, (key, value))\n    ~~~~~~~~~~~~~^^^^^^^^^^^^^^^^^^^^^^^^\n  File "/home/mrigankp/fuzz4py/cpython/Lib/dbm/sqlite3.py", line 81, in _execute\n    raise error(str(exc))\n  File "/home/mrigankp/fuzz4py/cpython/Lib/dbm/sqlite3.py", line 81, in _execute\n    raise error(str(exc))\n\nDuring handling of the above exception, another exception occurred:\n\n  File "/home/mrigankp/fuzz4py/cpython/Lib/dbm/sqlite3.py", line 81, in _execute\n    raise error(str(exc))\n  File "/home/mrigankp/fuzz4py/fuzz4py/inputs/790.py", line 15, in worker\n    db[str(data)] = data * 2\n    ~~^^^^^^^^^^^\n  File "/home/mrigankp/fuzz4py/cpython/Lib/threading.py", line 992, in run\n    self._target(*self._args, **self._kwargs)\n    ~~~~~~~~~~~~^^^^^^^^^^^^^^^^^^^^^^^^^^^^^\n\nDuring handling of the above exception, another exception occurred:\n\n  File "/home/mrigankp/fuzz4py/cpython/Lib/dbm/sqlite3.py", line 96, in __setitem__\n    self._execute(STORE_KV, (key, value))\n    ~~~~~~~~~~~~~^^^^^^^^^^^^^^^^^^^^^^^^\n  File "/home/mrigankp/fuzz4py/cpython/Lib/dbm/sqlite3.py", line 96, in __setitem__\n    self._execute(STORE_KV, (key, value))\n    ~~~~~~~~~~~~~^^^^^^^^^^^^^^^^^^^^^^^^\n  File "/home/mrigankp/fuzz4py/cpython/Lib/threading.py", line 992, in run\n    self._target(*self._args, **self._kwargs)\n    ~~~~~~~~~~~~^^^^^^^^^^^^^^^^^^^^^^^^^^^^^\n  File "/home/mrigankp/fuzz4py/cpython/Lib/threading.py", line 1041, in _bootstrap_inner\n    self.run()\n    ~~~~~~~~^^\nTraceback (most recent call last):\n  File "/home/mrigankp/fuzz4py/cpython/Lib/threading.py", line 992, in run\n    self._target(*self._args, **self._kwargs)\n    ~~~~~~~~~~~~^^^^^^^^^^^^^^^^^^^^^^^^^^^^^\n  File "/home/mrigankp/fuzz4py/fuzz4py/inputs/790.py", line 15, in worker\n    db[str(data)] = data * 2\n    ~~^^^^^^^^^^^\ndbm.sqlite3.error: SQLite objects created in a thread can only be used in that same thread. The object was created in thread id 124364096350016 and this is thread id 124364041225792.\n  File "/home/mrigankp/fuzz4py/cpython/Lib/threading.py", line 992, in run\n    self._target(*self._args, **self._kwargs)\n    ~~~~~~~~~~~~^^^^^^^^^^^^^^^^^^^^^^^^^^^^^\n  File "/home/mrigankp/fuzz4py/cpython/Lib/threading.py", line 992, in run\n    self._target(*self._args, **self._kwargs)\n    ~~~~~~~~~~~~^^^^^^^^^^^^^^^^^^^^^^^^^^^^^\n  File "/home/mrigankp/fuzz4py/cpython/Lib/dbm/sqlite3.py", line 96, in __setitem__\n    self._execute(STORE_KV, (key, value))\n    ~~~~~~~~~~~~~^^^^^^^^^^^^^^^^^^^^^^^^\ndbm.sqlite3.error: SQLite objects created in a thread can only be used in that same thread. The object was created in thread id 124364096350016 and this is thread id 124363718264384.\n  File "/home/mrigankp/fuzz4py/cpython/Lib/threading.py", line 992, in run\n    self._target(*self._args, **self._kwargs)\n    ~~~~~~~~~~~~^^^^^^^^^^^^^^^^^^^^^^^^^^^^^\n  File "/home/mrigankp/fuzz4py/cpython/Lib/threading.py", line 1041, in _bootstrap_inner\n    self.run()\n    ~~~~~~~~^^\n  File "/home/mrigankp/fuzz4py/cpython/Lib/threading.py", line 992, in run\n    self._target(*self._args, **self._kwargs)\n    ~~~~~~~~~~~~^^^^^^^^^^^^^^^^^^^^^^^^^^^^^\n  File "/home/mrigankp/fuzz4py/fuzz4py/inputs/790.py", line 15, in worker\n    db[str(data)] = data * 2\n    ~~^^^^^^^^^^^\n  File "/home/mrigankp/fuzz4py/cpython/Lib/threading.py", line 992, in run\n    self._target(*self._args, **self._kwargs)\n    ~~~~~~~~~~~~^^^^^^^^^^^^^^^^^^^^^^^^^^^^^\n  File "/home/mrigankp/fuzz4py/cpython/Lib/dbm/sqlite3.py", line 96, in __setitem__\n    self._execute(STORE_KV, (key, value))\n    ~~~~~~~~~~~~~^^^^^^^^^^^^^^^^^^^^^^^^\nTraceback (most recent call last):\n  File "/home/mrigankp/fuzz4py/cpython/Lib/dbm/sqlite3.py", line 96, in __setitem__\n    self._execute(STORE_KV, (key, value))\n    ~~~~~~~~~~~~~^^^^^^^^^^^^^^^^^^^^^^^^\n  File "/home/mrigankp/fuzz4py/cpython/Lib/threading.py", line 1041, in _bootstrap_inner\n    self.run()\n    ~~~~~~~~^^\nsqlite3.ProgrammingError: SQLite objects created in a thread can only be used in that same thread. The object was created in thread id 124364096350016 and this is thread id 124361715484224.\n  File "/home/mrigankp/fuzz4py/cpython/Lib/dbm/sqlite3.py", line 81, in _execute\n    raise error(str(exc))\n  File "/home/mrigankp/fuzz4py/fuzz4py/inputs/790.py", line 15, in worker\n    db[str(data)] = data * 2\n    ~~^^^^^^^^^^^\n  File "/home/mrigankp/fuzz4py/fuzz4py/inputs/790.py", line 15, in worker\n    db[str(data)] = data * 2\n    ~~^^^^^^^^^^^\n\nDuring handling of the above exception, another exception occurred:\n\n  File "/home/mrigankp/fuzz4py/cpython/Lib/dbm/sqlite3.py", line 96, in __setitem__\n    self._execute(STORE_KV, (key, value))\n    ~~~~~~~~~~~~~^^^^^^^^^^^^^^^^^^^^^^^^\nsqlite3.ProgrammingError: SQLite objects created in a thread can only be used in that same thread. The object was created in thread id 124364096350016 and this is thread id 124362118137408.\n  File "/home/mrigankp/fuzz4py/cpython/Lib/threading.py", line 992, in run\n    self._target(*self._args, **self._kwargs)\n    ~~~~~~~~~~~~^^^^^^^^^^^^^^^^^^^^^^^^^^^^^\n  File "/home/mrigankp/fuzz4py/fuzz4py/inputs/790.py", line 15, in worker\n    db[str(data)] = data * 2\n    ~~^^^^^^^^^^^\n  File "/home/mrigankp/fuzz4py/cpython/Lib/dbm/sqlite3.py", line 96, in __setitem__\n    self._execute(STORE_KV, (key, value))\n    ~~~~~~~~~~~~~^^^^^^^^^^^^^^^^^^^^^^^^\n  File "/home/mrigankp/fuzz4py/cpython/Lib/dbm/sqlite3.py", line 81, in _execute\n    raise error(str(exc))\n  File "/home/mrigankp/fuzz4py/cpython/Lib/dbm/sqlite3.py", line 81, in _execute\n    raise error(str(exc))\n  File "/home/mrigankp/fuzz4py/cpython/Lib/threading.py", line 1041, in _bootstrap_inner\n    self.run()\n    ~~~~~~~~^^\n  File "/home/mrigankp/fuzz4py/cpython/Lib/threading.py", line 1041, in _bootstrap_inner\n    self.run()\n    ~~~~~~~~^^\n  File "/home/mrigankp/fuzz4py/cpython/Lib/threading.py", line 992, in run\n    self._target(*self._args, **self._kwargs)\n    ~~~~~~~~~~~~^^^^^^^^^^^^^^^^^^^^^^^^^^^^^\nsqlite3.ProgrammingError: SQLite objects created in a thread can only be used in that same thread. The object was created in thread id 124364096350016 and this is thread id 124361684026944.\nTraceback (most recent call last):\n  File "/home/mrigankp/fuzz4py/cpython/Lib/dbm/sqlite3.py", line 96, in __setitem__\n    self._execute(STORE_KV, (key, value))\n    ~~~~~~~~~~~~~^^^^^^^^^^^^^^^^^^^^^^^^\n  File "/home/mrigankp/fuzz4py/fuzz4py/inputs/790.py", line 15, in worker\n    db[str(data)] = data * 2\n    ~~^^^^^^^^^^^\n  File "/home/mrigankp/fuzz4py/cpython/Lib/threading.py", line 992, in run\n    self._target(*self._args, **self._kwargs)\n    ~~~~~~~~~~~~^^^^^^^^^^^^^^^^^^^^^^^^^^^^^\ndbm.sqlite3.error: SQLite objects created in a thread can only be used in that same thread. The object was created in thread id 124364096350016 and this is thread id 124362520790592.\n  File "/home/mrigankp/fuzz4py/cpython/Lib/dbm/sqlite3.py", line 81, in _execute\n    raise error(str(exc))\n  File "/home/mrigankp/fuzz4py/cpython/Lib/dbm/sqlite3.py", line 81, in _execute\n    raise error(str(exc))\n  File "/home/mrigankp/fuzz4py/fuzz4py/inputs/790.py", line 15, in worker\n    db[str(data)] = data * 2\n    ~~^^^^^^^^^^^\n  File "/home/mrigankp/fuzz4py/cpython/Lib/threading.py", line 992, in run\n    self._target(*self._args, **self._kwargs)\n    ~~~~~~~~~~~~^^^^^^^^^^^^^^^^^^^^^^^^^^^^^\n  File "/home/mrigankp/fuzz4py/cpython/Lib/threading.py", line 1041, in _bootstrap_inner\n    self.run()\n    ~~~~~~~~^^\n  File "/home/mrigankp/fuzz4py/fuzz4py/inputs/790.py", line 15, in worker\n    db[str(data)] = data * 2\n    ~~^^^^^^^^^^^\n  File "/home/mrigankp/fuzz4py/cpython/Lib/dbm/sqlite3.py", line 96, in __setitem__\n    self._execute(STORE_KV, (key, value))\n    ~~~~~~~~~~~~~^^^^^^^^^^^^^^^^^^^^^^^^\n  File "/home/mrigankp/fuzz4py/fuzz4py/inputs/790.py", line 15, in worker\n    db[str(data)] = data * 2\n    ~~^^^^^^^^^^^\n  File "/home/mrigankp/fuzz4py/cpython/Lib/threading.py", line 1041, in _bootstrap_inner\n    self.run()\n    ~~~~~~~~^^\ndbm.sqlite3.error: SQLite objects created in a thread can only be used in that same thread. The object was created in thread id 124364096350016 and this is thread id 124362478847552.\n  File "/home/mrigankp/fuzz4py/fuzz4py/inputs/790.py", line 15, in worker\n    db[str(data)] = data * 2\n    ~~^^^^^^^^^^^\n  File "/home/mrigankp/fuzz4py/cpython/Lib/threading.py", line 1041, in _bootstrap_inner\n    self.run()\n    ~~~~~~~~^^\n\nDuring handling of the above exception, another exception occurred:\n\n  File "/home/mrigankp/fuzz4py/fuzz4py/inputs/790.py", line 15, in worker\n    db[str(data)] = data * 2\n    ~~^^^^^^^^^^^\n  File "/home/mrigankp/fuzz4py/fuzz4py/inputs/790.py", line 15, in worker\n    db[str(data)] = data * 2\n    ~~^^^^^^^^^^^\n  File "/home/mrigankp/fuzz4py/cpython/Lib/dbm/sqlite3.py", line 96, in __setitem__\n    self._execute(STORE_KV, (key, value))\n    ~~~~~~~~~~~~~^^^^^^^^^^^^^^^^^^^^^^^^\n  File "/home/mrigankp/fuzz4py/fuzz4py/inputs/790.py", line 15, in worker\n    db[str(data)] = data * 2\n    ~~^^^^^^^^^^^\n  File "/home/mrigankp/fuzz4py/cpython/Lib/dbm/sqlite3.py", line 81, in _execute\n    raise error(str(exc))\ndbm.sqlite3.error: SQLite objects created in a thread can only be used in that same thread. The object was created in thread id 124364096350016 and this is thread id 124363888133696.\n  File "/home/mrigankp/fuzz4py/cpython/Lib/dbm/sqlite3.py", line 81, in _execute\n    raise error(str(exc))\n  File "/home/mrigankp/fuzz4py/cpython/Lib/threading.py", line 992, in run\n    self._target(*self._args, **self._kwargs)\n    ~~~~~~~~~~~~^^^^^^^^^^^^^^^^^^^^^^^^^^^^^\n  File "/home/mrigankp/fuzz4py/fuzz4py/inputs/790.py", line 15, in worker\n    db[str(data)] = data * 2\n    ~~^^^^^^^^^^^\n\nDuring handling of the above exception, another exception occurred:\n\ndbm.sqlite3.error: SQLite objects created in a thread can only be used in that same thread. The object was created in thread id 124364096350016 and this is thread id 124362680174144.\n  File "/home/mrigankp/fuzz4py/cpython/Lib/dbm/sqlite3.py", line 96, in __setitem__\n    self._execute(STORE_KV, (key, value))\n    ~~~~~~~~~~~~~^^^^^^^^^^^^^^^^^^^^^^^^\n  File "/home/mrigankp/fuzz4py/cpython/Lib/dbm/sqlite3.py", line 96, in __setitem__\n    self._execute(STORE_KV, (key, value))\n    ~~~~~~~~~~~~~^^^^^^^^^^^^^^^^^^^^^^^^\n  File "/home/mrigankp/fuzz4py/cpython/Lib/threading.py", line 992, in run\n    self._target(*self._args, **self._kwargs)\n    ~~~~~~~~~~~~^^^^^^^^^^^^^^^^^^^^^^^^^^^^^\n  File "/home/mrigankp/fuzz4py/cpython/Lib/dbm/sqlite3.py", line 81, in _execute\n    raise error(str(exc))\n  File "/home/mrigankp/fuzz4py/fuzz4py/inputs/790.py", line 15, in worker\n    db[str(data)] = data * 2\n    ~~^^^^^^^^^^^\n  File "/home/mrigankp/fuzz4py/fuzz4py/inputs/790.py", line 15, in worker\n    db[str(data)] = data * 2\n    ~~^^^^^^^^^^^\ndbm.sqlite3.error: SQLite objects created in a thread can only be used in that same thread. The object was created in thread id 124364096350016 and this is thread id 124364062197312.\n  File "/home/mrigankp/fuzz4py/cpython/Lib/threading.py", line 992, in run\n    self._target(*self._args, **self._kwargs)\n    ~~~~~~~~~~~~^^^^^^^^^^^^^^^^^^^^^^^^^^^^^\n  File "/home/mrigankp/fuzz4py/cpython/Lib/dbm/sqlite3.py", line 96, in __setitem__\n    self._execute(STORE_KV, (key, value))\n    ~~~~~~~~~~~~~^^^^^^^^^^^^^^^^^^^^^^^^\ndbm.sqlite3.error: SQLite objects created in a thread can only be used in that same thread. The object was created in thread id 124364096350016 and this is thread id 124363103798848.\ndbm.sqlite3.error: SQLite objects created in a thread can only be used in that same thread. The object was created in thread id 124364096350016 and this is thread id 124361704998464.\nTraceback (most recent call last):\n  File "/home/mrigankp/fuzz4py/fuzz4py/inputs/790.py", line 15, in worker\n    db[str(data)] = data * 2\n    ~~^^^^^^^^^^^\n\nDuring handling of the above exception, another exception occurred:\n\n  File "/home/mrigankp/fuzz4py/cpython/Lib/threading.py", line 1041, in _bootstrap_inner\n    self.run()\n    ~~~~~~~~^^\n  File "/home/mrigankp/fuzz4py/cpython/Lib/dbm/sqlite3.py", line 81, in _execute\n    raise error(str(exc))\n  File "/home/mrigankp/fuzz4py/cpython/Lib/dbm/sqlite3.py", line 96, in __setitem__\n    self._execute(STORE_KV, (key, value))\n    ~~~~~~~~~~~~~^^^^^^^^^^^^^^^^^^^^^^^^\n  File "/home/mrigankp/fuzz4py/fuzz4py/inputs/790.py", line 15, in worker\n    db[str(data)] = data * 2\n    ~~^^^^^^^^^^^\nTraceback (most recent call last):\ndbm.sqlite3.error: SQLite objects created in a thread can only be used in that same thread. The object was created in thread id 124364096350016 and this is thread id 124362499819072.\n  File "/home/mrigankp/fuzz4py/cpython/Lib/dbm/sqlite3.py", line 96, in __setitem__\n    self._execute(STORE_KV, (key, value))\n    ~~~~~~~~~~~~~^^^^^^^^^^^^^^^^^^^^^^^^\n  File "/home/mrigankp/fuzz4py/fuzz4py/inputs/790.py", line 15, in worker\n    db[str(data)] = data * 2\n    ~~^^^^^^^^^^^\n  File "/home/mrigankp/fuzz4py/cpython/Lib/threading.py", line 992, in run\n    self._target(*self._args, **self._kwargs)\n    ~~~~~~~~~~~~^^^^^^^^^^^^^^^^^^^^^^^^^^^^^\n  File "/home/mrigankp/fuzz4py/cpython/Lib/dbm/sqlite3.py", line 96, in __setitem__\n    self._execute(STORE_KV, (key, value))\n    ~~~~~~~~~~~~~^^^^^^^^^^^^^^^^^^^^^^^^\n  File "/home/mrigankp/fuzz4py/fuzz4py/inputs/790.py", line 15, in worker\n    db[str(data)] = data * 2\n    ~~^^^^^^^^^^^\nTraceback (most recent call last):\n  File "/home/mrigankp/fuzz4py/cpython/Lib/threading.py", line 992, in run\n    self._target(*self._args, **self._kwargs)\n    ~~~~~~~~~~~~^^^^^^^^^^^^^^^^^^^^^^^^^^^^^\n  File "/home/mrigankp/fuzz4py/fuzz4py/inputs/790.py", line 15, in worker\n    db[str(data)] = data * 2\n    ~~^^^^^^^^^^^\n  File "/home/mrigankp/fuzz4py/fuzz4py/inputs/790.py", line 15, in worker\n    db[str(data)] = data * 2\n    ~~^^^^^^^^^^^\n  File "/home/mrigankp/fuzz4py/fuzz4py/inputs/790.py", line 15, in worker\n    db[str(data)] = data * 2\n    ~~^^^^^^^^^^^\n  File "/home/mrigankp/fuzz4py/cpython/Lib/dbm/sqlite3.py", line 96, in __setitem__\n    self._execute(STORE_KV, (key, value))\n    ~~~~~~~~~~~~~^^^^^^^^^^^^^^^^^^^^^^^^\nTraceback (most recent call last):\nTraceback (most recent call last):\n  File "/home/mrigankp/fuzz4py/fuzz4py/inputs/790.py", line 15, in worker\n    db[str(data)] = data * 2\n    ~~^^^^^^^^^^^\n  File "/home/mrigankp/fuzz4py/cpython/Lib/dbm/sqlite3.py", line 96, in __setitem__\n    self._execute(STORE_KV, (key, value))\n    ~~~~~~~~~~~~~^^^^^^^^^^^^^^^^^^^^^^^^\ndbm.sqlite3.error: SQLite objects created in a thread can only be used in that same thread. The object was created in thread id 124364096350016 and this is thread id 124362701145664.\n  File "/home/mrigankp/fuzz4py/fuzz4py/inputs/790.py", line 15, in worker\n    db[str(data)] = data * 2\n    ~~^^^^^^^^^^^\n  File "/home/mrigankp/fuzz4py/fuzz4py/inputs/790.py", line 15, in worker\n    db[str(data)] = data * 2\n    ~~^^^^^^^^^^^\n  File "/home/mrigankp/fuzz4py/fuzz4py/inputs/790.py", line 15, in worker\n    db[str(data)] = data * 2\n    ~~^^^^^^^^^^^\n  File "/home/mrigankp/fuzz4py/cpython/Lib/dbm/sqlite3.py", line 96, in __setitem__\n    self._execute(STORE_KV, (key, value))\n    ~~~~~~~~~~~~~^^^^^^^^^^^^^^^^^^^^^^^^\nTraceback (most recent call last):\n  File "/home/mrigankp/fuzz4py/cpython/Lib/dbm/sqlite3.py", line 81, in _execute\n    raise error(str(exc))\n  File "/home/mrigankp/fuzz4py/cpython/Lib/dbm/sqlite3.py", line 96, in __setitem__\n    self._execute(STORE_KV, (key, value))\n    ~~~~~~~~~~~~~^^^^^^^^^^^^^^^^^^^^^^^^\n  File "/home/mrigankp/fuzz4py/cpython/Lib/dbm/sqlite3.py", line 81, in _execute\n    raise error(str(exc))\n\nDuring handling of the above exception, another exception occurred:\n\ndbm.sqlite3.error: SQLite objects created in a thread can only be used in that same thread. The object was created in thread id 124364096350016 and this is thread id 124363114284608.\n  File "/home/mrigankp/fuzz4py/cpython/Lib/dbm/sqlite3.py", line 96, in __setitem__\n    self._execute(STORE_KV, (key, value))\n    ~~~~~~~~~~~~~^^^^^^^^^^^^^^^^^^^^^^^^\n  File "/home/mrigankp/fuzz4py/cpython/Lib/dbm/sqlite3.py", line 96, in __setitem__\n    self._execute(STORE_KV, (key, value))\n    ~~~~~~~~~~~~~^^^^^^^^^^^^^^^^^^^^^^^^\ndbm.sqlite3.error: SQLite objects created in a thread can only be used in that same thread. The object was created in thread id 124364096350016 and this is thread id 124363707778624.\n  File "/home/mrigankp/fuzz4py/cpython/Lib/threading.py", line 992, in run\n    self._target(*self._args, **self._kwargs)\n    ~~~~~~~~~~~~^^^^^^^^^^^^^^^^^^^^^^^^^^^^^\n  File "/home/mrigankp/fuzz4py/cpython/Lib/threading.py", line 992, in run\n    self._target(*self._args, **self._kwargs)\n    ~~~~~~~~~~~~^^^^^^^^^^^^^^^^^^^^^^^^^^^^^\n  File "/home/mrigankp/fuzz4py/fuzz4py/inputs/790.py", line 15, in worker\n    db[str(data)] = data * 2\n    ~~^^^^^^^^^^^\n  File "/home/mrigankp/fuzz4py/cpython/Lib/dbm/sqlite3.py", line 96, in __setitem__\n    self._execute(STORE_KV, (key, value))\n    ~~~~~~~~~~~~~^^^^^^^^^^^^^^^^^^^^^^^^\n  File "/home/mrigankp/fuzz4py/cpython/Lib/threading.py", line 1041, in _bootstrap_inner\n    self.run()\n    ~~~~~~~~^^\n  File "/home/mrigankp/fuzz4py/cpython/Lib/threading.py", line 992, in run\n    self._target(*self._args, **self._kwargs)\n    ~~~~~~~~~~~~^^^^^^^^^^^^^^^^^^^^^^^^^^^^^\nTraceback (most recent call last):\n  File "/home/mrigankp/fuzz4py/cpython/Lib/dbm/sqlite3.py", line 81, in _execute\n    raise error(str(exc))\ndbm.sqlite3.error: SQLite objects created in a thread can only be used in that same thread. The object was created in thread id 124364096350016 and this is thread id 124364051711552.\n\nDuring handling of the above exception, another exception occurred:\n\n  File "/home/mrigankp/fuzz4py/cpython/Lib/dbm/sqlite3.py", line 81, in _execute\n    raise error(str(exc))\n  File "/home/mrigankp/fuzz4py/cpython/Lib/dbm/sqlite3.py", line 96, in __setitem__\n    self._execute(STORE_KV, (key, value))\n    ~~~~~~~~~~~~~^^^^^^^^^^^^^^^^^^^^^^^^\n  File "/home/mrigankp/fuzz4py/fuzz4py/inputs/790.py", line 15, in worker\n    db[str(data)] = data * 2\n    ~~^^^^^^^^^^^\n  File "/home/mrigankp/fuzz4py/cpython/Lib/dbm/sqlite3.py", line 81, in _execute\n    raise error(str(exc))\n  File "/home/mrigankp/fuzz4py/cpython/Lib/dbm/sqlite3.py", line 96, in __setitem__\n    self._execute(STORE_KV, (key, value))\n    ~~~~~~~~~~~~~^^^^^^^^^^^^^^^^^^^^^^^^\n  File "/home/mrigankp/fuzz4py/cpython/Lib/dbm/sqlite3.py", line 81, in _execute\n    raise error(str(exc))\n  File "/home/mrigankp/fuzz4py/cpython/Lib/dbm/sqlite3.py", line 81, in _execute\n    raise error(str(exc))\n  File "/home/mrigankp/fuzz4py/fuzz4py/inputs/790.py", line 15, in worker\n    db[str(data)] = data * 2\n    ~~^^^^^^^^^^^\n  File "/home/mrigankp/fuzz4py/cpython/Lib/dbm/sqlite3.py", line 96, in __setitem__\n    self._execute(STORE_KV, (key, value))\n    ~~~~~~~~~~~~~^^^^^^^^^^^^^^^^^^^^^^^^\n  File "/home/mrigankp/fuzz4py/cpython/Lib/dbm/sqlite3.py", line 96, in __setitem__\n    self._execute(STORE_KV, (key, value))\n    ~~~~~~~~~~~~~^^^^^^^^^^^^^^^^^^^^^^^^\n  File "/home/mrigankp/fuzz4py/cpython/Lib/threading.py", line 992, in run\n    self._target(*self._args, **self._kwargs)\n    ~~~~~~~~~~~~^^^^^^^^^^^^^^^^^^^^^^^^^^^^^\n  File "/home/mrigankp/fuzz4py/cpython/Lib/dbm/sqlite3.py", line 81, in _execute\n    raise error(str(exc))\n  File "/home/mrigankp/fuzz4py/cpython/Lib/dbm/sqlite3.py", line 96, in __setitem__\n    self._execute(STORE_KV, (key, value))\n    ~~~~~~~~~~~~~^^^^^^^^^^^^^^^^^^^^^^^^\n  File "/home/mrigankp/fuzz4py/cpython/Lib/threading.py", line 1041, in _bootstrap_inner\n    self.run()\n    ~~~~~~~~^^\n  File "/home/mrigankp/fuzz4py/cpython/Lib/dbm/sqlite3.py", line 96, in __setitem__\n    self._execute(STORE_KV, (key, value))\n    ~~~~~~~~~~~~~^^^^^^^^^^^^^^^^^^^^^^^^\ndbm.sqlite3.error: SQLite objects created in a thread can only be used in that same thread. The object was created in thread id 124364096350016 and this is thread id 124361906325056.\n  File "/home/mrigankp/fuzz4py/cpython/Lib/dbm/sqlite3.py", line 81, in _execute\n    raise error(str(exc))\n  File "/home/mrigankp/fuzz4py/cpython/Lib/dbm/sqlite3.py", line 96, in __setitem__\n    self._execute(STORE_KV, (key, value))\n    ~~~~~~~~~~~~~^^^^^^^^^^^^^^^^^^^^^^^^\n  File "/home/mrigankp/fuzz4py/cpython/Lib/dbm/sqlite3.py", line 96, in __setitem__\n    self._execute(STORE_KV, (key, value))\n    ~~~~~~~~~~~~~^^^^^^^^^^^^^^^^^^^^^^^^\n  File "/home/mrigankp/fuzz4py/cpython/Lib/dbm/sqlite3.py", line 96, in __setitem__\n    self._execute(STORE_KV, (key, value))\n    ~~~~~~~~~~~~~^^^^^^^^^^^^^^^^^^^^^^^^\ndbm.sqlite3.error: SQLite objects created in a thread can only be used in that same thread. The object was created in thread id 124364096350016 and this is thread id 124363686807104.\nTraceback (most recent call last):\ndbm.sqlite3.error: SQLite objects created in a thread can only be used in that same thread. The object was created in thread id 124364096350016 and this is thread id 124363273668160.\n  File "/home/mrigankp/fuzz4py/fuzz4py/inputs/790.py", line 15, in worker\n    db[str(data)] = data * 2\n    ~~^^^^^^^^^^^\n  File "/home/mrigankp/fuzz4py/cpython/Lib/dbm/sqlite3.py", line 81, in _execute\n    raise error(str(exc))\n  File "/home/mrigankp/fuzz4py/cpython/Lib/dbm/sqlite3.py", line 81, in _execute\n    raise error(str(exc))\n  File "/home/mrigankp/fuzz4py/fuzz4py/inputs/790.py", line 15, in worker\n    db[str(data)] = data * 2\n    ~~^^^^^^^^^^^\n  File "/home/mrigankp/fuzz4py/fuzz4py/inputs/790.py", line 15, in worker\n    db[str(data)] = data * 2\n    ~~^^^^^^^^^^^\n  File "/home/mrigankp/fuzz4py/fuzz4py/inputs/790.py", line 15, in worker\n    db[str(data)] = data * 2\n    ~~^^^^^^^^^^^\n  File "/home/mrigankp/fuzz4py/cpython/Lib/threading.py", line 1041, in _bootstrap_inner\n    self.run()\n    ~~~~~~~~^^\n  File "/home/mrigankp/fuzz4py/cpython/Lib/dbm/sqlite3.py", line 81, in _execute\n    raise error(str(exc))\ndbm.sqlite3.error: SQLite objects created in a thread can only be used in that same thread. The object was created in thread id 124364096350016 and this is thread id 124363506452032.\n  File "/home/mrigankp/fuzz4py/fuzz4py/inputs/790.py", line 15, in worker\n    db[str(data)] = data * 2\n    ~~^^^^^^^^^^^\n  File "/home/mrigankp/fuzz4py/cpython/Lib/dbm/sqlite3.py", line 96, in __setitem__\n    self._execute(STORE_KV, (key, value))\n    ~~~~~~~~~~~~~^^^^^^^^^^^^^^^^^^^^^^^^\n  File "/home/mrigankp/fuzz4py/fuzz4py/inputs/790.py", line 15, in worker\n    db[str(data)] = data * 2\n    ~~^^^^^^^^^^^\ndbm.sqlite3.error: SQLite objects created in a thread can only be used in that same thread. The object was created in thread id 124364096350016 and this is thread id 124362510304832.\nTraceback (most recent call last):\n  File "/home/mrigankp/fuzz4py/cpython/Lib/dbm/sqlite3.py", line 81, in _execute\n    raise error(str(exc))\ndbm.sqlite3.error: SQLite objects created in a thread can only be used in that same thread. The object was created in thread id 124364096350016 and this is thread id 124362881500736.\n  File "/home/mrigankp/fuzz4py/cpython/Lib/dbm/sqlite3.py", line 81, in _execute\n    raise error(str(exc))\n  File "/home/mrigankp/fuzz4py/cpython/Lib/dbm/sqlite3.py", line 96, in __setitem__\n    self._execute(STORE_KV, (key, value))\n    ~~~~~~~~~~~~~^^^^^^^^^^^^^^^^^^^^^^^^\ndbm.sqlite3.error: SQLite objects created in a thread can only be used in that same thread. The object was created in thread id 124364096350016 and this is thread id 124361493186112.\n  File "/home/mrigankp/fuzz4py/cpython/Lib/threading.py", line 1041, in _bootstrap_inner\n    self.run()\n    ~~~~~~~~^^\ndbm.sqlite3.error: SQLite objects created in a thread can only be used in that same thread. The object was created in thread id 124364096350016 and this is thread id 124362107651648.\ndbm.sqlite3.error: SQLite objects created in a thread can only be used in that same thread. The object was created in thread id 124364096350016 and this is thread id 124363919590976.\n  File "/home/mrigankp/fuzz4py/cpython/Lib/threading.py", line 992, in run\n    self._target(*self._args, **self._kwargs)\n    ~~~~~~~~~~~~^^^^^^^^^^^^^^^^^^^^^^^^^^^^^\n  File "/home/mrigankp/fuzz4py/cpython/Lib/dbm/sqlite3.py", line 96, in __setitem__\n    self._execute(STORE_KV, (key, value))\n    ~~~~~~~~~~~~~^^^^^^^^^^^^^^^^^^^^^^^^\n  File "/home/mrigankp/fuzz4py/fuzz4py/inputs/790.py", line 15, in worker\n    db[str(data)] = data * 2\n    ~~^^^^^^^^^^^\ndbm.sqlite3.error: SQLite objects created in a thread can only be used in that same thread. The object was created in thread id 124364096350016 and this is thread id 124363072341568.\n  File "/home/mrigankp/fuzz4py/cpython/Lib/dbm/sqlite3.py", line 81, in _execute\n    raise error(str(exc))\n  File "/home/mrigankp/fuzz4py/cpython/Lib/threading.py", line 992, in run\n    self._target(*self._args, **self._kwargs)\n    ~~~~~~~~~~~~^^^^^^^^^^^^^^^^^^^^^^^^^^^^^\n  File "/home/mrigankp/fuzz4py/cpython/Lib/threading.py", line 1041, in _bootstrap_inner\n    self.run()\n    ~~~~~~~~^^\ndbm.sqlite3.error: SQLite objects created in a thread can only be used in that same thread. The object was created in thread id 124364096350016 and this is thread id 124363728750144.\n  File "/home/mrigankp/fuzz4py/cpython/Lib/dbm/sqlite3.py", line 96, in __setitem__\n    self._execute(STORE_KV, (key, value))\n    ~~~~~~~~~~~~~^^^^^^^^^^^^^^^^^^^^^^^^\n  File "/home/mrigankp/fuzz4py/fuzz4py/inputs/790.py", line 15, in worker\n    db[str(data)] = data * 2\n    ~~^^^^^^^^^^^\n  File "/home/mrigankp/fuzz4py/cpython/Lib/dbm/sqlite3.py", line 81, in _execute\n    raise error(str(exc))\n  File "/home/mrigankp/fuzz4py/cpython/Lib/dbm/sqlite3.py", line 81, in _execute\n    raise error(str(exc))\n  File "/home/mrigankp/fuzz4py/cpython/Lib/dbm/sqlite3.py", line 81, in _execute\n    raise error(str(exc))\n  File "/home/mrigankp/fuzz4py/fuzz4py/inputs/790.py", line 15, in worker\n    db[str(data)] = data * 2\n    ~~^^^^^^^^^^^\n  File "/home/mrigankp/fuzz4py/cpython/Lib/dbm/sqlite3.py", line 96, in __setitem__\n    self._execute(STORE_KV, (key, value))\n    ~~~~~~~~~~~~~^^^^^^^^^^^^^^^^^^^^^^^^\n  File "/home/mrigankp/fuzz4py/cpython/Lib/dbm/sqlite3.py", line 96, in __setitem__\n    self._execute(STORE_KV, (key, value))\n    ~~~~~~~~~~~~~^^^^^^^^^^^^^^^^^^^^^^^^\ndbm.sqlite3.error: SQLite objects created in a thread can only be used in that same thread. The object was created in thread id 124364096350016 and this is thread id 124362277520960.\n  File "/home/mrigankp/fuzz4py/cpython/Lib/dbm/sqlite3.py", line 81, in _execute\n    raise error(str(exc))\n  File "/home/mrigankp/fuzz4py/cpython/Lib/dbm/sqlite3.py", line 96, in __setitem__\n    self._execute(STORE_KV, (key, value))\n    ~~~~~~~~~~~~~^^^^^^^^^^^^^^^^^^^^^^^^\n  File "/home/mrigankp/fuzz4py/cpython/Lib/threading.py", line 1041, in _bootstrap_inner\n    self.run()\n    ~~~~~~~~^^\n  File "/home/mrigankp/fuzz4py/cpython/Lib/dbm/sqlite3.py", line 96, in __setitem__\n    self._execute(STORE_KV, (key, value))\n    ~~~~~~~~~~~~~^^^^^^^^^^^^^^^^^^^^^^^^\n  File "/home/mrigankp/fuzz4py/cpython/Lib/dbm/sqlite3.py", line 81, in _execute\n    raise error(str(exc))\nTraceback (most recent call last):\n  File "/home/mrigankp/fuzz4py/cpython/Lib/threading.py", line 992, in run\n    self._target(*self._args, **self._kwargs)\n    ~~~~~~~~~~~~^^^^^^^^^^^^^^^^^^^^^^^^^^^^^\n  File "/home/mrigankp/fuzz4py/fuzz4py/inputs/790.py", line 15, in worker\n    db[str(data)] = data * 2\n    ~~^^^^^^^^^^^\ndbm.sqlite3.error: SQLite objects created in a thread can only be used in that same thread. The object was created in thread id 124364096350016 and this is thread id 124363093313088.\n  File "/home/mrigankp/fuzz4py/cpython/Lib/threading.py", line 1041, in _bootstrap_inner\n    self.run()\n    ~~~~~~~~^^\n\nDuring handling of the above exception, another exception occurred:\n\ndbm.sqlite3.error: SQLite objects created in a thread can only be used in that same thread. The object was created in thread id 124364096350016 and this is thread id 124361514157632.\n  File "/home/mrigankp/fuzz4py/cpython/Lib/dbm/sqlite3.py", line 81, in _execute\n    raise error(str(exc))\n  File "/home/mrigankp/fuzz4py/cpython/Lib/dbm/sqlite3.py", line 81, in _execute\n    raise error(str(exc))\n  File "/home/mrigankp/fuzz4py/cpython/Lib/dbm/sqlite3.py", line 81, in _execute\n    raise error(str(exc))\n  File "/home/mrigankp/fuzz4py/cpython/Lib/dbm/sqlite3.py", line 81, in _execute\n    raise error(str(exc))\n  File "/home/mrigankp/fuzz4py/cpython/Lib/dbm/sqlite3.py", line 81, in _execute\n    raise error(str(exc))\n  File "/home/mrigankp/fuzz4py/cpython/Lib/dbm/sqlite3.py", line 96, in __setitem__\n    self._execute(STORE_KV, (key, value))\n    ~~~~~~~~~~~~~^^^^^^^^^^^^^^^^^^^^^^^^\n  File "/home/mrigankp/fuzz4py/cpython/Lib/dbm/sqlite3.py", line 96, in __setitem__\n    self._execute(STORE_KV, (key, value))\n    ~~~~~~~~~~~~~^^^^^^^^^^^^^^^^^^^^^^^^\n  File "/home/mrigankp/fuzz4py/cpython/Lib/threading.py", line 1041, in _bootstrap_inner\n    self.run()\n    ~~~~~~~~^^\ndbm.sqlite3.error: SQLite objects created in a thread can only be used in that same thread. The object was created in thread id 124364096350016 and this is thread id 124362722117184.\n  File "/home/mrigankp/fuzz4py/cpython/Lib/threading.py", line 992, in run\n    self._target(*self._args, **self._kwargs)\n    ~~~~~~~~~~~~^^^^^^^^^^^^^^^^^^^^^^^^^^^^^\n  File "/home/mrigankp/fuzz4py/cpython/Lib/dbm/sqlite3.py", line 81, in _execute\n    raise error(str(exc))\n  File "/home/mrigankp/fuzz4py/cpython/Lib/dbm/sqlite3.py", line 81, in _execute\n    raise error(str(exc))\n  File "/home/mrigankp/fuzz4py/cpython/Lib/threading.py", line 1041, in _bootstrap_inner\n    self.run()\n    ~~~~~~~~^^\ndbm.sqlite3.error: SQLite objects created in a thread can only be used in that same thread. The object was created in thread id 124364096350016 and this is thread id 124361864382016.\n  File "/home/mrigankp/fuzz4py/cpython/Lib/threading.py", line 1041, in _bootstrap_inner\n    self.run()\n    ~~~~~~~~^^\n  File "/home/mrigankp/fuzz4py/cpython/Lib/dbm/sqlite3.py", line 96, in __setitem__\n    self._execute(STORE_KV, (key, value))\n    ~~~~~~~~~~~~~^^^^^^^^^^^^^^^^^^^^^^^^\nTraceback (most recent call last):\ndbm.sqlite3.error: SQLite objects created in a thread can only be used in that same thread. The object was created in thread id 124364096350016 and this is thread id 124363516937792.\n  File "/home/mrigankp/fuzz4py/cpython/Lib/dbm/sqlite3.py", line 81, in _execute\n    raise error(str(exc))\n  File "/home/mrigankp/fuzz4py/cpython/Lib/dbm/sqlite3.py", line 81, in _execute\n    raise error(str(exc))\n  File "/home/mrigankp/fuzz4py/cpython/Lib/threading.py", line 992, in run\n    self._target(*self._args, **self._kwargs)\n    ~~~~~~~~~~~~^^^^^^^^^^^^^^^^^^^^^^^^^^^^^\n  File "/home/mrigankp/fuzz4py/cpython/Lib/threading.py", line 992, in run\n    self._target(*self._args, **self._kwargs)\n    ~~~~~~~~~~~~^^^^^^^^^^^^^^^^^^^^^^^^^^^^^\n  File "/home/mrigankp/fuzz4py/fuzz4py/inputs/790.py", line 15, in worker\n    db[str(data)] = data * 2\n    ~~^^^^^^^^^^^\n  File "/home/mrigankp/fuzz4py/cpython/Lib/threading.py", line 1041, in _bootstrap_inner\n    self.run()\n    ~~~~~~~~^^\n  File "/home/mrigankp/fuzz4py/cpython/Lib/dbm/sqlite3.py", line 96, in __setitem__\n    self._execute(STORE_KV, (key, value))\n    ~~~~~~~~~~~~~^^^^^^^^^^^^^^^^^^^^^^^^\n  File "/home/mrigankp/fuzz4py/cpython/Lib/dbm/sqlite3.py", line 81, in _execute\n    raise error(str(exc))\n  File "/home/mrigankp/fuzz4py/cpython/Lib/threading.py", line 1041, in _bootstrap_inner\n    self.run()\n    ~~~~~~~~^^\ndbm.sqlite3.error: SQLite objects created in a thread can only be used in that same thread. The object was created in thread id 124364096350016 and this is thread id 124362097165888.\n  File "/home/mrigankp/fuzz4py/fuzz4py/inputs/790.py", line 15, in worker\n    db[str(data)] = data * 2\n    ~~^^^^^^^^^^^\ndbm.sqlite3.error: SQLite objects created in a thread can only be used in that same thread. The object was created in thread id 124364096350016 and this is thread id 124361482700352.\n  File "/home/mrigankp/fuzz4py/cpython/Lib/dbm/sqlite3.py", line 96, in __setitem__\n    self._execute(STORE_KV, (key, value))\n    ~~~~~~~~~~~~~^^^^^^^^^^^^^^^^^^^^^^^^\n  File "/home/mrigankp/fuzz4py/cpython/Lib/dbm/sqlite3.py", line 96, in __setitem__\n    self._execute(STORE_KV, (key, value))\n    ~~~~~~~~~~~~~^^^^^^^^^^^^^^^^^^^^^^^^\ndbm.sqlite3.error: SQLite objects created in a thread can only be used in that same thread. The object was created in thread id 124364096350016 and this is thread id 124362468361792.\n  File "/home/mrigankp/fuzz4py/cpython/Lib/dbm/sqlite3.py", line 81, in _execute\n    raise error(str(exc))\n  File "/home/mrigankp/fuzz4py/cpython/Lib/dbm/sqlite3.py", line 81, in _execute\n    raise error(str(exc))\n  File "/home/mrigankp/fuzz4py/cpython/Lib/dbm/sqlite3.py", line 81, in _execute\n    raise error(str(exc))\n  File "/home/mrigankp/fuzz4py/cpython/Lib/threading.py", line 992, in run\n    self._target(*self._args, **self._kwargs)\n    ~~~~~~~~~~~~^^^^^^^^^^^^^^^^^^^^^^^^^^^^^\n  File "/home/mrigankp/fuzz4py/fuzz4py/inputs/790.py", line 15, in worker\n    db[str(data)] = data * 2\n    ~~^^^^^^^^^^^\ndbm.sqlite3.error: SQLite objects created in a thread can only be used in that same thread. The object was created in thread id 124364096350016 and this is thread id 124363315611200.\n  File "/home/mrigankp/fuzz4py/fuzz4py/inputs/790.py", line 15, in worker\n    db[str(data)] = data * 2\n    ~~^^^^^^^^^^^\n  File "/home/mrigankp/fuzz4py/cpython/Lib/dbm/sqlite3.py", line 96, in __setitem__\n    self._execute(STORE_KV, (key, value))\n    ~~~~~~~~~~~~~^^^^^^^^^^^^^^^^^^^^^^^^\ndbm.sqlite3.error: SQLite objects created in a thread can only be used in that same thread. The object was created in thread id 124364096350016 and this is thread id 124361874867776.\n  File "/home/mrigankp/fuzz4py/cpython/Lib/threading.py", line 992, in run\n    self._target(*self._args, **self._kwargs)\n    ~~~~~~~~~~~~^^^^^^^^^^^^^^^^^^^^^^^^^^^^^\ndbm.sqlite3.error: SQLite objects created in a thread can only be used in that same thread. The object was created in thread id 124364096350016 and this is thread id 124361895839296.\ndbm.sqlite3.error: SQLite objects created in a thread can only be used in that same thread. The object was created in thread id 124364096350016 and this is thread id 124362298492480.\n  File "/home/mrigankp/fuzz4py/cpython/Lib/dbm/sqlite3.py", line 81, in _execute\n    raise error(str(exc))\n  File "/home/mrigankp/fuzz4py/cpython/Lib/dbm/sqlite3.py", line 81, in _execute\n    raise error(str(exc))\n  File "/home/mrigankp/fuzz4py/cpython/Lib/threading.py", line 1041, in _bootstrap_inner\n    self.run()\n    ~~~~~~~~^^\ndbm.sqlite3.error: SQLite objects created in a thread can only be used in that same thread. The object was created in thread id 124364096350016 and this is thread id 124361090532928.\ndbm.sqlite3.error: SQLite objects created in a thread can only be used in that same thread. The object was created in thread id 124364096350016 and this is thread id 124362669688384.\ndbm.sqlite3.error: SQLite objects created in a thread can only be used in that same thread. The object was created in thread id 124364096350016 and this is thread id 124362267035200.\n  File "/home/mrigankp/fuzz4py/fuzz4py/inputs/790.py", line 15, in worker\n    db[str(data)] = data * 2\n    ~~^^^^^^^^^^^\ndbm.sqlite3.error: SQLite objects created in a thread can only be used in that same thread. The object was created in thread id 124364096350016 and this is thread id 124361080047168.\n  File "/home/mrigankp/fuzz4py/cpython/Lib/threading.py", line 1041, in _bootstrap_inner\n    self.run()\n    ~~~~~~~~^^\n  File "/home/mrigankp/fuzz4py/cpython/Lib/dbm/sqlite3.py", line 96, in __setitem__\n    self._execute(STORE_KV, (key, value))\n    ~~~~~~~~~~~~~^^^^^^^^^^^^^^^^^^^^^^^^\n  File "/home/mrigankp/fuzz4py/cpython/Lib/threading.py", line 992, in run\n    self._target(*self._args, **self._kwargs)\n    ~~~~~~~~~~~~^^^^^^^^^^^^^^^^^^^^^^^^^^^^^\n  File "/home/mrigankp/fuzz4py/cpython/Lib/threading.py", line 992, in run\n    self._target(*self._args, **self._kwargs)\n    ~~~~~~~~~~~~^^^^^^^^^^^^^^^^^^^^^^^^^^^^^\n  File "/home/mrigankp/fuzz4py/cpython/Lib/threading.py", line 1041, in _bootstrap_inner\n    self.run()\n    ~~~~~~~~^^\n  File "/home/mrigankp/fuzz4py/cpython/Lib/threading.py", line 992, in run\n    self._target(*self._args, **self._kwargs)\n    ~~~~~~~~~~~~^^^^^^^^^^^^^^^^^^^^^^^^^^^^^\ndbm.sqlite3.error: SQLite objects created in a thread can only be used in that same thread. The object was created in thread id 124364096350016 and this is thread id 124362871014976.\n  File "/home/mrigankp/fuzz4py/cpython/Lib/dbm/sqlite3.py", line 96, in __setitem__\n    self._execute(STORE_KV, (key, value))\n    ~~~~~~~~~~~~~^^^^^^^^^^^^^^^^^^^^^^^^\n  File "/home/mrigankp/fuzz4py/fuzz4py/inputs/790.py", line 15, in worker\n    db[str(data)] = data * 2\n    ~~^^^^^^^^^^^\n  File "/home/mrigankp/fuzz4py/cpython/Lib/dbm/sqlite3.py", line 81, in _execute\n    raise error(str(exc))\n  File "/home/mrigankp/fuzz4py/cpython/Lib/dbm/sqlite3.py", line 81, in _execute\n    raise error(str(exc))\ndbm.sqlite3.error: SQLite objects created in a thread can only be used in that same thread. The object was created in thread id 124364096350016 and this is thread id 124362711631424.\n  File "/home/mrigankp/fuzz4py/cpython/Lib/dbm/sqlite3.py", line 81, in _execute\n    raise error(str(exc))\ndbm.sqlite3.error: SQLite objects created in a thread can only be used in that same thread. The object was created in thread id 124364096350016 and this is thread id 124361312831040.\n  File "/home/mrigankp/fuzz4py/fuzz4py/inputs/790.py", line 15, in worker\n    db[str(data)] = data * 2\n    ~~^^^^^^^^^^^\ndbm.sqlite3.error: SQLite objects created in a thread can only be used in that same thread. The object was created in thread id 124364096350016 and this is thread id 124362690659904.\ndbm.sqlite3.error: SQLite objects created in a thread can only be used in that same thread. The object was created in thread id 124364096350016 and this is thread id 124361885353536.\n  File "/home/mrigankp/fuzz4py/cpython/Lib/threading.py", line 992, in run\n    self._target(*self._args, **self._kwargs)\n    ~~~~~~~~~~~~^^^^^^^^^^^^^^^^^^^^^^^^^^^^^\n  File "/home/mrigankp/fuzz4py/cpython/Lib/dbm/sqlite3.py", line 81, in _execute\n    raise error(str(exc))\ndbm.sqlite3.error: SQLite objects created in a thread can only be used in that same thread. The object was created in thread id 124364096350016 and this is thread id 124363485480512.\ndbm.sqlite3.error: SQLite objects created in a thread can only be used in that same thread. The object was created in thread id 124364096350016 and this is thread id 124363495966272.\n  File "/home/mrigankp/fuzz4py/cpython/Lib/threading.py", line 992, in run\n    self._target(*self._args, **self._kwargs)\n    ~~~~~~~~~~~~^^^^^^^^^^^^^^^^^^^^^^^^^^^^^\n  File "/home/mrigankp/fuzz4py/cpython/Lib/dbm/sqlite3.py", line 96, in __setitem__\n    self._execute(STORE_KV, (key, value))\n    ~~~~~~~~~~~~~^^^^^^^^^^^^^^^^^^^^^^^^\n  File "/home/mrigankp/fuzz4py/cpython/Lib/dbm/sqlite3.py", line 81, in _execute\n    raise error(str(exc))\ndbm.sqlite3.error: SQLite objects created in a thread can only be used in that same thread. The object was created in thread id 124364096350016 and this is thread id 124361069561408.\n  File "/home/mrigankp/fuzz4py/cpython/Lib/dbm/sqlite3.py", line 96, in __setitem__\n    self._execute(STORE_KV, (key, value))\n    ~~~~~~~~~~~~~^^^^^^^^^^^^^^^^^^^^^^^^\n  File "/home/mrigankp/fuzz4py/cpython/Lib/threading.py", line 992, in run\n    self._target(*self._args, **self._kwargs)\n    ~~~~~~~~~~~~^^^^^^^^^^^^^^^^^^^^^^^^^^^^^\n  File "/home/mrigankp/fuzz4py/cpython/Lib/dbm/sqlite3.py", line 81, in _execute\n    raise error(str(exc))\n  File "/home/mrigankp/fuzz4py/fuzz4py/inputs/790.py", line 15, in worker\n    db[str(data)] = data * 2\n    ~~^^^^^^^^^^^\ndbm.sqlite3.error: SQLite objects created in a thread can only be used in that same thread. The object was created in thread id 124364096350016 and this is thread id 124361059075648.\n  File "/home/mrigankp/fuzz4py/cpython/Lib/threading.py", line 992, in run\n    self._target(*self._args, **self._kwargs)\n    ~~~~~~~~~~~~^^^^^^^^^^^^^^^^^^^^^^^^^^^^^\n  File "/home/mrigankp/fuzz4py/fuzz4py/inputs/790.py", line 15, in worker\n    db[str(data)] = data * 2\n    ~~^^^^^^^^^^^\n  File "/home/mrigankp/fuzz4py/cpython/Lib/dbm/sqlite3.py", line 81, in _execute\n    raise error(str(exc))\n  File "/home/mrigankp/fuzz4py/cpython/Lib/dbm/sqlite3.py", line 96, in __setitem__\n    self._execute(STORE_KV, (key, value))\n    ~~~~~~~~~~~~~^^^^^^^^^^^^^^^^^^^^^^^^\ndbm.sqlite3.error: SQLite objects created in a thread can only be used in that same thread. The object was created in thread id 124364096350016 and this is thread id 124363909105216.\n  File "/home/mrigankp/fuzz4py/fuzz4py/inputs/790.py", line 15, in worker\n    db[str(data)] = data * 2\n    ~~^^^^^^^^^^^\n  File "/home/mrigankp/fuzz4py/cpython/Lib/dbm/sqlite3.py", line 81, in _execute\n    raise error(str(exc))\n  File "/home/mrigankp/fuzz4py/cpython/Lib/dbm/sqlite3.py", line 96, in __setitem__\n    self._execute(STORE_KV, (key, value))\n    ~~~~~~~~~~~~~^^^^^^^^^^^^^^^^^^^^^^^^\ndbm.sqlite3.error: SQLite objects created in a thread can only be used in that same thread. The object was created in thread id 124364096350016 and this is thread id 124361111504448.\ndbm.sqlite3.error: SQLite objects created in a thread can only be used in that same thread. The object was created in thread id 124364096350016 and this is thread id 124362891986496.\n  File "/home/mrigankp/fuzz4py/cpython/Lib/dbm/sqlite3.py", line 96, in __setitem__\n    self._execute(STORE_KV, (key, value))\n    ~~~~~~~~~~~~~^^^^^^^^^^^^^^^^^^^^^^^^\n  File "/home/mrigankp/fuzz4py/cpython/Lib/dbm/sqlite3.py", line 96, in __setitem__\n    self._execute(STORE_KV, (key, value))\n    ~~~~~~~~~~~~~^^^^^^^^^^^^^^^^^^^^^^^^\n  File "/home/mrigankp/fuzz4py/cpython/Lib/dbm/sqlite3.py", line 81, in _execute\n    raise error(str(exc))\nTraceback (most recent call last):\ndbm.sqlite3.error: SQLite objects created in a thread can only be used in that same thread. The object was created in thread id 124364096350016 and this is thread id 124360910177856.\n  File "/home/mrigankp/fuzz4py/cpython/Lib/dbm/sqlite3.py", line 96, in __setitem__\n    self._execute(STORE_KV, (key, value))\n    ~~~~~~~~~~~~~^^^^^^^^^^^^^^^^^^^^^^^^\n  File "/home/mrigankp/fuzz4py/cpython/Lib/threading.py", line 992, in run\n    self._target(*self._args, **self._kwargs)\n    ~~~~~~~~~~~~^^^^^^^^^^^^^^^^^^^^^^^^^^^^^\n  File "/home/mrigankp/fuzz4py/cpython/Lib/dbm/sqlite3.py", line 96, in __setitem__\n    self._execute(STORE_KV, (key, value))\n    ~~~~~~~~~~~~~^^^^^^^^^^^^^^^^^^^^^^^^\n  File "/home/mrigankp/fuzz4py/cpython/Lib/dbm/sqlite3.py", line 81, in _execute\n    raise error(str(exc))\ndbm.sqlite3.error: SQLite objects created in a thread can only be used in that same thread. The object was created in thread id 124364096350016 and this is thread id 124362076194368.\ndbm.sqlite3.error: SQLite objects created in a thread can only be used in that same thread. The object was created in thread id 124364096350016 and this is thread id 124362319464000.\n  File "/home/mrigankp/fuzz4py/cpython/Lib/dbm/sqlite3.py", line 96, in __setitem__\n    self._execute(STORE_KV, (key, value))\n    ~~~~~~~~~~~~~^^^^^^^^^^^^^^^^^^^^^^^^\ndbm.sqlite3.error: SQLite objects created in a thread can only be used in that same thread. The object was created in thread id 124364096350016 and this is thread id 124362308978240.\n  File "/home/mrigankp/fuzz4py/cpython/Lib/dbm/sqlite3.py", line 81, in _execute\n    raise error(str(exc))\n  File "/home/mrigankp/fuzz4py/fuzz4py/inputs/790.py", line 15, in worker\n    db[str(data)] = data * 2\n    ~~^^^^^^^^^^^\n  File "/home/mrigankp/fuzz4py/fuzz4py/inputs/790.py", line 15, in worker\n    db[str(data)] = data * 2\n    ~~^^^^^^^^^^^\n  File "/home/mrigankp/fuzz4py/cpython/Lib/dbm/sqlite3.py", line 96, in __setitem__\n    self._execute(STORE_KV, (key, value))\n    ~~~~~~~~~~~~~^^^^^^^^^^^^^^^^^^^^^^^^\n  File "/home/mrigankp/fuzz4py/cpython/Lib/dbm/sqlite3.py", line 81, in _execute\n    raise error(str(exc))\n  File "/home/mrigankp/fuzz4py/cpython/Lib/dbm/sqlite3.py", line 81, in _execute\n    raise error(str(exc))\n  File "/home/mrigankp/fuzz4py/fuzz4py/inputs/790.py", line 15, in worker\n    db[str(data)] = data * 2\n    ~~^^^^^^^^^^^\n  File "/home/mrigankp/fuzz4py/cpython/Lib/dbm/sqlite3.py", line 96, in __setitem__\n    self._execute(STORE_KV, (key, value))\n    ~~~~~~~~~~~~~^^^^^^^^^^^^^^^^^^^^^^^^\n  File "/home/mrigankp/fuzz4py/cpython/Lib/dbm/sqlite3.py", line 96, in __setitem__\n    self._execute(STORE_KV, (key, value))\n    ~~~~~~~~~~~~~^^^^^^^^^^^^^^^^^^^^^^^^\n  File "/home/mrigankp/fuzz4py/fuzz4py/inputs/790.py", line 15, in worker\n    db[str(data)] = data * 2\n    ~~^^^^^^^^^^^\n  File "/home/mrigankp/fuzz4py/fuzz4py/inputs/790.py", line 15, in worker\n    db[str(data)] = data * 2\n    ~~^^^^^^^^^^^\n  File "/home/mrigankp/fuzz4py/cpython/Lib/dbm/sqlite3.py", line 81, in _execute\n    raise error(str(exc))\n  File "/home/mrigankp/fuzz4py/cpython/Lib/dbm/sqlite3.py", line 81, in _execute\n    raise error(str(exc))\n  File "/home/mrigankp/fuzz4py/cpython/Lib/dbm/sqlite3.py", line 96, in __setitem__\n    self._execute(STORE_KV, (key, value))\n    ~~~~~~~~~~~~~^^^^^^^^^^^^^^^^^^^^^^^^\n  File "/home/mrigankp/fuzz4py/cpython/Lib/dbm/sqlite3.py", line 81, in _execute\n    raise error(str(exc))\ndbm.sqlite3.error: SQLite objects created in a thread can only be used in that same thread. The object was created in thread id 124364096350016 and this is thread id 124362912958016.\n  File "/home/mrigankp/fuzz4py/cpython/Lib/dbm/sqlite3.py", line 96, in __setitem__\n    self._execute(STORE_KV, (key, value))\n    ~~~~~~~~~~~~~^^^^^^^^^^^^^^^^^^^^^^^^\n  File "/home/mrigankp/fuzz4py/fuzz4py/inputs/790.py", line 15, in worker\n    db[str(data)] = data * 2\n    ~~^^^^^^^^^^^\ndbm.sqlite3.error: SQLite objects created in a thread can only be used in that same thread. The object was created in thread id 124364096350016 and this is thread id 124363326096960.\ndbm.sqlite3.error: SQLite objects created in a thread can only be used in that same thread. The object was created in thread id 124364096350016 and this is thread id 124361673541184.\ndbm.sqlite3.error: SQLite objects created in a thread can only be used in that same thread. The object was created in thread id 124364096350016 and this is thread id 124361663055424.\n  File "/home/mrigankp/fuzz4py/fuzz4py/inputs/790.py", line 15, in worker\n    db[str(data)] = data * 2\n    ~~^^^^^^^^^^^\n  File "/home/mrigankp/fuzz4py/cpython/Lib/dbm/sqlite3.py", line 96, in __setitem__\n    self._execute(STORE_KV, (key, value))\n    ~~~~~~~~~~~~~^^^^^^^^^^^^^^^^^^^^^^^^\n  File "/home/mrigankp/fuzz4py/cpython/Lib/dbm/sqlite3.py", line 81, in _execute\n    raise error(str(exc))\ndbm.sqlite3.error: SQLite objects created in a thread can only be used in that same thread. The object was created in thread id 124364096350016 and this is thread id 124363697292864.\n  File "/home/mrigankp/fuzz4py/cpython/Lib/dbm/sqlite3.py", line 96, in __setitem__\n    self._execute(STORE_KV, (key, value))\n    ~~~~~~~~~~~~~^^^^^^^^^^^^^^^^^^^^^^^^\ndbm.sqlite3.error: SQLite objects created in a thread can only be used in that same thread. The object was created in thread id 124364096350016 and this is thread id 124361916810816.\ndbm.sqlite3.error: SQLite objects created in a thread can only be used in that same thread. The object was created in thread id 124364096350016 and this is thread id 124363124770368.\ndbm.sqlite3.error: SQLite objects created in a thread can only be used in that same thread. The object was created in thread id 124364096350016 and this is thread id 124361302345280.\n  File "/home/mrigankp/fuzz4py/cpython/Lib/dbm/sqlite3.py", line 96, in __setitem__\n    self._execute(STORE_KV, (key, value))\n    ~~~~~~~~~~~~~^^^^^^^^^^^^^^^^^^^^^^^^\n  File "/home/mrigankp/fuzz4py/cpython/Lib/dbm/sqlite3.py", line 81, in _execute\n    raise error(str(exc))\n  File "/home/mrigankp/fuzz4py/cpython/Lib/dbm/sqlite3.py", line 81, in _execute\n    raise error(str(exc))\n  File "/home/mrigankp/fuzz4py/cpython/Lib/dbm/sqlite3.py", line 96, in __setitem__\n    self._execute(STORE_KV, (key, value))\n    ~~~~~~~~~~~~~^^^^^^^^^^^^^^^^^^^^^^^^\n  File "/home/mrigankp/fuzz4py/cpython/Lib/dbm/sqlite3.py", line 81, in _execute\n    raise error(str(exc))\n  File "/home/mrigankp/fuzz4py/cpython/Lib/dbm/sqlite3.py", line 96, in __setitem__\n    self._execute(STORE_KV, (key, value))\n    ~~~~~~~~~~~~~^^^^^^^^^^^^^^^^^^^^^^^^\n  File "/home/mrigankp/fuzz4py/cpython/Lib/dbm/sqlite3.py", line 81, in _execute\n    raise error(str(exc))\n  File "/home/mrigankp/fuzz4py/cpython/Lib/dbm/sqlite3.py", line 81, in _execute\n    raise error(str(exc))\n  File "/home/mrigankp/fuzz4py/cpython/Lib/dbm/sqlite3.py", line 81, in _execute\n    raise error(str(exc))\ndbm.sqlite3.error: SQLite objects created in a thread can only be used in that same thread. The object was created in thread id 124364096350016 and this is thread id 124363284153920.\n  File "/home/mrigankp/fuzz4py/cpython/Lib/dbm/sqlite3.py", line 81, in _execute\n    raise error(str(exc))\ndbm.sqlite3.error: SQLite objects created in a thread can only be used in that same thread. The object was created in thread id 124364096350016 and this is thread id 124362086680128.\n  File "/home/mrigankp/fuzz4py/cpython/Lib/dbm/sqlite3.py", line 81, in _execute\n    raise error(str(exc))\ndbm.sqlite3.error: SQLite objects created in a thread can only be used in that same thread. The object was created in thread id 124364096350016 and this is thread id 124361101018688.\ndbm.sqlite3.error: SQLite objects created in a thread can only be used in that same thread. The object was created in thread id 124364096350016 and this is thread id 124363898619456.\n  File "/home/mrigankp/fuzz4py/cpython/Lib/dbm/sqlite3.py", line 81, in _execute\n    raise error(str(exc))\n  File "/home/mrigankp/fuzz4py/cpython/Lib/dbm/sqlite3.py", line 81, in _execute\n    raise error(str(exc))\ndbm.sqlite3.error: SQLite objects created in a thread can only be used in that same thread. The object was created in thread id 124364096350016 and this is thread id 124361694512704.\n  File "/home/mrigankp/fuzz4py/cpython/Lib/dbm/sqlite3.py", line 81, in _execute\n    raise error(str(exc))\n  File "/home/mrigankp/fuzz4py/cpython/Lib/dbm/sqlite3.py", line 96, in __setitem__\n    self._execute(STORE_KV, (key, value))\n    ~~~~~~~~~~~~~^^^^^^^^^^^^^^^^^^^^^^^^\ndbm.sqlite3.error: SQLite objects created in a thread can only be used in that same thread. The object was created in thread id 124364096350016 and this is thread id 124363082827328.\n  File "/home/mrigankp/fuzz4py/cpython/Lib/dbm/sqlite3.py", line 81, in _execute\n    raise error(str(exc))\ndbm.sqlite3.error: SQLite objects created in a thread can only be used in that same thread. The object was created in thread id 124364096350016 and this is thread id 124361270888000.\ndbm.sqlite3.error: SQLite objects created in a thread can only be used in that same thread. The object was created in thread id 124364096350016 and this is thread id 124361715484224.\ndbm.sqlite3.error: SQLite objects created in a thread can only be used in that same thread. The object was created in thread id 124364096350016 and this is thread id 124363930076736.\ndbm.sqlite3.error: SQLite objects created in a thread can only be used in that same thread. The object was created in thread id 124364096350016 and this is thread id 124360899692096.\ndbm.sqlite3.error: SQLite objects created in a thread can only be used in that same thread. The object was created in thread id 124364096350016 and this is thread id 124361684026944.\n  File "/home/mrigankp/fuzz4py/cpython/Lib/dbm/sqlite3.py", line 81, in _execute\n    raise error(str(exc))\ndbm.sqlite3.error: SQLite objects created in a thread can only be used in that same thread. The object was created in thread id 124364096350016 and this is thread id 124361291859520.\ndbm.sqlite3.error: SQLite objects created in a thread can only be used in that same thread. The object was created in thread id 124364096350016 and this is thread id 124361260402240.\ndbm.sqlite3.error: SQLite objects created in a thread can only be used in that same thread. The object was created in thread id 124364096350016 and this is thread id 124360889206336.\ndbm.sqlite3.error: SQLite objects created in a thread can only be used in that same thread. The object was created in thread id 124364096350016 and this is thread id 124362065708608.\ndbm.sqlite3.error: SQLite objects created in a thread can only be used in that same thread. The object was created in thread id 124364096350016 and this is thread id 124361461728832.\ndbm.sqlite3.error: SQLite objects created in a thread can only be used in that same thread. The object was created in thread id 124364096350016 and this is thread id 124361281373760.\n  File "/home/mrigankp/fuzz4py/cpython/Lib/dbm/sqlite3.py", line 96, in __setitem__\n    self._execute(STORE_KV, (key, value))\n    ~~~~~~~~~~~~~^^^^^^^^^^^^^^^^^^^^^^^^\ndbm.sqlite3.error: SQLite objects created in a thread can only be used in that same thread. The object was created in thread id 124364096350016 and this is thread id 124361503671872.\ndbm.sqlite3.error: SQLite objects created in a thread can only be used in that same thread. The object was created in thread id 124364096350016 and this is thread id 124362118137408.\n  File "/home/mrigankp/fuzz4py/cpython/Lib/threading.py", line 1041, in _bootstrap_inner\n    self.run()\n    ~~~~~~~~^^\ndbm.sqlite3.error: SQLite objects created in a thread can only be used in that same thread. The object was created in thread id 124364096350016 and this is thread id 124364009768512.\n  File "/home/mrigankp/fuzz4py/cpython/Lib/dbm/sqlite3.py", line 81, in _execute\n    raise error(str(exc))\n  File "/home/mrigankp/fuzz4py/cpython/Lib/threading.py", line 992, in run\n    self._target(*self._args, **self._kwargs)\n    ~~~~~~~~~~~~^^^^^^^^^^^^^^^^^^^^^^^^^^^^^\ndbm.sqlite3.error: SQLite objects created in a thread can only be used in that same thread. The object was created in thread id 124364096350016 and this is thread id 124362288006720.\n  File "/home/mrigankp/fuzz4py/fuzz4py/inputs/790.py", line 15, in worker\n    db[str(data)] = data * 2\n    ~~^^^^^^^^^^^\n  File "/home/mrigankp/fuzz4py/cpython/Lib/dbm/sqlite3.py", line 96, in __setitem__\n    self._execute(STORE_KV, (key, value))\n    ~~~~~~~~~~~~~^^^^^^^^^^^^^^^^^^^^^^^^\n  File "/home/mrigankp/fuzz4py/cpython/Lib/dbm/sqlite3.py", line 81, in _execute\n    raise error(str(exc))\ndbm.sqlite3.error: SQLite objects created in a thread can only be used in that same thread. The object was created in thread id 124364096350016 and this is thread id 124361472214592.\n'
